Workbook
Name \a: #REF!
Name \b: #N/A
Name \g: #N/A
Name \n: #N/A
Name ________TGL1: #REF!
Name ________TGL2: #REF!
Name _______TGL1: #REF!
Name _______TGL2: #REF!
Name ______TGL1: #REF!
Name ______TGL2: #REF!
Name _____TGL1: #REF!
Name _____TGL2: #REF!
Name ____DAT1: #REF!
Name ____DAT10: #REF!
Name ____DAT11: #REF!
Name ____DAT12: #REF!
Name ____DAT13: #REF!
Name ____DAT14: #REF!
Name ____DAT15: #REF!
Name ____DAT16: #REF!
Name ____DAT17: #REF!
Name ____DAT18: #REF!
Name ____DAT19: #REF!
Name ____DAT2: #REF!
Name ____DAT20: #REF!
Name ____DAT3: #REF!
Name ____DAT4: #REF!
Name ____DAT5: #REF!
Name ____DAT6: #REF!
Name ____DAT7: #REF!
Name ____DAT8: #REF!
Name ____DAT9: #REF!
Name ____TGL1: #REF!
Name ____TGL2: #REF!
Name ___RSE2: '[1]CMA Addition'!$H$139
Name ___TGL1: #REF!
Name ___TGL2: #REF!
Name __COA08: [5]coa!$E$6:$E$944
Name __DAT1: #REF!
Name __DAT10: #REF!
Name __DAT11: #REF!
Name __DAT12: #REF!
Name __DAT13: #REF!
Name __DAT14: #REF!
Name __DAT15: #REF!
Name __DAT16: #REF!
Name __DAT17: #REF!
Name __DAT18: #REF!
Name __DAT19: #REF!
Name __DAT2: #REF!
Name __DAT20: #REF!
Name __DAT3: #REF!
Name __DAT4: #REF!
Name __DAT5: #REF!
Name __DAT6: #REF!
Name __DAT7: #REF!
Name __DAT8: #REF!
Name __DAT9: #REF!
Name __m70000: #REF!
Name __RSE1: '[1]CMA Addition'!$E$139

Sheet TB
C1: 2022 | E1: 2022 | G1: 2021 | I1: 2021 | K1: 2020 | M1: 2020
B2: Tanah | C2: 11934000000 | E2: =C2+D2 -> 11934000000 | G2: 11934000000 | I2: =G2+H2 -> 11934000000 | K2: 11934000000 | M2: =K2+L2 -> 11934000000
B3: Bangunan | C3: 24671108216 | E3: =C3+D3 -> 24671108216 | G3: 24671108216 | I3: =G3+H3 -> 24671108216 | K3: 14898332500 | M3: =K3+L3 -> 14898332500
B4: Mesin | C4: 12464903552 | E4: =C4+D4 -> 12464903552 | G4: 12427073552 | I4: =G4+H4 -> 12427073552 | K4: 12196073552 | M4: =K4+L4 -> 12196073552
B5: Kendaraan | C5: 1630238788 | E5: =C5+D5 -> 1630238788 | G5: 1431471000 | I5: =G5+H5 -> 1431471000 | K5: 1431471000 | M5: =K5+L5 -> 1431471000
B6: Kendaraan Alat Berat | C6: 545000000 | E6: =C6+D6 -> 545000000 | G6: 545000000 | I6: =G6+H6 -> 545000000 | K6: 545000000 | M6: =K6+L6 -> 545000000
B7: Peralatan Kantor | C7: 234184005 | E7: =C7+D7 -> 234184005 | G7: 229134005 | I7: =G7+H7 -> 229134005 | K7: 227534005 | M7: =K7+L7 -> 227534005
B8: Peralatan Produksi | C8: 1389452351 | E8: =C8+D8 -> 1389452351 | G8: 1371567751 | I8: =G8+H8 -> 1371567751 | K8: 1356328751 | M8: =K8+L8 -> 1356328751
B9: Sumur Bor | C9: 337941600 | E9: =C9+D9 -> 337941600 | G9: 337941600 | I9: =G9+H9 -> 337941600 | K9: 337941600 | M9: =K9+L9 -> 337941600
B10: Peralatan Labolatorium | C10: 112970000 | E10: =C10+D10 -> 112970000 | G10: 112970000 | I10: =G10+H10 -> 112970000 | K10: 112970000 | M10: =K10+L10 -> 112970000
C11: =SUM(C2:C10) -> 53319798512 | E11: =SUM(E2:E10) -> 53319798512 | G11: =SUM(G2:G10) -> 53060266124 | I11: =SUM(I2:I10) -> 53060266124 | K11: =SUM(K2:K10) -> 43039651408 | L11: =SUM(L2:L10) -> 0 | M11: =SUM(M2:M10) -> 43039651408
M12: =M11-'ADJ 2020'!F18 -> -4.1695423e+10
B14: Akum Peny. Bangunan | C14: 5887753759 | E14: =C14-D14 -> 5887753759 | G14: 4654194214 | H14: ='ADJ 2021'!G21 -> -2.6862994e+09 | I14: =G14-H14 -> 7.3404936e+09 | K14: 3909277573 | L14: ='ADJ 2020'!G21 -> -2.0223688e+09 | M14: =K14-L14 -> 5.9316464e+09
B15: Aum. Peny. Mesin | C15: 5321002979 | E15: =C15-D15 -> 5321002979 | G15: 4543719794 | H15: ='ADJ 2021'!G22 -> -1.0220462e+10 | I15: =G15-H15 -> 1.4764182e+10 | K15: 3779058952 | L15: ='ADJ 2020'!G22 -> -8.1596562e+09 | M15: =K15-L15 -> 1.1938715e+10
B16: Akum. Peny. Kendaraan | C16: 758337911 | E16: =C16-D16 -> 758337911 | G16: 575795564 | H16: ='ADJ 2021'!G23 -> -5728781936 | I16: =G16-H16 -> 6304577500 | K16: 396861684 | L16: ='ADJ 2020'!G23 -> -4865695816 | M16: =K16-L16 -> 5262557500
B17: Akum. Peny. Kendaraan Alat Berat | C17: 523581250 | E17: =C17-D17 -> 523581250 | G17: 467031250 | H17: ='ADJ 2021'!G24 -> 142467250 | I17: =G17-H17 -> 324564000 | K17: 398906250 | L17: ='ADJ 2020'!G24 -> 146956250 | M17: =K17-L17 -> 251950000
B18: Akum. Peny. Peralatan Kantor | C18: 202378387 | E18: =C18-D18 -> 202378387 | G18: 176328564 | H18: ='ADJ 2021'!G25 -> -9.1383662e+08 | I18: =G18-H18 -> 1.0901652e+09 | K18: 145371960 | L18: ='ADJ 2020'!G25 -> -8.6361391e+08 | M18: =K18-L18 -> 1.0089859e+09
B19: Akum. Peny. Peralatan Produksi | C19: 1323116936 | E19: =C19-D19 -> 1323116936 | G19: 1281284963 | H19: ='ADJ 2021'!G26 -> -6.440213e+09 | I19: =G19-H19 -> 7.7214979e+09 | K19: 1238393423 | L19: ='ADJ 2020'!G26 -> -5.1164124e+09 | M19: =K19-L19 -> 6.3548058e+09
B20: Akum. Peny. Sumur Bor | C20: 284202368 | E20: =C20-D20 -> 284202368 | G20: 247367639 | H20: ='ADJ 2021'!G27 -> -55558486 | I20: =G20-H20 -> 302926125 | K20: 205124939 | L20: ='ADJ 2020'!G27 -> -42168748 | M20: =K20-L20 -> 2.4729369e+08
B21: Akum. Peny. Peralatan Labolatorium | C21: 112970014 | E21: =C21-D21 -> 112970014 | G21: 96085012 | H21: ='ADJ 2021'!G28 -> -2.780119e+09 | I21: =G21-H21 -> 2.876204e+09 | K21: 67842508 | L21: ='ADJ 2020'!G28 -> -2.3111475e+09 | M21: =K21-L21 -> 2.37899e+09
C22: =SUM(C14:C21) -> 14413343604 | E22: =SUM(E14:E21) -> 14413343604 | G22: =SUM(G14:G21) -> 12041807000 | I22: =SUM(I14:I21) -> 4.072461e+10 | K22: =SUM(K14:K21) -> 10140837289 | L22: =SUM(L14:L21) -> -2.3234107e+10 | M22: =SUM(M14:M21) -> 3.3374944e+10
M23: =M22-'ADJ 2020'!F29 -> 0
B24: R/E | C24: 8151563821 | E24: =C24-D24 -> 8151563821 | G24: 2701171287 | I24: =G24-H24 -> 2701171287 | K24: 695537211 | L24: =-'ADJ 2020'!K38-'ADJ 2020'!K55 -> 1.7853017e+10 | M24: =K24-L24 -> -1.7157479e+10
B25: tahun berjalan | E25: =C25-D25 -> 0 | I25: =G25-H25 -> 0 | K25: 2005634076 | M25: =K25-L25 -> 2005634076
A27: COGS | B27: Depreciation | C27: 2328601782 | E27: =C27+D27 -> 2328601782 | G27: 1841766477 | I27: =G27+H27 -> 1841766477 | K27: 1216185335 | L27: =-'ADJ 2020'!G43 -> 4.319879e+09 | M27: =K27+L27 -> 5.5360643e+09
M28: =M27-'ADJ 2020'!F43 -> 0
A30: Opex | B30: Beban Depresiasi Dan Amortisasi | E30: =C30+D30 -> 0 | I30: =G30+H30 -> 0 | K30: 662689697 | L30: =-'ADJ 2020'!G44 -> -662689697 | M30: =K30+L30 -> 0
B31: Penyusutan Peralatan Kantor | C31: 26049820 | E31: =C31+D31 -> 26049820 | G31: 30960732 | I31: =G31+H31 -> 30960732 | L31: =-'ADJ 2020'!G45 -> 1.8287965e+08 | M31: =K31+L31 -> 1.8287965e+08
B32: Penyusutan Peralatan LAB | C32: 16885002 | E32: =C32+D32 -> 16885002 | G32: 28242504 | I32: =G32+H32 -> 28242504 | L32: =-'ADJ 2020'!G46 -> 4.9721397e+08 | M32: =K32+L32 -> 4.9721397e+08
B33: Penyusutan Kendaraan | E33: =C33+D33 -> 0 | I33: =G33+H33 -> 0 | L33: =-'ADJ 2020'!G47 -> 1043807500 | M33: =K33+L33 -> 1043807500
C34: =SUM(C30:C33) -> 42934822 | E34: =SUM(E30:E33) -> 42934822 | G34: =SUM(G30:G33) -> 59203236 | I34: =SUM(I30:I33) -> 59203236 | K34: =SUM(K30:K33) -> 662689697 | L34: =SUM(L30:L33) -> 1.0612114e+09 | M34: =SUM(M30:M33) -> 1.7239011e+09
C36: =C27+C34 -> 2371536604 | E36: =E27+E34 -> 2371536604 | G36: =G27+G34 -> 1900969713 | I36: =I27+I34 -> 1900969713 | K36: =K27+K34 -> 1878875032 | L36: =L27+L34 -> 5.3810904e+09 | M36: =K36+L36 -> 7.2599655e+09
M37: =M36-'ADJ 2020'!F48 -> 0

Sheet ADJ 2022
A1: Klien | C1: : | D1: PT. INDO AMERICAN SEAFOODS
A2: Tahun Buku | C2: : | D2: 31 Desember 2022
A3: Adjustment Audited
A5: No. | B5: No. Akun | C5: Jurnal | H5: Debit | I5: Kredit | J5: Efek Ke Neraca | M5: Efek ke LR | O5: Keterangan
J6: Debit | K6: Kredit | M6: Debit | N6: Kredit
A8: 1 | D8: Harga perolehan | E8: Inhouse | F8: Daftar Aset Tetap | G8: Selisih
D9: =TB!B2 -> Tanah | E9: =TB!C2 -> 11934000000 | F9: ='1. Tanah'!D4 -> 655809273 | G9: =E9-F9 -> 11278190727
D10: =TB!B3 -> Bangunan | E10: =TB!C3 -> 24671108216 | F10: ='2. Bangunan'!E128 -> 3.7188156e+10 | G10: =E10-F10 -> -1.2517048e+10
D11: =TB!B4 -> Mesin | E11: =TB!C4 -> 12464903552 | F11: ='5. Mesin'!E328 -> 3.7618136e+10 | G11: =E11-F11 -> -2.5153233e+10
D12: =TB!B5 -> Kendaraan | E12: =TB!C5 -> 1630238788 | F12: ='7. Kendaraan'!E81 -> 8342660000 | G12: =E12-F12 -> -6712421212
D13: =TB!B6 -> Kendaraan Alat Berat | E13: =TB!C6 -> 545000000 | F13: ='6. Instalasi Elektrik'!E55 -> 1452280000 | G13: =E13-F13 -> -907280000
D14: =TB!B7 -> Peralatan Kantor | E14: =TB!C7 -> 234184005 | F14: ='8 Peralatan & Perlengkapan'!E161 -> 1274154796 | G14: =E14-F14 -> -1039970791
D15: =TB!B8 -> Peralatan Produksi | E15: =TB!C8 -> 1389452351 | F15: ='9. Infrastruktur'!E62 -> 1.1170379e+10 | G15: =E15-F15 -> -9.7809271e+09
D16: =TB!B9 -> Sumur Bor | E16: =TB!C9 -> 337941600 | F16: ='3. Sumur Bor'!E53 -> 445059500 | G16: =E16-F16 -> -107117900
D17: =TB!B10 -> Peralatan Labolatorium | E17: =TB!C10 -> 112970000 | F17: ='4. Sarana & Prasarana'!E42 -> 6200217370 | G17: =E17-F17 -> -6087247370
E18: =SUM(E9:E17) -> 53319798512 | F18: =SUM(F9:F17) -> 1.0434685e+11
A20: 2 | D20: Akumulasi Penyusutan | E20: Inhouse | F20: Daftar Aset Tetap | G20: Selisih
D21: =TB!B14 -> Akum Peny. Bangunan | E21: =TB!C14 -> 5887753759 | F21: ='2. Bangunan'!AI115 -> 9.2122918e+09 | G21: =E21-F21 -> -3.324538e+09
D22: =TB!B15 -> Aum. Peny. Mesin | E22: =TB!C15 -> 5321002979 | F22: ='5. Mesin'!AH315 -> 1.8146072e+10 | G22: =E22-F22 -> -1.2825069e+10
D23: =TB!B16 -> Akum. Peny. Kendaraan | E23: =TB!C16 -> 758337911 | F23: ='7. Kendaraan'!AH69 -> 7346435000 | G23: =E23-F23 -> -6588097089
D24: =TB!B17 -> Akum. Peny. Kendaraan Alat Berat | E24: =TB!C17 -> 523581250 | F24: ='6. Instalasi Elektrik'!AH43 -> 397178000 | G24: =E24-F24 -> 126403250
D25: =TB!B18 -> Akum. Peny. Peralatan Kantor | E25: =TB!C18 -> 202378387 | F25: ='8 Peralatan & Perlengkapan'!AH149 -> 1.1746927e+09 | G25: =E25-F25 -> -9.7231429e+08
D26: =TB!B19 -> Akum. Peny. Peralatan Produksi | E26: =TB!C19 -> 1323116936 | F26: ='9. Infrastruktur'!AH50 -> 9.0558485e+09 | G26: =E26-F26 -> -7.7327316e+09
D27: =TB!B20 -> Akum. Peny. Sumur Bor | E27: =TB!C20 -> 284202368 | F27: ='3. Sumur Bor'!AI40 -> 3.5855856e+08 | G27: =E27-F27 -> -74356194
D28: =TB!B21 -> Akum. Peny. Peralatan Labolatorium | E28: =TB!C21 -> 112970014 | F28: ='4. Sarana & Prasarana'!AI29 -> 3366962620 | G28: =E28-F28 -> -3253992606
E29: =SUM(E21:E28) -> 14413343604 | F29: =SUM(F21:F28) -> 4.9058039e+10
F30: =E29-F29 -> -3.4644696e+10
D32: =D21 -> Akum Peny. Bangunan | H32: =G21 -> -3.324538e+09 | J32: =H32 -> -3.324538e+09
D33: =D22 -> Aum. Peny. Mesin | H33: =G22 -> -1.2825069e+10 | J33: =H33 -> -1.2825069e+10
D34: =D24 -> Akum. Peny. Kendaraan Alat Berat | H34: =G24 -> 126403250 | J34: =H34 -> 126403250
D35: =D26 -> Akum. Peny. Peralatan Produksi | H35: =G26 -> -7.7327316e+09 | J35: =H35 -> -7.7327316e+09
D36: =D28 -> Akum. Peny. Peralatan Labolatorium | H36: =G28 -> -3253992606 | J36: =H36 -> -3253992606
D37: R/E | I37: =SUM(H32:H36)-SUM(I38:I40) -> -3.4644696e+10 | K37: =I37 -> -3.4644696e+10
D38: =D23 -> Akum. Peny. Kendaraan | I38: =-G23 -> 6588097089 | K38: =I38 -> 6588097089
D39: =D25 -> Akum. Peny. Peralatan Kantor | I39: =-G25 -> 9.7231429e+08 | K39: =I39 -> 9.7231429e+08
D40: =D27 -> Akum. Peny. Sumur Bor | I40: =-G27 -> 74356194 | K40: =I40 -> 74356194
D41: (Penyesuaian akumulasi penyusutan aset tetap sesuai dengan daftar aset tetap)
A43: 3 | D43: Beban Penyusutan | E43: Inhouse | F43: Daftar Aset Tetap | G43: Selisih
D44: Depreciation | E44: =TB!C27 -> 2328601782 | F44: ='2. Bangunan'!AH115+'5. Mesin'!AG315+'6. Instalasi Elektrik'!AG43+'9. Infrastruktur'!AG50+'3. Sumur Bor'!AH40 -> 6.704861e+09 | G44: =E44-F44 -> -4.3762593e+09
D45: Beban Depresiasi Dan Amortisasi | E45: =TB!C30 -> 0 | G45: =E45-F45 -> 0
...

Sheet ADJ 2021
A1: Klien | C1: : | D1: PT. INDO AMERICAN SEAFOODS
A2: Tahun Buku | C2: : | D2: 31 Desember 2021
A3: Adjustment Audited
A5: No. | B5: No. Akun | C5: Jurnal | H5: Debit | I5: Kredit | J5: Efek Ke Neraca | M5: Efek ke LR | O5: Keterangan
J6: Debit | K6: Kredit | M6: Debit | N6: Kredit
A8: 1 | D8: Harga perolehan | E8: Inhouse | F8: Daftar Aset Tetap | G8: Selisih
D9: =TB!B2 -> Tanah | E9: =TB!G2 -> 11934000000 | F9: ='1. Tanah'!D4 -> 655809273 | G9: =E9-F9 -> 11278190727
D10: =TB!B3 -> Bangunan | E10: =TB!G3 -> 24671108216 | F10: ='2. Bangunan'!E127 -> 3.7188156e+10 | G10: =E10-F10 -> -1.2517048e+10
D11: =TB!B4 -> Mesin | E11: =TB!G4 -> 12427073552 | F11: ='5. Mesin'!E327 -> 3.7601207e+10 | G11: =E11-F11 -> -2.5174133e+10
D12: =TB!B5 -> Kendaraan | E12: =TB!G5 -> 1431471000 | F12: ='7. Kendaraan'!E80 -> 8342660000 | G12: =E12-F12 -> -6911189000
D13: =TB!B6 -> Kendaraan Alat Berat | E13: =TB!G6 -> 545000000 | F13: ='6. Instalasi Elektrik'!E54 -> 1452280000 | G13: =E13-F13 -> -907280000
D14: =TB!B7 -> Peralatan Kantor | E14: =TB!G7 -> 229134005 | F14: ='8 Peralatan & Perlengkapan'!E160 -> 1212799796 | G14: =E14-F14 -> -983665791
D15: =TB!B8 -> Peralatan Produksi | E15: =TB!G8 -> 1371567751 | F15: ='9. Infrastruktur'!E61 -> 1.1170379e+10 | G15: =E15-F15 -> -9.7988117e+09
D16: =TB!B9 -> Sumur Bor | E16: =TB!G9 -> 337941600 | F16: ='3. Sumur Bor'!E52 -> 445059500 | G16: =E16-F16 -> -107117900
D17: =TB!B10 -> Peralatan Labolatorium | E17: =TB!G10 -> 112970000 | F17: ='4. Sarana & Prasarana'!E41 -> 6200217370 | G17: =E17-F17 -> -6087247370
E18: =SUM(E9:E17) -> 53060266124 | F18: =SUM(F9:F17) -> 1.0426857e+11
A20: 2 | D20: Akumulasi Penyusutan | E20: Inhouse | F20: Daftar Aset Tetap | G20: Selisih
D21: =TB!B14 -> Akum Peny. Bangunan | E21: =TB!G14 -> 4654194214 | F21: ='2. Bangunan'!AF115 -> 7.3404936e+09 | G21: =E21-F21 -> -2.6862994e+09
D22: =TB!B15 -> Aum. Peny. Mesin | E22: =TB!G15 -> 4543719794 | F22: ='5. Mesin'!AE315 -> 1.4764182e+10 | G22: =E22-F22 -> -1.0220462e+10
D23: =TB!B16 -> Akum. Peny. Kendaraan | E23: =TB!G16 -> 575795564 | F23: ='7. Kendaraan'!AE69 -> 6304577500 | G23: =E23-F23 -> -5728781936
D24: =TB!B17 -> Akum. Peny. Kendaraan Alat Berat | E24: =TB!G17 -> 467031250 | F24: ='6. Instalasi Elektrik'!AE43 -> 324564000 | G24: =E24-F24 -> 142467250
D25: =TB!B18 -> Akum. Peny. Peralatan Kantor | E25: =TB!G18 -> 176328564 | F25: ='8 Peralatan & Perlengkapan'!AE149 -> 1.0901652e+09 | G25: =E25-F25 -> -9.1383662e+08
D26: =TB!B19 -> Akum. Peny. Peralatan Produksi | E26: =TB!G19 -> 1281284963 | F26: ='9. Infrastruktur'!AE50 -> 7.7214979e+09 | G26: =E26-F26 -> -6.440213e+09
D27: =TB!B20 -> Akum. Peny. Sumur Bor | E27: =TB!G20 -> 247367639 | F27: ='3. Sumur Bor'!AF40 -> 302926125 | G27: =E27-F27 -> -55558486
D28: =TB!B21 -> Akum. Peny. Peralatan Labolatorium | E28: =TB!G21 -> 96085012 | F28: ='4. Sarana & Prasarana'!AF29 -> 2.876204e+09 | G28: =E28-F28 -> -2.780119e+09
E29: =SUM(E21:E28) -> 12041807000 | F29: =SUM(F21:F28) -> 4.072461e+10
F30: =E29-F29 -> -2.8682803e+10
D31: =D21 -> Akum Peny. Bangunan | H31: =G21 -> -2.6862994e+09 | J31: =H31 -> -2.6862994e+09
D32: =D22 -> Aum. Peny. Mesin | H32: =G22 -> -1.0220462e+10 | J32: =H32 -> -1.0220462e+10
D33: Akum. Peny. Kendaraan | H33: =G23 -> -5728781936 | J33: =H33 -> -5728781936
D34: =D24 -> Akum. Peny. Kendaraan Alat Berat | H34: =G24 -> 142467250 | J34: =H34 -> 142467250
D35: =D25 -> Akum. Peny. Peralatan Kantor | H35: =G25 -> -9.1383662e+08 | J35: =H35 -> -9.1383662e+08
D36: =D26 -> Akum. Peny. Peralatan Produksi | H36: =G26 -> -6.440213e+09 | J36: =H36 -> -6.440213e+09
D37: =D27 -> Akum. Peny. Sumur Bor | H37: =G27 -> -55558486 | J37: =H37 -> -55558486
D38: =D28 -> Akum. Peny. Peralatan Labolatorium | H38: =G28 -> -2.780119e+09 | J38: =H38 -> -2.780119e+09
D39: R/E | I39: =SUM(H31:H38) -> -2.8682803e+10 | K39: =I39 -> -2.8682803e+10
D40: (Penyesuaian akumulasi penyusutan aset tetap sesuai dengan daftar aset tetap)
A42: 3 | D42: Beban Penyusutan | E42: Inhouse | F42: Daftar Aset Tetap | G42: Selisih
D43: Depreciation | E43: =TB!G27 -> 1841766477 | F43: ='2. Bangunan'!AE115+'5. Mesin'!AD315+'6. Instalasi Elektrik'!AD43+'9. Infrastruktur'!AD50+'3. Sumur Bor'!AE40 -> 5.740677e+09 | G43: =E43-F43 -> -3.8989105e+09
D44: Beban Depresiasi Dan Amortisasi | E44: =TB!G30 -> 0 | G44: =E44-F44 -> 0
...

Sheet ADJ 2020
A1: Klien | C1: : | D1: PT. INDO AMERICAN SEAFOODS
A2: Tahun Buku | C2: : | D2: 31 Desember 2020
A3: Adjustment Audited
A5: No. | B5: No. Akun | C5: Jurnal | H5: Debit | I5: Kredit | J5: Efek Ke Neraca | M5: Efek ke LR | O5: Keterangan
J6: Debit | K6: Kredit | M6: Debit | N6: Kredit
A8: 1 | D8: Harga perolehan | E8: Inhouse | F8: Daftar Aset Tetap | G8: Selisih
D9: =TB!B2 -> Tanah | E9: =TB!K2 -> 11934000000 | F9: ='1. Tanah'!D4 -> 655809273 | G9: =E9-F9 -> 11278190727
D10: =TB!B3 -> Bangunan | E10: =TB!K3 -> 14898332500 | F10: ='2. Bangunan'!E126 -> 2.7419763e+10 | G10: =E10-F10 -> -1.252143e+10
D11: =TB!B4 -> Mesin | E11: =TB!K4 -> 12196073552 | F11: ='5. Mesin'!E326 -> 2.8284388e+10 | G11: =E11-F11 -> -1.6088314e+10
D12: =TB!B5 -> Kendaraan | E12: =TB!K5 -> 1431471000 | F12: ='7. Kendaraan'!E79 -> 8342660000 | G12: =E12-F12 -> -6911189000
D13: =TB!B6 -> Kendaraan Alat Berat | E13: =TB!K6 -> 545000000 | F13: ='6. Instalasi Elektrik'!E53 -> 1007800000 | G13: =E13-F13 -> -462800000
D14: =TB!B7 -> Peralatan Kantor | E14: =TB!K7 -> 227534005 | F14: ='8 Peralatan & Perlengkapan'!E159 -> 1208997796 | G14: =E14-F14 -> -981463791
D15: =TB!B8 -> Peralatan Produksi | E15: =TB!K8 -> 1356328751 | F15: ='9. Infrastruktur'!E60 -> 1.1170379e+10 | G15: =E15-F15 -> -9.8140507e+09
D16: =TB!B9 -> Sumur Bor | E16: =TB!K9 -> 337941600 | F16: ='3. Sumur Bor'!E51 -> 445059500 | G16: =E16-F16 -> -107117900
D17: =TB!B10 -> Peralatan Labolatorium | E17: =TB!K10 -> 112970000 | F17: ='4. Sarana & Prasarana'!E40 -> 6200217370 | G17: =E17-F17 -> -6087247370
E18: =SUM(E9:E17) -> 43039651408 | F18: =SUM(F9:F17) -> 8.4735074e+10
A20: 2 | D20: Akumulasi Penyusutan | E20: Inhouse | F20: Daftar Aset Tetap | G20: Selisih
D21: =TB!B14 -> Akum Peny. Bangunan | E21: =TB!K14 -> 3909277573 | F21: ='2. Bangunan'!AC115 -> 5.9316464e+09 | G21: =E21-F21 -> -2.0223688e+09
D22: =TB!B15 -> Aum. Peny. Mesin | E22: =TB!K15 -> 3779058952 | F22: ='5. Mesin'!AB315 -> 1.1938715e+10 | G22: =E22-F22 -> -8.1596562e+09
D23: =TB!B16 -> Akum. Peny. Kendaraan | E23: =TB!K16 -> 396861684 | F23: ='7. Kendaraan'!AB69 -> 5262557500 | G23: =E23-F23 -> -4865695816
D24: =TB!B17 -> Akum. Peny. Kendaraan Alat Berat | E24: =TB!K17 -> 398906250 | F24: ='6. Instalasi Elektrik'!AB43 -> 251950000 | G24: =E24-F24 -> 146956250
D25: =TB!B18 -> Akum. Peny. Peralatan Kantor | E25: =TB!K18 -> 145371960 | F25: ='8 Peralatan & Perlengkapan'!AB149 -> 1.0089859e+09 | G25: =E25-F25 -> -8.6361391e+08
D26: =TB!B19 -> Akum. Peny. Peralatan Produksi | E26: =TB!K19 -> 1238393423 | F26: ='9. Infrastruktur'!AB50 -> 6.3548058e+09 | G26: =E26-F26 -> -5.1164124e+09
D27: =TB!B20 -> Akum. Peny. Sumur Bor | E27: =TB!K20 -> 205124939 | F27: ='3. Sumur Bor'!AC40 -> 2.4729369e+08 | G27: =E27-F27 -> -42168748
D28: =TB!B21 -> Akum. Peny. Peralatan Labolatorium | E28: =TB!K21 -> 67842508 | F28: ='4. Sarana & Prasarana'!AC29 -> 2.37899e+09 | G28: =E28-F28 -> -2.3111475e+09
E29: =SUM(E21:E28) -> 10140837289 | F29: =SUM(F21:F28) -> 3.3374944e+10
F30: =E29-F29 -> -2.3234107e+10
D31: =D21 -> Akum Peny. Bangunan | H31: =G21 -> -2.0223688e+09 | J31: =H31 -> -2.0223688e+09
D32: =D22 -> Aum. Peny. Mesin | H32: =G22 -> -8.1596562e+09 | J32: =H32 -> -8.1596562e+09
D33: =D24 -> Akum. Peny. Kendaraan Alat Berat | H33: =G24 -> 146956250 | J33: =H33 -> 146956250
D34: =D25 -> Akum. Peny. Peralatan Kantor | H34: =G25 -> -8.6361391e+08 | J34: =H34 -> -8.6361391e+08
D35: =D26 -> Akum. Peny. Peralatan Produksi | H35: =G26 -> -5.1164124e+09 | J35: =H35 -> -5.1164124e+09
D36: =D27 -> Akum. Peny. Sumur Bor | H36: =G27 -> -42168748 | J36: =H36 -> -42168748
D37: =D28 -> Akum. Peny. Peralatan Labolatorium | H37: =G28 -> -2.3111475e+09 | J37: =H37 -> -2.3111475e+09
D38: R/E | I38: =SUM(H31:H37)-I39 -> -2.3234107e+10 | K38: =I38 -> -2.3234107e+10
D39: =D23 -> Akum. Peny. Kendaraan | I39: =-G23 -> 4865695816 | K39: =I39 -> 4865695816
D40: (Penyesuaian akumulasi penyusutan aset tetap sesuai dengan daftar aset tetap)
A42: 3 | D42: Beban Penyusutan | E42: Inhouse | F42: Daftar Aset Tetap | G42: Selisih
D43: Depreciation | E43: =TB!K27 -> 1216185335 | F43: ='2. Bangunan'!AB115+'5. Mesin'!AA315+'6. Instalasi Elektrik'!AA43+'9. Infrastruktur'!AA50+'3. Sumur Bor'!AB40 -> 5.5360643e+09 | G43: =E43-F43 -> -4.319879e+09
D44: Beban Depresiasi Dan Amortisasi | E44: =TB!K30 -> 662689697 | G44: =E44-F44 -> 662689697
...

Sheet Aset Tetap
D1: PT. INDOKOM SAMUDERA PERSADA
D2: DIVISI COLD STORAGE 1
D3: DAFTAR ASET TETAP DAN PENYUSUTAN | Q3: Bak mobil Budidaya
D4: DESEMBER 2022
B5: 1 | C5: 1 | K5: 1.4112772e+11 | L5: 7.4137718e+09 | M5: 15636001272 | N5: 1.3291008e+11 | O5: 4.2713813e+10 | P5: 1.0115152e+10 | Q5: 2.5693171e+09 | R5: 5.0259648e+10 | S5: Dalam Rupiah (Rp)
D6: No | F6: Nama Asset | I6: Tahun | J6: % | K6: Harga Perolehan | L6: Mutasi | N6: Harga Perolehan | O6: Akm. Penyusutan | P6: Penyusutan Desember 2021 | R6: Akm. Penyusutan | S6: Nilai Buku
I8: Perolehan | K8: Per | N8: Per | O8: s/d | R8: s/d | S8: Per
K9: 31 Desember 2021 | L9: Penambahan | M9: Pengurangan | N9: 31 Desember 2022 | O9: 31 Desember 2021 | P9: Penambahan | Q9: Pengurangan | R9: 31 Desember 2022 | S9: 31 Desember 2022
A11: COLD STORAGE | B11: TANAH | C11: TANAH | D11: 1 | E11: TANAH
A12: COLD STORAGE | E12: 1.1 | F12: Tanah Cold Storage
A13: COLD STORAGE | H13: Tanah Divisi Cold Storage 1 | I13: 2002 | K13: 893958647 | L13: 0 | N13: =K13+L13-M13 -> 893958647 | O13: 0 | P13: 0 | Q13: 0 | R13: =O13+P13-Q13 -> 0 | S13: =N13-R13 -> 893958647
A14: COLD STORAGE | H14: Tanah Divisi Cold Storage 2 | I14: 2002 | K14: 200000000 | L14: 0 | N14: =K14+L14-M14 -> 200000000 | O14: 0 | P14: 0 | Q14: 0 | R14: =O14+P14-Q14 -> 0 | S14: =N14-R14 -> 200000000
H15: Tanah SHM NO.776,777,778 | I15: 2002 | K15: 226850626 | L15: 0 | N15: =K15+L15-M15 -> 226850626 | O15: 0 | P15: 0 | Q15: 0 | R15: =O15+P15-Q15 -> 0 | S15: =N15-R15 -> 226850626
A16: COLD STORAGE | E16: Subtotal Tanah Cold Storage | K16: =SUM(K13:K15) -> 1320809273 | L16: =SUM(L13:L15) -> 0 | M16: =SUM(M13:M15) -> 0 | N16: =SUM(N13:N15) -> 1320809273 | O16: =SUM(O13:O15) -> 0 | P16: =SUM(P13:P15) -> 0 | Q16: =SUM(Q13:Q15) -> 0 | R16: =SUM(R13:R15) -> 0 | S16: =SUM(S13:S15) -> 1320809273
A18: GEBANG | E18: 1.2 | F18: Tanah Gebang
A19: GEBANG | H19: Tanah Divisi Gebang | I19: 2005 | K19: 2538567500 | L19: 0 | M19: 0 | N19: =K19+L19-M19 -> 2538567500 | O19: 0 | P19: 0 | Q19: 0 | R19: =O19+P19-Q19 -> 0 | S19: =N19-R19 -> 2538567500
A20: GEBANG | E20: Subtotal Tanah Gebang | K20: =SUM(K19) -> 2538567500 | L20: =SUM(L19) -> 0 | M20: =SUM(M19) -> 0 | N20: =SUM(N19) -> 2538567500 | O20: =SUM(O19) -> 0 | P20: =SUM(P19) -> 0 | Q20: =SUM(Q19) -> 0 | R20: =SUM(R19) -> 0 | S20: =SUM(S19) -> 2538567500
A22: HOLDING | E22: 1.3 | F22: Tanah Holding
A23: HOLDING | H23: Tanah Divisi Holding | I23: 2008 | K23: 1533972000 | L23: 0 | M23: 0 | N23: =K23+L23-M23 -> 1533972000 | O23: 0 | P23: 0 | Q23: 0 | R23: =O23+P23-Q23 -> 0 | S23: =N23-R23 -> 1533972000
A24: HOLDING | H24: Tanah Divisi Maringgai | I24: 2002 | K24: 202373350 | L24: 0 | M24: 0 | N24: =K24+L24-M24 -> 202373350 | O24: 0 | P24: 0 | Q24: 0 | R24: =O24+P24-Q24 -> 0 | S24: =N24-R24 -> 202373350
A25: HOLDING | E25: Subtotal Tanah Holding | K25: =SUM(K23:K24) -> 1736345350 | L25: =SUM(L23:L24) -> 0 | M25: =SUM(M23:M24) -> 0 | N25: =SUM(N23:N24) -> 1736345350 | O25: =SUM(O23:O24) -> 0 | P25: =SUM(P23:P24) -> 0 | Q25: =SUM(Q23:Q24) -> 0 | R25: =SUM(R23:R24) -> 0 | S25: =SUM(S23:S24) -> 1736345350
A27: KETAPANG | E27: 1.4 | F27: Tanah Ketapang
A28: KETAPANG | H28: Tanah Divisi Ketapang | K28: 3436245000 | L28: 0 | M28: 0 | N28: =K28+L28-M28 -> 3436245000 | O28: 0 | P28: 0 | Q28: 0 | R28: =O28+P28-Q28 -> 0 | S28: =N28-R28 -> 3436245000
A29: KETAPANG | E29: Subtotal Tanah Ketapang | K29: =SUM(K28) -> 3436245000 | L29: =SUM(L28) -> 0 | M29: =SUM(M28) -> 0 | N29: =SUM(N28) -> 3436245000 | O29: =SUM(O28) -> 0 | P29: =SUM(P28) -> 0 | Q29: =SUM(Q28) -> 0 | R29: =SUM(R28) -> 0 | S29: =SUM(S28) -> 3436245000
A31: PAKAN | E31: 1.4 | F31: Tanah Pakan
A32: PAKAN | H32: Tanah Divisi Pakan | I32: 2006 | K32: 0 | L32: 0 | N32: =K32+L32-M32 -> 0 | O32: 0 | P32: 0 | Q32: 0 | R32: =O32+P32-Q32 -> 0 | S32: =N32-R32 -> 0
A33: PAKAN | E33: Subtotal Tanah Pakan | K33: =SUM(K32) -> 0 | L33: =SUM(L32) -> 0 | M33: =SUM(M32) -> 0 | N33: =SUM(N32) -> 0 | O33: =SUM(O32) -> 0 | P33: =SUM(P32) -> 0 | Q33: =SUM(Q32) -> 0 | R33: =SUM(R32) -> 0 | S33: =SUM(S32) -> 0
D35: TOTAL TANAH | K35: =K16+K20+K25+K29 -> 9031967123 | L35: =L16+L20+L25+L29 -> 0 | M35: =M16+M20+M25+M29 -> 0 | N35: =N16+N20+N25+N29 -> 9031967123 | O35: =O16+O20+O25+O29 -> 0 | P35: =P16+P20+P25+P29 -> 0 | Q35: =Q16+Q20+Q25+Q29 -> 0 | R35: =R16+R20+R25+R29 -> 0 | S35: =S16+S20+S25+S29 -> 9031967123
A37: COLD STORAGE | B37: BANGUNAN | C37: BANGUNAN | D37: 2 | E37: BANGUNAN
A38: COLD STORAGE | E38: 2.1 | F38: Bangunan Cold Storage
A39: COLD STORAGE | F39: 2.1.1 | G39: DIVISI ISP 1
A40: COLD STORAGE | H40: Bangunan ISP 1 | I40: 2005 | J40: 0.05 | K40: 5564855579 | L40: 0 | N40: =K40+L40-M40 -> 5564855579 | O40: 1.133304e+09 | P40: =23186898.2458333*12 -> 2.7824278e+08 | R40: =O40+P40-Q40 -> 1.4115468e+09 | S40: =N40-R40 -> 4.1533088e+09
A41: COLD STORAGE | H41: Bangunan Pos Satpam | I41: 2005 | J41: 0.05 | K41: 39450000 | L41: 0 | M41: 0 | N41: =K41+L41-M41 -> 39450000 | O41: 11835000 | P41: =164375*12 -> 1972500 | R41: =O41+P41-Q41 -> 13807500 | S41: =N41-R41 -> 25642500
A42: COLD STORAGE | H42: Bangunan Genset | I42: 2005 | J42: 0.05 | K42: 742420000 | L42: 0 | M42: 0 | N42: =K42+L42-M42 -> 742420000 | O42: 2.22726e+08 | P42: =3093416.66666667*12 -> 37121000 | R42: =O42+P42-Q42 -> 2.59847e+08 | S42: =N42-R42 -> 4.82573e+08
A43: COLD STORAGE | H43: KM/WC | I43: 2005 | J43: 0.05 | K43: 8100000 | L43: 0 | M43: 0 | N43: =K43+L43-M43 -> 8100000 | O43: 2430000 | P43: =33750*12 -> 405000 | R43: =O43+P43-Q43 -> 2835000 | S43: =N43-R43 -> 5265000
A44: COLD STORAGE | H44: Kantor 1 | I44: 2006 | J44: 0.05 | K44: 203210000 | L44: 0 | M44: 0 | N44: =K44+L44-M44 -> 203210000 | O44: 42335416 | P44: =846708.333333333*12 -> 10160500 | R44: =O44+P44-Q44 -> 52495916 | S44: =N44-R44 -> 150714084
A45: COLD STORAGE | H45: Kantin & KM/WC | I45: 2010 | J45: 0.05 | K45: 262080000 | L45: 0 | M45: 0 | N45: =K45+L45-M45 -> 262080000 | O45: 78624000 | P45: =1092000*12 -> 13104000 | R45: =O45+P45-Q45 -> 91728000 | S45: =N45-R45 -> 170352000
A46: COLD STORAGE | H46: Mushola | I46: 2010 | J46: 0.05 | K46: 194080000 | L46: 0 | M46: 0 | N46: =K46+L46-M46 -> 194080000 | O46: 58224000 | P46: =808666.666666667*12 -> 9704000 | R46: =O46+P46-Q46 -> 67928000 | S46: =N46-R46 -> 1.26152e+08
A47: COLD STORAGE | H47: Cafetaria | I47: 2010 | J47: 0.05 | K47: 313090000 | L47: 0 | M47: 0 | N47: =K47+L47-M47 -> 313090000 | O47: 93927000 | P47: =1304541.66666667*12 -> 15654500 | R47: =O47+P47-Q47 -> 1.095815e+08 | S47: =N47-R47 -> 2.035085e+08
A48: COLD STORAGE | H48: Panggung Ekspor | I48: 2010 | J48: 0.05 | K48: 23340000 | L48: 0 | M48: 0 | N48: =K48+L48-M48 -> 23340000 | O48: 4862500 | P48: =97250*12 -> 1167000 | R48: =O48+P48-Q48 -> 6029500 | S48: =N48-R48 -> 17310500
...

Sheet Summary
B1: Aet Tambak Ketapang | F1: Aset Lainnya | J1: Total Aset yang akan di takeout
A2: 1 | B2: Tanah | C2: ='1. Tanah'!D16 -> 0 | E2: 1 | F2: Tanah | G2: 0
A3: 2 | B3: Bangunan | C3: =SUM('2. Bangunan'!E82:E106) -> 0 | E3: 2 | F3: Bangunan | G3: ='2. Bangunan'!E10+'2. Bangunan'!E44+'2. Bangunan'!E55+'2. Bangunan'!E63+'2. Bangunan'!E73+'2. Bangunan'!E75 -> 0 | J3: Aet Tambak Ketapang | K3: =C11 -> 0
A4: 3 | B4: Sumur Bor | C4: =SUM('3. Sumur Bor'!E25:E36) -> 0 | E4: 3 | F4: Sumur Bor | G4: =SUM('3. Sumur Bor'!E8:E11) -> 0 | J4: Aset Lainnya | K4: =G11 -> 0
A5: 4 | B5: Sarana & Prasarana | C5: =SUM('4. Sarana & Prasarana'!E18:E27) -> 0 | E5: 4 | F5: Sarana & Prasarana | G5: =SUM('4. Sarana & Prasarana'!E13:E14)+'4. Sarana & Prasarana'!E16 -> 0 | K5: =SUM(K3:K4) -> 0
A6: 5 | B6: Mesin | C6: =SUM('5. Mesin'!E240:E308) -> 0 | E6: 5 | F6: Mesin | G6: ='5. Mesin'!E80+'5. Mesin'!E87+'5. Mesin'!E88 -> 0
A7: 6 | B7: Instalasi Elektrik | C7: =SUM('6. Instalasi Elektrik'!E13:E40) -> 0 | E7: 6 | F7: Instalasi Elektrik | G7: 0
A8: 7 | B8: Kendaraan | C8: =SUM('7. Kendaraan'!E51:E62) -> 0 | E8: 7 | F8: Kendaraan | G8: ='7. Kendaraan'!E46 -> 0 | J8: Hutang Pak Usman | K8: 2.0363316e+10
A9: 8 | B9: Perlengkapan | C9: 0 | E9: 8 | F9: Perlengkapan | G9: ='8 Peralatan & Perlengkapan'!E87+'8 Peralatan & Perlengkapan'!E89+'8 Peralatan & Perlengkapan'!E95+'8 Peralatan & Perlengkapan'!E102+'8 Peralatan & Perlengkapan'!E104+'8 Peralatan & Perlengkapan'!E108+'8 Peralatan & Perlengkapan'!E109+'8 Peralatan & Perlengkapan'!E111 -> 0 | J9: Surplus RAT | K9: 56060619982
A10: 9 | B10: Infrastruktur | C10: =SUM('9. Infrastruktur'!E37:E44)-'9. Infrastruktur'!E38 -> 0 | E10: 9 | F10: Infrastruktur | G10: ='9. Infrastruktur'!E11+'9. Infrastruktur'!E32+'9. Infrastruktur'!E34+'9. Infrastruktur'!E35 -> 0 | K10: =K5-K8-K9 -> -7.6423936e+10
C11: =SUM(C2:C10) -> 0 | G11: =SUM(G2:G10) -> 0
J12: Penyusutan Peralatan Tambak ,Biaya
J13: Penyusutan Peralatan Produksi, Biaya
B14: Akmulasi Penyusutan Tambak Ketapang 2020 | F14: Akumulasi Penyusutan Aset Lainnya 2020 | J14: Penyusutan Sarana & Prasarana, Biaya
A15: 1 | B15: Bangunan | C15: =SUM('2. Bangunan'!AC82:AC106) -> 0 | E15: 1 | F15: Bangunan | G15: ='2. Bangunan'!AC10+'2. Bangunan'!AC44+'2. Bangunan'!AC55+'2. Bangunan'!AC63+'2. Bangunan'!AC73+'2. Bangunan'!AC75 -> 0 | J15: Penyusutan Bangunan, Biaya
A16: =A15+1 -> 2 | B16: Sumur Bor | C16: =SUM('3. Sumur Bor'!AC25:AC36) -> 0 | E16: =E15+1 -> 2 | F16: Sumur Bor | G16: ='3. Sumur Bor'!AC8+'3. Sumur Bor'!AC9+'3. Sumur Bor'!AC10+'3. Sumur Bor'!AC11 -> 0 | J16: Penyusutan Electricity Instalasi, Biaya
A17: =A16+1 -> 3 | B17: Sarana & Prasarana | C17: =SUM('4. Sarana & Prasarana'!AC18:AC27) -> 0 | E17: =E16+1 -> 3 | F17: Sarana & Prasarana | G17: =SUM('4. Sarana & Prasarana'!AC13+'4. Sarana & Prasarana'!AC14+'4. Sarana & Prasarana'!AC16) -> 0 | J17: Penyusutan Infrastruktur, Biaya
A18: =A17+1 -> 4 | B18: Mesin | C18: =SUM('5. Mesin'!AB240:AB308) -> 0 | E18: =E17+1 -> 4 | F18: Mesin | G18: =SUM('5. Mesin'!AB80+'5. Mesin'!AB87+'5. Mesin'!AB88) -> 0 | J18: Penyusutan Kendaraan, Biaya
A19: =A18+1 -> 5 | B19: Instalasi Elektrik | C19: =SUM('6. Instalasi Elektrik'!AB13:AB40) -> 0 | E19: =E18+1 -> 5 | F19: Kendaraan | G19: =SUM('7. Kendaraan'!AB46) -> 0 | J19: Penyusutan Mesin-Mesin, Biaya
A20: =A19+1 -> 6 | B20: Kendaraan | C20: =SUM('7. Kendaraan'!AB51:AB62) -> 0 | E20: =E19+1 -> 6 | F20: Perlengkapan | G20: =SUM('8 Peralatan & Perlengkapan'!AB87+'8 Peralatan & Perlengkapan'!AB89+'8 Peralatan & Perlengkapan'!AB95+'8 Peralatan & Perlengkapan'!AB102+'8 Peralatan & Perlengkapan'!AB104+'8 Peralatan & Perlengkapan'!AB108+'8 Peralatan & Perlengkapan'!AB109+'8 Peralatan & Perlengkapan'!AB111) -> 0 | J20: Penyusutan Peralatan Kantor, Biaya
A21: =A20+1 -> 7 | B21: Infrastruktur | C21: =SUM('9. Infrastruktur'!AB37:AB44)-'9. Infrastruktur'!AB38 -> 0 | E21: =E20+1 -> 7 | F21: Infrastruktur | G21: =SUM('9. Infrastruktur'!AB11+'9. Infrastruktur'!AB32+'9. Infrastruktur'!AB34+'9. Infrastruktur'!AB35) -> 0 | J21: Penyusutan Sumur Bor, Biaya
B24: Beban Penyusutan Tambak Ketapang 2020 | F24: Beban Penyusutam Aset Lainnya 2020
A25: 1 | B25: Bangunan | C25: =SUM('2. Bangunan'!AB82:AB106) -> 0 | E25: 1 | F25: Bangunan | G25: ='2. Bangunan'!AB10+'2. Bangunan'!AB44+'2. Bangunan'!AB55+'2. Bangunan'!AB63+'2. Bangunan'!AB73+'2. Bangunan'!AB75 -> 0
A26: =A25+1 -> 2 | B26: Sumur Bor | C26: =SUM('3. Sumur Bor'!AB25:AB36) -> 0 | E26: =E25+1 -> 2 | F26: Sumur Bor | G26: ='3. Sumur Bor'!AB8+'3. Sumur Bor'!AB9+'3. Sumur Bor'!AB10+'3. Sumur Bor'!AB11 -> 0
A27: =A26+1 -> 3 | B27: Sarana & Prasarana | C27: =SUM('4. Sarana & Prasarana'!AB18:AB27) -> 0 | E27: =E26+1 -> 3 | F27: Sarana & Prasarana | G27: ='4. Sarana & Prasarana'!AB13+'4. Sarana & Prasarana'!AB14+'4. Sarana & Prasarana'!AB16 -> 0
A28: =A27+1 -> 4 | B28: Mesin | C28: =SUM('5. Mesin'!AA240:AA308) -> 0 | E28: =E27+1 -> 4 | F28: Mesin | G28: ='5. Mesin'!AA80+'5. Mesin'!AA87+'5. Mesin'!AA88 -> 0
A29: =A28+1 -> 5 | B29: Instalasi Elektrik | C29: =SUM('6. Instalasi Elektrik'!AA13:AA40) -> 0 | E29: =E28+1 -> 5 | F29: Kendaraan | G29: ='7. Kendaraan'!AA46 -> 0
A30: =A29+1 -> 6 | B30: Kendaraan | C30: =SUM('7. Kendaraan'!AA51:AA62) -> 0 | E30: =E29+1 -> 6 | F30: Perlengkapan | G30: ='8 Peralatan & Perlengkapan'!AA87+'8 Peralatan & Perlengkapan'!AA89+'8 Peralatan & Perlengkapan'!AA95+'8 Peralatan & Perlengkapan'!AA102+'8 Peralatan & Perlengkapan'!AA104+'8 Peralatan & Perlengkapan'!AA108+'8 Peralatan & Perlengkapan'!AA109+'8 Peralatan & Perlengkapan'!AA111 -> 0
A31: =A30+1 -> 7 | B31: Infrastruktur | C31: =SUM('9. Infrastruktur'!AA37:AA44)-'9. Infrastruktur'!AA38 -> 0 | E31: =E30+1 -> 7 | F31: Infrastruktur | G31: ='9. Infrastruktur'!AA11+'9. Infrastruktur'!AA32+'9. Infrastruktur'!AA34+'9. Infrastruktur'!AA35 -> 0

Sheet AT
D1: PT. INDOKOM SAMUDERA PERSADA
D2: DIVISI COLD STORAGE 1
D3: DAFTAR ASET TETAP DAN PENYUSUTAN | Q3: Bak mobil Budidaya
D4: DESEMBER 2022
B5: 1 | C5: 1 | K5: 1.4112772e+11 | L5: 7.4137718e+09 | M5: 15636001272 | N5: 1.3291008e+11 | O5: 4.2713813e+10 | P5: 1.0115152e+10 | Q5: 2.5693171e+09 | R5: 5.0259648e+10 | S5: Dalam Rupiah (Rp)
D6: No | F6: Nama Asset | I6: Tahun | J6: % | K6: Harga Perolehan | L6: Mutasi | N6: Harga Perolehan | O6: Akm. Penyusutan | P6: Penyusutan Desember 2022 | R6: Akm. Penyusutan | S6: Nilai Buku
I8: Perolehan | K8: Per | N8: Per | O8: s/d | R8: s/d | S8: Per
K9: 44561 | L9: Penambahan | M9: Pengurangan | N9: 31 Desember 2022 | O9: 44561 | P9: Penambahan | Q9: Pengurangan | R9: 31 Desember 2022 | S9: 31 Desember 2022
A11: COLD STORAGE | B11: TANAH | C11: TANAH | D11: 1 | E11: TANAH
A12: COLD STORAGE | E12: 1.1 | F12: Tanah Cold Storage
A13: COLD STORAGE | H13: Tanah Divisi Cold Storage 1 | I13: 2002 | K13: 655809273 | L13: 0 | N13: =K13+L13-M13 -> 655809273 | O13: 0 | P13: 0 | Q13: 0 | R13: =O13+P13-Q13 -> 0 | S13: =N13-R13 -> 655809273
A14: COLD STORAGE | H14: Tanah Divisi Cold Storage 2 | I14: 2002 | K14: 200000000 | L14: 0 | N14: =K14+L14-M14 -> 200000000 | O14: 0 | P14: 0 | Q14: 0 | R14: =O14+P14-Q14 -> 0 | S14: =N14-R14 -> 200000000
H15: Tanah SHM NO.776,777,778 | I15: 2002 | K15: 226850626 | L15: 0 | N15: =K15+L15-M15 -> 226850626 | O15: 0 | P15: 0 | Q15: 0 | R15: =O15+P15-Q15 -> 0 | S15: =N15-R15 -> 226850626
A16: COLD STORAGE | E16: Subtotal Tanah Cold Storage | K16: =SUM(K13:K15) -> 1082659899 | L16: =SUM(L13:L15) -> 0 | M16: =SUM(M13:M15) -> 0 | N16: =SUM(N13:N15) -> 1082659899 | O16: =SUM(O13:O15) -> 0 | P16: =SUM(P13:P15) -> 0 | Q16: =SUM(Q13:Q15) -> 0 | R16: =SUM(R13:R15) -> 0 | S16: =SUM(S13:S15) -> 1082659899
A18: GEBANG | E18: 1.2 | F18: Tanah Gebang
A19: GEBANG | H19: Tanah Divisi Gebang | I19: 2005 | K19: 2538567500 | L19: 0 | M19: 0 | N19: =K19+L19-M19 -> 2538567500 | O19: 0 | P19: 0 | Q19: 0 | R19: =O19+P19-Q19 -> 0 | S19: =N19-R19 -> 2538567500
A20: GEBANG | E20: Subtotal Tanah Gebang | K20: =SUM(K19) -> 2538567500 | L20: =SUM(L19) -> 0 | M20: =SUM(M19) -> 0 | N20: =SUM(N19) -> 2538567500 | O20: =SUM(O19) -> 0 | P20: =SUM(P19) -> 0 | Q20: =SUM(Q19) -> 0 | R20: =SUM(R19) -> 0 | S20: =SUM(S19) -> 2538567500
A22: HOLDING | E22: 1.3 | F22: Tanah Holding
A23: HOLDING | H23: Tanah Divisi Holding | I23: 2008 | K23: 1533972000 | L23: 0 | M23: 0 | N23: =K23+L23-M23 -> 1533972000 | O23: 0 | P23: 0 | Q23: 0 | R23: =O23+P23-Q23 -> 0 | S23: =N23-R23 -> 1533972000
A24: HOLDING | H24: Tanah Divisi Maringgai | I24: 2002 | K24: 202373350 | L24: 0 | M24: 0 | N24: =K24+L24-M24 -> 202373350 | O24: 0 | P24: 0 | Q24: 0 | R24: =O24+P24-Q24 -> 0 | S24: =N24-R24 -> 202373350
A25: HOLDING | E25: Subtotal Tanah Holding | K25: =SUM(K23:K24) -> 1736345350 | L25: =SUM(L23:L24) -> 0 | M25: =SUM(M23:M24) -> 0 | N25: =SUM(N23:N24) -> 1736345350 | O25: =SUM(O23:O24) -> 0 | P25: =SUM(P23:P24) -> 0 | Q25: =SUM(Q23:Q24) -> 0 | R25: =SUM(R23:R24) -> 0 | S25: =SUM(S23:S24) -> 1736345350
A27: KETAPANG | E27: 1.4 | F27: Tanah Ketapang
A28: KETAPANG | H28: Tanah Divisi Ketapang | K28: 3436245000 | L28: 0 | M28: 0 | N28: =K28+L28-M28 -> 3436245000 | O28: 0 | P28: 0 | Q28: 0 | R28: =O28+P28-Q28 -> 0 | S28: =N28-R28 -> 3436245000
A29: KETAPANG | E29: Subtotal Tanah Ketapang | K29: =SUM(K28) -> 3436245000 | L29: =SUM(L28) -> 0 | M29: =SUM(M28) -> 0 | N29: =SUM(N28) -> 3436245000 | O29: =SUM(O28) -> 0 | P29: =SUM(P28) -> 0 | Q29: =SUM(Q28) -> 0 | R29: =SUM(R28) -> 0 | S29: =SUM(S28) -> 3436245000
A31: PAKAN | E31: 1.4 | F31: Tanah Pakan
A32: PAKAN | H32: Tanah Divisi Pakan | I32: 2006 | K32: 0 | L32: 0 | N32: =K32+L32-M32 -> 0 | O32: 0 | P32: 0 | Q32: 0 | R32: =O32+P32-Q32 -> 0 | S32: =N32-R32 -> 0
A33: PAKAN | E33: Subtotal Tanah Pakan | K33: =SUM(K32) -> 0 | L33: =SUM(L32) -> 0 | M33: =SUM(M32) -> 0 | N33: =SUM(N32) -> 0 | O33: =SUM(O32) -> 0 | P33: =SUM(P32) -> 0 | Q33: =SUM(Q32) -> 0 | R33: =SUM(R32) -> 0 | S33: =SUM(S32) -> 0
D35: TOTAL TANAH | K35: =K16+K20+K25+K29 -> 8793817749 | L35: =L16+L20+L25+L29 -> 0 | M35: =M16+M20+M25+M29 -> 0 | N35: =N16+N20+N25+N29 -> 8793817749 | O35: =O16+O20+O25+O29 -> 0 | P35: =P16+P20+P25+P29 -> 0 | Q35: =Q16+Q20+Q25+Q29 -> 0 | R35: =R16+R20+R25+R29 -> 0 | S35: =S16+S20+S25+S29 -> 8793817749
A37: COLD STORAGE | B37: BANGUNAN | C37: BANGUNAN | D37: 2 | E37: BANGUNAN
A38: COLD STORAGE | E38: 2.1 | F38: Bangunan Cold Storage
A39: COLD STORAGE | F39: 2.1.1 | G39: DIVISI ISP 1
A40: COLD STORAGE | H40: Bangunan ISP 1 | I40: 2005 | J40: 0.05 | K40: 5564855579 | L40: 0 | N40: =K40+L40-M40 -> 5564855579 | O40: 1.4115468e+09 | P40: =N40*J40 -> 2.7824278e+08 | R40: =O40+P40-Q40 -> 1.6897896e+09 | S40: =N40-R40 -> 3.875066e+09
A41: COLD STORAGE | H41: Bangunan Pos Satpam | I41: 2005 | J41: 0.05 | K41: 39450000 | L41: 0 | M41: 0 | N41: =K41+L41-M41 -> 39450000 | O41: 11835000 | P41: =N41*J41 -> 1972500 | R41: =O41+P41-Q41 -> 13807500 | S41: =N41-R41 -> 25642500
A42: COLD STORAGE | H42: Bangunan Genset | I42: 2005 | J42: 0.05 | K42: 742420000 | L42: 0 | M42: 0 | N42: =K42+L42-M42 -> 742420000 | O42: 2.22726e+08 | P42: =N42*J42 -> 37121000 | R42: =O42+P42-Q42 -> 2.59847e+08 | S42: =N42-R42 -> 4.82573e+08
A43: COLD STORAGE | H43: KM/WC | I43: 2005 | J43: 0.05 | K43: 8100000 | L43: 0 | M43: 0 | N43: =K43+L43-M43 -> 8100000 | O43: 2430000 | P43: =N43*J43 -> 405000 | R43: =O43+P43-Q43 -> 2835000 | S43: =N43-R43 -> 5265000
A44: COLD STORAGE | H44: Kantor 1 | I44: 2006 | J44: 0.05 | K44: 203210000 | L44: 0 | M44: 0 | N44: =K44+L44-M44 -> 203210000 | O44: 52495916 | P44: =N44*J44 -> 10160500 | R44: =O44+P44-Q44 -> 62656416 | S44: =N44-R44 -> 1.4055358e+08
A45: COLD STORAGE | H45: Kantin & KM/WC | I45: 2010 | J45: 0.05 | K45: 262080000 | L45: 0 | M45: 0 | N45: =K45+L45-M45 -> 262080000 | O45: 78624000 | P45: =N45*J45 -> 13104000 | R45: =O45+P45-Q45 -> 91728000 | S45: =N45-R45 -> 170352000
A46: COLD STORAGE | H46: Mushola | I46: 2010 | J46: 0.05 | K46: 194080000 | L46: 0 | M46: 0 | N46: =K46+L46-M46 -> 194080000 | O46: 58224000 | P46: =N46*J46 -> 9704000 | R46: =O46+P46-Q46 -> 67928000 | S46: =N46-R46 -> 1.26152e+08
A47: COLD STORAGE | H47: Cafetaria | I47: 2010 | J47: 0.05 | K47: 313090000 | L47: 0 | M47: 0 | N47: =K47+L47-M47 -> 313090000 | O47: 93927000 | P47: =N47*J47 -> 15654500 | R47: =O47+P47-Q47 -> 1.095815e+08 | S47: =N47-R47 -> 2.035085e+08
A48: COLD STORAGE | H48: Panggung Ekspor | I48: 2010 | J48: 0.05 | K48: 23340000 | L48: 0 | M48: 0 | N48: =K48+L48-M48 -> 23340000 | O48: 6029500 | P48: =N48*J48 -> 1167000 | R48: =O48+P48-Q48 -> 7196500 | S48: =N48-R48 -> 16143500
...

Sheet COA AT
A2: No. Akun | B2: COA
A3: 1-61.101 | B3: Hak atas Tanah
A4: 1-61.102 | B4: Tanah (Tax Amnesty)
A5: 1-61.103 | B5: Bangunan
A6: 1-61.104 | B6: Sarana & Prasarana
A7: 1-61.105 | B7: Mesin & Perlengkapan
A8: 1-61.106 | B8: Kendaraan
A9: 1-61.107 | B9: Peralatan & Perlengkapan
A10: 1-61.108 | B10: Instalasi Listrik
A11: 1-61.109 | B11: Infrastruktur
A12: 1-61.110 | B12: Sumur Bor
A14: 1-61.201 | B14: Akumulasi Bangunan
... A23: 5-11.700 | B23: Depresiasi
A25: 6-11.501 | B25: Penyusutan Peralatan & Perlengkapan, Biaya | C25: OPEX | E25: 51186083
A26: 6-11.502 | B26: Penyusutan Sarana & Prasarana, Biaya | C26: OPEX | E26: 4.9721397e+08
A27: 6-11.503 | B27: Penyusutan Bangunan, Biaya | C27: OPEX | E27: 41407000
A28: 6-11.504 | B28: Penyusutan Electricity Instalasi, Biaya | C28: COGS | E28: 0
A29: 6-11.505 | B29: Penyusutan Infrastruktur, Biaya | C29: COGS | E29: 0
A30: 6-11.506 | B30: Penyusutan Kendaraan, Biaya | C30: OPEX | E30: 789225000
A31: 6-11.507 | B31: Penyusutan Mesin-Mesin, Biaya | C31: COGS | E31: 0
A32: 6-11.508 | B32: Penyusutan Sumur Bor, Biaya | C32: COGS | E32: 0

Sheet Adjustment 2023
D1: =E1-F1 -> 0 | E1: =SUM(E4:E295) -> 1.2622752e+10 | F1: =SUM(F4:F295) -> 1.2622752e+10
A2: Tanggal | B2: Account No. | C2: Account Name | D2: WP Reff | E2: Balance Sheet | G2: Description
E3: Debit | F3: Credit
B5: 6-11.501 | C5: Penyusutan Peralatan & Perlengkapan, Biaya | E5: ='Disclosure Aset'!E32 -> 64098844 | G5: Adjustment Penyusutan Aset Tetap Jan s.d Des 2023
B6: 6-11.502 | C6: Penyusutan Sarana & Prasarana, Biaya | E6: ='Disclosure Aset'!E28 -> 378489750 | G6: =G5 -> Adjustment Penyusutan Aset Tetap Jan s.d Des 2023
B7: 6-11.503 | C7: Penyusutan Bangunan, Biaya | E7: ='Disclosure Aset'!E26 -> 1.8603735e+09 | G7: =G6 -> Adjustment Penyusutan Aset Tetap Jan s.d Des 2023
B8: 6-11.504 | C8: Penyusutan Electricity Instalasi, Biaya | E8: ='Disclosure Aset'!E30 -> 72614000 | G8: =G7 -> Adjustment Penyusutan Aset Tetap Jan s.d Des 2023
B9: 6-11.505 | C9: Penyusutan Infrastruktur, Biaya | E9: ='Disclosure Aset'!E33 -> 1.3247535e+09 | G9: =G8 -> Adjustment Penyusutan Aset Tetap Jan s.d Des 2023
B10: 6-11.506 | C10: Penyusutan Kendaraan, Biaya | E10: ='Disclosure Aset'!E31 -> 982475000 | G10: =G9 -> Adjustment Penyusutan Aset Tetap Jan s.d Des 2023
B11: 6-11.507 | C11: Penyusutan Mesin-Mesin, Biaya | E11: ='Disclosure Aset'!E29 -> 3.2177823e+09 | G11: =G10 -> Adjustment Penyusutan Aset Tetap Jan s.d Des 2023
B12: 6-11.508 | C12: Penyusutan Sumur Bor, Biaya | E12: ='Disclosure Aset'!E27 -> 53507438 | G12: =G11 -> Adjustment Penyusutan Aset Tetap Jan s.d Des 2023
B13: 1-61.201 | C13: Akumulasi Bangunan | F13: =E7 -> 1.8603735e+09 | G13: =G12 -> Adjustment Penyusutan Aset Tetap Jan s.d Des 2023
B14: 1-61.202 | C14: Akumulasi Sarana & Prasarana | F14: =E6 -> 378489750 | G14: =G13 -> Adjustment Penyusutan Aset Tetap Jan s.d Des 2023
B15: 1-61.203 | C15: Akumulasi Mesin & Perlengkapan | F15: =E11 -> 3.2177823e+09 | G15: =G14 -> Adjustment Penyusutan Aset Tetap Jan s.d Des 2023
B16: 1-61.204 | C16: Akumulasi Kendaraan | F16: =E10 -> 982475000 | G16: =G15 -> Adjustment Penyusutan Aset Tetap Jan s.d Des 2023
B17: 1-61.205 | C17: Akumulasi Peralatan & Perlengkapan | F17: =E5 -> 64098844 | G17: =G16 -> Adjustment Penyusutan Aset Tetap Jan s.d Des 2023
B18: 1-61.206 | C18: Akumulasi Instalasi Listrik | F18: =E8 -> 72614000 | G18: =G17 -> Adjustment Penyusutan Aset Tetap Jan s.d Des 2023
B19: 1-61.207 | C19: Akumulasi Infrastruktur | F19: =E9 -> 1.3247535e+09 | G19: =G18 -> Adjustment Penyusutan Aset Tetap Jan s.d Des 2023
B20: 1-61.208 | C20: Akumulasi Sumur Bor | F20: =E12 -> 53507438 | G20: =G19 -> Adjustment Penyusutan Aset Tetap Jan s.d Des 2023
B22: 5-11.700 | C22: Depresiasi | E22: =SUM(F23:F26) -> 4.6686572e+09 | G22: Reklas Penyusutan GA ke penyusutan COGS per 2023
B23: ='COA AT'!A28 -> 6-11.504 | C23: ='COA AT'!B28 -> Penyusutan Electricity Instalasi, Biaya | F23: =E8 -> 72614000 | G23: =G22 -> Reklas Penyusutan GA ke penyusutan COGS per 2023
B24: ='COA AT'!A29 -> 6-11.505 | C24: ='COA AT'!B29 -> Penyusutan Infrastruktur, Biaya | F24: =E9 -> 1.3247535e+09 | G24: =G23 -> Reklas Penyusutan GA ke penyusutan COGS per 2023
B25: ='COA AT'!A31 -> 6-11.507 | C25: ='COA AT'!B31 -> Penyusutan Mesin-Mesin, Biaya | F25: =E11 -> 3.2177823e+09 | G25: =G24 -> Reklas Penyusutan GA ke penyusutan COGS per 2023
B26: ='COA AT'!A32 -> 6-11.508 | C26: ='COA AT'!B32 -> Penyusutan Sumur Bor, Biaya | F26: =E12 -> 53507438 | G26: =G25 -> Reklas Penyusutan GA ke penyusutan COGS per 2023

Sheet Disclosure Aset
M1: 0.05
B2: ASET TETAP | G2: PMK >> | L2: 8 thn | M2: 0.125
B3: Akm Penyusutan 2016 | M3: 0.25
C4: WS | L4: 16 thn | M4: 0.0625
C5: 2023
C6: Saldo Awal | E6: Penambahan | G6: Pengurangan | I6: Reklasifikasi | K6: Saldo Akhir | Q6: WBS | S6: Selisih
B8: Nilai Perolehan
B9: Tanah | C9: =K46 -> 0 | E9: =0 -> 0 | G9: 0 | K9: =C9+E9+G9+I9 -> 0
B10: Bangunan | C10: =K47 -> 3.7188156e+10 | E10: ='2. Bangunan'!F129 -> 0 | G10: 0 | I10: 0 | K10: =C10+E10+G10+I10 -> 3.7188156e+10
B11: Sumur Bor | C11: =K48 -> 445059500 | E11: ='3. Sumur Bor'!F54 -> 0 | G11: 0 | K11: =C11+E11+G11+I11 -> 445059500
B12: Sarana dan Prasarana | C12: =K49 -> 6200217370 | E12: ='4. Sarana & Prasarana'!F43 -> 0 | G12: 0 | K12: =C12+E12+G12+I12 -> 6200217370
B13: Mesin | C13: =K50 -> 3.7618136e+10 | E13: ='5. Mesin'!F329 -> 0 | G13: 0 | K13: =C13+E13+G13+I13 -> 3.7618136e+10
B14: Instalasi Elektrik | C14: =K51 -> 1452280000 | E14: ='6. Instalasi Elektrik'!F56 -> 0 | G14: 0 | K14: =C14+E14+G14+I14 -> 1452280000
B15: Kendaraan | C15: =K52 -> 8342660000 | E15: ='7. Kendaraan'!F82 -> 120000000 | G15: 0 | I15: 0 | K15: =C15+E15+G15+I15 -> 8462660000
B16: Peralatan dan Perlengkapan | C16: =K53 -> 1274154796 | E16: ='8 Peralatan & Perlengkapan'!F162 -> 29115000 | G16: 0 | I16: 0 | K16: =C16+E16+G16+I16 -> 1303269796
B17: Infrastruktur | C17: =K54 -> 1.1170379e+10 | E17: ='9. Infrastruktur'!F63 -> 0 | G17: 0 | I17: 0 | K17: =C17+E17+G17+I17 -> 1.1170379e+10 | AQ17: WBS | AR17: Selisih
B19: Sub-Jumlah | C19: =SUM(C9:C17) -> 1.0369104e+11 | E19: =SUM(E9:E17) -> 149115000 | G19: =SUM(G9:G17) -> 0 | H19: =SUM(H10:H17) -> 0 | I19: =SUM(I10:I17) -> 0 | J19: =SUM(J10:J17) -> 0 | K19: =SUM(K9:K17) -> 1.0384016e+11 | AQ19: 1.0384016e+11 | AR19: =AQ19-K19 -> 0.8999939
B21: Aset Tetap Dalam Pembangunan | C21: =K58 -> 0 | G21: 0 | I21: 0 | K21: =C21+E21-G21+I21 -> 0
B23: Jumlah | C23: =C19+C21 -> 1.0369104e+11 | E23: =E19+E21 -> 149115000 | G23: =G19+G21 -> 0 | H23: =SUM(H14:H21) -> 0 | I23: =SUM(I14:I21) -> 0 | J23: =SUM(J14:J21) -> 0 | K23: =K19+K21 -> 1.0384016e+11
C24: 2023 | AQ24: Akumulasi akhir WBS | AR24: Diff | AT24: Beban Penyusutan WBS | AU24: Diff
B25: Akumulasi Penyusutan
B26: Bangunan | C26: =K63 -> 9.2122918e+09 | E26: ='2. Bangunan'!AQ115 -> 1.8603735e+09 | G26: 0 | I26: 0 | K26: =C26+E26+G26+I26 -> 1.1072665e+10 | AG26: =E26/C26 -> 0.2019447 | AQ26: -10981268315 | AR26: =AQ26+K26 -> 91396967
B27: Sumur Bor | C27: =K64 -> 3.5855856e+08 | E27: ='3. Sumur Bor'!AQ40 -> 53507438 | G27: 0 | K27: =C27+E27+G27+I27 -> 412066000 | AQ27: -412066001 | AR27: =AQ27+K27 -> -1
B28: Sarana dan Prasarana | C28: =K65 -> 3.3669626e+09 | E28: ='4. Sarana & Prasarana'!AQ29 -> 378489750 | G28: 0 | K28: =C28+E28+G28+I28 -> 3.7454524e+09 | AQ28: -3745452370 | AR28: =AQ28+K28 -> 0
B29: Mesin | C29: =K66 -> 1.8146072e+10 | E29: ='5. Mesin'!AP315 -> 3.2177823e+09 | G29: 0 | K29: =C29+E29+G29+I29 -> 2.1363854e+10 | AG29: =E29/C29 -> 0.17732665 | AQ29: -21314681680 | AR29: =AQ29+K29 -> 49172771
B30: Instalasi Elektrik | C30: =K67 -> 397178000 | E30: ='6. Instalasi Elektrik'!AP43 -> 72614000 | G30: 0 | K30: =C30+E30+G30+I30 -> 469792000 | AQ30: -469792000 | AR30: =AQ30+K30 -> 0
B31: Kendaraan | C31: =K68 -> 7346435000 | E31: ='7. Kendaraan'!AP69 -> 982475000 | G31: 0 | I31: 0 | K31: =C31+E31+G31+I31+0.5 -> 8.32891e+09 | AQ31: -8328910000 | AR31: =AQ31+K31 -> 0.5
B32: Peralatan dan Perlengkapan | C32: =K69 -> 1.1746927e+09 | E32: ='8 Peralatan & Perlengkapan'!AP149 -> 64098844 | G32: 0 | I32: 0 | K32: =C32+E32+G32+I32 -> 1.2387915e+09 | AQ32: -1238791525 | AR32: =AQ32+K32 -> 0.16666675
B33: Infrastruktur | C33: =K70 -> 9.0731326e+09 | E33: ='9. Infrastruktur'!AP50 -> 1.3247535e+09 | G33: 0 | I33: 0 | K33: =C33+E33+G33+I33 -> 1.0397886e+10 | AQ33: -10397886078 | AR33: =AQ33+K33 -> 0.35000038
B35: Jumlah | C35: =SUM(C26:C34) -> 4.9075323e+10 | E35: =SUM(E26:E34) -> 7.9540943e+09 | G35: =SUM(G26:G34) -> 0 | H35: =SUM(H26:H33) -> 0 | I35: =SUM(I26:I34) -> 0 | K35: =SUM(K26:K34) -> 5.7029418e+10 | AQ35: WBS | AR35: Selisih By Penyusutan | AS35: WBS | AT35: Selisih Akm Penyusutan
AQ36: 7.9540943e+09 | AR36: =AQ36-E35 -> 0 | AS36: 5.7029418e+10 | AT36: =K35+AS36 -> 1.1405884e+11
B37: Nilai Buku | C37: =C23-C35 -> 5.461572e+10 | K37: =K23-K35 -> 4.6810741e+10
C41: WS
C42: 2022
C43: Saldo Awal | E43: Penambahan | G43: Pengurangan | I43: Reklasifikasi | K43: Saldo Akhir
B45: Nilai Perolehan
B46: Tanah | C46: =K85 -> 0 | E46: 0 | G46: 0 | K46: =C46+E46+G46+I46 -> 0 | Q46: 5357572749 | S46: =K46-Q46 -> -5357572749 | T46: 5357572749 | U46: =K46-T46 -> -5357572749
B47: Bangunan | C47: =K86 -> 3.7188156e+10 | E47: ='2. Bangunan'!F128 -> 0 | G47: 0 | I47: 0 | K47: =C47+E47+G47+I47 -> 3.7188156e+10 | Q47: 36346508225 | S47: =K47-Q47 -> 8.4164793e+08 | T47: 36346558225 | U47: =K47-T47 -> 8.4159793e+08 | AF47: 36346558225 | AG47: =K47-AF47 -> 8.4159793e+08
B48: Sumur Bor | C48: =K87 -> 445059500 | E48: ='3. Sumur Bor'!F53 -> 0 | G48: 0 | K48: =C48+E48+G48+I48 -> 445059500 | Q48: 445059500 | S48: =K48-Q48 -> 0 | T48: 445059500 | U48: =K48-T48 -> 0 | AF48: 445059500 | AG48: =K48-AF48 -> 0
B49: Sarana dan Prasarana | C49: =K88 -> 6200217370 | E49: ='4. Sarana & Prasarana'!F42 -> 0 | G49: 0 | K49: =C49+E49+G49+I49 -> 6200217370 | Q49: 6241971770 | S49: =K49-Q49 -> -41754400 | T49: 6241971770 | U49: =K49-T49 -> -41754400 | AF49: 6200217370 | AG49: =K49-AF49 -> 0
...

Sheet NBV sdh habis
A1: KATEGORI ASET YANG SUDAH HABIS NBV
C3: 2024 | F3: =SUM(F5:F279) -> 3.076226e+10 | K3: 2023 | N3: =SUM(N5:N253) -> 2.5397181e+10
B4: No | C4: Kategori Aset | D4: Nama Aset | E4: Tahun Perolehan | F4: Nilai Aset | J4: No | K4: Kategori Aset | L4: Nama Aset | M4: Tahun Perolehan | N4: Nilai Aset
B5: 1 | C5: Sumur Bor | D5: ='3. Sumur Bor'!B5 -> Sumur Bor | E5: ='3. Sumur Bor'!C5 -> 37257 | F5: ='3. Sumur Bor'!E5 -> 222800000 | J5: 1 | K5: Sumur Bor | L5: ='3. Sumur Bor'!B5 -> Sumur Bor | M5: ='3. Sumur Bor'!C5 -> 37257 | N5: ='3. Sumur Bor'!E5 -> 222800000
B6: =B5+1 -> 2 | C6: Sumur Bor | D6: ='3. Sumur Bor'!B6 -> Sumur Bor | E6: ='3. Sumur Bor'!C6 -> 38353 | F6: ='3. Sumur Bor'!E6 -> 68200000 | J6: =J5+1 -> 2 | K6: Sumur Bor | L6: ='3. Sumur Bor'!B6 -> Sumur Bor | M6: ='3. Sumur Bor'!C6 -> 38353 | N6: ='3. Sumur Bor'!E6 -> 68200000
B7: =B6+1 -> 3 | C7: Sumur Bor | D7: ='3. Sumur Bor'!B7 -> Sumur Bor | E7: ='3. Sumur Bor'!C7 -> 38718 | F7: ='3. Sumur Bor'!E7 -> 68500000 | J7: =J6+1 -> 3 | K7: Sumur Bor | L7: ='3. Sumur Bor'!B7 -> Sumur Bor | M7: ='3. Sumur Bor'!C7 -> 38718 | N7: ='3. Sumur Bor'!E7 -> 68500000
B8: =B7+1 -> 4 | C8: Sumur Bor | D8: ='3. Sumur Bor'!B8 -> Pompa Submersible SP17 | E8: 42005 | F8: ='3. Sumur Bor'!E12 -> 17000000 | J8: =J7+1 -> 4 | K8: Sumur Bor | L8: ='3. Sumur Bor'!B12 -> Pompa Submersible Type MS 4000 | M8: ='3. Sumur Bor'!C12 -> 42005 | N8: ='3. Sumur Bor'!E12 -> 17000000
B9: =B8+1 -> 5 | C9: Sarana dan Prasarana | D9: Perkerasan Paving Blok | E9: 40544 | F9: ='4. Sarana & Prasarana'!E6 -> 573153000 | J9: =J8+1 -> 5 | K9: Sarana & Prasarana | L9: ='4. Sarana & Prasarana'!B6 -> Perkerasan Paving Blok | M9: ='4. Sarana & Prasarana'!C6 -> 40544 | N9: ='4. Sarana & Prasarana'!E6 -> 573153000
B10: =B9+1 -> 6 | C10: Sarana dan Prasarana | D10: Paving Blok Uni Abu-Abu | E10: 43466 | F10: ='4. Sarana & Prasarana'!E8 -> 397432750 | J10: =J9+1 -> 6 | K10: Sarana & Prasarana | L10: ='4. Sarana & Prasarana'!B8 -> Paving Blok Uni Abu-Abu | M10: ='4. Sarana & Prasarana'!C8 -> 43466 | N10: ='4. Sarana & Prasarana'!E8 -> 397432750
B11: =B10+1 -> 7 | C11: Sarana dan Prasarana | D11: Talud | E11: 38353 | F11: ='4. Sarana & Prasarana'!E10 -> 117276000 | J11: =J10+1 -> 7 | K11: Sarana & Prasarana | L11: ='4. Sarana & Prasarana'!B10 -> Talud | M11: ='4. Sarana & Prasarana'!C10 -> 38353 | N11: ='4. Sarana & Prasarana'!E10 -> 117276000
B12: =B11+1 -> 8 | C12: Sarana dan Prasarana | D12: Pagar | E12: 41640 | F12: ='4. Sarana & Prasarana'!E12 -> 125361500 | J12: =J11+1 -> 8 | K12: Sarana & Prasarana | L12: ='4. Sarana & Prasarana'!B12 -> Pagar | M12: ='4. Sarana & Prasarana'!C12 -> 41640 | N12: ='4. Sarana & Prasarana'!E12 -> 125361500
B13: =B12+1 -> 9 | C13: Sarana dan Prasarana | D13: Jembatan Automatis Feeder | E13: 43344 | F13: ='4. Sarana & Prasarana'!E15 -> 77464120 | J13: =J12+1 -> 9 | K13: Sarana & Prasarana | L13: ='4. Sarana & Prasarana'!B15 -> Jembatan Automatis Feeder | M13: ='4. Sarana & Prasarana'!C15 -> 43344 | N13: ='4. Sarana & Prasarana'!E15 -> 77464120
B14: =B13+1 -> 10 | C14: Mesin | D14: Panel Genset / Kabel Dll | E14: 37257 | F14: 70900000 | J14: =J13+1 -> 10 | K14: Mesin | L14: ='5. Mesin'!B19 -> Panel Genset / Kabel Dll | M14: ='5. Mesin'!C19 -> 37257 | N14: ='5. Mesin'!E19 -> 70900000
B15: =B14+1 -> 11 | C15: Mesin | D15: Genset 500 KVA Mercy | E15: 38353 | F15: 441100000 | J15: =J14+1 -> 11 | K15: Mesin | L15: ='5. Mesin'!B20 -> Genset 500 KVA Mercy | M15: ='5. Mesin'!C20 -> 38353 | N15: ='5. Mesin'!E20 -> 441100000
B16: =B15+1 -> 12 | C16: Mesin | D16: Genset MWM 500 KVA | E16: 40909 | F16: 176900000 | J16: =J15+1 -> 12 | K16: Mesin | L16: ='5. Mesin'!B21 -> Genset MWM 500 KVA | M16: ='5. Mesin'!C21 -> 40909 | N16: ='5. Mesin'!E21 -> 176900000
B17: =B16+1 -> 13 | C17: Mesin | D17: Water Treatment Machine | E17: 37257 | F17: 1400000 | J17: =J16+1 -> 13 | K17: Mesin | L17: ='5. Mesin'!B23 -> Water Treatment Machine | M17: ='5. Mesin'!C23 -> 37257 | N17: ='5. Mesin'!E23 -> 1400000
B18: =B17+1 -> 14 | C18: Mesin | D18: Water Treatment Machine | E18: 38353 | F18: 2600000 | J18: =J17+1 -> 14 | K18: Mesin | L18: ='5. Mesin'!B24 -> Water Treatment Machine | M18: ='5. Mesin'!C24 -> 38353 | N18: ='5. Mesin'!E24 -> 2600000
B19: =B18+1 -> 15 | C19: Mesin | D19: Compresor (Budiono) | E19: 37257 | F19: 52800000 | J19: =J18+1 -> 15 | K19: Mesin | L19: ='5. Mesin'!B28 -> Compresor (Budiono) | M19: ='5. Mesin'!C28 -> 37257 | N19: ='5. Mesin'!E28 -> 52800000
B20: =B19+1 -> 16 | C20: Mesin | D20: Compressor (Grasco) | E20: 37257 | F20: 252600000 | J20: =J19+1 -> 16 | K20: Mesin | L20: ='5. Mesin'!B29 -> Compressor (Grasco) | M20: ='5. Mesin'!C29 -> 37257 | N20: ='5. Mesin'!E29 -> 252600000
B21: =B20+1 -> 17 | C21: Mesin | D21: Asesoris Compressor | E21: 37622 | F21: 74900000 | J21: =J20+1 -> 17 | K21: Mesin | L21: ='5. Mesin'!B30 -> Asesoris Compressor | M21: ='5. Mesin'!C30 -> 37622 | N21: ='5. Mesin'!E30 -> 74900000
B22: =B21+1 -> 18 | C22: Mesin | D22: Compressor Mycom | E22: 38353 | F22: 86200000 | J22: =J21+1 -> 18 | K22: Mesin | L22: ='5. Mesin'!B31 -> Compressor Mycom | M22: ='5. Mesin'!C31 -> 38353 | N22: ='5. Mesin'!E31 -> 86200000
B23: =B22+1 -> 19 | C23: Mesin | D23: Cylinder Liner Comp. Grasso | E23: 39448 | F23: 4600000 | J23: =J22+1 -> 19 | K23: Mesin | L23: ='5. Mesin'!B32 -> Cylinder Liner Comp. Grasso | M23: ='5. Mesin'!C32 -> 39448 | N23: ='5. Mesin'!E32 -> 4600000
B24: =B23+1 -> 20 | C24: Mesin | D24: Compressor Mycom-Djunisanu | E24: 39448 | F24: 155200000 | J24: =J23+1 -> 20 | K24: Mesin | L24: ='5. Mesin'!B33 -> Compressor Mycom-Djunisanu | M24: ='5. Mesin'!C33 -> 39448 | N24: ='5. Mesin'!E33 -> 155200000
B25: =B24+1 -> 21 | C25: Mesin | D25: Conveyor | E25: 39083 | F25: 168100000 | J25: =J24+1 -> 21 | K25: Mesin | L25: ='5. Mesin'!B37 -> Conveyor | M25: ='5. Mesin'!C37 -> 39083 | N25: ='5. Mesin'!E37 -> 168100000
B26: =B25+1 -> 22 | C26: Mesin | D26: Material Inter Cooler | E26: 39448 | F26: 39300000 | J26: =J25+1 -> 22 | K26: Mesin | L26: ='5. Mesin'!B38 -> Material Inter Cooler | M26: ='5. Mesin'!C38 -> 39448 | N26: ='5. Mesin'!E38 -> 39300000
B27: =B26+1 -> 23 | C27: Mesin | D27: Siku Conveyor | E27: 39448 | F27: 20800000 | J27: =J26+1 -> 23 | K27: Mesin | L27: ='5. Mesin'!B39 -> Siku Conveyor | M27: ='5. Mesin'!C39 -> 39448 | N27: ='5. Mesin'!E39 -> 20800000
B28: =B27+1 -> 24 | C28: Mesin | D28: Besi Conveyor | E28: 39448 | F28: 10500000 | J28: =J27+1 -> 24 | K28: Mesin | L28: ='5. Mesin'!B40 -> Besi Conveyor | M28: ='5. Mesin'!C40 -> 39448 | N28: ='5. Mesin'!E40 -> 10500000
B29: =B28+1 -> 25 | C29: Mesin | D29: Wayer Pompa Grundfos | E29: 39814 | F29: 7900000 | J29: =J28+1 -> 25 | K29: Mesin | L29: ='5. Mesin'!B41 -> Wayer Pompa Grundfos | M29: ='5. Mesin'!C41 -> 39814 | N29: ='5. Mesin'!E41 -> 7900000
B30: =B29+1 -> 26 | C30: Mesin | D30: Shrimp Cutter Machine | E30: 39814 | F30: 97100000 | J30: =J29+1 -> 26 | K30: Mesin | L30: ='5. Mesin'!B42 -> Shrimp Cutter Machine | M30: ='5. Mesin'!C42 -> 39814 | N30: ='5. Mesin'!E42 -> 97100000
B31: =B30+1 -> 27 | C31: Mesin | D31: Mesin Foot Impulse Sealer | E31: 40544 | F31: 4800000 | J31: =J30+1 -> 27 | K31: Mesin | L31: ='5. Mesin'!B43 -> Mesin Foot Impulse Sealer | M31: ='5. Mesin'!C43 -> 40544 | N31: ='5. Mesin'!E43 -> 4800000
B32: =B31+1 -> 28 | C32: Mesin | D32: Meteran Solar 1 1/2" | E32: 40909 | F32: 5000000 | J32: =J31+1 -> 28 | K32: Mesin | L32: ='5. Mesin'!B44 -> Meteran Solar 1 1/2" | M32: ='5. Mesin'!C44 -> 40909 | N32: ='5. Mesin'!E44 -> 5000000
B33: =B32+1 -> 29 | C33: Mesin | D33: Steam Boiler Miura | E33: 40909 | F33: 248145455 | J33: =J32+1 -> 29 | K33: Mesin | L33: ='5. Mesin'!B45 -> Steam Boiler Miura | M33: ='5. Mesin'!C45 -> 40909 | N33: ='5. Mesin'!E45 -> 248145455
B34: =B33+1 -> 30 | C34: Mesin | D34: Inverter LS 20 HP | E34: 41275 | F34: 9200000 | J34: =J33+1 -> 30 | K34: Mesin | L34: ='5. Mesin'!B46 -> Inverter LS 20 HP | M34: ='5. Mesin'!C46 -> 41275 | N34: ='5. Mesin'!E46 -> 9200000
B35: =B34+1 -> 31 | C35: Mesin | D35: Tangki Amoniak | E35: 41275 | F35: 36200000 | J35: =J34+1 -> 31 | K35: Mesin | L35: ='5. Mesin'!B47 -> Tangki Amoniak | M35: ='5. Mesin'!C47 -> 41275 | N35: ='5. Mesin'!E47 -> 36200000
B36: =B35+1 -> 32 | C36: Mesin | D36: Blower Impeler | E36: 41275 | F36: 28000000 | J36: =J35+1 -> 32 | K36: Mesin | L36: ='5. Mesin'!B48 -> Blower Impeler | M36: ='5. Mesin'!C48 -> 41275 | N36: ='5. Mesin'!E48 -> 28000000
... B45: =B44+1 -> 41 | C45: Mesin | D45: Mesin Pompa Air | E45: 42247 | F45: 5300000 | J45: =J44+1 -> 41 | K45: Mesin | L45: ='5. Mesin'!B57 -> Mesin Pompa Air | M45: ='5. Mesin'!C57 -> 42247 | N45: ='5. Mesin'!E57 -> 5300000
B46: =B45+1 -> 42 | C46: Mesin | D46: Pompa Submersible HCP @ 1 uit | E46: 42594 | F46: 8600000 | J46: =J45+1 -> 42 | K46: Mesin | L46: ='5. Mesin'!B73 -> Steam Boiler Cold Storage 2 | M46: ='5. Mesin'!C73 -> 39448 | N46: ='5. Mesin'!E73 -> 26600000
B47: =B46+1 -> 43 | C47: Mesin | D47: Inventer | E47: 42630 | F47: 15925000 | J47: =J46+1 -> 43 | K47: Mesin | L47: ='5. Mesin'!B74 -> Roller Chains 40x1 | M47: ='5. Mesin'!C74 -> 39814 | N47: ='5. Mesin'!E74 -> 3200000
B48: =B47+1 -> 44 | C48: Mesin | D48: Steam Boiler Cold Storage 2 | E48: 39448 | F48: 26600000 | J48: =J47+1 -> 44 | K48: Mesin | L48: ='5. Mesin'!B75 -> Sproket SS RS 40x60 | M48: ='5. Mesin'!C75 -> 39814 | N48: ='5. Mesin'!E75 -> 5700000
B49: =B48+1 -> 45 | C49: Mesin | D49: Roller Chains 40x1 | E49: 39814 | F49: 3200000 | J49: =J48+1 -> 45 | K49: Mesin | L49: ='5. Mesin'!B77 -> Mesin Cutter Zeppelin & Shrimp Cutter Machine | M49: ='5. Mesin'!C77 -> 40179 | N49: ='5. Mesin'!E77 -> 111400000
...

Sheet Disclosure Aset DES 24
B2: WS
B3: 45627
B4: Saldo Awal | D4: Penambahan | F4: Pengurangan | H4: Reklasifikasi | J4: Saldo Akhir
A6: Nilai Perolehan
A7: Tanah | B7: ='Disclosure Aset'!K9 -> 0 | J7: =B7+D7+F7+H7 -> 0
A8: Bangunan | B8: ='Disclosure Aset'!K10 -> 3.7188156e+10 | J8: =B8+D8+F8+H8 -> 3.7188156e+10
A9: Sumur Bor | B9: ='Disclosure Aset'!K11 -> 445059500 | J9: =B9+D9+F9+H9 -> 445059500
A10: Sarana dan Prasarana | B10: ='Disclosure Aset'!K12 -> 6200217370 | J10: =B10+D10+F10+H10 -> 6200217370
A11: Mesin | B11: ='Disclosure Aset'!K13 -> 3.7618136e+10 | D11: ='5. Mesin'!F330 -> 170000000 | J11: =B11+D11+F11+H11 -> 3.7788136e+10
A12: Instalasi Elektrik | B12: ='Disclosure Aset'!K14 -> 1452280000 | J12: =B12+D12+F12+H12 -> 1452280000
A13: Kendaraan | B13: ='Disclosure Aset'!K15 -> 8462660000 | J13: =B13+D13+F13+H13 -> 8462660000
A14: Peralatan dan Perlengkapan | B14: ='Disclosure Aset'!K16 -> 1303269796 | J14: =B14+D14+F14+H14 -> 1303269796
A15: Infrastruktur | B15: ='Disclosure Aset'!K17 -> 1.1170379e+10 | J15: =B15+D15+F15+H15 -> 1.1170379e+10
