Workbook

Sheet AJE CAJE Juni 23
B2: Account No. | C2: Date | D2: Account Name | F2: WP Reff | G2: Balance Sheet | I2: PL | K2: Description
G3: Debit | H3: Credit | I3: Debit | J3: Credit
B5: CAJE 1 | D5: Akum. Peny. Mesin | G5: =J9 -> 2999996 | K5: Adj menyamakan nilai Peny
B6: CAJE 1 | D6: Akum. Peny. Peralatan Kantor | G6: =J10 -> 33313.229 | K6: =K5 -> Adj menyamakan nilai Peny
B7: CAJE 1 | D7: Penyusutan Bangunan | I7: 9784354.4 | K7: =K6 -> Adj menyamakan nilai Peny
B8: CAJE 1 | E8: Akum. Peny. Sumur Bor | H8: =I11 -> 3 | K8: =K7 -> Adj menyamakan nilai Peny
B9: =B7 -> CAJE 1 | E9: Penyusutan Mesin-Mesin | J9: 2999996 | K9: =K8 -> Adj menyamakan nilai Peny
B10: =B9 -> CAJE 1 | E10: Penyusutan Peralatan Kantor | J10: 33313.229 | K10: =K9 -> Adj menyamakan nilai Peny
B11: =B10 -> CAJE 1 | D11: Penyusutan Sumur Bor | I11: 3 | K11: =K10 -> Adj menyamakan nilai Peny
B12: =B11 -> CAJE 1 | E12: Akum Peny. Bangunan | G12: 4090645.9 | K12: =K11 -> Adj menyamakan nilai Peny
B13: =B12 -> CAJE 1 | E13: Akum. Peny. Kendaraan | H13: 2 | K13: =K12 -> Adj menyamakan nilai Peny
B14: =B13 -> CAJE 1 | D14: Akum. Peny. Peralatan Produksi | G14: 1 | K14: =K13 -> Adj menyamakan nilai Peny
B15: =B14 -> CAJE 1 | D15: Rumah Tangga Kantor | J15: 13874999 | K15: =K14 -> Adj menyamakan nilai Peny
B17: RKLS 1 | D17: Depreciation | I17: =SUM(J18:J23) -> 1.1571403e+09 | K17: Reklas Beban Peny GA ke COGS
B18: =B17 -> RKLS 1 | E18: Penyusutan Bangunan | J18: 616777705 | K18: =K17 -> Reklas Beban Peny GA ke COGS
B19: =B18 -> RKLS 1 | E19: Penyusutan Mesin-Mesin | J19: 389528236 | K19: =K18 -> Reklas Beban Peny GA ke COGS
B20: =B19 -> RKLS 1 | E20: Penyusutan Kendaraan | J20: 1.0188992e+08 | K20: =K19 -> Reklas Beban Peny GA ke COGS
B21: =B20 -> RKLS 1 | E21: Penyusutan Peralatan Produksi | J21: 22060056 | K21: =K20 -> Reklas Beban Peny GA ke COGS
B22: =B21 -> RKLS 1 | E22: Penyusutan Sumur Bor | J22: 13009413 | K22: =K21 -> Reklas Beban Peny GA ke COGS
E23: Penyusutan Electricity Instalasi | J23: 13875000 | K23: =K22 -> Reklas Beban Peny GA ke COGS
B25: CAJE 2 | D25: PT Indokom Samudra Persada - Utang | G25: 7919262741 | K25: Adj Menyamakan Utang Piutang Afiliasi IAS-ISP Jun 23
B26: =B25 -> CAJE 2 | E26: PT Indokom Samudra Persada - Piutang | H26: =G25 -> 7919262741 | K26: =K25 -> Adj Menyamakan Utang Piutang Afiliasi IAS-ISP Jun 23
B28: CAJE 3 | D28: Pajak Lain-Lain | I28: =H29-G30 -> 10621125 | K28: Adj atas Pemb Pajak PPh 21 & 23
B29: =B28 -> CAJE 3 | E29: Utang PPh 21 | H29: 10621147 | K29: =K28 -> Adj atas Pemb Pajak PPh 21 & 23
B30: CAJE 3 | E30: Utang PPh 23 | G30: 22 | K30: =K29 -> Adj atas Pemb Pajak PPh 21 & 23
B32: CAJE 4 | D32: Materai, Koran & Majalah | I32: 2335000 | K32: Adj angka minus
B33: =B32 -> CAJE 4 | D33: Surat-Surat Perizinan | I33: 873540 | K33: =K32 -> Adj angka minus
B34: =B33 -> CAJE 4 | E34: BYMH | H34: =SUM(I32:I33) -> 3208540 | K34: =K33 -> Adj angka minus
B36: CAJE 5 | D36: BYMH | G36: =SUM(H37:H39) -> 2443062
B37: =B36 -> CAJE 5 | E37: Utang PPh 21 | H37: 2443062
B38: =B37 -> CAJE 5 | E38: Utang Pph 22 | H38: =49398282*0 -> 0
B39: =B38 -> CAJE 5 | E39: Utang Pph 23 | H39: =33436121*0 -> 0
B41: CAJE 6 | D41: BYMH
B42: =B41 -> CAJE 6 | E42: Gaji
B45: CAJE 7 | D45: Aset dalam Pembangunan | G45: 168752996
B46: =B45 -> CAJE 7 | D46: Mesin Dalam Pelaksanaan | G46: 192000000
B47: =B46 -> CAJE 7 | E47: CV Kanian Persada | H47: =SUM(G45:G46) -> 360752996
D48: (Adj Aset dalam Proses ke Piutang CV Kanian)
B50: CAJE 8 | D50: Beban Pajak Kini | I50: =SUM(H51:H53) -> 301219820 | K50: Perhitungan Pajak Badan Juni 2023
B51: =B50 -> CAJE 8 | E51: Prepaid PPh 25 | H51: 55018816 | K51: =K50 -> Perhitungan Pajak Badan Juni 2023
...

Sheet AJE CAJE Juni 24
B3: Account No. | C3: Date | D3: Account Name | F3: WP Reff | G3: Balance Sheet | I3: PL | K3: Description
G4: Debit | H4: Credit | I4: Debit | J4: Credit
B6: CAJE 1 | D6: Akum. Peny. Kendaraan | G6: 12187500 | K6: Adj menyamakan nilai Peny
B7: =B6 -> CAJE 1 | E7: Akum. Peny. Kendaraan Alat Berat | H7: =G6 -> 12187500 | K7: =K6 -> Adj menyamakan nilai Peny
B9: CAJE 2 | E9: Akum Peny. Bangunan | H9: 2 | K9: Adj menyamakan nilai Peny
B10: =B9 -> CAJE 2 | D10: Akum. Peny. Mesin | G10: 2 | K10: =K9 -> Adj menyamakan nilai Peny
B11: =B10 -> CAJE 2 | E11: Akum. Peny. Peralatan Kantor | H11: 1 | K11: =K10 -> Adj menyamakan nilai Peny
B12: =B11 -> CAJE 2 | E12: Akum. Peny. Peralatan Produksi | H12: 1 | K12: =K11 -> Adj menyamakan nilai Peny
B13: =B12 -> CAJE 2 | E13: Akum. Peny. Sumur Bor | H13: 3 | K13: =K12 -> Adj menyamakan nilai Peny
B14: =B13 -> CAJE 2 | D14: Penyusutan Peralatan Kantor | I14: 1 | K14: =K13 -> Adj menyamakan nilai Peny
B15: =B14 -> CAJE 2 | D15: Penyusutan Bangunan | I15: 1 | K15: =K14 -> Adj menyamakan nilai Peny
B16: =B15 -> CAJE 2 | E16: Penyusutan Mesin-Mesin | J16: 2 | K16: =K15 -> Adj menyamakan nilai Peny
B17: =B16 -> CAJE 2 | D17: Penyusutan Peralatan Produksi | I17: 1 | K17: =K16 -> Adj menyamakan nilai Peny
B18: =B17 -> CAJE 2 | D18: Penyusutan Sumur Bor | I18: 3 | K18: =K17 -> Adj menyamakan nilai Peny
B20: RKLS 1 | D20: Depreciation | I20: =SUM(J21:J25) -> 1040987145 | K20: Reklas Beban Peny GA ke COGS
B21: =B20 -> RKLS 1 | E21: Penyusutan Bangunan | J21: 616777705 | K21: =K20 -> Reklas Beban Peny GA ke COGS
B22: =B21 -> RKLS 1 | E22: Penyusutan Mesin-Mesin | J22: 389528236 | K22: =K21 -> Reklas Beban Peny GA ke COGS
B23: =B22 -> RKLS 1 | E23: Penyusutan Kendaraan | J23: 12187500 | K23: =K22 -> Reklas Beban Peny GA ke COGS
B24: =B23 -> RKLS 1 | E24: Penyusutan Peralatan Produksi | J24: 9484291 | K24: =K23 -> Reklas Beban Peny GA ke COGS
B25: =B24 -> RKLS 1 | E25: Penyusutan Sumur Bor | J25: 13009413 | K25: =K24 -> Reklas Beban Peny GA ke COGS
B27: CAJE 3 | D27: Eastern Fish Company LLC | G27: 1451616400 | K27: Adj Penj exp dari bulan selanjutnya
B28: =B27 -> CAJE 3 | D28: Censea Inc | G28: 19756663414 | K28: =K27 -> Adj Penj exp dari bulan selanjutnya
B29: =B28 -> CAJE 3 | E29: Udang-Exp | J29: =SUM(G27:G28) -> 21208279814 | K29: =K28 -> Adj Penj exp dari bulan selanjutnya
B31: CAJE 4 | D31: Biaya yang masih dibayar | G31: 15000000 | K31: Adj atas Beban Sewa yang sdh di akui di 2023
B32: =B31 -> CAJE 4 | E32: Biaya Sewa IPAL | J32: =G31 -> 15000000 | K32: =K31 -> Adj atas Beban Sewa yang sdh di akui di 2023
B34: CAJE 5 | D34: PT Indokom Samudra Persada - Utang | G34: 4045423564 | K34: Adj Menyamakan Utang Piutang Afiliasi IAS-ISP Jun 24
B35: =B34 -> CAJE 5 | E35: PT Indokom Samudra Persada - Piutang | H35: =G34 -> 4045423564 | K35: =K34 -> Adj Menyamakan Utang Piutang Afiliasi IAS-ISP Jun 24
B37: CAJE 6 | D37: Pajak Lain-Lain | I37: 26704968 | K37: Adj atas Pemb Pajak PPh 21
B38: =B37 -> CAJE 6 | E38: Utang PPh 21 | H38: =I37 -> 26704968 | K38: =K37 -> Adj atas Pemb Pajak PPh 21
B40: CAJE 7 | D40: Prepaid PPh 22 | G40: =H41 -> 15505370 | K40: Adj atas Pemb Pajak PPh 22
B41: =B40 -> CAJE 7 | E41: Utang Pph 22 | H41: 15505370 | K41: =K40 -> Adj atas Pemb Pajak PPh 22
B43: CAJE 8 | D43: Prepaid 25 | G43: 158105967 | K43: Adj atas Pemb Pajak PPh 25
B44: =B43 -> CAJE 8 | E44: Utang Pph 25 | H44: =G43 -> 158105967 | K44: =K43 -> Adj atas Pemb Pajak PPh 25
B46: CAJE 9 | D46: Utang Pph 23 | G46: 1 | K46: Adj atas Pemb Pajak PPh 23
B47: =B46 -> CAJE 9 | E47: Pajak Lain-Lain | J47: 1 | K47: =K46 -> Adj atas Pemb Pajak PPh 23
B49: CAJE 10 | D49: BYMH | G49: =SUM(H50:H53) -> 90033000 | K49: Reklas atas utang Pajak
B50: =B49 -> CAJE 10 | E50: Utang Pph 25 | H50: 52701989 | K50: =K49 -> Reklas atas utang Pajak
B51: =B50 -> CAJE 10 | E51: Utang PPh 21 | H51: 3477203 | K51: =K50 -> Reklas atas utang Pajak
B52: =B51 -> CAJE 10 | E52: Utang Pph 22 | H52: 13312446 | K52: =K51 -> Reklas atas utang Pajak
B53: =B52 -> CAJE 10 | E53: Utang Pph 23 | H53: 20541362 | K53: =K52 -> Reklas atas utang Pajak
...

Sheet AJE CAJE Sept 23
B2: Account No. | C2: Date | D2: Account Name | F2: WP Reff | G2: Balance Sheet | I2: PL | K2: Description
G3: Debit | H3: Credit | I3: Debit | J3: Credit
B5: CAJE 1 | D5: Akum. Peny. Mesin | G5: =J9 -> 5999994 | K5: Adj menyamakan nilai Peny
B6: CAJE 1 | D6: Akum. Peny. Peralatan Kantor | G6: =J10 -> 133252.23 | K6: =K5 -> Adj menyamakan nilai Peny
B7: CAJE 1 | E7: Penyusutan Bangunan | J7: 8181288.9 | K7: =K6 -> Adj menyamakan nilai Peny
B8: CAJE 1 | E8: Akum. Peny. Sumur Bor | H8: =I11 -> 3.75 | K8: =K7 -> Adj menyamakan nilai Peny
B9: =B7 -> CAJE 1 | E9: Penyusutan Mesin-Mesin | J9: 5999994 | K9: =K8 -> Adj menyamakan nilai Peny
B10: =B9 -> CAJE 1 | E10: Penyusutan Peralatan Kantor | J10: 133252.23 | K10: =K9 -> Adj menyamakan nilai Peny
B11: =B10 -> CAJE 1 | D11: Penyusutan Sumur Bor | I11: 3.75 | K11: =K10 -> Adj menyamakan nilai Peny
B12: =B11 -> CAJE 1 | E12: Akum Peny. Bangunan | G12: =J7 -> 8181288.9 | K12: =K11 -> Adj menyamakan nilai Peny
B13: =B12 -> CAJE 1 | D13: Akum. Peny. Peralatan Produksi | G13: =J14 -> 0.5625 | K13: =K12 -> Adj menyamakan nilai Peny
B14: =B13 -> CAJE 1 | E14: Penyusutan Peralatan Produksi | J14: 0.5625 | K14: =K13 -> Adj menyamakan nilai Peny
B16: RKLS 1 | D16: Depreciation | I16: =SUM(J17:J22) -> 1696263520 | K16: Reklas Beban Peny GA ke COGS
B17: =B16 -> RKLS 1 | E17: Penyusutan Bangunan | J17: 904354058 | K17: =K16 -> Reklas Beban Peny GA ke COGS
B18: =B17 -> RKLS 1 | E18: Penyusutan Mesin-Mesin | J18: 584292354 | K18: =K17 -> Reklas Beban Peny GA ke COGS
B19: =B18 -> RKLS 1 | E19: Penyusutan Kendaraan | J19: 134200406 | K19: =K18 -> Reklas Beban Peny GA ke COGS
B20: =B19 -> RKLS 1 | E20: Penyusutan Peralatan Produksi | J20: 33090083 | K20: =K19 -> Reklas Beban Peny GA ke COGS
B21: =B20 -> RKLS 1 | E21: Penyusutan Sumur Bor | J21: 19514119 | K21: =K20 -> Reklas Beban Peny GA ke COGS
B22: =B21 -> RKLS 1 | E22: Penyusutan Electricity Instalasi | J22: 20812500 | K22: =K21 -> Reklas Beban Peny GA ke COGS
B24: CAJE 2 | D24: PT Indokom Samudra Persada - Utang | G24: 8.9856203e+09 | K24: Adj Menyamakan Utang Piutang Afiliasi IAS-ISP Jun 23
B25: =B24 -> CAJE 2 | E25: PT Indokom Samudra Persada - Piutang | H25: =G24 -> 8.9856203e+09 | K25: =K24 -> Adj Menyamakan Utang Piutang Afiliasi IAS-ISP Jun 23
B27: CAJE 3 | D27: Pajak Lain-Lain | I27: =SUM(H28:H29)-G29 -> 14980428 | K27: Adj atas Pemb Pajak PPh 21 & 23
B28: =B27 -> CAJE 3 | E28: Utang PPh 21 | H28: 14980451 | K28: =K27 -> Adj atas Pemb Pajak PPh 21 & 23
B29: CAJE 3 | E29: Utang PPh 23 | G29: 23 | K29: =K28 -> Adj atas Pemb Pajak PPh 21 & 23
B31: CAJE 4 | D31: Materai, Koran & Majalah | I31: 3620000 | K31: Adj angka minus
B32: =B31 -> CAJE 4 | D32: Surat-Surat Perizinan | I32: 21493790 | K32: =K31 -> Adj angka minus
B33: =B32 -> CAJE 4 | E33: BYMH | H33: =SUM(I31:I32) -> 25113790 | K33: =K32 -> Adj angka minus
B35: CAJE 5 | D35: BYMH | G35: =SUM(H36:H38) -> 47192104 | K35: Reklas atas utang Pajak
B36: =B35 -> CAJE 5 | E36: Utang PPh 21 | H36: 2479613 | K36: =K35 -> Reklas atas utang Pajak
B37: =B36 -> CAJE 5 | E37: Utang Pph 22 | H37: 30384164 | K37: =K36 -> Reklas atas utang Pajak
B38: =B37 -> CAJE 5 | E38: Utang Pph 23 | H38: 14328327 | K38: =K37 -> Reklas atas utang Pajak
B40: CAJE 7 | D40: Aset dalam Pembangunan | G40: 168752996
B41: =B40 -> CAJE 7 | D41: Mesin Dalam Pelaksanaan | G41: 192000000
B42: =B41 -> CAJE 7 | E42: CV Kanian Persada | H42: =SUM(G40:G41) -> 360752996
D43: (Adj Aset dalam Proses ke Piutang CV Kanian)
B45: RLKS 2 | D45: PT Irian Marine Product Development | G45: 2e+08 | K45: Reklas Atas Piutang Irian Marine
B46: =B45 -> RLKS 2 | E46: PT Irian Marine Product Development | H46: =G45 -> 2e+08 | K46: =K45 -> Reklas Atas Piutang Irian Marine
B49: RLKS 3 | D49: Akum. Peny. Kendaraan | G49: 18281250 | K49: Reklas akm penyusutan Aset
B50: =B49 -> RLKS 3 | E50: Akum. Peny. Kendaraan Alat Berat | H50: =G49 -> 18281250 | K50: =K49 -> Reklas akm penyusutan Aset
B52: CAJE 8 | D52: Rumah Tangga Kantor | G52: =H53 -> 2 | K52: Adj Akm Penyusutan
...

Sheet AJE CAJE Sept 24
B3: Account No. | C3: Date | D3: Account Name | F3: WP Reff | G3: Balance Sheet | I3: PL | K3: Description
G4: Debit | H4: Credit | I4: Debit | J4: Credit
B6: CAJE 1 | D6: Akum. Peny. Kendaraan | G6: 13076156 | K6: Adj menyamakan nilai Peny
B7: =B6 -> CAJE 1 | D7: Penyusutan Kendaraan | I7: =H8-G6 -> 5205094.1 | K7: Adj menyamakan nilai Peny
B8: =B6 -> CAJE 1 | E8: Akum. Peny. Kendaraan Alat Berat | H8: 18281250 | K8: =K6 -> Adj menyamakan nilai Peny
B10: CAJE 2 | E10: Akum Peny. Bangunan | H10: 3 | K10: Adj menyamakan nilai Peny
B11: =B10 -> CAJE 2 | D11: Akum. Peny. Mesin | H11: =63019280.937499-3 -> 63019278 | K11: =K10 -> Adj menyamakan nilai Peny
B12: =B11 -> CAJE 2 | D12: Akum. Peny. Peralatan Kantor | G12: 340165.67 | K12: =K11 -> Adj menyamakan nilai Peny
B13: =B12 -> CAJE 2 | D13: Akum. Peny. Peralatan Produksi | G13: 2364210.8 | K13: =K12 -> Adj menyamakan nilai Peny
B14: =B13 -> CAJE 2 | E14: Akum. Peny. Sumur Bor | H14: 4 | K14: =K13 -> Adj menyamakan nilai Peny
B15: =B14 -> CAJE 2 | E15: Penyusutan Peralatan Kantor | J15: =G12 -> 340165.67 | K15: =K14 -> Adj menyamakan nilai Peny
B16: =B15 -> CAJE 2 | D16: Penyusutan Bangunan | I16: =H10-0.01800537109375 -> 2.9819946 | K16: =K15 -> Adj menyamakan nilai Peny
B17: =B16 -> CAJE 2 | E17: Penyusutan Mesin-Mesin | I17: =H11 -> 63019278 | J17: =G11 -> 0 | K17: =K16 -> Adj menyamakan nilai Peny
B18: =B17 -> CAJE 2 | E18: Penyusutan Peralatan Produksi | J18: =G13 -> 2364210.8 | K18: =K17 -> Adj menyamakan nilai Peny
B19: =B18 -> CAJE 2 | D19: Penyusutan Sumur Bor | I19: =H14 -> 4 | K19: =K18 -> Adj menyamakan nilai Peny
B21: RKLS 1 | D21: Depreciation | I21: =SUM(J22:J26) -> 1.622489e+09 | K21: Reklas Beban Peny GA ke COGS
B22: =B21 -> RKLS 1 | E22: Penyusutan Bangunan | J22: =925166558.1+0.881 -> 9.2516656e+08 | K22: =K21 -> Reklas Beban Peny GA ke COGS
B23: =B22 -> RKLS 1 | E23: Penyusutan Mesin-Mesin | J23: 6.4731163e+08 | K23: =K22 -> Reklas Beban Peny GA ke COGS
B24: =B23 -> RKLS 1 | E24: Penyusutan Kendaraan | J24: 18634480 | K24: =K23 -> Reklas Beban Peny GA ke COGS
B25: =B24 -> RKLS 1 | E25: Penyusutan Peralatan Produksi | J25: 11862224 | K25: =K24 -> Reklas Beban Peny GA ke COGS
B26: =B25 -> RKLS 1 | E26: Penyusutan Sumur Bor | J26: 19514119 | K26: =K25 -> Reklas Beban Peny GA ke COGS
B28: CAJE 3 | D28: Eastern Fish Company LLC | K28: Adj Penj exp dari bulan selanjutnya
B29: =B28 -> CAJE 3 | D29: Censea Inc | K29: =K28 -> Adj Penj exp dari bulan selanjutnya
B30: =B29 -> CAJE 3 | E30: Udang-Exp | K30: =K29 -> Adj Penj exp dari bulan selanjutnya
B32: CAJE 4 | D32: Biaya yang masih dibayar | G32: 15000000 | K32: Adj atas Beban Sewa yang sdh di akui di 2023
B33: =B32 -> CAJE 4 | E33: Biaya Sewa IPAL | J33: =G32 -> 15000000 | K33: =K32 -> Adj atas Beban Sewa yang sdh di akui di 2023
B35: CAJE 5 | D35: PT Indokom Samudra Persada - Utang | G35: 2.760129e+10 | K35: Adj Menyamakan Utang Piutang Afiliasi IAS-ISP Jun 24
B36: =B35 -> CAJE 5 | E36: PT Indokom Samudra Persada - Piutang | H36: =G35 -> 2.760129e+10 | K36: =K35 -> Adj Menyamakan Utang Piutang Afiliasi IAS-ISP Jun 24
B38: CAJE 6 | D38: Pajak Lain-Lain | K38: Adj atas Pemb Pajak PPh 21
B39: =B38 -> CAJE 6 | E39: Utang PPh 21 | K39: =K38 -> Adj atas Pemb Pajak PPh 21
B41: CAJE 7 | D41: Prepaid PPh 22 | G41: 24522154 | K41: Adj atas Pemb Pajak PPh 22
B42: =B41 -> CAJE 7 | E42: Utang Pph 22 | H42: =G41 -> 24522154 | K42: =K41 -> Adj atas Pemb Pajak PPh 22
B44: CAJE 8 | D44: Prepaid 25 | G44: 316211934 | K44: Adj atas Pemb Pajak PPh 25
B45: =B44 -> CAJE 8 | E45: Utang Pph 25 | H45: =G44 -> 316211934 | K45: =K44 -> Adj atas Pemb Pajak PPh 25
B47: CAJE 9 | D47: Utang Pph 23 | K47: Adj atas Pemb Pajak PPh 23
B48: =B47 -> CAJE 9 | E48: Pajak Lain-Lain | K48: =K47 -> Adj atas Pemb Pajak PPh 23
B50: CAJE 10 | D50: BYMH | G50: =SUM(H51:H54) -> 165770757 | K50: Reklas atas utang Pajak
B51: =B50 -> CAJE 10 | E51: Utang Pph 25 | H51: 52701989 | K51: =K50 -> Reklas atas utang Pajak
B52: =B51 -> CAJE 10 | E52: Utang PPh 21 | H52: 4471644 | K52: =K51 -> Reklas atas utang Pajak
B53: =B52 -> CAJE 10 | E53: Utang Pph 22 | H53: 88055762 | K53: =K52 -> Reklas atas utang Pajak
...

Sheet AJE CAJE Des 24
A2: Account No. | B2: Date | C2: Account Name | E2: WP Reff | F2: Balance Sheet | H2: PL | J2: Description
F3: Debit | G3: Credit | H3: Debit | I3: Credit
H4: 0.25
A5: CAJE 1 | C5: Akum. Peny. Sumur Bor | F5: =I16 -> 5655776 | J5: Adj menyamakan nilai Peny
A6: =A5 -> CAJE 1 | C6: Akum. Peny. Peralatan Produksi | F6: =I15 -> 5036130.8 | J6: Adj menyamakan nilai Peny
A7: =A6 -> CAJE 1 | C7: Akum. Peny. Mesin | F7: =I14 -> 4.473959 | J7: Adj menyamakan nilai Peny
A8: =A7 -> CAJE 1 | C8: Akum. Peny. Peralatan Kantor | F8: =I13 -> 2289582 | J8: Adj menyamakan nilai Peny
A9: =A8 -> CAJE 1 | C9: Akum. Peny. Kendaraan | F9: =I12 -> 6093750 | J9: Adj menyamakan nilai Peny
A10: =A9 -> CAJE 1 | D10: Akum Peny. Bangunan | G10: =H11 -> 3.2833338 | J10: Adj menyamakan nilai Peny
A11: CAJE 1 | C11: Penyusutan Bangunan | H11: =2.80000019073486+0.483333587646484 -> 3.2833338 | J11: Adj menyamakan nilai Peny
A12: =A11 -> CAJE 1 | D12: Penyusutan Kendaraan | I12: =6093749.5+0.5 -> 6093750 | J12: Adj menyamakan nilai Peny
A13: =A12 -> CAJE 1 | D13: Penyusutan Peralatan Kantor | I13: 2289582 | J13: Adj menyamakan nilai Peny
A14: =A13 -> CAJE 1 | D14: Penyusutan Mesin-Mesin | I14: =4+0.473958969116211 -> 4.473959 | J14: Adj menyamakan nilai Peny
A15: =A14 -> CAJE 1 | D15: Penyusutan Peralatan Produksi | I15: =5036131.14583333-0.312499761581421 -> 5036130.8 | J15: Adj menyamakan nilai Peny
A16: =A15 -> CAJE 1 | D16: Penyusutan Sumur Bor | I16: =5655776.25-0.25 -> 5655776 | J16: Adj menyamakan nilai Peny
A18: RLKS 1 | C18: Akum. Peny. Kendaraan | F18: =G19 -> 18281250
A19: RLKS 1 | D19: Akum. Peny. Kendaraan Alat Berat | G19: =ROUND(18281250,0) -> 18281250
A22: CAJE 2 | C22: Depreciation | H22: =SUM(I23:I27) -> 2.2689685e+09 | J22: Reklas Beban Peny GA ke COGS
A23: =A22 -> CAJE 2 | D23: Penyusutan Bangunan | I23: 1.2335554e+09 | J23: Reklas Beban Peny GA ke COGS
A24: =A23 -> CAJE 2 | D24: Penyusutan Mesin-Mesin | I24: 7.7905647e+08 | J24: Reklas Beban Peny GA ke COGS
A25: =A24 -> CAJE 2 | D25: Penyusutan Kendaraan | I25: 222061098 | J25: Reklas Beban Peny GA ke COGS
A26: =A25 -> CAJE 2 | D26: Penyusutan Peralatan Produksi | I26: 13932449 | J26: Reklas Beban Peny GA ke COGS
A27: =A26 -> CAJE 2 | D27: Penyusutan Sumur Bor | I27: 20363044 | J27: Reklas Beban Peny GA ke COGS
A29: CAJE 3 | C29: Biaya Emisi Saham | F29: =G30 -> 3115944915
A30: =A29 -> CAJE 3 | D30: Biaya Pra IPO | G30: 3115944915
C31: (Adj atas Biaya Pra IPO ke Biaya Emisi Saham)
A33: CAJE 4 | C33: Accrued Expanse - Angkut | F33: =1288005813.6*0 -> 0 | J33: PT Rahayu Perdana Trans
A34: CAJE 4 | C34: Accrued Expanse - Angkut | F34: =1186562411.6*0 -> 0 | J34: PT Samudera Naga Global
A35: CAJE 4 | C35: Accrued Expanse - Angkut | F35: =651018689.4*0 -> 0 | J35: PT Samudera Naga Global
A36: CAJE 4 | C36: Accrued Expanse - Angkut | F36: =630543008*0 -> 0 | J36: PT Samudera Naga Global
A37: CAJE 4 | C37: Accrued Expanse - Angkut | F37: =531954338*0 -> 0 | J37: PT Harmoni Prima Indonesia
A38: CAJE 4 | D38: Beban Pengiriman | I38: =SUM(F33:F37) -> 0 | J38: Beban Pingiriman
C39: (Adj atas Accrued Beban Pengiriman)
A41: CAJE 5 | C41: Accrued Expanse - Angkut | F41: =I42 -> 0 | J41: New York Custom Brokers, Inc
A42: =A41 -> CAJE 5 | D42: Duty | I42: =555106934.74*0 -> 0 | J42: New York Custom Brokers, Inc
C43: (Adj atas Accrued Beban Duty)
A45: RLKS 1 | C45: Uang Muka Pembelian Bahan Baku | F45: =SUM(G46:G49) -> 2.7862788e+10 | J45: Reklas atas Uang Muka
A46: =A45 -> RLKS 1 | D46: Shaka Bahari Abadi, PT | G46: 9.3474967e+09 | J46: =J45 -> Reklas atas Uang Muka
A47: =A46 -> RLKS 1 | D47: Marubeni Indonesia, PT | G47: =206460000 -> 206460000 | J47: =J46 -> Reklas atas Uang Muka
A48: =A47 -> RLKS 1 | D48: Hendro Hariyanto | G48: 5.8396535e+09 | J48: =J47 -> Reklas atas Uang Muka | K48: Uang Muka Info Pak Nanda
...

Sheet WS
A4: Note
A7: KONSOLIDASI PT INDO AMERICAN SEAFOODS & PT INDOKOM SAMUDRA PERSADA | C7: =C159 -> 3.0114393e+11 | E7: =E159 -> 3.0013417e+11 | J7: =J159 -> 3.2571294e+11 | N7: =N159 -> 3.0114393e+11 | P7: =P159 -> 3.2494132e+11 | U7: =U159 -> 3.0331116e+11 | W7: =W159 -> 3.0114393e+11 | X7: 3.0114393e+11 | AA7: =AA159 -> 1.7661193e+11 | AC7: =AC159 -> 2.9063231e+11 | AH7: =AH159 -> 281676261822 | AJ7: =AJ159 -> 1.7661193e+11 | AK7: 1.7661193e+11 | AN7: =AN159 -> 1.5390316e+11
A8: WORKING BALANCE SHEETS AND PROFIT OR LOSS | C8: =C329 -> 3.0114393e+11 | E8: =E329 -> 3.0013417e+11 | J8: =J329 -> 3.2571294e+11 | N8: =N329 -> 3.0114393e+11 | P8: =P329 -> 3.2494132e+11 | U8: =U329 -> 3.0331116e+11 | W8: =W329 -> 3.0114393e+11 | X8: 3.0114393e+11 | AA8: =AA329 -> 1.7661193e+11 | AC8: =AC329 -> 2.9063231e+11 | AH8: =AH329 -> 281676261822 | AJ8: =AJ329 -> 1.7661193e+11 | AK8: 1.7661193e+11 | AN8: =AN329 -> 1.5390316e+11
A9: UNTUK TAHUN YANG BERAKHIR 31 DES 2023, 2022 & 31 DES 2021 | C9: =C7-C8 -> 0.99450684 | E9: =E7-E8 -> -0.31549072 | J9: =J7-J8 -> 0.484375 | N9: =N7-N8 -> 0.99450684 | P9: =P7-P8 -> 0.067871094 | U9: =U7-U8 -> 0.049926758 | W9: =W7-W8 -> 0.99450684 | X9: 0.9944458 | AA9: =AA7-AA8 -> -0.12997437 | AC9: =AC7-AC8 -> -0.13000488 | AH9: =AH7-AH8 -> 0 | AJ9: =AJ7-AJ8 -> -0.12997437 | AK9: -0.080047607 | AN9: =AN7-AN8 -> 0.18997192
A11: No Account | B11: Description | C11: Audited PT IAS | D11: Mutasi (Jan-Des) | E11: Unaudited | F11: Auditor AJE/ RJE/ CAJE | J11: Audited | L11: 16162 | N11: Audited PT IAS | O11: Mutasi (Jan-Sept) | P11: Unaudited | Q11: Auditor AJE/ RJE/ CAJE | U11: Audited | W11: Audited PT IAS | X11: Audited Update | AA11: Audited PT IAS | AB11: Mutasi (Jan-Sept) | AC11: Unaudited | AD11: Auditor AJE/ RJE/ CAJE | AH11: Audited | AJ11: Audited PT IAS | AK11: Audited Update | AN11: Audited PT IAS
C12: 31 Desember 2023 | D12: =SUM(D18:D503) -> -0.31002235 | E12: 31 Desember 2024 | F12: Reff | G12: Dr | H12: Reff | I12: Cr | J12: =E12 -> 31 Desember 2024 | K12: Bukti | L12: IDR (Kurs) | M12: Note | N12: 31 Desember 2023 | O12: =SUM(O18:O503) -> 0.073485374 | P12: 30 Sept 2024 | Q12: Reff | R12: Dr | S12: Reff | T12: Cr | U12: =P12 -> 30 Sept 2024 | W12: 31 Desember 2023 | X12: 31 Desember 2023 | AA12: 31 Desember 2022 | AB12: =SUM(AB18:AB503) -> -9.5367432e-07 | AC12: 31 Sept 2023 | AD12: Reff | AE12: Dr | AF12: Reff | AG12: Cr | AH12: =AC12 -> 31 Sept 2023 | AJ12: 31 Desember 2022 | AK12: 31 Desember 2022 | AN12: 31 Desember 2021
A14: ASSETS
A15: Current Assets
A16: Cash
A17: Kas Besar
B18: Kas in Lampung | C18: =W18 -> 52356867 | D18: 1.2038949e+08 | E18: =C18+D18 -> 1.7274635e+08 | J18: =E18+G18-I18 -> 1.7274635e+08 | N18: =W18 -> 52356867 | O18: 1.6936066e+08 | P18: =N18+O18 -> 2.2171753e+08 | U18: =P18+R18-T18 -> 2.2171753e+08 | W18: 52356867 | X18: 52356867 | Y18: =W18-X18 -> 0 | AA18: =AJ18 -> 48995723 | AB18: 11311239 | AC18: =AA18+AB18 -> 60306962 | AH18: =ROUND(AC18+AE18-AG18,0) -> 60306962 | AJ18: 48995723 | AK18: 48995723 | AL18: =AJ18-AK18 -> -0.42001343 | AN18: 19218284
A19: Kas Kecil
B20: Kas in Lampung (Petty Cash) | C20: =W20 -> 685258 | D20: -685258 | E20: =C20+D20 -> 0 | J20: =E20+G20-I20 -> 0 | N20: =W20 -> 685258 | O20: -685258 | P20: =N20+O20 -> 0 | U20: =P20+R20-T20 -> 0 | W20: 685258 | X20: 685258 | Y20: =W20-X20 -> 0 | AA20: =AJ20 -> 685258 | AC20: =AA20+AB20 -> 685258 | AH20: =ROUND(AC20+AE20-AG20,0) -> 685258 | AJ20: 685258 | AK20: 685258 | AL20: =AJ20-AK20 -> 0 | AN20: 928838
B21: Total Cash | C21: =SUM(C18:C20) -> 53042125 | E21: =SUM(E18:E20) -> 1.7274635e+08 | J21: =SUM(J18:J20) -> 1.7274635e+08 | N21: =SUM(N18:N20) -> 53042125 | P21: =SUM(P18:P20) -> 2.2171753e+08 | U21: =SUM(U18:U20) -> 2.2171753e+08 | W21: =SUM(W18:W20) -> 53042125 | X21: 53042125 | Y21: =W21-X21 -> 0 | AA21: =SUM(AA18:AA20) -> 49680981 | AC21: =SUM(AC18:AC20) -> 60992220 | AH21: =SUM(AH18:AH20) -> 60992220 | AJ21: =SUM(AJ18:AJ20) -> 49680981 | AK21: 49680981 | AL21: =AJ21-AK21 -> -0.42001343 | AN21: =SUM(AN18:AN20) -> 20147122
A22: BANK
A23: Bank IDR
B24: Bank Mandiri Rp A/c 114.0031009999 | C24: =W24 -> 0 | E24: =C24+D24 -> 0 | J24: =E24+G24-I24 -> 0 | N24: =W24 -> 0 | P24: =N24+O24 -> 0 | U24: =P24+R24-T24 -> 0 | AA24: =AJ24 -> 3297318 | AB24: -2475000 | AC24: =AA24+AB24 -> 822318 | AH24: =ROUND(AC24+AE24-AG24,0) -> 822318 | AJ24: 3297318 | AK24: 3297318 | AN24: 4103681
B25: Bank Mandiri Rp A/c 114.0004692854 | C25: =W25 -> 2265171 | D25: 2169096.8 | E25: =C25+D25 -> 4434267.8 | I25: ='AJE CAJE Des 24'!G99 -> 786.61 | J25: =E25+G25-I25 -> 4433481.2 | K25: 4433481.2 | M25: =J25-K25 -> 0 | N25: =W25 -> 2265171 | O25: 8478266.9 | P25: =N25+O25 -> 10743438 | U25: =P25+R25-T25 -> 10743438 | W25: 2265171 | X25: 0 | Y25: =W25-X26 -> 0 | AA25: =AJ25 -> 364262986 | AB25: -3.1575321e+08 | AC25: =AA25+AB25 -> 48509780 | AH25: =ROUND(AC25+AE25-AG25,0) -> 48509780 | AJ25: 364262986 | AK25: 364262986 | AN25: 2105276
B26: Bank BNI Rp A/c 111-559-9552 | C26: =W26 -> 0 | D26: 15129380 | E26: =C26+D26 -> 15129380 | J26: =E26+G26-I26 -> 15129380 | K26: 15129380 | M26: =J26-K26 -> 0 | O26: 8.1921479e+09 | P26: =N26+O26 -> 8.1921479e+09 | U26: =P26+R26-T26 -> 8.1921479e+09 | X26: 2265171 | AA26: =AJ26 -> 0 | AC26: =AA26+AB26 -> 0 | AH26: =ROUND(AC26+AE26-AG26,0) -> 0 | AK26: 4306134
B27: Bank BNI Rp A/c 115-599-4474 | C27: =W27 -> 1432417 | D27: -191691 | E27: =C27+D27 -> 1240726 | J27: =E27+G27-I27 -> 1240726 | K27: 1240726 | M27: =J27-K27 -> 0 | N27: =W27 -> 1432417 | O27: 5984165 | P27: =N27+O27 -> 7416582 | U27: =P27+R27-T27 -> 7416582 | W27: 1432417 | X27: 1432417 | AA27: =AJ27 -> 4306134 | AB27: -3301285 | AC27: =AA27+AB27 -> 1004849 | AH27: =ROUND(AC27+AE27-AG27,0) -> 1004849 | AJ27: 4306134 | AK27: 1129932080 | AN27: 9386921
B28: Bank JTRUST Rp A/c 1100024132 | C28: =W28 -> 4766585 | D28: -852937 | E28: =C28+D28 -> 3913648 | J28: =E28+G28-I28 -> 3913648 | K28: 3913648 | M28: =J28-K28 -> 0 | N28: =W28 -> 4766585 | O28: -708074 | P28: =N28+O28 -> 4058511 | U28: =P28+R28-T28 -> 4058511 | W28: 4766585 | X28: 4766585 | AA28: =AJ28 -> 1129932080 | AB28: -1072076414 | AC28: =AA28+AB28 -> 57855666 | AH28: =ROUND(AC28+AE28-AG28,0) -> 57855666 | AJ28: 1129932080 | AK28: 1362643218 | AN28: 17089985
B29: Bank JTRUST Rp A/c 2100596827 | C29: =W29 -> 1056635 | D29: -330000 | E29: =C29+D29 -> 726635 | I29: ='AJE CAJE Des 24'!G100 -> 40 | J29: =E29+G29-I29 -> 726595 | K29: 726595 | M29: =J29-K29 -> 0 | N29: =W29 -> 1056635 | O29: -240000 | P29: =N29+O29 -> 816635 | U29: =P29+R29-T29 -> 816635 | W29: 1056635 | X29: 1056635 | AA29: =AJ29 -> 1362643218 | AB29: -809947 | AC29: =AA29+AB29 -> 1361833271 | AH29: =ROUND(AC29+AE29-AG29,0) -> 1361833271 | AJ29: 1362643218 | AK29: 3003977 | AN29: 1372702466
B30: PT Bank Mega Syariah | C30: =W30 -> 2098047 | D30: -1414425.5 | E30: =C30+D30 -> 683621.48 | I30: ='AJE CAJE Des 24'!G101 -> 0.52 | J30: =E30+G30-I30 -> 683620.96 | K30: 683620.96 | M30: =J30-K30 -> 0 | N30: =W30 -> 2098047 | O30: -1328468.1 | P30: =N30+O30 -> 769578.89 | U30: =P30+R30-T30 -> 769578.89 | W30: 2098047 | X30: 2098047 | AA30: =AJ30 -> 3003977 | AB30: -631407.01 | AC30: =AA30+AB30 -> 2372570 | AH30: =ROUND(AC30+AE30-AG30,0) -> 2372570 | AJ30: 3003977 | AK30: 5000000 | AN30: 3233855
B31: PT Bank BTPN | C31: =W31 -> 30768284 | D31: 36445715 | E31: =C31+D31 -> 67213999 | I31: ='AJE CAJE Des 24'!G102 -> 65 | J31: =E31+G31-I31 -> 67213934 | K31: 67213934 | M31: =J31-K31 -> 0 | N31: =W31 -> 30768284 | O31: 15737742 | P31: =N31+O31 -> 46506026 | U31: =P31+R31-T31 -> 46506026 | W31: 30768284 | X31: 30768284 | AA31: =AJ31 -> 5000000 | AB31: 161397714 | AC31: =AA31+AB31 -> 166397714 | AH31: =ROUND(AC31+AE31-AG31,0) -> 166397714 | AJ31: 5000000 | AN31: 0
B32: Bank BRI Rp A/c 0285-01-220000-30-7 | C32: =W32 -> 794277 | D32: -794277 | E32: =C32+D32 -> 0 | J32: =E32+G32-I32 -> 0 | M32: =J32-K32 -> 0 | N32: =W32 -> 794277 | O32: -794277 | P32: =N32+O32 -> 0 | U32: =P32+R32-T32 -> 0 | W32: 794277 | X32: 0 | AA32: =AJ32 -> 0 | AB32: 3002177 | AC32: =AA32+AB32 -> 3002177 | AH32: =ROUND(AC32+AE32-AG32,0) -> 3002177
B33: Bank BRI Rp A/c 0652-01-111111-301 | D33: 50621267 | E33: =C33+D33 -> 50621267 | J33: =E33+G33-I33 -> 50621267 | K33: 50621267 | M33: =J33-K33 -> 0 | O33: 609796408 | P33: =N33+O33 -> 609796408 | U33: =P33+R33-T33 -> 609796408 | X33: 794277
A34: Bank USD | E34: =C34+D34 -> 0 | J34: =E34+G34-I34 -> 0 | P34: =N34+O34 -> 0 | U34: =P34+R34-T34 -> 0 | AC34: =AA34+AB34 -> 0 | AH34: =ROUND(AC34+AE34-AG34,0) -> 0 | AK34: 52754538
B35: PT Bank Mandiri (Persero) Tbk | C35: =W35 -> 3820389 | D35: 8286562 | E35: =C35+D35 -> 12106951 | G35: ='AJE CAJE Des 24'!F94 -> 3.2 | J35: =E35+G35-I35 -> 12106954 | K35: 749.1 | L35: =K35*L11 -> 12106954 | M35: =J35-L35 -> 0 | N35: =W35 -> 3820389 | O35: -2112523 | P35: =N35+O35 -> 1707866 | U35: =P35+R35-T35 -> 1707866 | W35: 3820389 | X35: 3820389 | AA35: =AJ35 -> 52754538 | AB35: -37521674 | AC35: =AA35+AB35 -> 15232864 | AH35: =ROUND(AC35+AE35-AG35,0) -> 15232864 | AJ35: 52754538 | AN35: 13023877
B36: Bank Mandiri $ (114.002.744.8284) USD | C36: =W36 -> 1927000 | D36: -1927000 | E36: =C36+D36 -> 0 | J36: =E36+G36-I36 -> 0 | N36: =W36 -> 1927000 | O36: -1927000 | P36: =N36+O36 -> 0 | U36: =P36+R36-T36 -> 0 | W36: 1927000 | X36: 1927000 | AA36: =AJ36 -> 0 | AC36: =AA36+AB36 -> 0 | AH36: =ROUND(AC36+AE36-AG36,0) -> 0 | AK36: 60924433 | AN36: 0
B37: PT Bank Negara Indonesia (Persero) Tbk $ | C37: =W37 -> 8054849 | D37: 12640257 | E37: =C37+D37 -> 20695106 | G37: ='AJE CAJE Des 24'!F95 -> 11.77 | J37: =E37+G37-I37 -> 20695118 | K37: 1280.48 | L37: =K37*L11 -> 20695118 | M37: =J37-L37 -> 0 | N37: =W37 -> 8054849 | O37: 537619.9 | P37: =N37+O37 -> 8592468.9 | U37: =P37+R37-T37 -> 8592468.9 | W37: 8054849 | X37: 8054849 | AA37: =AJ37 -> 60924433 | AB37: -43887455 | AC37: =AA37+AB37 -> 17036978 | AH37: =ROUND(AC37+AE37-AG37,0) -> 17036978 | AJ37: 60924433 | AK37: 23270396 | AN37: 1126429101
B38: Bank JTRUST (1100024149) | C38: =W38 -> 9044094 | D38: -668469.14 | E38: =C38+D38 -> 8375624.9 | G38: ='AJE CAJE Des 24'!F96 -> 8.4 | J38: =E38+G38-I38 -> 8375633.3 | K38: 518.23 | L38: =K38*L11 -> 8375633.3 | M38: =J38-L38 -> 0 | N38: =W38 -> 9044094 | O38: -901222.14 | P38: =N38+O38 -> 8142871.9 | U38: =P38+R38-T38 -> 8142871.9 | W38: 9044094 | X38: 9044094 | AA38: =AJ38 -> 23270396 | AB38: -12235452 | AC38: =AA38+AB38 -> 11034944 | AH38: =ROUND(AC38+AE38-AG38,0) -> 11034944 | AJ38: 23270396 | AK38: 14629830 | AN38: 1927119772
B39: Bank Mega Syariah (1000236601) | C39: =W39 -> 13411920 | D39: -6259103 | E39: =C39+D39 -> 7152817 | I39: ='AJE CAJE Des 24'!G98 -> 0.66 | J39: =E39+G39-I39 -> 7152816.3 | K39: 442.57 | L39: =K39*L11 -> 7152816.3 | M39: =J39-L39 -> 0 | N39: =W39 -> 13411920 | O39: -6394397 | P39: =N39+O39 -> 7017523 | U39: =P39+R39-T39 -> 7017523 | W39: 13411920 | X39: 13411920 | AA39: =AJ39 -> 14629830 | AB39: -889320 | AC39: =AA39+AB39 -> 13740510 | AH39: =ROUND(AC39+AE39-AG39,0) -> 13740510 | AJ39: 14629830 | AK39: 7865500 | AN39: 14126310
B40: PT Bank BTPN | C40: =W40 -> 2023630252 | D40: -1969448007 | E40: =C40+D40 -> 54182245 | G40: ='AJE CAJE Des 24'!F97 -> 51.9 | J40: =E40+G40-I40 -> 54182297 | K40: 3352.45 | L40: =K40*L11 -> 54182297 | M40: =J40-L40 -> 0 | N40: =W40 -> 2023630252 | O40: 253139290 | P40: =N40+O40 -> 2276769542 | U40: =P40+R40-T40 -> 2276769542 | W40: 2023630252 | X40: 2023630252 | AA40: =AJ40 -> 7865500 | AB40: 15743485 | AC40: =AA40+AB40 -> 23608985 | AH40: =ROUND(AC40+AE40-AG40,0) -> 23608985 | AJ40: 7865500 | AN40: 0
B41: Bank BRI (0285-02-000022-30-5) USD | C41: =W41 -> 3242911 | D41: -1782511 | E41: =C41+D41 -> 1460400 | I41: ='AJE CAJE Des 24'!G103 -> 1.68 | J41: =E41+G41-I41 -> 1460398.3 | K41: 90.36 | L41: =K41*L11 -> 1460398.3 | M41: =J41-L41 -> 0 | N41: =W41 -> 3242911 | O41: -1420900 | P41: =N41+O41 -> 1822011 | U41: =P41+R41-T41 -> 1822011 | W41: 3242911 | X41: 3242911 | AA41: =AJ41 -> 0 | AB41: 15455357 | AC41: =AA41+AB41 -> 15455357 | AH41: =ROUND(AC41+AE41-AG41,0) -> 15455357 | AK41: 0 | AN41: 0
B42: Total Bank | C42: =SUM(C24:C41) -> 2106312831 | E42: =SUM(E24:E41) -> 2.4793669e+08 | J42: =SUM(J24:J41) -> 2.4793587e+08 | N42: =SUM(N24:N41) -> 2106312831 | P42: =SUM(P24:P41) -> 1.1176307e+10 | U42: =SUM(U24:U41) -> 1.1176307e+10 | W42: =SUM(W24:W41) -> 2106312831 | X42: 2106312831 | Y42: =W42-X42 -> 0 | AA42: =SUM(AA24:AA41) -> 3.0318904e+09 | AC42: =SUM(AC24:AC41) -> 1.737908e+09 | AH42: =SUM(AH24:AH41) -> 1737907983 | AJ42: =SUM(AJ24:AJ41) -> 3.0318904e+09 | AK42: 3.0318904e+09 | AL42: =AJ42-AK42 -> 0 | AN42: =SUM(AN24:AN41) -> 4489321244
B43: Total Cash and Cash Equivalents | C43: =C21+C42 -> 2159354956 | E43: =E21+E42 -> 4.2068304e+08 | J43: =J21+J42 -> 4.2068222e+08 | N43: =N21+N42 -> 2159354956 | P43: =P21+P42 -> 1.1398025e+10 | U43: =U21+U42 -> 1.1398025e+10 | W43: =W21+W42 -> 2159354956 | X43: 2159354956 | Y43: =W43-X43 -> 0 | AA43: =AA21+AA42 -> 3.0815714e+09 | AC43: =AC21+AC42 -> 1.7989002e+09 | AH43: =AH21+AH42 -> 1798900203 | AJ43: =AJ21+AJ42 -> 3.0815714e+09 | AK43: 3.0815714e+09 | AL43: =AJ43-AK43 -> -0.42001343 | AN43: =AN21+AN42 -> 4509468366
A44: Trade Receivable
B45: Piutang Usaha - IDR | X45: 0 | AK45: 0
B46: CV Kanian Persada | C46: =W46 -> 211054410 | D46: 182881020 | E46: =C46+D46 -> 393935430 | J46: =E46+G46-I46 -> 393935430 | N46: =W46 -> 211054410 | O46: 128840071 | P46: =N46+O46 -> 339894481 | U46: =P46+R46-T46 -> 339894481 | W46: 211054410 | X46: 211054410 | Y46: =W46-X46 -> 0 | AA46: =AJ46 -> 338387925 | AB46: 1.4448648e+08 | AC46: =AA46+AB46 -> 4.8287441e+08 | AH46: =ROUND(AC46+AE46-AG46,0) -> 482874409 | AJ46: 338387925 | AK46: 338387925 | AL46: =AJ46-AK46 -> 0 | AN46: 174380445
B47: Mochamad Riduwan | C47: =W47 -> 0 | E47: =C47+D47 -> 0 | J47: =E47+G47-I47 -> 0 | N47: =W47 -> 0 | P47: =N47+O47 -> 0 | U47: =P47+R47-T47 -> 0 | W47: 0 | X47: 0 | AA47: =AJ47 -> 14980 | AC47: =AA47+AB47 -> 14980 | AH47: =ROUND(AC47+AE47-AG47,0) -> 14980 | AJ47: 14980 | AK47: 14980 | AL47: =AJ47-AK47 -> 0 | AN47: 14980
...

Sheet BS
A1: PT INDO AMERICAN SEAFOODS
A2: LAPORAN POSISI KEUANGAN
A3: Tanggal 31 Desember 2024 dan 2023
A4: (Disajikan dalam Rupiah, kecuali dinyatakan lain)
F6: Catatan/
F7: CATATAN
F10: Notes | H10: 2024 | J10: 45536 | L10: 2023
A12: ASET | N12: ASSETS
A13: ASET LANCAR | N13: CURRENT ASSETS
A14: Kas dan Bank | F14: 4 | H14: =WS!J43 -> 4.2068222e+08 | J14: =WS!U43 -> 1.1398025e+10 | L14: =WS!W43 -> 2159354956 | N14: Cash on Hand and in Banks
A15: Piutang Usaha | N15: Trade Accounts Receivable
B16: Pihak Berelasi | F16: 5 | H16: =WS!J75 -> 8079657361 | J16: =WS!U75 -> 2.6370908e+09 | L16: =WS!W75 -> 8079657361 | O16: Related Parties
B17: Pihak Ketiga | F17: 5 | H17: =WS!J70+WS!J79 -> 4.4619752e+10 | J17: =WS!U70+WS!U79 -> 22964047771 | L17: =WS!W70+WS!W79 -> 13123277095 | O17: Third Parties
A18: Piutang Lain-lain dari Pihak Berelasi | F18: 6 | H18: =WS!J90 -> 91174796671 | J18: =WS!U90 -> 94963698422 | L18: =WS!W90 -> 133158984576 | N18: Other Receivables from Related Parties
A19: Persediaan | F19: 7 | H19: =WS!J97 -> 117254789147 | J19: =WS!U97 -> 1.3533008e+11 | L19: =WS!W97 -> 108322822660 | N19: Inventories
A20: Pajak Dibayar Dimuka | F20: 14a | H20: =SUM(WS!J99:J104) -> 8.3889488e+09 | J20: =SUM(WS!U99:U103) -> 8.0039853e+09 | L20: =SUM(WS!W99:W103) -> 6807425746 | N20: Prepaid Taxes
A21: Biaya Dibayar Dimuka | H21: =SUM(WS!J106:J111) -> 2.9458466e+10 | J21: =SUM(WS!U106:U110) -> 1.2084349e+09 | L21: =SUM(WS!W106:W109) -> 897473228 | N21: Prepaid Expenses
A23: Jumlah Aset Lancar | H23: =SUM(H14:H21) -> 2.9939709e+11 | J23: =SUM(J14:J21) -> 2.7650536e+11 | L23: =SUM(L14:L21) -> 272548995622 | N23: Total Current Assets
A25: ASET TIDAK LANCAR | N25: Non-Current Assets
A26: Aset Tetap | N26: Property, Plant and Equipment
A27: Aset Dalam Proses | F27: 8 | N27: Work in Process
B28: (Setelah dikurangi akumulasi | O28: (Net of accumulated
B29: penyusutan sebesar | O29: depreciation of
B30: Rp 18.960.855.664 | O30: Rp 18.960.855.664
B31: dan Rp 16.681.774.940 | O31: and Rp 16.681.774.940
B32: masing-masing pada | O32: as of December 31, 2024
B33: 31 Desember 2024 dan 2023) | F33: 9 | H33: =WS!J124-WS!J134+WS!J138 -> 2.5023283e+10 | J33: =WS!U124-WS!U134+WS!U138 -> 2.5513227e+10 | L33: =WS!W124-WS!W134+WS!W138-1 -> 27302363571 | O33: and 2023 respectively)
A34: Investasi | H34: =WS!J143 -> 1050000000 | J34: =WS!U143 -> 1050000000 | L34: =WS!W143 -> 1050000000 | N34: Investment
A35: Aset Pajak Tangguhan | F35: 14d | H35: =SUM(WS!J145:J146)-WS!J148 -> 2.4256979e+08 | J35: =SUM(WS!U145:U146)-WS!U148 -> 2.4256979e+08 | L35: =SUM(WS!W145:W146)-WS!W148 -> 2.4256979e+08 | N35: Deferred Tax Assets
A37: Jumlah Aset Tidak Lancar | H37: =SUM(H27:H35) -> 2.6315853e+10 | J37: =SUM(J27:J35) -> 2.6805796e+10 | L37: =SUM(L27:L35) -> 2.8594933e+10 | N37: Total Non-Current Assets
A39: JUMLAH ASET | H39: =H23+H37 -> 3.2571294e+11 | J39: =J23+J37 -> 3.0331116e+11 | L39: =L23+L37 -> 3.0114393e+11 | N39: TOTAL ASSETS
F42: Catatan/
F43: Notes | H43: 2024 | J43: =J10 -> 45536 | L43: 2023
A44: LIABILITAS DAN EKUITAS | N44: LIABILITIES AND EQUITY
A45: LIABILITAS | N45: LIABILITIES
A46: LIABILITAS JANGKA PENDEK | N46: CURRENT LIABILITIES
A47: Utang Usaha | N47: Trade Accounts Payable
B48: Pihak Berelasi | F48: 10 | H48: =WS!J241 -> 3.3114818e+10 | J48: =WS!U241 -> 3.4916763e+10 | L48: =WS!W241 -> 62518053072 | O48: Related Parties
B49: Pihak Ketiga | F49: 10 | H49: =WS!J237 -> 4.2917358e+09 | J49: =WS!U237 -> 3.7095089e+09 | L49: =WS!W237 -> 12029137713 | O49: Third Parties
A50: Utang Lain-lain | N50: Other Payables
...

Sheet PL
A1: PT INDO AMERICAN SEAFOODS
A2: LAPORAN LABA RUGI DAN PENGHASILAN KOMPREHENSIF LAIN
A3: UNTUK TAHUN YANG BERAKHIR PADA TANGGAL-TANGGAL
A4: 31 Desember 2024 dan 2023
A5: (Disajikan dalam Rupiah, kecuali dinyatakan lain)
D7: Catatan/ | V7: Gross Margin
D8: Notes | F8: 2024 | H8: 45536 | J8: 45170 | L8: 2023 | N8: 2022 | P8: 2021*) | W8: 45627 | X8: 45536 | Y8: 45536 | Z8: 45170 | AA8: 45261
A10: PENJUALAN | D10: 19 | F10: =WS!J338 -> 1.8249335e+11 | H10: =WS!U338 -> 1.0029508e+11 | J10: =WS!AH338 -> 145641937120 | L10: =WS!W338 -> 189007036121 | N10: =WS!AJ338 -> 245651809706 | P10: =WS!AN338 -> 212866021082 | S10: SALES | W10: =F13/F10 -> 0.23621948 | X10: =F13/F10 -> 0.23621948 | Y10: =H13/H10 -> 0.29503238 | Z10: =J13/J10 -> 0.17903335 | AA10: =L13/L10 -> 0.17190125
A11: BEBAN POKOK PENJUALAN | D11: 20 | F11: =-WS!J399 -> -1.3938487e+11 | H11: =-WS!U399 -> -7.0704787e+10 | J11: =-WS!AH399 -> -119567172509 | L11: =-WS!W399 -> -156516490239 | N11: =-WS!AJ399 -> -2.0108262e+11 | P11: =-WS!AN399 -> -1.7815083e+11 | S11: COST OF GOODS SOLD
A13: LABA KOTOR | F13: =ROUND(F10+F11,0) -> 43108483705 | H13: =ROUND(H10+H11,0) -> 29590297673 | J13: =ROUND(J10+J11,0) -> 26074764611 | L13: =ROUND(L10+L11,0) -> 32490545882 | N13: =ROUND(N10+N11,0) -> 44569188164 | P13: =ROUND(P10+P11,0) -> 34715189205 | S13: GROSS PROFIT
A14: Beban Penjualan | D14: 21 | F14: =-WS!J416 -> -1.4110744e+10 | H14: =-WS!U416 -> -9.3927967e+09 | J14: =-WS!AH416 -> -12120734220 | L14: =-WS!W416 -> -11943842250 | N14: =-WS!AJ416 -> -1.9921262e+10 | P14: =-WS!AN416 -> -1.6958316e+10 | S14: Selling Expenses | W14: =-F14/F10 -> 0.077321963 | X14: =-F14/F10 -> 0.077321963 | Y14: =-H14/H10 -> 0.093651615 | Z14: =-J14/J10 -> 0.08322283 | AA14: =-L14/$L$10 -> 0.06319258
A15: Beban Umum dan Administrasi | D15: 22 | F15: =-WS!J465 -> -1.4884752e+10 | H15: =-WS!U465 -> -1.3159815e+10 | J15: =-WS!AH465 -> -6007580878 | L15: =-WS!W465 -> -8581798722 | N15: =-WS!AJ465 -> -1.0213045e+10 | P15: =-WS!AN465 -> -8.7014883e+09 | S15: General and Administration Expenses | W15: =-F15/F10 -> 0.081563256 | X15: =-F15/F10 -> 0.081563256 | Y15: =-H15/H10 -> 0.13121097 | Z15: =-J15/J10 -> 0.041248977 | AA15: =-L15/$L$10 -> 0.045404652
A16: Pendapatan (Beban) Lain-lain - Bersih | D16: 23 | F16: =WS!J474 -> -1.612506e+09 | H16: =WS!U474 -> 1.6476179e+09 | J16: =WS!AH474 -> -693108623 | L16: =WS!W474 -> -601084731 | N16: =WS!AJ474 -> -1.1384742e+09 | P16: =WS!AN474 -> -1.2463122e+08 | S16: Other Income (Charges) - Net
A17: Beban Bunga dan Keuangan | D17: 24 | F17: =-WS!J485 -> -9.4242921e+09 | H17: =-WS!U485 -> -6.7069744e+09 | J17: =-WS!AH485 -> -6430690329 | L17: =-WS!W485 -> -9.3523807e+09 | N17: =-WS!AJ485 -> -6651524107 | P17: =-WS!AN485 -> -4810236291 | S17: Interest and Finance Cost
A19: Sub Jumlah | F19: =SUM(F14:F17) -> -4.0032294e+10 | H19: =SUM(H14:H17) -> -2.7611968e+10 | J19: =SUM(J14:J17) -> -25252114050 | L19: =SUM(L14:L17) -> -3.0479106e+10 | N19: =SUM(N14:N17) -> -3.7924305e+10 | P19: =SUM(P14:P17) -> -3.0594672e+10 | S19: Sub Total
A21: LABA SEBELUM PAJAK PENGHASILAN | F21: =F13+F19 -> 3.0761898e+09 | H21: =H13+H19 -> 1.9783296e+09 | J21: =J13+J19 -> 822650561 | L21: =L13+L19 -> 2.0114394e+09 | N21: =N13+N19 -> 6.6448833e+09 | P21: =P13+P19 -> 4.120517e+09 | S21: PROFIT INCOME BEFORE TAX
A22: Manfaat (Beban) Pajak Penghasilan: | S22: Income Tax Benefit (Expenses)
B23: Pajak Kini | D23: 14c | F23: =-WS!J489 -> -1135531100 | H23: =-WS!U489 -> -1066942140 | J23: =-WS!AH489 -> -299497000 | L23: =-WS!W489 -> -6.7332782e+08 | N23: =-WS!AJ489 -> -1515553820 | P23: =-WS!AN489 -> -8.7911142e+08 | T23: Current Income Tax
B24: Pajak Tangguhan | D24: 14c | F24: =-WS!J492 -> 0 | H24: =-WS!U492 -> 0 | J24: =-WS!AH492 -> 0 | L24: =-WS!W492 -> 61828681 | N24: =-WS!AJ492 -> 81839521 | P24: =WS!AN492 -> 93846379 | T24: Deferred Tax
A26: LABA BERSIH TAHUN BERJALAN | F26: =F21+F24+F23 -> 1.9406587e+09 | H26: =H21+H24+H23 -> 9.1138744e+08 | J26: =J21+J24+J23 -> 523153561 | L26: =L21+L24+L23 -> 1.3999403e+09 | N26: =N21+N24+N23 -> 5.211169e+09 | P26: =P21+P24+P23 -> 3.335252e+09 | S26: NET INCOME FOR THE YEAR
A27: Pengukuran Kembali Imbalan Pasti | D27: 25 | F27: =WS!J498 -> 0 | H27: =WS!U498 -> 0 | J27: =WS!AH498 -> 0 | L27: =WS!W498 -> -5379083 | N27: =WS!AJ498 -> 156702531 | P27: =WS!AN498 -> 27264083 | S27: Remeasurement of Defined Benefit
A28: Pajak Penghasilan Terkait | D28: 25 | F28: =-WS!J501 -> 0 | H28: =-WS!U501 -> 0 | J28: =-WS!AH501 -> 0 | L28: =-WS!W501 -> 1183398.3 | N28: =-WS!AJ501 -> -34474557 | P28: =-WS!AN501 -> -5998098 | S28: Income Tax Related
A30: LABA KOMPREHENSIF | S30: COMPREHENSIVE INCOME
A31: TAHUN BERJALAN | F31: =F26+F27+F28 -> 1.9406587e+09 | H31: =H26+H27+H28 -> 9.1138744e+08 | J31: =J26+J27+J28 -> 523153561 | L31: =L26+L27+L28 -> 1.3957446e+09 | N31: =N26+N27+N28 -> 5.333397e+09 | P31: =P26+P27+P28 -> 3.356518e+09 | S31: FOR THE YEAR
A33: LABA PER SAHAM DASAR | D33: 26 | L33: 1.7446805 | N33: 6.5139613 | P33: 4.169065 | S33: BASIC EARNINGS PER SHARE
L35: =L27*22% -> -1183398.3 | N35: =N27*22% -> 34474557 | P35: =P27*22% -> 5998098.3
D37: Ctrl | F37: =F31-WS!J503 -> 0.30603027 | H37: =H31-WS!U503 -> 0.11767387 | J37: =J31-WS!AH503 -> 0 | L37: =L31-WS!W503 -> 0 | N37: =N31-[1]WBS!BX535 -> -0.35416031 | P37: =P31-[1]WBS!CE535 -> -0.12252998
A71: Penghasilan Komprehensif Lain

Sheet LPE
A1: =[2]PL!A1 -> PT INDO AMERICAN SEAFOODS
A2: LAPORAN PERUBAHAN EKUITAS INTERIM
A3: UNTUK TAHUN YANG BERAKHIR PADA ENAM BULAN
A4: 30 September 2024 dan 2023
A5: (Disajikan dalam Rupiah, kecuali dinyatakan lain)
I12: Tambahan | K12: Penghasilan | N12: Saldo Laba/ Retained Earning | R12: Surplus Revaluasi
I13: Modal Disetor | K13: Komprehensif Lain/ | N13: Ditentukan | P13: Tidak Ditentukan | R13: Aset tetap
E14: Catatan/ | F14: Modal Saham/ | I14: Additional | K14: Other Comprehensive | N14: Penggunaannya/ | P14: Penggunaannya/ | R14: Asset Revalution | T14: Jumlah Ekuitas/
E15: Notes | F15: Share Capital | I15: Paid-in-Capital | K15: Income | N15: Appropriated | P15: Unappropriated | R15: Surplus | T15: Total Equity
A18: Saldo 1 Januari 2020 | F18: 40000000000 | I18: 25871690669 | K18: -893983003 | N18: 0 | P18: 7.6832486e+09 | R18: =[2]BS!AL90 -> 0 | T18: =SUM(F18:R18) -> 7.2660956e+10 | V18: Balance as of January 1, 2020
A19: Pengukuran Kembali Program | V19: Remeasurement of
A20: Imbalan Pasti | K20: 2.7189854e+08 | N20: 0 | P20: 0 | R20: 0 | T20: =SUM(F20:P20) -> 2.7189854e+08 | V20: Defined Benefit
A21: Laba Tahun Berjalan | F21: 0 | I21: 0 | K21: 0 | N21: 0 | P21: =2407833315.7075+1 -> 2.4078333e+09 | R21: 0 | T21: =SUM(F21:P21) -> 2.4078333e+09 | V21: Profit for The Year
A23: Penyajian Kembali sesuai PSAK 26 | F23: 0 | I23: 0 | K23: 0 | P23: ='[2]AJE CAJE 2020'!G46*0 -> 0 | R23: 0 | T23: =P23 -> 0 | V23: Restatement in accordance with PSAK 26
A25: Saldo 31 Desember 2020 | F25: =[2]WBS!CL346 -> 40000000000 | I25: =[2]WBS!CL347 -> 25871690669 | K25: =SUM(K18:K21) -> -6.2208447e+08 | N25: =[2]WBS!CK354 -> 0 | P25: =SUM(P18:P21)+P23+1 -> 1.0091082e+10 | R25: =SUM(R18:R21) -> 0 | T25: =T18+T20+T21+T23+1 -> 7.5340688e+10 | V25: Balance as of December 31, 2020
A27: Pengukuran Kembali Program | V27: Remeasurement of
A28: Imbalan Pasti | F28: 0 | I28: 0 | K28: 21265985 | N28: 0 | P28: 0 | R28: 0 | T28: =SUM(F28:R28) -> 21265985 | V28: Defined Benefit
A29: Laba Tahun Berjalan | F29: 0 | I29: 0 | K29: 0 | N29: 0 | P29: =[3]PL!N26-1 -> 3.335252e+09 | R29: 0 | T29: =SUM(F29:R29) -> 3.335252e+09 | V29: Profit for The Year
A31: Saldo 31 Desember 2021 | F31: =SUM(F25:F29) -> 40000000000 | I31: =SUM(I25:I29) -> 25871690669 | K31: =SUM(K25:K29) -> -6.0081848e+08 | N31: =SUM(N25:N29) -> 0 | P31: =SUM(P25:P29) -> 1.3426334e+10 | R31: =R25 -> 0 | T31: =SUM(T25:T29) -> 7.8697206e+10 | V31: Balance as of December 31, 2021
A33: Pengukuran Kembali Program | V33: Remeasurement of
A34: Imbalan Pasti | F34: 0 | I34: 0 | K34: 1.2222797e+08 | N34: 0 | P34: 0 | R34: 0 | T34: =SUM(F34:R34) -> 1.2222797e+08 | V34: Defined Benefit
A35: Laba Tahun Berjalan | F35: 0 | I35: 0 | K35: 0 | N35: 0 | P35: 5.211169e+09 | R35: 0 | T35: =SUM(F35:R35) -> 5.211169e+09 | V35: Profit for The Year
A36: Cadangan Umum | F36: 0 | I36: 0 | K36: 0 | N36: 400000000 | P36: -400000000 | T36: =SUM(F36:R36) -> 0 | V36: General Reserves
A38: Saldo 1 Januari 2023 | F38: =SUM(F31:F37) -> 40000000000 | I38: =SUM(I31:I37) -> 25871690669 | K38: =SUM(K31:K37) -> -4.7859051e+08 | N38: =SUM(N31:N37) -> 400000000 | P38: =SUM(P31:P37) -> 1.8237503e+10 | R38: =SUM(R31:R37) -> 0 | T38: =SUM(T31:T37) -> 8.4030603e+10 | V38: Balance as of January 1, 2023
A40: Pengukuran Kembali Program | V40: Remeasurement of
A41: Imbalan Pasti | F41: 0 | I41: 0 | K41: =WS!W324 -> -4195684.7 | N41: 0 | P41: 0 | R41: 0 | T41: =SUM(F41:R41) -> -4195684.7 | V41: Defined Benefit
A42: Laba Tahun Berjalan | F42: 0 | I42: 0 | N42: 0 | P42: =PL!L26 -> 1.3999403e+09 | R42: 0 | T42: =SUM(F42:R42) -> 1.3999403e+09 | V42: Profit for The Year
A43: Cadangan Umum | F43: 0 | I43: 0 | K43: 0 | N43: 0 | P43: 0 | T43: =SUM(F43:R43) -> 0 | V43: General Reserves
A45: Laba Tahun Berjalan | F45: 0 | I45: 0 | K45: 0 | N45: 0 | P45: =PL!J26 -> 523153561 | R45: 0 | T45: =SUM(F45:R45) -> 523153561 | V45: Profit for The Year
A47: Saldo 30 September 2023 | F47: =F38+F45 -> 40000000000 | I47: =I38+I45 -> 25871690669 | K47: =K38+K45 -> -4.7859051e+08 | N47: =N38+N45 -> 400000000 | P47: =P38+P45 -> 1.8760656e+10 | R47: =SUM(R40:R46) -> 0 | T47: =T38+T45 -> 8.4553757e+10 | V47: Balance as of September 30, 2023
A49: Saldo 31 Desember 2023 | F49: =F38+SUM(F40:F43) -> 40000000000 | I49: =I38+SUM(I40:I43) -> 25871690669 | K49: =K38+SUM(K40:K43) -> -4.8278619e+08 | N49: =N38+SUM(N40:N43) -> 400000000 | P49: =P38+SUM(P41:P43)-1 -> 1.9637443e+10 | R49: =SUM(R37:R43) -> 0 | T49: =T38+SUM(T41:T43)-1 -> 8.5426348e+10 | V49: Balance as of December 31, 2023
A51: Setoran Modal | F51: =-WS!O309 -> 15000000000 | P51: =-WS!O316 -> -15000000000 | T51: =SUM(F51:R51) -> 0 | V51: Paid up Capital
A52: Pengukuran Kembali Program | V52: Remeasurement of
A53: Imbalan Pasti | F53: 0 | I53: 0 | J53: 0 | K53: 0 | L53: 0 | M53: 0 | N53: 0 | P53: 0 | R53: 0 | T53: =SUM(F53:R53) -> 0 | V53: Defined Benefit
A54: Tambahan Modal Disetor | F54: 0 | I54: =SUM(WS!U312:U313) -> 54884055085 | K54: 0 | N54: 0 | P54: 0 | T54: =SUM(F54:R54) -> 54884055085 | V54: Additional Paid-in Capital | X54: Blm dikurangi biaya emisi
A55: Setoran Modal | F55: =WS!U310 -> 14500000000 | I55: 0 | K55: 0 | N55: 0 | P55: 0 | T55: =SUM(F55:R55) -> 14500000000 | V55: Paid-up Capital
A56: Laba Tahun Berjalan | F56: 0 | I56: 0 | K56: 0 | N56: 0 | P56: =PL!H26 -> 9.1138744e+08 | R56: 0 | T56: =SUM(F56:R56) -> 9.1138744e+08 | V56: Profit for The Year
A57: Cadangan Umum | F57: 0 | I57: 0 | K57: 0 | P57: =-N57 -> 0 | T57: =SUM(F57:R57) -> 0 | V57: General Reserves | X57: apakah 1% lgsg disesuaikan dengan Modal nya?
A59: Saldo 30 September 2024 | F59: =F49+SUM(F51:F57) -> 69500000000 | I59: =I49+SUM(I51:I57) -> 80755745754 | K59: =K49+SUM(K51:K57) -> -4.8278619e+08 | N59: =N49+SUM(N51:N57) -> 400000000 | P59: =P49+SUM(P51:P57) -> 5.5488306e+09 | R59: =SUM(R51:R57) -> 0 | T59: =T49+SUM(T51:T57) -> 1.5572179e+11 | V59: Balance as of September 30, 2024
A61: Setoran Modal | F61: =-WS!D309 -> 15000000000 | P61: =-WS!D326 -> 0 | T61: =SUM(F61:R61) -> 15000000000 | V61: Paid up Capital
...

Sheet CF
A1: PT INDO AMERICAN SEAFOODS TBK
A2: LAPORAN ARUS KAS
A3: Untuk Tahun-tahun yang Berakhir pada 31 Desember 2024 dan 2023
A4: (Disajikan dalam Rupiah, kecuali Dinyatakan Lain)
D6: Catatan/
D7: Notes | F7: 2024 | H7: 2023
A9: ARUS KAS DARI AKTIVITAS | K9: CASH FLOWS FROM OPERATING
A10: OPERASI | K10: ACTIVITIES
A11: Penerimaan Kas dari Pelanggan | D11: 4,5,20 | F11: ='CF 2024'!B11 -> 150996874613 | H11: =ROUND('CF 2023'!B11,0) -> 218713811464 | K11: Cash Receipts from Customers
A13: Pembayaran Kepada Pemasok | D13: 6,7,10,11,13,15 | F13: ='CF 2024'!B12 -> -181964095253 | H13: =ROUND('CF 2023'!B12,0) -> -248400274278 | K13: Cash Paid to Supplier
A14: Pembayaran Kepada Karyawan | D14: 21.23 | F14: ='CF 2024'!B13 -> -5127549818 | H14: ='CF 2023'!B13 -> -5127549818 | K14: Cash Paid to Employees
A16: Pembayaran Beban Operasional Lainnya | D16: 15,17,22,23 | F16: ='CF 2024'!B14 -> -15194741148 | H16: =ROUNDDOWN('CF 2023'!B14,0)+1 -> -11291352070 | K16: Cash Paid for Other Operating Expenses
A17: Pembayaran Kepada Karyawan | F17: 0 | H17: 0 | K17: Payment to Employees
A18: Pembayaran Beban Lainnya
A20: Kas Dihasilkan dari Operasi | F20: =SUM(F11:F18) -> -51289511606 | H20: =SUM(H11:H18) -> -46105364702 | K20: Cash Generated from Operating
A21: Penerimaan bunga | D21: 22 | K21: Interest Received
A22: Pembayaran Pajak Penghasilan | D22: 15 | F22: ='CF 2024'!B20 -> -1135531100 | H22: =ROUND('CF 2023'!B20,0) -> -673327820 | K22: Cash Paid for Income Taxes Paid
A24: Pembayaran Beban Bunga dan Keuangan | D24: 25 | F24: ='CF 2024'!B19 -> -9424292095 | H24: =ROUND('CF 2023'!B19,0) -> -9352380745 | K24: Payment of Interest and Finance Costs
A28: Kas Bersih Digunakan untuk | K28: Net Cash Used in
A29: Aktivitas Operasi | F29: =SUM(F20:F24) -> -61849334801 | H29: =SUM(H20:H24) -> -56131073267 | K29: Operating Expenses
A32: ARUS KAS DARI AKTIVITAS
A33: INVESTASI | K33: CASH FLOWS FROM INVESTING
A34: Hasil Penjualan Aset Tetap
A35: Penempatan Invetasi pada Entitas Asosiasi | D35: 9 | F35: ='CF 2024'!B28 -> 0 | H35: ='CF 2023'!B28 -> -1050000000 | K35: Placement of Investment in Association Entities
A36: Aset Tetap | D36: 8 | F36: 0 | H36: 0 | K36: Property, Plant and Equipment
K37: Acquisition of Property, Plant
A38: Penambahan Aset Tetap | D38: 10 | F38: ='CF 2024'!B27 -> 0 | H38: ='CF 2023'!B27 -> 0 | K38: Acquisition of Fixed Assets
A39: Perolehan Aset Hak Guna
A42: Kas Bersih Digunakan untuk | K42: Net Cash Used for Obtained from
A43: dari Aktivitas Investasi | F43: =SUM(F34:F39) -> 0 | H43: =SUM(H34:H39) -> -1050000000 | K43: Investment Activities
A46: ARUS KAS DARI AKTIVITAS
A47: PENDANAAN | K47: CASH FLOWS FROM FINANCING
A48: Utang Bank | K48: Bank Loan
A49: Penerimaan | D49: 16 | F49: ='CF 2024'!B36 -> -9156032995 | H49: 366674261027 | K49: Proceeds
A50: Pembayaran | D50: 16 | F50: ='CF 2024'!B37 -> 0 | H50: -310030333899 | K50: Payments
A51: Utang Pembelian Aset Tetap | K51: Liabilities for Purchase of Fixed Asset
B52: Pembayaran | D52: 14 | F52: ='CF 2024'!B39 -> -76360023 | H52: ='CF 2023'!B39 -> -67475296 | K52: Payments
A53: Modal Disetor dari Penawaran Umum | K53: Paid-Up Capital from Initial
A54: Perdana Saham | F54: ='CF 2024'!B43 -> 14500000000 | H54: 0 | K54: Public Offering of Share
A55: Agio Saham atas Penawaran Umum | K55: Premium on Capital Stock Initial
...

Sheet CF 2024
C1: =SUM(C7:L7) -> 3.0114393e+11 | F1: 153903160236
C2: =SUM(N7:AD7) -> -3.0114393e+11
C3: =C1+C2 -> -0.0054931641
C4: Kas dan Bank | D4: Piutang Usaha Kepada Pihak Ketiga | E4: Piutang Usaha Kepada Pihak Berelasi | F4: Piutang Lain-Lain | G4: Persediaan | H4: Prepaid Tax | I4: Prepaid | J4: Investasi pada Entitas Asosias | K4: Aset Tetap | L4: Aset Pajak Tangguhan | M4: Biaya Pra IPO | N4: Short Term Bank Loans | O4: Bank Loan - Short part of long | P4: Utang Usaha Pihak Berelasi | Q4: Utang Usaha Pihak Ketiga | R4: Biaya Yang Masih Harus Dibayar | S4: Utang Lain2 Pihak Ketiga | T4: Utang Lembaga Pembiayaan | U4: Utang Bank & Leasing | V4: Utang Pajak | W4: Imbalan Pasca Kerja | X4: Modal Saham | Y4: Tambahan Modal Disetor | Z4: Masyarakat Saham Baru | AA4: Agio Saham | AB4: Biaya Emisi | AC4: Penghasilan Komprehensif Lainnya | AD4: Saldo Laba | AE4: Pendapatan Usaha | AF4: Beban Pokok Pendapatan Usaha | AG4: Beban Penjualan | AH4: Beban Umum dan Administrasi | AI4: Beban(Pendapatan) Lain-lain | AJ4: Beban Bunga dan Keuangan | AK4: Income Tax | AL4: Income Tax | AM4: Other Comprehensive Income | AN4: 17999087818 | AO4: =AN4-AN6 -> 1.7999088e+10
B6: December 31, 2024 | C6: =BS!H14 -> 4.2068222e+08 | D6: =BS!H17 -> 4.4619752e+10 | E6: =BS!H16 -> 8079657361 | F6: =BS!H18 -> 91174796671 | G6: =BS!H19 -> 117254789147 | H6: =BS!H20 -> 8.3889488e+09 | I6: =BS!H21 -> 2.9458466e+10 | J6: =BS!H34 -> 1050000000 | K6: =BS!H33 -> 2.5023283e+10 | L6: =BS!H35 -> 2.4256979e+08 | M6: 0 | N6: =-BS!H53 -> -126612232871 | O6: 0 | P6: =-BS!H48 -> -3.3114818e+10 | Q6: =-(BS!H49+BS!H51) -> -4.2917358e+09 | R6: =-BS!H54 -> -1.5639524e+09 | S6: =-BS!H52 -> 0 | T6: =-BS!H59 -> 0 | U6: 0 | V6: =-BS!H55 -> -7.3139746e+08 | W6: =-BS!H70 -> -2647745936 | X6: =-BS!H86+(WS!J310) -> -55000000000 | Y6: =Y7 -> -25871690669 | Z6: =-WS!J310 -> -14500000000 | AA6: =-WS!J312 -> -58000000000 | AB6: =-WS!J313 -> 3115944915 | AC6: =-BS!H89 -> 4.8278619e+08 | AD6: =AD7+WS!D316 -> -5.0374432e+09 | AE6: =-PL!F10 -> -1.8249335e+11 | AF6: =-PL!F11 -> 1.3938487e+11 | AG6: =-PL!F14 -> 1.4110744e+10 | AH6: =-PL!F15 -> 1.4884752e+10 | AI6: =-PL!F16 -> 1.612506e+09 | AJ6: =-PL!F17 -> 9.4242921e+09 | AK6: =-PL!F24 -> 0 | AL6: =-PL!F23 -> 1135531100 | AM6: 0 | AN6: =SUM(C6:AM6) -> 0.48443413
B7: 45291 | C7: =BS!L14 -> 2159354956 | D7: =BS!L17 -> 13123277095 | E7: =BS!L16 -> 8079657361 | F7: =BS!L18 -> 133158984576 | G7: =BS!L19 -> 108322822660 | H7: =BS!L20 -> 6807425746 | I7: =BS!L21 -> 897473228 | J7: =BS!L34 -> 1050000000 | K7: =BS!L33 -> 27302363571 | L7: =BS!L35 -> 2.4256979e+08 | M7: 0 | N7: =-BS!L53 -> -135768265866 | O7: 0 | P7: =-BS!L48 -> -62518053072 | Q7: =-(BS!L49+BS!L51) -> -12029137713 | R7: =-BS!L54 -> -937337041 | S7: =-BS!L52 -> -41000000 | T7: =-BS!L59 -> -76360023 | U7: 0 | V7: =-BS!L55 -> -1.6996817e+09 | W7: =-BS!L70 -> -2647745936 | X7: =-BS!L86 -> -40000000000 | Y7: =-BS!L87 -> -25871690669 | AC7: =-BS!L89 -> 4.8278619e+08 | AD7: =-(BS!L92+BS!L93+BS!L91) -> -2.0037443e+10 | AN7: =SUM(C7:AM7) -> -0.0054931641 | AO7: =AN7/2 -> -0.002746582
B8: Selisih | C8: =C6-C7 -> -1.7386727e+09 | D8: =D6-D7 -> 3.1496475e+10 | E8: =E6-E7 -> 0 | F8: =F6-F7 -> -41984187905 | G8: =G6-G7 -> 8931966487 | H8: =H6-H7 -> 1.5815231e+09 | I8: =I6-I7 -> 2.8560992e+10 | J8: =J6-J7 -> 0 | ... AM8: =AM6-AM7 -> 0 | AN8: =SUM(C8:AM8) -> 0.48998833 | AO8: =AN8/2 -> 0.24499416 | AP8: =AO8/2 -> 0.12249708
B9: Movement
A10: ARUS KAS DARI AKTIVITAS OPERASI
A11: Penerimaan Kas dari Pelanggan | B11: =ROUND(SUM(D11:AM11),0) -> 150996874613 | D11: =-D8 -> -3.1496475e+10 | E11: =-E8 -> 0 | AE11: =-AE8 -> 1.8249335e+11
A12: Pembayaran Kepada Pemasok | B12: =ROUND(SUM(D12:AM12),0) -> -181964095253 | F12: =-F8 -> 41984187905 | G12: =-G8 -> -8931966487 | H12: =-H8 -> -1.5815231e+09 | I12: =-I8 -> -2.8560992e+10 | K12: =-K8-K27 -> 2.2790807e+09 | M12: =-M8 -> 0 | P12: =-P8 -> -2.9403235e+10 | Q12: =-Q8 -> -7.737402e+09 | R12: =-R8 -> 6.2661534e+08 | AC12: =-AC8-AC28 -> 0 | AF12: =-AF8-AF13 -> -1.391434e+11 | AH12: =-AH8-AH13-AH14 -> -9.8829513e+09 | AI12: =-(AI8+AI14+AI19) -> -1.612506e+09 | AK12: =-(AK8-AL16) -> 0 | AM12: =-AM20-AM8 -> 0
A13: Pembayaran Kepada Karyawan | B13: =SUM(D13:AM13) -> -5127549818 | AF13: -241462283 | AH13: -4886087535
A14: Pembayaran Beban Operasional Lainnya | B14: =ROUND(SUM(D14:AM14),0) -> -15194741148 | L14: =-L8 -> 0 | V14: =-V8 -> -9.6828422e+08 | W14: =-W8 -> 0 | AG14: =-AG8 -> -1.4110744e+10 | AH14: -115712938
A15: Penerimaan Bunga | B15: =SUM(D15:AM15) -> 0
A16: Deferred tax | B16: =SUM(D16:AM16) -> 0 | AM16: 0
A17: Employee benefit | B17: =SUM(D17:AM17) -> 0
A18: Pembayaran Deviden | B18: =SUM(D18:AM18) -> 0
A19: Pembayaran Bunga | B19: =ROUND(SUM(D19:AM19),0) -> -9424292095 | AJ19: =-AJ8 -> -9.4242921e+09
A20: Pembayaran Pajak Penghasilan | B20: =SUM(D20:AM20) -> -1135531100 | AL20: =-AL8 -> -1135531100
A21: Kas diperoleh dari (digunakan untuk) operasi | B21: =SUM(B11:B20) -> -61849334801
A24: Kas Bersih Diperoleh dari Aktivitas Operasi
A26: ARUS KAS DARI AKTIVITAS INVESTASI
A27: Penambahan Aset Tetap | B27: =SUM(D27:AM27) -> 0
A28: Penempatan Investasi pada Ventura Bersama | B28: =SUM(D28:AM28) -> 0 | J28: =-J8 -> 0
A29: Penambahan Aset Tersedia untuk dijual | B29: =SUM(D29:AM29) -> 0
A30: Penambahan PI | B30: =SUM(D30:AM30) -> 0
A31: Penerimaan Piutang lain-lain dari Pihak Berelasi | B31: =SUM(D31:AM31) -> 0
A32: Pinjaman kepada Entitas Berelasi | B32: =SUM(D32:AM32) -> 0
A33: Kas Bersih Diperoleh dari (Digunakan untuk) Aktivitas Investasi | B33: =SUM(B27:B32) -> 0
A35: ARUS KAS DARI AKTIVITAS PENDANAAN
A36: Penerimaan Pinjaman dari Bank | B36: =SUM(D36:AM36) -> -9156032995 | N36: =-N8 -> -9156032995 | O36: =-O8 -> 0
A37: Pembayaran Pinjaman Bank | B37: =SUM(D37:AM37) -> 0 | U37: =-U8 -> 0
A38: Pinjaman kepada Koperasi | B38: =SUM(D38:AM38) -> 0
A39: Lembaga Pembiayaan | B39: =SUM(D39:AM39) -> -76360023 | T39: =-T8 -> -76360023
A40: Setoran Laba | B40: =SUM(D40:AM40) -> 0 | X40: =-X8 -> 15000000000 | AD40: =-AD8 -> -15000000000
A41: pembayaran Deviden | B41: =SUM(D41:AM41) -> 0
A42: Pembayaran Pembelian Aset Tetap | B42: =SUM(D42:AM42) -> 0
A43: Modal Disetor dari Penawaran Umum Perdana Saham | B43: =SUM(D43:AM43) -> 14500000000 | Z43: =-Z8 -> 14500000000
A44: Agio Saham atas Penawaran Umum Perdana Saham | B44: =SUM(D44:AM44) -> 58000000000 | AA44: =-AA8 -> 58000000000
A45: Biaya Emisi atas Penawaran Umum Perdana Saham | B45: =SUM(D45:AM45) -> -3115944915 | AB45: =-AB8 -> -3115944915
...

Sheet CF 2023
B1: 1.7661193e+11 | C1: =SUM(C7:L7) -> 1.7661193e+11 | F1: 153903160236
A2: =C3/2 -> 0 | C2: =SUM(N7:AA7) -> -1.7661193e+11
C3: =C1+C2 -> 0
C4: Kas dan Bank | D4: Piutang Usaha Kepada Pihak Ketiga | E4: Piutang Usaha Kepada Pihak Berelasi | F4: Piutang Lain-Lain | G4: Persediaan | H4: Prepaid Tax | I4: Prepaid | J4: Investasi pada Entitas Asosias | K4: Aset Tetap | L4: Aset Pajak Tangguhan | M4: Biaya Pra IPO | N4: Short Term Bank Loans | O4: Bank Loan - Short part of long | P4: Utang Usaha Pihak Berelasi | Q4: Utang Usaha Pihak Ketiga | R4: Biaya Yang Masih Harus Dibayar | S4: Utang Lain2 Pihak Ketiga | T4: Utang Lembaga Pembiayaan | U4: Utang Bank & Leasing | V4: Utang Pajak | W4: Imbalan Pasca Kerja | X4: Modal Saham | Y4: Tambahan Modal Disetor | Z4: Penghasilan Komprehensif Lainnya | AA4: Saldo Laba | AB4: Pendapatan Usaha | AC4: Beban Pokok Pendapatan Usaha | AD4: Beban Penjualan | AE4: Beban Umum dan Administrasi | AF4: Beban(Pendapatan) Lain-lain | AG4: Beban Bunga dan Keuangan | AH4: Income Tax | AI4: Income Tax | AJ4: Other Comprehensive Income | AK4: 17999087818 | AL4: =AK4-AK6 -> 1.7999088e+10
