Workbook
Name \a: [1]JUL!#REF!
Name \APR: #REF!
Name \AUG: #REF!
Name \b: [2]T.B!#REF!
Name \BCYTD: '[3]CF WORKSHEET'!#REF!
Name \BRYTD: #REF!
Name \BSYTD: #REF!
Name \BTWO: #REF!
Name \BUYTD: #REF!
Name \C: #REF!
Name \CTWO: #REF!
Name \d: [2]T.B!#REF!
Name \DEC: #REF!
Name \DTWO: #REF!
Name \E: [4]SMITH!#REF!
Name \F: [4]SMITH!#REF!
Name \FEB: #REF!
Name \JAN: #REF!
Name \m: [2]T.B!#REF!
Name \MAR: #REF!
Name \MAY: #REF!
Name \NOV: #REF!
Name \OCT: #REF!
Name \p: #REF!
Name \r: #REF!
Name \s: #REF!
Name \SEP: #REF!
Name \T: '[3]CF WORKSHEET'!#REF!
Name \T2: '[5]ban-ling'!#REF!
Name \u: #REF!
Name \Z: #REF!
Name ___________DAT1: [6]K.6DEPOSIT!#REF!
Name __________DAT1: [6]K.6DEPOSIT!#REF!
Name __________xlnm.Print_Titles_1: #REF!
Name _________DAT1: [6]K.6DEPOSIT!#REF!
Name _________KD1: #REF!
Name _________KD2: #REF!
Name _________KD3: #REF!
Name _________KD4: #REF!
Name _________KD5: #REF!
Name _________KE1: #REF!
Name _________KE2: #REF!
Name _________KE3: #REF!
Name _________KE4: #REF!
Name _________KE5: #REF!
Name _________KF1: #REF!
Name _________KF2: #REF!
Name _________KF3: #REF!
Name _________KF4: #REF!
Name _________KF5: #REF!
Name _________KG1: #REF!
Name _________KG2: #REF!
Name _________KG3: #REF!
Name _________KG4: #REF!
Name _________KG5: #REF!
Name _________mm02: #REF!
Name _________mm2: #REF!
Name _________PL1: #REF!
Name _________PL2: #REF!
Name _________PL3: #REF!

Sheet ELIM Juni 23
A1: Konsolidasi Juni 2023
A4: Account No. | B4: Date | C4: Account Name | E4: WP Reff | F4: Balance Sheet | H4: PL | J4: Description
F5: Debit | G5: Credit | H5: Debit | I5: Credit
A7: ELIM 1 | C7: PT Indo American Seafoods (Keuangan) | F7: 97221191334 | J7: Eleminasi Utang Piutang Keuangan
A8: =A7 -> ELIM 1 | D8: PT Indokom Samudra Persada (Keuangan) | G8: =F7 -> 97221191334 | J8: =J7 -> Eleminasi Utang Piutang Keuangan
A10: ELIM 2 | C10: PT Indokom Samudra Persada | F10: 39815441380 | J10: Eleminasi Utang Piutang
A11: =A10 -> ELIM 2 | D11: PT Indo American Seafoods | G11: =F10 -> 39815441380 | J11: =J10 -> Eleminasi Utang Piutang
A13: ELIM 3 | C13: PT Indo American Seafoods | F13: 7507763245 | J13: Eleminasi Utang Piutang
A14: =A13 -> ELIM 3 | D14: PT Indokom Samudra Persada | G14: =F13 -> 7507763245 | J14: =J13 -> Eleminasi Utang Piutang
A16: ELIM 4 | C16: Penjualan Lokal ISP to IAS | H16: 52200380108 | J16: Eleminasi Penjualan ISP to IAS
A17: =A16 -> ELIM 4 | C17: Pendapatan Lain-Lain | H17: 311335980 | J17: =J16 -> Eleminasi Penjualan ISP to IAS
A18: =A17 -> ELIM 4 | C18: Penjualan Roti | H18: 919030200 | J18: =J17 -> Eleminasi Penjualan ISP to IAS
A19: =A18 -> ELIM 4 | D19: Pembelian to IAS | I19: 52200380108 | J19: =J18 -> Eleminasi Penjualan ISP to IAS
A20: =A19 -> ELIM 4 | D20: Pembelian Lain-lain | I20: 1230366180 | J20: =J19 -> Eleminasi Penjualan ISP to IAS
A22: ELIM 5 | C22: Penjualan IAS | H22: 7575726102 | J22: Eleminasi Penjualan IAS to ISP
A23: =A22 -> ELIM 5 | D23: Pembelian Bahan Baku to ISP | I23: 7526189302 | J23: =J22 -> Eleminasi Penjualan IAS to ISP
D24: Pembelian Bahan Pembantu to ISP | I24: 49536800
A26: ELIM 7 | C26: LABA DITAHAN | H26: 5868638298
A27: =A26 -> ELIM 7 | D27: Tambahan Modal Disetor (Tax Amnesty) | I27: =H26 -> 5868638298

Sheet ELIM & CAJE Juni 24
B1: JURNAL ELIMINASI
B2: Konsolidasi Juni 2024
B5: Account No. | C5: Date | D5: Account Name | F5: WP Reff | G5: Balance Sheet | I5: PL | K5: Description
G6: Debit | H6: Credit | I6: Debit | J6: Credit
B8: ELIM 1 | D8: PT Indo American Seafoods (Keuangan) | G8: =H9 -> 101208651861 | K8: Eleminasi Utang Piutang Keuangan
B9: =B8 -> ELIM 1 | E9: PT Indokom Samudra Persada (Keuangan) | H9: 101208651861 | K9: =K8 -> Eleminasi Utang Piutang Keuangan
B11: ELIM 2 | D11: PT Indokom Samudra Persada | G11: 58472629508 | K11: Eleminasi Utang Piutang
B12: =B11 -> ELIM 2 | E12: PT Indo American Seafoods | H12: =G11 -> 58472629508 | K12: =K11 -> Eleminasi Utang Piutang
B14: ELIM 3 | D14: PT Indo American Seafoods | G14: =H15 -> 2563261534 | K14: Eleminasi Utang Piutang
B15: =B14 -> ELIM 3 | E15: PT Indokom Samudra Persada | H15: 2563261534 | K15: =K14 -> Eleminasi Utang Piutang
B17: ELIM 4 | D17: Indo American Seafoods, PT (Saham) | G17: 1050000000 | K17: Eleminasi IAS Investasi pada Anak
B18: =B17 -> ELIM 4 | E18: PT Indo American Seafoods (Modal) | H18: =G17 -> 1050000000 | K18: =K17 -> Eleminasi IAS Investasi pada Anak
B21: ELIM 5 | D21: Penjualan Lokal ISP to IAS | I21: 12316866928 | K21: Eleminasi Penjualan ISP to IAS
B22: ELIM 5 | D22: Pendapatan Lain-Lain | I22: 194016790 | K22: =K21 -> Eleminasi Penjualan ISP to IAS
B23: ELIM 5 | D23: Penjualan Roti | I23: 1056351000 | K23: =K22 -> Eleminasi Penjualan ISP to IAS
B24: ELIM 5 | E24: Pembelian to IAS | J24: 12316866928 | K24: =K23 -> Eleminasi Penjualan ISP to IAS
B25: ELIM 5 | E25: Pembelian Lain-lain | J25: 1250367790 | K25: =K24 -> Eleminasi Penjualan ISP to IAS
B27: ELIM 6 | D27: Penjualan IAS | I27: 6225265015 | K27: Eleminasi Penjualan IAS to ISP
B28: ELIM 6 | E28: Pembelian ISP | J28: =I27 -> 6225265015 | K28: =K27 -> Eleminasi Penjualan IAS to ISP
B30: ELIM 7 | D30: LABA DITAHAN | I30: 5868638298
B31: =B30 -> ELIM 7 | E31: Tambahan Modal Disetor (Tax Amnesty) | J31: =I30 -> 5868638298
B34: CAJE 1 | E34: LABA DITAHAN | H34: 2
B35: =B34 -> CAJE 1 | D35: Piutang Lain-lain di bawah Rp 20.000.000,- | G35: 2
D36: (Adj atas Ctrl)

Sheet ELIM & CAJE Sept 23
A1: Konsolidasi September 2023
A4: Account No. | B4: Date | C4: Account Name | E4: WP Reff | F4: Balance Sheet | H4: PL | J4: Description
F5: Debit | G5: Credit | H5: Debit | I5: Credit
A7: ELIM 1 | C7: PT Indo American Seafoods (Keuangan) | F7: 123411723048 | J7: Eleminasi Utang Piutang Keuangan
A8: =A7 -> ELIM 1 | D8: PT Indokom Samudra Persada (Keuangan) | G8: =F7 -> 123411723048 | J8: =J7 -> Eleminasi Utang Piutang Keuangan
A10: ELIM 2 | C10: PT Indokom Samudra Persada | F10: 6441405695 | J10: Eleminasi Utang Piutang
A11: =A10 -> ELIM 2 | D11: PT Indo American Seafoods | G11: =F10 -> 6441405695 | J11: =J10 -> Eleminasi Utang Piutang
A13: ELIM 3 | C13: PT Indo American Seafoods | F13: 55459611170 | J13: Eleminasi Utang Piutang
A14: =A13 -> ELIM 3 | D14: PT Indokom Samudra Persada | G14: =F13 -> 55459611170 | J14: =J13 -> Eleminasi Utang Piutang
A16: ELIM 4 | C16: Penjualan Lokal ISP to IAS | H16: 71326250958 | J16: Eleminasi Penjualan ISP to IAS
A17: =A16 -> ELIM 4 | C17: Pendapatan Lain-Lain | H17: 497965132 | J17: =J16 -> Eleminasi Penjualan ISP to IAS
A18: =A17 -> ELIM 4 | C18: Penjualan Roti | H18: 1148410200 | J18: =J17 -> Eleminasi Penjualan ISP to IAS
A19: =A18 -> ELIM 4 | D19: Pembelian to IAS | I19: 10264188776 | J19: =J18 -> Eleminasi Penjualan ISP to IAS
A20: =A19 -> ELIM 4 | D20: Pembelian Lain-lain | I20: 65549600 | J20: =J19 -> Eleminasi Penjualan ISP to IAS
A22: ELIM 5 | C22: Penjualan IAS | H22: 10329738376 | J22: Eleminasi Penjualan IAS to ISP
A23: =A22 -> ELIM 5 | D23: Pembelian Bahan Baku to ISP | I23: 71326250958 | J23: =J22 -> Eleminasi Penjualan IAS to ISP
A24: =A23 -> ELIM 5 | D24: Pembelian Bahan Pembantu to ISP | I24: 1646375332 | J24: =J23 -> Eleminasi Penjualan IAS to ISP
A26: ELIM 7 | C26: LABA DITAHAN | H26: 5868638298
A27: =A26 -> ELIM 7 | D27: Tambahan Modal Disetor (Tax Amnesty) | I27: =H26 -> 5868638298

Sheet LPK Analysis
A1: PT INDO AMERICAN SEAFOODS DAN ENTAS ANAK
A2: Laporan Posisi Keuangan
A3: Tanggal 30 September 2024, 31 Desember 2023, 2022 dan 2021
A6: Keterangan | B6: 45565 | C6: 31 Desember | I6: Difference | N6: % Growth
B7: 2024 | C7: 2024 | D7: 2023 | E7: 2022 | F7: 2021 | I7: 45536 | J7: 45627 | K7: 45261 | L7: 44896 | N7: 45536 | O7: 45627 | P7: 45261 | Q7: 44896
A8: ASET
A9: Aset Lancar
A10: Kas dan Setara Kas | B10: ='BS Konsol-Des 24'!I11 -> 13187388399 | C10: ='BS Konsol-Des 24'!G11 -> 918209485 | D10: 2570121355 | E10: 4920468963 | F10: 4972845584 | H10: =D10-E10 -> -2350347608 | I10: =B10-D10 -> 10617267044 | J10: =C10-D10 -> -1651911870 | K10: =D10-E10 -> -2350347608 | L10: =E10-F10 -> -52376621 | N10: =I10/D10 -> 4.1310372 | O10: =J10/D10 -> -0.64273691 | P10: =K10/E10 -> -0.4776674 | Q10: =L10/F10 -> -0.010532525
A11: Piutang Usaha dari Pihak Ketiga - Bersih | B11: ='BS Konsol-Des 24'!I14 -> 37856978018 | C11: ='BS Konsol-Des 24'!G14 -> 94399254849 | D11: 19981020112 | E11: 53102808880 | F11: 38673285818 | I11: =B11-D11 -> 17875957906 | J11: =C11-D11 -> 74418234737 | K11: =D11-E11 -> -33121788768 | L11: =E11-F11 -> 14429523062 | N11: =I11/D11 -> 0.89464691 | O11: =J11/D11 -> 3.7244462 | P11: =K11/E11 -> -0.62372951 | Q11: =L11/F11 -> 0.37311345
A12: Piutang Usaha dari Pihak Berelasi | B12: ='BS Konsol-Des 24'!I13 -> 339894481 | C12: ='BS Konsol-Des 24'!G13 -> 393935430 | D12: 211054410 | E12: 1729176327 | F12: 1565918952 | I12: =B12-D12 -> 128840071 | J12: =C12-D12 -> 182881020 | K12: =D12-E12 -> -1518121917 | L12: =E12-F12 -> 163257375 | N12: =I12/D12 -> 0.61045903 | O12: =J12/D12 -> 0.86651125 | P12: =K12/E12 -> -0.87794512 | Q12: =L12/F12 -> 0.10425659
A13: Piutang Lain-lain dari Pihak Ketiga | B13: ='BS Konsol-Des 24'!I15 -> 510634104 | C13: ='BS Konsol-Des 24'!G15 -> 697232257 | D13: 510634104 | E13: 549732399 | F13: 466154019 | I13: =B13-D13 -> 0 | J13: =C13-D13 -> 186598153 | K13: =D13-E13 -> -39098295 | L13: =E13-F13 -> 83578380 | N13: =I13/D13 -> 0 | O13: =J13/D13 -> 0.36542438 | P13: =K13/E13 -> -0.071122414 | Q13: =L13/F13 -> 0.17929349
A14: Piutang lain-lain dari pihak berelasi | B14: =0 -> 0 | C14: =0 -> 0 | D14: 7022707423 | E14: 7197443207 | F14: 6836690211 | I14: =B14-D14 -> -7022707423 | J14: =C14-D14 -> -7022707423 | K14: =D14-E14 -> -174735784 | L14: =E14-F14 -> 360752996 | N14: =I14/D14 -> -1 | O14: =J14/D14 -> -1 | P14: =K14/E14 -> -0.02427748 | Q14: =L14/F14 -> 0.052767199
A15: Persediaan | B15: ='BS Konsol-Des 24'!I16 -> 262102659717 | C15: ='BS Konsol-Des 24'!G16 -> 217742151701 | D15: 218071396362 | E15: 137179893500 | F15: 95865646086 | I15: =B15-D15 -> 44031263355 | J15: =C15-D15 -> -329244661 | K15: =D15-E15 -> 80891502862 | L15: =E15-F15 -> 41314247414 | N15: =I15/D15 -> 0.20191214 | O15: =J15/D15 -> -0.0015098021 | P15: =K15/E15 -> 0.58967463 | Q15: =L15/F15 -> 0.43095988
A16: Aset Biologis | B16: ='BS Konsol-Des 24'!I17 -> 3489807904 | C16: ='BS Konsol-Des 24'!G17 -> 913803984 | D16: 2415719386 | E16: 651253829 | F16: 871760289 | H16: =E16-D16 -> -1764465557 | I16: =B16-D16 -> 1074088518 | J16: =C16-D16 -> -1501915402 | K16: =D16-E16 -> 1764465557 | L16: =E16-F16 -> -220506460 | N16: =I16/D16 -> 0.4446247 | O16: =J16/D16 -> -0.62172594 | P16: =K16/E16 -> 2.7093362 | Q16: =L16/F16 -> -0.25294391
A17: Pajak Dibayar di Muka | B17: ='BS Konsol-Des 24'!I18 -> 11345112342 | C17: ='BS Konsol-Des 24'!G18 -> 9035601705 | D17: 9663458887 | E17: 8035438770 | F17: 8635897222 | H17: =E17-D17 -> -1628020117 | I17: =B17-D17 -> 1681653455 | J17: =C17-D17 -> -627857182 | K17: =D17-E17 -> 1628020117 | L17: =E17-F17 -> -600458452 | N17: =I17/D17 -> 0.1740219 | O17: =J17/D17 -> -0.064972303 | P17: =K17/E17 -> 0.20260501 | Q17: =L17/F17 -> -0.069530523
A18: Biaya Dibayar di Muka | B18: 0 | C18: 0 | D18: 0 | E18: 0 | F18: 0 | I18: =B18-D18 -> 0 | J18: =C18-D18 -> 0 | K18: =D18-E18 -> 0 | L18: =E18-F18 -> 0 | N18: =I18/D18 -> #DIV/0! | O18: =J18/D18 -> #DIV/0! | P18: =K18/E18 -> #DIV/0! | Q18: =L18/F18 -> #DIV/0!
A19: Uang Muka | B19: ='BS Konsol-Des 24'!I20 -> 1488682854 | C19: ='BS Konsol-Des 24'!G20 -> 33893674735 | D19: 1104447053 | E19: 349309986 | F19: 227462120 | I19: =B19-D19 -> 384235801 | J19: =C19-D19 -> 32789227682 | K19: =D19-E19 -> 755137067 | L19: =E19-F19 -> 121847866 | N19: =I19/D19 -> 0.3478988 | O19: =J19/D19 -> 29.688365 | P19: =K19/E19 -> 2.1617964 | Q19: =L19/F19 -> 0.53568421
A20: Jumlah Aset Lancar | B20: =SUM(B10:B19) -> 330321157819 | C20: =SUM(C10:C19) -> 357993864146 | D20: =SUM(D10:D19) -> 261550559092 | E20: =SUM(E10:E19) -> 213715525861 | F20: =SUM(F10:F19) -> 158115660301 | H20: =D20-E20 -> 47835033231 | I20: =B20-D20 -> 68770598727 | J20: =C20-D20 -> 96443305054 | K20: =D20-E20 -> 47835033231 | L20: =E20-F20 -> 55599865560 | N20: =I20/D20 -> 0.26293424 | O20: =J20/D20 -> 0.36873676 | P20: =K20/E20 -> 0.22382573 | Q20: =L20/F20 -> 0.35164047
A21: Aset Tidak Lancar
A22: Aset Tetap – setelah dikurangi akumulasi Penyusutan | B22: ='BS Konsol-Des 24'!I29 -> 68366993855 | C22: ='BS Konsol-Des 24'!G29 -> 66637513685 | D22: ='[188]BS Konsol'!I37 -> 74113104582 | E22: ='[188]BS Konsol'!K37 -> 84248284795 | F22: ='BS Konsol-Des 24'!U29 -> 94612283276 | I22: =B22-D22 -> -5746110727 | J22: =C22-D22 -> -7475590897 | K22: =D22-E22 -> -10135180213 | L22: =E22-F22 -> -10363998481 | N22: =I22/D22 -> -0.077531642 | O22: =J22/D22 -> -0.10086733 | P22: =K22/E22 -> -0.12030132 | Q22: =L22/F22 -> -0.10954179
A23: Aset Hak-Guna – setelah dikurangi akumulasi penyusutan | B23: ='BS Konsol-Des 24'!I33 -> 7635332866 | C23: ='BS Konsol-Des 24'!G33 -> 7556618094 | D23: ='[188]BS Konsol'!I46 -> 7871477182 | E23: ='[188]BS Konsol'!K46 -> 8186336269 | F23: ='BS Konsol-Des 24'!U33 -> 8501195356 | I23: =B23-D23 -> -236144316 | J23: =C23-D23 -> -314859088 | K23: =D23-E23 -> -314859087 | L23: =E23-F23 -> -314859087 | N23: =I23/D23 -> -0.03 | O23: =J23/D23 -> -0.04 | P23: =K23/E23 -> -0.038461538 | Q23: =L23/F23 -> -0.037037037
A24: Aset Pajak Tangguhan | B24: ='BS Konsol'!H45 -> 1790182139 | C24: ='BS Konsol-Des 24'!G37 -> 1848977778 | D24: ='[188]BS Konsol'!I48 -> 1790182139 | E24: ='[188]BS Konsol'!K48 -> 1508277305 | F24: ='BS Konsol-Des 24'!U37 -> 1486561645 | I24: =B24-D24 -> 0 | J24: =C24-D24 -> 58795639 | K24: =D24-E24 -> 281904834 | L24: =E24-F24 -> 21715660 | N24: =I24/D24 -> 0 | O24: =J24/D24 -> 0.032843384 | P24: =K24/E24 -> 0.18690518 | Q24: =L24/F24 -> 0.014607978
A25: Jumlah Aset Tidak Lancar | B25: =SUM(B22:B24) -> 77792508860 | C25: =SUM(C22:C24) -> 76043109557 | D25: =SUM(D22:D24) -> 83774763903 | E25: =SUM(E22:E24) -> 93942898369 | F25: =SUM(F22:F24) -> 104600040277 | I25: =B25-D25 -> -5982255043 | J25: =C25-D25 -> -7731654346 | K25: =D25-E25 -> -10168134466 | L25: =E25-F25 -> -10657141908 | N25: =I25/D25 -> -0.071408796 | O25: =J25/D25 -> -0.092290971 | P25: =K25/E25 -> -0.10823739 | Q25: =L25/F25 -> -0.10188468
A26: JUMLAH ASET | B26: =B20+B25 -> 408113666679 | C26: =C20+C25 -> 434036973703 | D26: =D20+D25 -> 345325322995 | E26: =E20+E25 -> 307658424230 | F26: =F20+F25 -> 262715700578 | I26: =B26-D26 -> 62788343684 | J26: =C26-D26 -> 88711650708 | K26: =D26-E26 -> 37666898765 | L26: =E26-F26 -> 44942723652 | N26: =I26/D26 -> 0.18182375 | O26: =J26/D26 -> 0.25689298 | P26: =K26/E26 -> 0.1224309 | Q26: =L26/F26 -> 0.1710698
A28: LIABILITAS DAN EKUITAS
A29: Liabilitas Jangka Pendek
A30: Utang Usaha kepada Pihak Ketiga | B30: ='BS Konsol-Des 24'!I52 -> 10645094570 | C30: ='BS Konsol-Des 24'!G52 -> 10364486466 | D30: 20407901137 | E30: 12347357380 | F30: 14116621585 | I30: =B30-D30 -> -9762806567 | J30: =C30-D30 -> -10043414671 | K30: =D30-E30 -> 8060543757 | L30: =E30-F30 -> -1769264205 | N30: =I30/D30 -> -0.47838367 | O30: =J30/D30 -> -0.49213364 | P30: =K30/E30 -> 0.6528153 | Q30: =L30/F30 -> -0.12533199
A31: Utang Lain-lain kepada Pihak Berelasi | D31: 0 | E31: 0 | F31: 0 | I31: =B31-D31 -> 0 | K31: =D31-E31 -> 0 | L31: =E31-F31 -> 0 | N31: =I31/D31 -> #DIV/0! | O31: =J31/D31 -> #DIV/0! | P31: =K31/E31 -> #DIV/0! | Q31: =L31/F31 -> #DIV/0!
A32: Utang Lain-lain kepada Pihak Ketiga | D32: 0 | E32: 0 | F32: 0 | I32: =B32-D32 -> 0 | K32: =D32-E32 -> 0 | L32: =E32-F32 -> 0 | N32: =IFERROR(I32/D32,0) -> 0 | O32: =J32/D32 -> #DIV/0! | P32: =IFERROR(K32/E32,0) -> 0 | Q32: =IFERROR(L32/F32,0) -> 0
A33: Utang Bank | B33: ='BS Konsol-Des 24'!I55 -> 196870184183 | C33: ='BS Konsol-Des 24'!G55 -> 231271837921 | D33: 195441714689 | E33: 155339616431 | F33: 110815447741 | I33: =B33-D33 -> 1428469494 | J33: =C33-D33 -> 35830123232 | K33: =D33-E33 -> 40102098258 | L33: =E33-F33 -> 44524168690 | N33: =IFERROR(I33/D33,0) -> 0.0073089284 | O33: =J33/D33 -> 0.18332894 | P33: =IFERROR(K33/E33,0) -> 0.25815757 | Q33: =IFERROR(L33/F33,0) -> 0.40178666
A34: Beban Akrual | B34: ='BS Konsol-Des 24'!I56 -> 4949487657 | C34: ='BS Konsol-Des 24'!G56 -> 4970839301 | D34: 2870843988 | E34: 5031429971 | F34: 5655591014 | I34: =B34-D34 -> 2078643669 | J34: =C34-D34 -> 2099995313 | K34: =D34-E34 -> -2160585983 | L34: =E34-F34 -> -624161043 | N34: =I34/D34 -> 0.72405316 | O34: =J34/D34 -> 0.73149057 | P34: =K34/E34 -> -0.42941788 | Q34: =L34/F34 -> -0.11036177
A35: Utang Pajak | B35: ='BS Konsol-Des 24'!I57 -> 4409068751 | C35: ='BS Konsol-Des 24'!G57 -> 1467515499 | D35: 2863697915 | E35: 2152621331 | F35: 712242589 | I35: =B35-D35 -> 1545370836 | J35: =C35-D35 -> -1396182416 | K35: =D35-E35 -> 711076584 | L35: =E35-F35 -> 1440378742 | N35: =I35/D35 -> 0.53964171 | O35: =J35/D35 -> -0.48754528 | P35: =K35/E35 -> 0.33033055 | Q35: =L35/F35 -> 2.0223148
A36: Utang Jangka Pendek
A37: yang Jatuh Tempo dalam
A38: Satu Tahun
A39: Utang Pembelian Aset Tetap | B39: ='BS Konsol-Des 24'!I61 -> 19446177 | C39: ='BS Konsol-Des 24'!G61 -> 0 | D39: 76360023 | E39: 67475296 | F39: ='[188]BS Konsol'!M75 -> 0 | I39: =B39-D39 -> -56913846 | J39: =C39-D39 -> -76360023 | K39: =D39-E39 -> 8884727 | L39: =E39-F39 -> 67475296 | N39: =I39/D39 -> -0.74533563 | O39: =J39/D39 -> -1 | P39: =K39/E39 -> 0.13167378 | Q39: =L39/F39 -> #DIV/0!
A40: Liabilitas Sewa kepada Pihak Berelasi | B40: ='BS Konsol'!H68 -> 0 | C40: ='BS Konsol-Des 24'!G63 -> 0 | D40: 624277457 | E40: 3539216266 | F40: 0 | I40: =B40-D40 -> -624277457 | J40: =C40-D40 -> -624277457 | K40: =D40-E40 -> -2914938809 | L40: =E40-F40 -> 3539216266 | N40: =I40/D40 -> -1 | O40: =J40/D40 -> -1 | P40: =K40/E40 -> -0.82361138 | Q40: =L40/F40 -> #DIV/0!
A41: Utang Bank | B41: ='BS Konsol-Des 24'!I64 -> 900894064 | C41: ='BS Konsol-Des 24'!G64 -> 0 | D41: 3807894064 | E41: 3403633332 | F41: 3403633332 | I41: =B41-D41 -> -2907000000 | J41: =C41-D41 -> -3807894064 | K41: =D41-E41 -> 404260732 | L41: =E41-F41 -> 0 | N41: =IFERROR(I41/D41,0) -> -0.76341409 | O41: =J41/D41 -> -1 | P41: =IFERROR(K41/E41,0) -> 0.11877329 | Q41: =IFERROR(L41/F41,0) -> 0
A42: Jumlah Liabilitas Jangka Pendek | B42: =SUM(B29:B41) -> 217794175402 | C42: =SUM(C29:C41) -> 248074679187 | D42: =SUM(D29:D41) -> 226092689273 | E42: =SUM(E29:E41) -> 181881350007 | F42: =SUM(F29:F41) -> 134703536261 | I42: =B42-D42 -> -8298513871 | J42: =C42-D42 -> 21981989914 | K42: =D42-E42 -> 44211339266 | L42: =E42-F42 -> 47177813746 | N42: =I42/D42 -> -0.036704035 | O42: =J42/D42 -> 0.097225567 | P42: =K42/E42 -> 0.24307791 | Q42: =L42/F42 -> 0.35023441
A43: Liabilitas Jangka Panjang
...

Sheet PL-Analysis
A1: PT INDO AMERICAN SEAFOODS DAN ENTAS ANAK
A2: Laporan Laba Rugi dan Penghasilan Komprehensif Lain
A3: Tanggal 31 Desember 2024, 2023, 2022 dan 2021
A7: Keterangan | D7: 31 Desember
B8: 45565 | C8: 45565 | D8: 2024*) | E8: 2023*) | F8: 2022*) | G8: 2021*) | J8: Difference | O8: % Growth
B9: 2024 | C9: 2024 | D9: (12 Bulan) | E9: (12 Bulan) | F9: (12 Bulan) | G9: (12 Bulan) | J9: September | K9: 45627 | L9: 45261 | M9: 44896 | O9: September | P9: 45627 | Q9: 45261 | R9: 44896
A10: PENJUALAN DAN PENDAPATAN USAHA | B10: ='PL Konsol'!F11 -> 160540499628 | C10: ='PL Konsol'!H11 -> 149774869471 | D10: ='PL Konsol'!M11 -> 3.2256021e+11 | E10: 199222794205 | F10: 382316276945 | G10: 303872116071 | J10: =B10-C10 -> 10765630157 | K10: =D10-E10 -> 1.2333742e+11 | L10: =E10-F10 -> -183093482740 | M10: =F10-G10 -> 78444160874 | O10: =J10/C10 -> 0.071878748 | P10: =K10/E10 -> 0.61909291 | Q10: =L10/F10 -> -0.4789058 | R10: =M10/G10 -> 0.2581486
A11: BEBAN POKOK PENJUALAN | B11: ='PL Konsol'!F12 -> -107535872927 | C11: ='PL Konsol'!H12 -> -97141890286 | D11: ='PL Konsol'!M12 -> -2.4693474e+11 | E11: -134214335812 | F11: -298009655959 | G11: -235513908676 | J11: =B11-C11 -> -10393982641 | K11: =D11-E11 -> -1.127204e+11 | L11: =E11-F11 -> 163795320147 | M11: =F11-G11 -> -62495747283 | O11: =J11/C11 -> 0.10699795 | P11: =K11/E11 -> 0.83985367 | Q11: =L11/F11 -> -0.54963092 | R11: =M11/G11 -> 0.26535905
A12: LABA BRUTO | B12: =B10+B11 -> 53004626701 | C12: =C10+C11 -> 52632979185 | D12: =D10+D11 -> 7.5625474e+10 | E12: =E10+E11 -> 65008458393 | F12: =F10+F11 -> 84306620986 | G12: =G10+G11 -> 68358207395 | J12: =B12-C12 -> 371647516 | K12: =D12-E12 -> 1.0617016e+10 | L12: =E12-F12 -> -19298162593 | M12: =F12-G12 -> 15948413591 | O12: =J12/C12 -> 0.0070611149 | P12: =K12/E12 -> 0.16331746 | Q12: =L12/F12 -> -0.22890447 | R12: =M12/G12 -> 0.23330649
A13: Beban Penjualan | B13: ='PL Konsol'!F16 -> -13450215380 | C13: ='PL Konsol'!H16 -> -18108262146 | D13: ='PL Konsol'!M16 -> -16258997299 | E13: -17958725423 | F13: -33826918356 | G13: -26521142401 | J13: =B13-C13 -> 4658046766 | K13: =D13-E13 -> 1699728124 | L13: =E13-F13 -> 15868192933 | M13: =F13-G13 -> -7305775955 | O13: =J13/C13 -> -0.25723323 | P13: =K13/E13 -> -0.094646367 | Q13: =L13/F13 -> -0.46909957 | R13: =M13/G13 -> 0.27546988
A14: Beban Umum dan Administrasi | B14: ='PL Konsol'!F17 -> -26167728635 | C14: ='PL Konsol'!H17 -> -20819164640 | D14: ='PL Konsol'!M17 -> -36246687170 | E14: -27733745691 | F14: -28248056723 | G14: -26942834062 | J14: =B14-C14 -> -5348563995 | K14: =D14-E14 -> -8512941479 | L14: =E14-F14 -> 514311032 | M14: =F14-G14 -> -1305222661 | O14: =J14/C14 -> 0.25690579 | P14: =K14/E14 -> 0.30695246 | Q14: =L14/F14 -> -0.018206953 | R14: =M14/G14 -> 0.048444149
A15: Pendapatan (Beban) Lain-Lain - Bersih | B15: ='PL Konsol'!F18 -> 2273092655 | C15: ='PL Konsol'!H18 -> -906733107 | D15: ='PL Konsol'!M18 -> -2610994654 | E15: -1084534135 | F15: -602810576 | G15: 112244184 | J15: =B15-C15 -> 3179825762 | K15: =D15-E15 -> -1526460519 | L15: =E15-F15 -> -481723559 | M15: =F15-G15 -> -715054760 | O15: =J15/C15 -> -3.5069038 | P15: =K15/E15 -> 1.4074804 | Q15: =L15/F15 -> 0.79912924 | R15: =M15/G15 -> -6.3705284
A16: Beban bunga dan Keuangan | B16: ='PL Konsol'!F19 -> -12487102791 | C16: ='PL Konsol'!H19 -> -11466799581 | D16: ='PL Konsol'!M19 -> -18184572249 | E16: -15677499788 | F16: -13403963086 | G16: -9352093192 | J16: =B16-C16 -> -1020303210 | K16: =D16-E16 -> -2507072461 | L16: =E16-F16 -> -2273536702 | M16: =F16-G16 -> -4051869894 | O16: =J16/C16 -> 0.0889789 | P16: =K16/E16 -> 0.15991532 | Q16: =L16/F16 -> 0.16961675 | R16: =M16/G16 -> 0.43325808
A17: Laba Sebelum Pajak Penghasilan | B17: =SUM(B12:B16) -> 3172672550 | C17: =SUM(C12:C16) -> 1332019711 | D17: =SUM(D12:D16) -> 2.324223e+09 | E17: =SUM(E12:E16) -> 2553953356 | F17: =SUM(F12:F16) -> 8224872245 | G17: =SUM(G12:G16) -> 5654381924 | J17: =B17-C17 -> 1840652839 | K17: =D17-E17 -> -2.2973031e+08 | L17: =E17-F17 -> -5670918889 | M17: =F17-G17 -> 2570490321 | O17: =J17/C17 -> 1.3818511 | P17: =K17/E17 -> -0.089950862 | Q17: =L17/E17 -> -2.2204473 | R17: =M17/G17 -> 0.45460147
A18: Manfaat (Beban) Pajak Penghasilan:
A19: Pajak Kini | B19: ='PL Konsol'!F25 -> -1487297460 | C19: ='PL Konsol'!H25 -> -518727440 | D19: ='PL Konsol'!M25 -> -2052132941 | E19: -1088072700 | F19: -2076985900 | G19: -1421390520 | J19: =B19-C19 -> -968570020 | K19: =D19-E19 -> -964060241 | L19: =E19-F19 -> 988913200 | M19: =F19-G19 -> -655595380 | O19: =J19/C19 -> 1.8672041 | P19: =K19/E19 -> 0.88602558 | Q19: =L19/E19 -> -0.90886684 | R19: =M19/G19 -> 0.46123523
A20: Pajak Tangguhan | B20: 0 | C20: 0 | D20: ='PL Konsol'!M26 -> 76646095 | E20: 279570745 | F20: 90168897 | G20: 1446845971 | J20: =B20-C20 -> 0 | K20: =D20-E20 -> -202924650 | L20: =E20-F20 -> 189401848 | M20: =F20-G20 -> -1356677074 | O20: 0 | P20: =K20/E20 -> -0.72584365 | Q20: =L20/E20 -> 0.67747378 | R20: =M20/G20 -> -0.93767899
A21: LABA PERIODE / TAHUN BERJALAN | B21: =SUM(B17:B20) -> 1685375090 | C21: =SUM(C17:C20) -> 813292271
A22: SEBELUM DAMPAK PENYESUAIAN PROFORMA | B22: 0 | C22: 0 | D22: =SUM(D17:D20) -> 3.487362e+08 | E22: =SUM(E17:E20) -> 1745451401 | F22: =SUM(F17:F20) -> 6238055242 | G22: =SUM(G17:G20) -> 5679837375 | J22: =B22-C22 -> 0 | K22: =D22-E22 -> -1.3967152e+09 | L22: =E22-F22 -> -4492603841 | M22: =F22-G22 -> 558217867 | O22: 0 | P22: =K22/E22 -> -0.80020286 | Q22: =L22/E23 -> #DIV/0! | R22: =M22/G23 -> -0.23808809
A23: DAMPAK PENYESUAIAN PROFORMA | D23: 0 | E23: 0 | F23: -1.0268862e+09 | G23: -2.3445854e+09 | J23: =B23+E23 -> 0 | K23: =D23+E23 -> 0 | L23: =E23+F23 -> -1.0268862e+09 | M23: =F23-G23 -> 1.3176992e+09 | O23: 0 | P23: =K23/E23 -> #DIV/0! | Q23: =L23/E23 -> #DIV/0! | R23: =M23/G23 -> -0.562018
A24: LABA PERIODE / TAHUN BERJALAN
A25: SETELAH DAMPAK PENYESUAIAN PROFORMA | B25: =B22+B23 -> 0 | C25: =C22+C23 -> 0 | D25: =D22+D23 -> 3.487362e+08 | E25: =E22+E23 -> 1745451401 | F25: =F22+F23 -> 5.211169e+09 | G25: =G22+G23 -> 3.335252e+09 | J25: =B25-C25 -> 0 | K25: =D25-E25 -> -1.3967152e+09 | L25: =E25+F25 -> 6.9566204e+09 | M25: =F25-G25 -> 1.8759171e+09 | O25: 0 | P25: =K25/E25 -> -0.80020286 | Q25: =L25/E25 -> 3.985571 | R25: =M25/G25 -> 0.56245138
A26: Pengukuran Kembali Imbalan Pasti | B26: =0 -> 0 | C26: =0 -> 0 | D26: ='PL Konsol'!M41 -> 81138444 | E26: -10609502 | F26: 311151073 | G26: 21039938 | J26: =B26-C26 -> 0 | K26: =D26-E26 -> 91747946 | L26: =E26+F26 -> 300541571 | M26: =F26-G26 -> 290111135 | O26: 0 | P26: =K26/E26 -> -8.6477147 | Q26: =L26/E26 -> -28.327585 | R26: =M26/G26 -> 13.788593
A27: Pajak Penghasilan Terkait | B27: 0 | C27: 0 | D27: ='PL Konsol'!M42 -> -17850458 | E27: 2334090 | F27: -68453236 | G27: -4628786 | J27: =B27-C27 -> 0 | K27: =D27-E27 -> -20184548 | L27: =E27+F27 -> -66119146 | M27: =F27-G27 -> -63824450 | O27: 0 | P27: =K27/E27 -> -8.6477162 | Q27: =L27/E27 -> -28.327591 | R27: =M27/G27 -> 13.788594
A28: JUMLAH PENGHASILAN KOMPREHENSIF LAIN | B28: =B26+B27+'WS Konsol'!W759+'WS Konsol'!W762 -> 0 | C28: =C26+C27+'WS Konsol'!AT759+'WS Konsol'!AT762 -> 0 | D28: =SUM(D26:D27) -> 63287986 | E28: =SUM(E26:E27) -> -8275412 | F28: =SUM(F26:F27) -> 242697837 | G28: =SUM(G26:G27) -> 16411152 | J28: =B28-C28 -> 0 | K28: =D28-E28 -> 71563398 | L28: =E28-F28 -> -250973249 | M28: =F28-G28 -> 226286685 | O28: 0 | P28: =K28/E28 -> -8.6477142 | Q28: =L28/E28 -> 30.327584 | R28: =M28/G28 -> 13.788592
A29: DAMPAK PENYESUAIAN PROFORMA | D29: 0 | E29: 0 | F29: 1.8842722e+08 | G29: -7593457.1 | J29: =B29-C29 -> 0 | K29: =D29-E29 -> 0 | L29: =E29-F29 -> -1.8842722e+08 | M29: =F29-G29 -> 1.9602068e+08 | O29: 0 | P29: =K29/E29 -> #DIV/0! | Q29: =L29/E29 -> #DIV/0! | R29: =M29/G29 -> -25.814418
A30: LABA KOMPREHENSIF PERIODE / TAHUN BERJALAN | B30: =B25+B28+B29 -> 0 | C30: =C25+C28+C29 -> 0 | D30: =D25+D28+D29 -> 4.1202419e+08 | E30: =E25+E28+E29+309 -> 1737176298 | F30: =F25+F28+F29+1262 -> 5.6422953e+09 | G30: =G25+G28+G29+1140 -> 3.3440708e+09 | J30: =B30-C30 -> 0 | K30: =D30-E30 -> -1.3251521e+09 | L30: =E30-F30 -> -3.9051191e+09 | M30: =F30-G30 -> 2.2982245e+09 | O30: 0 | P30: =K30/E30 -> -0.76281959 | Q30: =L30/E30 -> -2.2479693 | R30: =M30/G30 -> 0.68725355
A31: Laba per saham dasar | E31: 2.1818143 | F31: 6.5139613 | G31: 4.169065 | J31: =B31-E31 -> -2.1818143 | K31: =D31-E31 -> -2.1818143 | L31: =E31-F31 -> -4.332147 | M31: =F31-G31 -> 2.3448963 | O31: 0 | P31: =K31/E31 -> -1 | Q31: =L31/E31 -> -1.985571 | R31: =M31/G31 -> 0.56245138
A32: *) Konsolidasian

Sheet CF Analysis
A1: PT INDO AMERICAN SEAFOODS DAN ENTAS ANAK
A2: Laporan Arus Kas
A3: Tanggal 31 Desember 2024, 2023, 2022 dan 2021
A7: Keterangan | D7: 31 Desember
B8: 45565 | C8: 45565 | D8: 2024*) | E8: 2023*) | F8: 2022*) | G8: 2021*) | J8: Difference | O8: % Growth
B9: 2024 | C9: 2023 | D9: (12 Bulan) | E9: (12 Bulan) | F9: (12 Bulan) | G9: (12 Bulan) | J9: September | K9: 45627 | L9: 45261 | M9: 44896 | O9: September | P9: 45627 | Q9: 45261 | R9: 44896
A11: ARUS KAS AKTIVITAS OPERASI
A12: Arus Kas Bersih Diperoleh dari (Digunakan untuk) Aktivitas Operasi | B12: ='CF Konsol'!H22 -> -60184010806 | C12: ='CF Konsol'!J22 -> -7.132382e+09 | D12: ='CF Konsol'!F22 -> -1.0861459e+11 | E12: -3.0698923e+10 | F12: -38731871094 | G12: -2.2046803e+09 | J12: =B12-C12 -> -5.3051629e+10 | K12: =D12-E12 -> -7.7915667e+10 | L12: =E12-F12 -> 8.0329486e+09 | M12: =F12-G12 -> -3.6527191e+10 | O12: =C12/J12 -> 0.13444228 | P12: =K12/E12 -> 2.5380587 | Q12: =L12/F12 -> -0.20739893 | R12: =M12/G12 -> 16.568021
A14: ARUS KAS AKTIVITAS INVESTASI
A15: Arus Kas Bersih digunakan untuk Aktivitas Investasi | B15: ='CF Konsol'!H37 -> 7022707423 | C15: ='CF Konsol'!J37 -> -149115000 | D15: ='CF Konsol'!F37 -> 6852707423 | E15: -149115000 | F15: -337817118 | G15: -1.7752124e+10 | J15: =B15-C15 -> 7171822423 | K15: =D15-E15 -> 7001822423 | L15: =E15-F15 -> 188702118 | M15: =F15-G15 -> 1.7414307e+10 | O15: =C15/J15 -> -0.020791786 | P15: =K15/E15 -> -46.955856 | Q15: =L15/F15 -> -0.55859253 | R15: =M15/G15 -> -0.98097033
A17: ARUS KAS AKTIVITAS PENDANAAN
A18: Arus Kas Bersih digunakan untuk Aktivitas Pendanaan | B18: ='CF Konsol'!H61 -> 63778570427 | C18: ='CF Konsol'!J61 -> 5175401254 | D18: ='CF Konsol'!F61 -> 100109970078 | E18: 28497689903 | F18: 39017311591 | G18: 19415033454 | J18: =B18-C18 -> 58603169173 | K18: =D18-E18 -> 71612280175 | L18: =E18-F18 -> -10519621688 | M18: =F18-G18 -> 19602278137 | O18: =C18/J18 -> 0.088312651 | P18: =K18/E18 -> 2.5129153 | Q18: =L18/F18 -> -0.26961421 | R18: =M18/G18 -> 1.0096443
A20: KENAIKAN (PENURUNAN) BERSIH KAS DAN BANK | B20: ='CF Konsol'!H65 -> 10617267044 | C20: ='CF Konsol'!J65 -> -2.1060957e+09 | D20: ='CF Konsol'!F65 -> -1.6519119e+09 | E20: -2.3503476e+09 | F20: -52376621 | G20: -541770942 | J20: =B20-C20 -> 1.2723363e+10 | K20: =D20-E20 -> 6.9843574e+08 | L20: =E20-F20 -> -2.297971e+09 | M20: =F20-G20 -> 489394321 | O20: =C20/J20 -> -0.1655298 | P20: =K20/E20 -> -0.29716274 | Q20: =L20/F20 -> 43.873983 | R20: =M20/G20 -> -0.90332331
A22: SALDO KAS DAN BANK AWAL TAHUN | B22: ='CF Konsol'!H69 -> 2570121355 | C22: ='CF Konsol'!J69 -> 4920468963 | D22: ='CF Konsol'!F69 -> 2570121355 | E22: 4.920469e+09 | F22: 4.9728456e+09 | G22: 5.5146165e+09 | J22: =B22-C22 -> -2350347608 | K22: =D22-E22 -> -2.3503476e+09 | L22: =E22-F22 -> -52376621 | M22: =F22-G22 -> -541770942 | O22: =C22/J22 -> -2.0935069 | P22: =K22/E22 -> -0.4776674 | Q22: =L22/F22 -> -0.010532525 | R22: =M22/G22 -> -0.098242723
A24: SALDO KAS DAN BANK AKHIR TAHUN | B24: ='CF Konsol'!H73 -> 13187388399 | C24: ='CF Konsol'!J73 -> 2.8143732e+09 | D24: ='CF Konsol'!F73 -> 918209485 | E24: 2.5701214e+09 | F24: 4.920469e+09 | G24: 4.9728456e+09 | J24: =B24-C24 -> 1.0373015e+10 | K24: =D24-E24 -> -1.6519119e+09 | L24: =E24-F24 -> -2.3503476e+09 | M24: =F24-G24 -> -52376621 | O24: =C24/J24 -> 0.2713168 | P24: =K24/E24 -> -0.64273691 | Q24: =L24/F24 -> -0.4776674 | R24: =M24/G24 -> -0.010532525
A26: *) Konsolidasian

Sheet RASIO KEUANGAN
B1: PT INDO AMERICAN SEAFOODS DAN ENTAS ANAK
B2: RASIO-RASIO KEUANGAN PENTING
B4: Keterangan | C4: 31 Desember
C5: 2024 | D5: 2023 | E5: 2022 | F5: 2021
B6: Profitabilitas
B7: Laba (Rugi) Neto Tahun Berjalan terhadap Jumlah Aset | C7: ='PL-Analysis'!D25/'LPK Analysis'!C26 -> 0.00080347119 | D7: ='PL-Analysis'!E25/'LPK Analysis'!D26 -> 0.0050545132 | E7: ='PL-Analysis'!F25/'LPK Analysis'!E26 -> 0.016938165 | F7: ='PL-Analysis'!G25/'LPK Analysis'!F26 -> 0.01269529
B8: Laba (Rugi) Neto Tahun Berjalan terhadap Jumlah Ekuitas | C8: ='PL-Analysis'!D25/'LPK Analysis'!C65 -> 0.0019472662 | D8: ='PL-Analysis'!E25/'LPK Analysis'!D65 -> 0.015970229 | E8: ='PL-Analysis'!F25/'LPK Analysis'!E65 -> 0.048450347 | F8: ='PL-Analysis'!G25/'LPK Analysis'!F65 -> 0.03299742
B9: Laba (Rugi) Neto Tahun Berjalan terhadap Penjualan Bersih | C9: ='PL-Analysis'!D25/'PL-Analysis'!D10 -> 0.0010811507 | D9: ='PL-Analysis'!E25/'PL-Analysis'!E10 -> 0.0087613037 | E9: ='PL-Analysis'!F25/'PL-Analysis'!F10 -> 0.013630518 | F9: ='PL-Analysis'!G25/'PL-Analysis'!G10 -> 0.010975841
B10: Laba (Rugi) Bruto terhadap Pendapatan Usaha | C10: ='PL-Analysis'!D12/'PL-Analysis'!D10 -> 0.23445382 | D10: ='PL-Analysis'!E12/'PL-Analysis'!E10 -> 0.32631034 | E10: ='PL-Analysis'!F12/'PL-Analysis'!F10 -> 0.22051538 | F10: ='PL-Analysis'!G12/'PL-Analysis'!G10 -> 0.22495716
B11: Laba (Rugi) Usaha terhadap Pendapatan Usaha | C11: ='PL-Analysis'!D25/'PL-Analysis'!D10 -> 0.0010811507 | D11: ='PL-Analysis'!E25/'PL-Analysis'!E10 -> 0.0087613037 | E11: ='PL-Analysis'!F25/'PL-Analysis'!F10 -> 0.013630518 | F11: ='PL-Analysis'!G25/'PL-Analysis'!G10 -> 0.010975841
B12: EBITDA terhadap Penjualan | C12: ='Rasio DSCR'!B23 -> 0.088497869 | D12: ='Rasio DSCR'!C23 -> 0.14611871 | E12: ='Rasio DSCR'!D23 -> 0.082938642 | F12: ='Rasio DSCR'!E23 -> 0.077944212
B14: Solvabilitas
B15: Liabilitas terhadap Aset | C15: ='LPK Analysis'!C53/'LPK Analysis'!C26 -> 0.59483232 | D15: ='LPK Analysis'!D53/'LPK Analysis'!D26 -> 0.68350403 | E15: ='LPK Analysis'!E53/'LPK Analysis'!E26 -> 0.65040158 | F15: ='LPK Analysis'!F53/'LPK Analysis'!F26 -> 0.61526416
B16: Liabilitas terhadap Ekuitas | C16: ='LPK Analysis'!C53/'LPK Analysis'!C65 -> 1.4416159 | D16: ='LPK Analysis'!D53/'LPK Analysis'!D65 -> 2.1595979 | E16: ='LPK Analysis'!E53/'LPK Analysis'!E65 -> 1.8604249 | F16: ='LPK Analysis'!F53/'LPK Analysis'!F65 -> 1.599186
B17: DSCR | C17: ='Rasio DSCR'!B10 -> 0.025346307 | D17: ='Rasio DSCR'!C10 -> 0.036221536 | E17: ='Rasio DSCR'!D10 -> 0.052715429 | F17: ='Rasio DSCR'!E10 -> 0.040564103
B18: ICR | C18: ='Rasio DSCR'!B11 -> 1.1320278 | D18: ='Rasio DSCR'!C11 -> 1.1807383 | E18: ='Rasio DSCR'!D11 -> 1.5437313 | F18: ='Rasio DSCR'!E11 -> 1.508618
B21: Likuiditas
B22: Aset Lancar terhadap Liabilitas Jangka Pendek | C22: ='LPK Analysis'!C20/'LPK Analysis'!C42 -> 1.4430891 | D22: ='LPK Analysis'!D20/'LPK Analysis'!D42 -> 1.1568289 | E22: ='LPK Analysis'!E20/'LPK Analysis'!E42 -> 1.1750272 | F22: ='LPK Analysis'!F20/'LPK Analysis'!F42 -> 1.1738048 | G22: Rasio Lancar
B23: Kas terhadap Liabilitas Jangka Pendek | C23: ='LPK Analysis'!C10/'LPK Analysis'!C42 -> 0.003701343 | D23: ='LPK Analysis'!D10/'LPK Analysis'!D42 -> 0.011367556 | E23: ='LPK Analysis'!E10/'LPK Analysis'!E42 -> 0.02705318 | F23: ='LPK Analysis'!F10/'LPK Analysis'!F42 -> 0.036916964
B26: Pertumbuhan
B27: Pendapatan Usaha | C27: =('PL-Analysis'!D10-'PL-Analysis'!E10)/'PL-Analysis'!E10 -> 0.61909291 | D27: =('PL-Analysis'!E10-'PL-Analysis'!F10)/'PL-Analysis'!F10 -> -0.4789058 | E27: =('PL-Analysis'!F10-'PL-Analysis'!G10)/'PL-Analysis'!G10 -> 0.2581486
B28: Laba (Rugi) Bruto | C28: =('PL-Analysis'!D12-'PL-Analysis'!E12)/'PL-Analysis'!E12 -> 0.16331746 | D28: =('PL-Analysis'!E12-'PL-Analysis'!F12)/'PL-Analysis'!F12 -> -0.22890447 | E28: =('PL-Analysis'!F12-'PL-Analysis'!G12)/'PL-Analysis'!G12 -> 0.23330649
B29: Laba Bersih | C29: =('PL-Analysis'!D25-'PL-Analysis'!E25)/'PL-Analysis'!E25 -> -0.80020286 | D29: =('PL-Analysis'!E25-'PL-Analysis'!F25)/'PL-Analysis'!F25 -> -0.66505569 | E29: =('PL-Analysis'!F25-'PL-Analysis'!G25)/'PL-Analysis'!G25 -> 0.56245138
B30: Aset | C30: =('LPK Analysis'!C26-'LPK Analysis'!D26)/'LPK Analysis'!D26 -> 0.25689298 | D30: =('LPK Analysis'!D26-'LPK Analysis'!E26)/'LPK Analysis'!E26 -> 0.1224309 | E30: =('LPK Analysis'!E26-'LPK Analysis'!F26)/'LPK Analysis'!F26 -> 0.1710698
B31: Liabilitas | C31: =('LPK Analysis'!C53-'LPK Analysis'!D53)/'LPK Analysis'!D53 -> 0.093834912 | D31: =('LPK Analysis'!D53-'LPK Analysis'!E53)/'LPK Analysis'!E53 -> 0.17955746 | E31: =('LPK Analysis'!E53-'LPK Analysis'!F53)/'LPK Analysis'!F53 -> 0.237949

Sheet Rasio DSCR
A1: PT INDO AMERICAN SEAFOODS DAN ENTAS ANAK
A2: PERHITUNGAN DSCR DAN ICR
A4: Keterangan | B4: 31 Desember
B5: 2024 | C5: 2023*) | D5: 2022*) | E5: 2021*)
B6: (12 Bulan) | C6: (12 Bulan) | D6: (12 Bulan) | E6: (12 Bulan)
A7: EBIT | B7: =B13 -> 2.0585441e+10 | C7: =C13 -> 18511023889 | D7: =D13 -> 2.0692118e+10 | E7: =E13 -> 1.4108736e+10
A8: Bunga Bank | B8: =B16 -> 18184572249 | C8: =C16 -> 15677499788 | D8: =D16 -> 13403963086 | E8: =E16 -> 9352093192
A9: Total Pembayaran Utang | B9: =-'CF Konsol'!F43 -> 793982710777 | C9: =-'CF Konsol'!P43 -> 495372719131 | D9: =-'CF Konsol'!R43 -> 379120929829 | E9: =-'CF Konsol'!T43 -> 338461235558
A10: DSCR | B10: =B7/(B8+B9) -> 0.025346307 | C10: =C7/(C8+C9) -> 0.036221536 | D10: =D7/(D8+D9) -> 0.052715429 | E10: =E7/(E8+E9) -> 0.040564103
A11: ICR | B11: =B7/B8 -> 1.1320278 | C11: =C7/C8 -> 1.1807383 | D11: =D7/D8 -> 1.5437313 | E11: =E7/E8 -> 1.508618
A13: EBIT = Laba Bersih + Bunga + Pajak | B13: =SUM(B15:B17) -> 2.0585441e+10 | C13: =SUM(C15:C17) -> 18511023889 | D13: =SUM(D15:D17) -> 2.0692118e+10 | E13: =SUM(E15:E17) -> 1.4108736e+10
A14: EBITDA = | B14: =B13+B18+B19 -> 2.8545891e+10 | C14: =C13+C18+C19 -> 29110178188 | D14: =D13+D18+D19 -> 3.1708793e+10 | E14: =E13+E18+E19 -> 2.3685073e+10
A15: Laba Bersih | B15: ='PL-Analysis'!D25 -> 3.487362e+08 | C15: ='PL-Analysis'!E25 -> 1745451401 | D15: ='PL-Analysis'!F25 -> 5.211169e+09 | E15: ='PL-Analysis'!G25 -> 3.335252e+09
A16: Beban Bunga | B16: =-'PL-Analysis'!D16 -> 18184572249 | C16: =-'PL-Analysis'!E16 -> 15677499788 | D16: =-'PL-Analysis'!F16 -> 13403963086 | E16: =-'PL-Analysis'!G16 -> 9352093192
A17: Beban Pajak Penghasilan Badan | B17: =-'PL-Analysis'!D19 -> 2052132941 | C17: =-'PL-Analysis'!E19 -> 1088072700 | D17: =-'PL-Analysis'!F19 -> 2076985900 | E17: =-'PL-Analysis'!G19 -> 1421390520
A18: Amortisasi | B18: ='WS Konsol'!M619+'WS Konsol'!M715 -> 314859088 | C18: ='WS Konsol'!AI619+'WS Konsol'!AI715 -> 314859087 | D18: ='WS Konsol'!BF619+'WS Konsol'!BF715 -> 314859086 | E18: ='WS Konsol'!BH619+'WS Konsol'!BH715 -> 314859087
A19: Depresiasi | B19: =SUM('WS Konsol'!M707:M714)+'WS Konsol'!M623+'WS Konsol'!M618 -> 7645590897 | C19: =SUM('WS Konsol'!AI707:AI714)+'WS Konsol'!AI623+'WS Konsol'!AI618 -> 10284295212 | D19: ='WS Konsol'!BF718+SUM('WS Konsol'!BF707:BF714)+'WS Konsol'!BF623+'WS Konsol'!BF618 -> 10701815600 | E19: ='WS Konsol'!BH718+SUM('WS Konsol'!BH707:BH714)+'WS Konsol'!BH623+'WS Konsol'!BH618 -> 9261477767
A22: Ebitda thd pendapatan (%) | B22: ='PL-Analysis'!D10 -> 3.2256021e+11 | C22: ='PL-Analysis'!E10 -> 199222794205 | D22: ='PL-Analysis'!F10 -> 382316276945 | E22: ='PL-Analysis'!G10 -> 303872116071
B23: =B14/B22 -> 0.088497869 | C23: =C14/C22 -> 0.14611871 | D23: =D14/D22 -> 0.082938642 | E23: =E14/E22 -> 0.077944212
A25: Total Aset | B25: ='LPK Analysis'!C26 -> 434036973703 | C25: ='LPK Analysis'!D26 -> 345325322995 | D25: ='LPK Analysis'!E26 -> 307658424230 | E25: ='LPK Analysis'!F26 -> 262715700578
B26: =B15/B25 -> 0.00080347119 | C26: =C15/C25 -> 0.0050545132 | D26: =D15/D25 -> 0.016938165 | E26: =E15/E25 -> 0.01269529
A28: Total Ekuitas | B28: ='LPK Analysis'!C65 -> 179090153044 | C28: ='LPK Analysis'!D65 -> 1.0929407e+11 | D28: ='LPK Analysis'!E65 -> 107556897781 | E28: ='LPK Analysis'!F65 -> 101076144702
B29: =B15/B28 -> 0.0019472662 | C29: =C15/C28 -> 0.015970229 | D29: =D15/D28 -> 0.048450347 | E29: =E15/E28 -> 0.03299742

Sheet Sheet1
C3: 71587587813
B4: 0.9 | C4: =C3*B4 -> 6.4428829e+10 | D4: Pembelian Bahan Baku
B5: 0.05 | C5: =C3*B5 -> 3.5793794e+09 | D5: Biaya Penjualan
B6: 0.0485 | C6: =B6*C3 -> 3.471998e+09 | D6: Perawatan & utilitas
B7: =100%-SUM(B4:B6) -> 0.0015 | C7: =B7*C3 -> 1.0738138e+08 | D7: Keperluan Kantor

Sheet KK CF Konsol Juni 24
A1: Aset | B1: =SUM(C7:V7) -> 347660437458 | C1: ='BS Konsol'!H48-B1 -> 0
A2: Liabilities | B2: =SUM(X7:AK7) -> -237494444229 | C2: =B2+'BS Konsol'!H87 -> 0
A3: Ekuitas | B3: =SUM(AL7:BC7) -> -110165993229 | C3: =B3+'BS Konsol'!H107 -> 0
C4: Kas dan Bank | D4: Piutang Usaha Kepada Pihak Ketiga | E4: Piutang Usaha Kepada Pihak Berelasi | F4: CKPN | G4: Piutang dari Karyawan | H4: Piutang Lain-Lain | I4: Piutang Lain - Lain dari Pihak Ketiga | J4: Persediaan | K4: Uang Muka | L4: Aset Biologis | M4: Prepaid Tax | N4: Prepaid | O4: Project In Progress | P4: Uang Muka Pembelian | Q4: Pajak Dibayar Dimuka | R4: Aset Tetap | S4: Uang Muka Pembelian Aset Tetap | T4: Investasi | U4: Aset Hak Guna | V4: Aset Pajak Tangguhan | W4: Biaya pra IPO | X4: Short Term Bank Loans | Y4: Bank Loan - Short part of long | Z4: Utang Usaha Pihak Berelasi | AA4: Utang Usaha Pihak Ketiga | AB4: Uang Muka Pelangan | AC4: Biaya Yang Masih Harus Dibayar | AD4: Utang Lain2 Pihak Ketiga | AE4: Utang Lain2 Pihak Berelasi | AF4: Liabilitas Sewa Jangka pendek | AG4: Liabilitas Sewa Jangka Panjang | AH4: Utang Bank & Leasing | AI4: Utang Pajak | AJ4: Utang pembelian aset tetap jangka pendek | AK4: Imbalan Pasca Kerja | AL4: Modal Saham | AM4: Tambahan Modal Disetor | AN4: Surplus | AO4: Penghasilan Komprehensif Lainnya | AP4: Koreksi Auditor | AQ4: Ditentukan Penggunaannya | AR4: Dividen | AS4: Proforma Ekuitas | AT4: Saldo Laba | AU4: Pendapatan Usaha | AV4: Beban Pokok Pendapatan Usaha | AW4: Beban Penjualan | AX4: Beban Umum dan Administrasi | AY4: Beban(Pendapatan) Lain-lain | AZ4: Beban Bunga dan Keuangan | BA4: Income Tax | BB4: Penyesuain Audit | BC4: Other Comprehensive Income
H5: Pihak Berelasi | N5: Expenses
B7: 45473 | C7: ='BS Konsol'!H11 -> 565886797 | D7: ='BS Konsol'!H14 -> 26199584563 | E7: ='BS Konsol'!H13 -> 422639675 | H7: ='BS Konsol'!H26 -> 0 | I7: ='BS Konsol'!H16 -> 510634104 | J7: ='BS Konsol'!H17 -> 224990831176 | K7: ='BS Konsol'!H20 -> 2074112410 | L7: ='BS Konsol'!H18 -> 2649404556 | M7: ='BS Konsol'!H19 -> 10425187749 | N7: 0 | R7: ='BS Konsol'!H34 -> 70317926651 | U7: ='BS Konsol'!H43 -> 7714047638 | V7: ='BS Konsol'!H45 -> 1790182139 | X7: =-'BS Konsol'!H61 -> -207371015601 | Y7: =-'BS Konsol'!H69 -> -1869894064 | Z7: 0 | AA7: =-'BS Konsol'!H58 -> -14186291754 | AC7: =-'BS Konsol'!H62 -> -4322494743 | AD7: 0 | AE7: 0 | AF7: 0 | AG7: 0 | AH7: 0 | AI7: =-'BS Konsol'!H63 -> -404042742 | AJ7: =-'BS Konsol'!H66 -> -38822068 | AK7: =-'BS Konsol'!H81 -> -9301883257 | AL7: =-'BS Konsol'!H97 -> -55000000000 | AM7: =-'BS Konsol'!H99 -> -49739416785 | AN7: 0 | AO7: =-'BS Konsol'!H102 -> 377072852 | AQ7: =-'BS Konsol'!H104 -> -410000000 | AR7: 15000000000 | AS7: 0 | AT7: =AT8 -> -19521729837 | AU7: =-'PL Konsol'!J11 -> -106697349798 | AV7: =-'PL Konsol'!J12 -> 69221185606 | AW7: =-'PL Konsol'!J16 -> 8866046154 | AX7: =-'PL Konsol'!J17 -> 13412401091 | AY7: =-'PL Konsol'!J18 -> 4496948237 | AZ7: =-'PL Konsol'!J19 -> 9308297571 | BA7: =-'PL Konsol'!J25 -> 520551680 | BD7: =SUM(C7:BC7) -> 0 | BE7: =BD7/2 -> 0 | BF7: =BE7/2 -> 0
B8: 45291 | C8: ='BS Konsol'!L11 -> 2570121355 | D8: ='BS Konsol'!L14 -> 19981020112 | E8: ='BS Konsol'!L13 -> 211054410 | H8: ='BS Konsol'!L26 -> 7022707423 | I8: ='BS Konsol'!L16 -> 510634104 | J8: ='BS Konsol'!L17 -> 218071396362 | K8: ='BS Konsol'!L20 -> 1104447053 | L8: ='BS Konsol'!L18 -> 2415719386 | M8: ='BS Konsol'!L19 -> 9663458887 | N8: 0 | R8: ='BS Konsol'!L34 -> 74113104582 | U8: ='BS Konsol'!L43 -> 7871477182 | V8: ='BS Konsol'!L45 -> 1790182139 | X8: =-'BS Konsol'!L61 -> -195441714689 | Y8: =-'BS Konsol'!L69 -> -3807894064 | Z8: 0 | AA8: =-'BS Konsol'!L58 -> -20407901137 | AC8: =-'BS Konsol'!L62 -> -2870843988 | AD8: =-'BS Konsol'!L77 -> -41000000 | AE8: =-'BS Konsol'!L76 -> -595676695 | AF8: =-'BS Konsol'!L68 -> -624277457 | AG8: 0 | AH8: 0 | AI8: =-'BS Konsol'!L63 -> -2863697915 | AJ8: =-'BS Konsol'!L66 -> -76360023 | AK8: =-'BS Konsol'!L81 -> -9301883257 | AL8: =-'BS Konsol'!L97 -> -40000000000 | AM8: =-'BS Konsol'!L99 -> -49739416785 | AN8: 0 | AO8: =-'BS Konsol'!L102 -> 377072852 | AP8: =-6464981.73071289 -> -6464981.7 | AQ8: =-'BS Konsol'!L104-'KK CF Konsol Juni 24'!AP8 -> -4.0353502e+08 | AS8: 0 | AT8: =-'BS Konsol'!L105 -> -19521729837 | BD8: =SUM(C8:BC8) -> 0
B9: Selisih | C9: =C7-C8 -> -2004234558 | D9: =D7-D8 -> 6218564451 | E9: =E7-E8 -> 211585265 | F9: =F7-F8 -> 0 | G9: =G7-G8 -> 0 | H9: =H7-H8 -> -7022707423 | I9: =I7-I8 -> 0 | J9: =J7-J8 -> 6919434814 | ... N9: =N7-N8 -> 0 | P9: =P7-P8 -> 0 | Q9: =Q7-Q8 -> 0 | R9: =R7-R8 -> -3795177931 | S9: =S7-S8 -> 0 | T9: =T7-T8 -> 0 | U9: =U7-U8 -> -157429544 | V9: =V7-V8 -> 0 | W9: =W7-W8 -> 0 | ... BC9: =BC7-BC8 -> 0 | BD9: =SUM(C9:BC9) -> 0 | BE9: =BD9/2 -> 0 | BF9: =BE9/2 -> 0
B10: Movement
A11: ARUS KAS DARI AKTIVITAS OPERASI
A12: Penerimaan Kas dari Pelanggan | B12: =SUM(D12:BC12) -> 100267200082 | D12: =-D9 -> -6218564451 | E12: =-E9 -> -211585265 | F12: =-F9 -> 0 | AB12: =-AB9 -> 0 | AU12: =-AU9 -> 106697349798
A13: Pembayaran Kepada Pemasok | B13: =SUM(D13:BC13) -> -73323475715 | H13: =-H9 -> 7022707423 | I13: =-I9 -> 0 | J13: =-J9 -> -6919434814 | K13: =-K9 -> -969665357 | N13: =-N9 -> 0 | P13: =-P9 -> 0 | Q13: =-Q9 -> 0 | W13: =-W9 -> 0 | Z13: =-Z9 -> 0 | AA13: =-AA9 -> -6221609383 | AC13: =-AC9 -> 1451650755 | AD13: =-AD9 -> -41000000 | AF13: =-AF9-AF40 -> 0 | AH13: =-AH9 -> 0 | AJ13: =-AJ9 -> -37537955 | AO13: =-AO9-AO29 -> 0 | AV13: =-AV9-AV14-AV15 -> -58462757120 | AX13: =-AX9-AX14-AX15 -> -4648881027 | AY13: =-(AY9+AY15+AY20) -> -4496948237 | BB13: =-2767717677.36858*0 -> 0 | BC13: =-BC9 -> 0
A14: Pembayaran Kepada Karyawan | B14: =SUM(D14:BC14) -> -15569341077 | G14: =-G9 -> 0 | AP14: =-AP9 -> -6464981.7 | AQ14: =-AQ9 -> 6464981.7 | AV14: =-(SUM('WS Konsol'!AF609:AF614)+'WS Konsol'!AF617+'WS Konsol'!AF620) -> -7409494527 | AX14: =-'WS Konsol'!AH665 -> -8159846550
A15: Pembayaran Beban Operasional Lainnya | B15: =SUM(D15:BC15) -> -7910563784 | L15: =-L9 -> -233685170 | M15: =-M9 -> -761728862 | R15: =-R9 -> 3795177931 | U15: =-U9 -> 157429544 | V15: =-V9 -> 0 | X15: =-X9-X37-X38 -> 1938000000 | AG15: =-AG9 -> 0 | AI15: =-AI9-AI21 -> 533448080 | AK15: =-AK9 -> 0 | AV15: =-('WS Konsol'!AF618+'WS Konsol'!AF619+'WS Konsol'!AF623) -> -3348933959 | AW15: =-AW9 -> -8866046154 | AX15: =-SUM('WS Konsol'!AF707:AF718) -> -603673514 | AY15: =68879296*0 -> 0 | BA15: =-BA9 -> -520551680
A16: Penerimaan Bunga | B16: =SUM(D16:BC16) -> 0
A17: Deferred tax | B17: =SUM(D17:BC17) -> 0 | BC17: 0
A18: Employee benefit | B18: =SUM(D18:BC18) -> 0
A19: Pembayaran Deviden | B19: =SUM(D19:BC19) -> 0 | BF19: 2993103253
A20: Pembayaran Bunga | B20: =SUM(D20:BC20) -> -9308297571 | AZ20: =-AZ9 -> -9308297571 | BE20: Beban Pajak Kini Juni 24 | BF20: =-BA21 -> 0
A21: Pembayaran Pajak Penghasilan | B21: =SUM(D21:BC21) -> -2993103253 | AI21: -2993103253 | BE21: Selisih | BF21: =BF19-BF20 -> 2993103253
A22: Kas diperoleh dari (digunakan untuk) operasi | B22: =SUM(B12:B21) -> -8837581318
BE23: Utang Pajak IAS 23 | BF23: 1699681675
BE24: Utang Pajak ISP 23 | BF24: 1164016240
A25: Kas Bersih Diperoleh dari Aktivitas Operasi | BE25: Total | BF25: =SUM(BF23:BF24) -> 2863697915
BE26: Selisih | BF26: =BF19-BF25 -> 129405338
A27: ARUS KAS DARI AKTIVITAS INVESTASI
A28: Penambahan Aset Tetap | B28: =SUM(D28:BC28) -> 0 | R28: 0 | S28: =-S9 -> 0 | AS28: 0 | AT28: =-AT9 -> 0 | BE28: Utang Pajak PPh 29 ISP 22-23 | BF28: 464326518
A29: Penempatan Investasi pada Ventura Bersama | B29: =SUM(D29:BC29) -> 0 | BF29: 478730259
A30: Penambahan Aset Tersedia untuk dijual | B30: =SUM(D30:BC30) -> 0 | BF30: 97162281
A31: Penambahan PI | B31: =SUM(D31:BC31) -> 0 | BE31: Total Utang Pajak PPh 29 ISP 21-23 | BF31: =SUM(BF28:BF30) -> 1040219058
A32: Penerimaan Piutang lain-lain dari Pihak Berelasi | B32: =SUM(D32:BC32) -> 0
A33: Pinjaman kepada Entitas Berelasi | B33: =SUM(D33:BC33) -> 0 | BE33: Utang Pajak PPh 29 IAS 22-23 | BF33: 1063969216
A34: Kas Bersih Diperoleh dari (Digunakan untuk) Aktivitas Investasi | B34: =SUM(B28:B33) -> 0 | BF34: 577405049
BE35: Total Utang Pajak PPh 29 IAS 22-23 | BF35: =SUM(BF33:BF34) -> 1641374265
A36: ARUS KAS DARI AKTIVITAS PENDANAAN | BE36: Total Utang Pajak PPh 29 IAS ISP | BF36: =BF35+BF31 -> 2681593323
A37: Penerimaan Pinjaman dari Bank | B37: =SUM(E37:BC37) -> 369706236685 | X37: 369706236685 | BE37: Selisih | BF37: =BF36-BF21 -> -311509930
A38: Pembayaran Pinjaman Bank | B38: =SUM(E38:BC38) -> -361652935773 | X38: -359714935773 | Y38: =-Y9 -> -1938000000 | BF38: =BF26-BF37 -> 440915268
A39: Pinjaman kepada Koperasi | B39: =SUM(D39:BC39) -> 0
A40: Lembaga Pembiayaan | B40: =SUM(D40:BC40) -> -624277457 | AF40: =-'BS Konsol'!L68 -> -624277457
A41: Setoran Modal | B41: =SUM(D41:BC41) -> 0 | AL41: =-AL9 -> 15000000000 | AR41: =-AR9 -> -15000000000
...

Sheet ELIM & CAJE Des 24
A1: JURNAL ELIMINASI | F1: Diff | G1: =G2-H2 -> 0.11999512
A2: Konsolidasi Desember 2024 | F2: Kontrol | G2: =F3+H3 -> 1.7481431e+11 | H2: =G3+I3 -> 1.7481431e+11
F3: =SUM(F8:F48) -> 1.2777847e+11 | G3: =SUM(G8:G48) -> 1.2777847e+11 | H3: =SUM(H8:H48) -> 4.7035845e+10 | I3: =SUM(I8:I48) -> 4.7035845e+10
A5: Account No. | B5: Date | C5: Account Name | E5: WP Reff | F5: Balance Sheet | H5: PL | J5: Description
F6: Debit | G6: Credit | H6: Debit | I6: Credit
A8: ELIM 1 | C8: PT Indo American Seafoods (Keuangan) | F8: 86709426551 | J8: Eleminasi Utang Piutang Keuangan
A9: =A8 -> ELIM 1 | D9: PT Indokom Samudra Persada (Keuangan) | G9: =F8 -> 86709426551 | J9: =J8 -> Eleminasi Utang Piutang Keuangan
A11: ELIM 2 | C11: PT Indokom Samudra Persada | F11: 29592782261 | J11: Eleminasi Utang Piutang
A12: =A11 -> ELIM 2 | D12: PT Indo American Seafoods | G12: =F11 -> 29592782261 | J12: =J11 -> Eleminasi Utang Piutang
A14: ELIM 3 | C14: PT Indo American Seafoods | F14: 4557621225 | J14: Eleminasi Utang Piutang
A15: =A14 -> ELIM 3 | D15: PT Indokom Samudra Persada | G15: =F14 -> 4557621225 | J15: =J14 -> Eleminasi Utang Piutang
A17: ELIM 4 | C17: Indo American Seafoods, PT (Saham) | F17: 1050000000 | J17: Eleminasi IAS Investasi pada Anak
A18: =A17 -> ELIM 4 | D18: PT Indo American Seafoods (Modal) | G18: =F17 -> 1050000000 | J18: =J17 -> Eleminasi IAS Investasi pada Anak
A21: ELIM 5 | C21: Penjualan Lokal ISP to IAS | H21: 2.9814768e+10 | J21: Eleminasi Penjualan ISP to IAS
A22: ELIM 5 | C22: Pendapatan Lain-Lain | H22: 390631231 | J22: =J21 -> Eleminasi Penjualan ISP to IAS
A23: ELIM 5 | C23: Penjualan Roti | H23: 1744087000 | J23: =J22 -> Eleminasi Penjualan ISP to IAS
A24: ELIM 5 | D24: Pembelian Bahan Baku to IAS | I24: 2.9814768e+10 | J24: =J23 -> Eleminasi Penjualan ISP to IAS
A25: ELIM 5 | D25: Pembelian Baku Pembantunya | I25: 2134718228 | J25: =J24 -> Eleminasi Penjualan ISP to IAS
A27: ELIM 6 | C27: Penjualan IAS | H27: 1.5071359e+10 | J27: Eleminasi Penjualan IAS to ISP
A28: ELIM 6 | D28: Pembelian ISP | I28: =14960074583+111284000 -> 15071358583 | J28: =J27 -> Eleminasi Penjualan IAS to ISP
A30: ELIM 7 | C30: LABA DITAHAN | F30: =4762924959.34294+105713339 -> 4.8686383e+09
A31: =A30 -> ELIM 7 | D31: Tambahan Modal Disetor (Tax Amnesty) | G31: =F30 -> 4.8686383e+09
A33: ELIM 8 | C33: Modal Disetor (ISP) | F33: 1000000000
A34: =A33 -> ELIM 8 | D34: Tambahan Modal Disetor (Tax Amnesty) | G34: =F33 -> 1000000000
C35: (Mengeliminasi modal disetor ISP selain kepemilikan IAS menjadi tambahan modal disetor atas kombinasi bisnis entitas sepengendali)
A37: =A38 -> CAJE 1 | C37: Pendapatan Lain-Lain | F37: =G38 -> 2
A38: CAJE 1 | D38: LABA DITAHAN | G38: 2
C39: (Adj atas Ctrl)
A41: ELIM 8 | C41: Pendapatan Lain-Lain | H41: 15000000
A42: =A41 -> ELIM 8 | D42: Sewa IPAL | I42: =H41 -> 15000000
C43: (Eleminasi Sewa IPAL 2024)

Sheet ELIM & CAJE Sept 24
B1: JURNAL ELIMINASI
B2: Konsolidasi September 2024
B5: Account No. | C5: Date | D5: Account Name | F5: WP Reff | G5: Balance Sheet | I5: PL | K5: Description
G6: Debit | H6: Credit | I6: Debit | J6: Credit
B8: ELIM 1 | D8: PT Indo American Seafoods (Keuangan) | G8: =H9 -> 94963698422 | K8: Eleminasi Utang Piutang Keuangan
B9: =B8 -> ELIM 1 | E9: PT Indokom Samudra Persada (Keuangan) | H9: 94963698422 | K9: =K8 -> Eleminasi Utang Piutang Keuangan
B11: ELIM 2 | D11: PT Indokom Samudra Persada | G11: 34916763132 | K11: Eleminasi Utang Piutang
B12: =B11 -> ELIM 2 | E12: PT Indo American Seafoods | H12: =G11 -> 34916763132 | K12: =K11 -> Eleminasi Utang Piutang
B14: ELIM 3 | D14: PT Indo American Seafoods | G14: 2637090788 | K14: Eleminasi Utang Piutang
B15: =B14 -> ELIM 3 | E15: PT Indokom Samudra Persada | H15: =G14 -> 2637090788 | K15: =K14 -> Eleminasi Utang Piutang
B17: ELIM 4 | D17: Indo American Seafoods, PT (Saham) | G17: 1050000000 | K17: Eleminasi IAS Investasi pada Anak
B18: =B17 -> ELIM 4 | E18: PT Indo American Seafoods (Modal) | H18: =G17 -> 1050000000 | K18: =K17 -> Eleminasi IAS Investasi pada Anak
B21: ELIM 5 | D21: Penjualan Lokal ISP to IAS | I21: 19246827883 | K21: Eleminasi Penjualan ISP to IAS
B22: ELIM 5 | D22: Pendapatan Lain-Lain | I22: 271648678 | K22: =K21 -> Eleminasi Penjualan ISP to IAS
B23: ELIM 5 | D23: Penjualan Roti | I23: 1388066000 | K23: =K22 -> Eleminasi Penjualan ISP to IAS
B24: ELIM 5 | E24: Pembelian to IAS | J24: 19246827883 | K24: =K23 -> Eleminasi Penjualan ISP to IAS
B25: ELIM 5 | E25: Pembelian Lain-lain | J25: 1659714678 | K25: =K24 -> Eleminasi Penjualan ISP to IAS
B27: ELIM 6 | D27: Penjualan IAS | I27: 11201885196 | K27: Eleminasi Penjualan IAS to ISP
B28: ELIM 6 | E28: Pembelian ISP | J28: 11201885196 | K28: =K27 -> Eleminasi Penjualan IAS to ISP
B30: ELIM 7 | D30: LABA DITAHAN | I30: 5868638298
B31: =B30 -> ELIM 7 | E31: Tambahan Modal Disetor (Tax Amnesty) | J31: =I30 -> 5868638298
B34: CAJE 1 | E34: LABA DITAHAN | H34: 2
B35: =B34 -> CAJE 1 | D35: Piutang Lain-lain di bawah Rp 20.000.000,- | G35: =H34 -> 2
D36: (Adj atas Ctrl)

Sheet DTA Konsol
H3: Dibebankan ke
H4: Penghasilan
H5: komprehensif
D6: 1 Januari | F6: Dikreditkan | H6: lain/ | J6: 31 Desember
D7: 2024/ | F7: ke laba rugi/ | H7: Charged to | J7: 2024/
D8: January 1, | F8: Credited to | H8: other | J8: December 31,
D9: 2024 | F9: Profit or loss | H9: comprehensive | J9: 2024
C11: Imbalan kerja | D11: =J28 -> 2045497897 | F11: ='DTA ISP'!F12+'DTA IAS'!F11 -> 1.9443526e+08 | G11: ='DTA ISP'!F12+'DTA IAS'!F11 -> 1.9443526e+08 | H11: ='DTA IAS'!H11+'DTA ISP'!H12 -> 4867315.9 | J11: =D11+F11+H11 -> 2.2448005e+09 | K11: Employee benefits
C12: Cadangan Kerugian Piutang | D12: =J29 -> 352336430 | F12: ='DTA ISP'!F13+'DTA IAS'!F12 -> -77205942 | H12: 0 | J12: =SUM(D12:H12) -> 2.7513049e+08 | K12: Allowance for Impairment Losses
C13: Penyusutan Aset Tetap | D13: =J30 -> -607652187 | F13: ='DTA IAS'!F13 -> 0 | H13: 0 | J13: =SUM(D13:H13) -> -607652187 | K13: Depreciation
C15: Aset pajak tangguhan | D15: =SUM(D11:D13) -> 1790182140 | F15: =SUM(F11:F13) -> 1.1722932e+08 | H15: =SUM(H11:H13) -> 4867315.9 | J15: =SUM(J11:J13) -> 1.9122788e+09 | K15: Deferred tax assets
D16: ='BS Konsol-Des 24'!Q37 -> 1790182140 | F16: ='PL Konsol'!M26 -> 76646095 | H16: ='PL Konsol'!M42 -> -17850458 | J16: ='BS Konsol-Des 24'!G37 -> 1848977778
D17: =D15-D16 -> 0 | F17: =F15+F16 -> 1.9387542e+08 | H17: =H15-H16 -> 22717774 | J17: =J15-J16 -> 63301001
H20: Dibebankan ke
H21: Penghasilan
H22: komprehensif
D23: 1 Januari | F23: Dikreditkan | H23: lain/ | J23: 31 Desember
D24: 2023/ | F24: ke laba rugi/ | H24: Charged to | J24: 2023/
D25: January 1, | F25: Credited to | H25: other | J25: December 31,
D26: 2023 | F26: Profit or loss | H26: comprehensive | J26: 2023
C28: Imbalan kerja | D28: 1818231019 | F28: 224932788 | H28: 2334090 | J28: 2045497897 | K28: Employee benefits
C29: Cadangan Kerugian Piutang | D29: 249921940 | F29: 102414490 | H29: - | J29: 352336430 | K29: Allowance for Impairment Losses
C30: Penyusutan | D30: -559875653 | F30: -47776534 | H30: - | J30: -607652187 | K30: Depreciation
C32: Aset Pajak Tangguhan | D32: =SUM(D28:D30) -> 1508277306 | F32: =SUM(F28:F30) -> 279570744 | H32: =SUM(H28:H30) -> 2334090 | J32: =SUM(J28:J30) -> 1790182140 | K32: Deferred tax assets
D38: Desember 2023 | F38: Desember 2024
C39: Beban Imbalan Pasca kerja | D39: ='WS Konsol'!AI693 -> 872138766 | F39: ='WS Konsol'!M693 -> 883796658
C40: Utang Imbalan Pasca Kerja | D40: ='BS Konsol-Des 24'!Q76 -> 9301883257 | F40: ='BS Konsol-Des 24'!G76 -> 10104541472
C41: OCI IPK | D41: ='WS Konsol'!AI758 -> -10609502 | F41: ='WS Konsol'!M758 -> 81138443
C42: Beban CKPN | D42: ='WS Konsol'!AI727 -> -119304064 | F42: ='WS Konsol'!M727 -> -417767101
C43: Penyusutan Aset Tetap | D43: ='WS Konsol'!BK705*50% -> 2.0761029e+08 | F43: ='WS Konsol'!BJ705*50% -> 724750431

Sheet DTA ISP
H4: Dibebankan ke
H5: Penghasilan
H6: komprehensif
D7: 1 Januari | F7: Dikreditkan | H7: lain/ | J7: 31 Desember
D8: 2024/ | F8: ke laba rugi/ | H8: Charged to | J8: 2024/
D9: January 1, | F9: Credited to | H9: other | J9: December 31,
D10: 2024 | F10: Profit or loss | H10: comprehensive | J10: 2024
C12: Imbalan kerja | D12: 1462993790 | F12: 130595067 | H12: -6491571 | J12: =SUM(D12:H12) -> 1587097286 | K12: Employee benefits
C13: Cadangan Kerugian Piutang | D13: 152790529 | F13: -117789170 | H13: 0 | J13: =SUM(D13:H13) -> 35001359 | K13: Allowance for Impairment Losses
C14: Aset Hak Guna | D14: -68171964 | F14: 0 | H14: 0 | J14: =SUM(D14:H14) -> -68171964 | K14: Depreciation
C16: Aset pajak tangguhan | D16: =SUM(D12:D14) -> 1547612355 | F16: =SUM(F12:F14) -> 12805897 | H16: =SUM(H12:H14) -> -6491571 | J16: =SUM(J12:J14) -> 1553926681 | K16: Deferred tax assets

Sheet DTA IAS
H3: Dibebankan ke
H4: Penghasilan
H5: komprehensif
D6: 1 Januari | F6: Dikreditkan | H6: lain/ | J6: 31 Desember
D7: 2024/ | F7: ke laba rugi/ | H7: Charged to | J7: 2024/
D8: January 1, | F8: Credited to | H8: other | J8: December 31,
D9: 2024 | F9: Profit or loss | H9: comprehensive | J9: 2024
C11: Imbalan kerja | D11: =J28 -> 582504106 | F11: 63840198 | H11: ='[189]AJE-CAJE-Des Audit'!J21 -> 11358887 | J11: =SUM(D11:H11) -> 6.5770319e+08 | K11: Employee benefits
C12: Cadangan Kerugian Piutang | D12: =J29 -> 199545901 | F12: 40583228 | J12: =SUM(D12:H12)+1 -> 2.4012913e+08 | K12: Allowance for Impairment Losses
C13: Penyusutan | D13: =J30 -> -539480223 | F13: ='[189]AJE-CAJE-Des Audit'!I29 -> 0 | J13: =SUM(D13:H13) -> -539480223 | K13: Depreciation
C15: Aset pajak tangguhan | D15: =SUM(D11:D13) -> 242569784 | F15: =SUM(F11:F13) -> 1.0442343e+08 | H15: =SUM(H11:H13) -> 11358887 | J15: =SUM(J11:J13) -> 3.583521e+08 | K15: Deferred tax assets
F16: 1.0442343e+08 | H16: =[190]PL!$F$28 -> 11358887 | J16: 3.583521e+08
F17: =F15-F16 -> 0 | H17: =H15-H16 -> 0 | J17: =J15-J16 -> -0.032033086
H20: Dibebankan ke
H21: Penghasilan
H22: komprehensif
D23: 1 Januari | F23: Dikreditkan | H23: lain/ | J23: 31 Desember
D24: 2023/ | F24: ke laba rugi/ | H24: Charged to | J24: 2023/
D25: January 1, | F25: Credited to | H25: other | J25: December 31,
D26: 2023 | F26: Profit or loss | H26: comprehensive | J26: 2023
C28: Imbalan kerja | D28: 519812376 | F28: 61508332 | H28: 1183398 | J28: =SUM(D28:H28) -> 582504106 | K28: Employee benefits
C29: Cadangan Kerugian Piutang | D29: 173299007 | F29: 26246894 | H29: - | J29: =SUM(D29:H29) -> 199545901 | K29: Allowance for Impairment Losses
C30: Penyusutan | D30: -513553677 | F30: -25926546 | H30: - | J30: =SUM(D30:H30) -> -539480223 | K30: Depreciation
C32: Aset Pajak Tangguhan | D32: =SUM(D28:D30) -> 179557706 | F32: =SUM(F28:F30) -> 61828680 | H32: =SUM(H28:H30) -> 1183398 | J32: =SUM(J28:J30) -> 242569784 | K32: Deferred tax assets
D38: Desember 2023 | F38: Desember 2024
C39: Beban Imbalan Pasca kerja | D39: =[189]WS!AB446 -> 279583328 | F39: =[189]WS!Q446 -> 290182718
C40: Utang Imbalan Pasca Kerja | D40: =[189]BS!L65 -> 2647745936 | F40: =[189]BS!H65 -> 2886297350
C41: OCI IPK | D41: =[189]WS!AB499 -> -5379083 | F41: =[189]WS!Q499 -> 51631304
C42: Beban CKPN | D42: =[189]WS!AB484 -> 0 | F42: =[189]WS!Q484 -> -8.2428015e+08
C43: Penyusutan Aset Tetap | D43: =[189]WS!AB457 -> 19295242 | F43: =[189]WS!Q457 -> 10112250

Sheet IPK IAS
D5: 2024 | F5: 2023
C7: Saldo awal | D7: =F16 -> 2647745936 | F7: 2362783525
C8: Beban imbalan paska kerja
C9: selama tahun berjalan | D9: 290182718 | F9: 279583328
C10: Pengukuran kembali atas
C11: liabilitas diestimasi atas
C12: imbalan kerja karyawan | D12: -51631304 | F12: 5379083 | I12: =F16 -> 2647745936 | J12: Saldo awal ipk des 23 | K12: liabilitas
C13: Pembayaran Imbalan Pasca | I13: =D23 -> 107488248 | J13: Biaya Jasa Kini | K13: beban opex
C14: Kerja pada tahun berjalan | F14: 0 | I14: =D24 -> 182694470 | J14: Biaya Bunga | K14: beban opex
C16: Saldo Akhir Liabilitas | D16: =SUM(D7:D14) -> 2886297350 | F16: =SUM(F7:F14) -> 2647745936 | I16: =D12 -> -51631304 | J16: Pendapatan oci berjalan | K16: oci pl
I18: =SUM(I12:I16) -> 2886297350 | J18: Saldo akhir ipk des 24 | K18: liabilitas
C19: Total beban imbalan paska kerja karyawan adalah sebagai berikut:
I20: jurnal
D21: 2024 | F21: 2023 | I21: =I14+I13 -> 290182718 | J21: beban ipk (opex)
J22: =I16 -> -51631304 | K22: oci pl berjalan ipk
