Workbook
Name \: #REF!
Name \: #REF!
Name \_A: #N/A
Name \0: #REF!
Name \0: #REF!
Name \0: #N/A
Name \1: #REF!
Name \1: #REF!
Name \1: #REF!
Name \2: #REF!
Name \3: #REF!
Name \4: #REF!
Name \5: #REF!
Name \6: #REF!
Name \A: #REF!
Name \a: #REF!
Name \A: #REF!
Name \APR: #REF!
Name \APR: #REF!
Name \AUG: #REF!
Name \AUG: #REF!
Name \B: #REF!
Name \b: #REF!
Name \b: #N/A
Name \BCYTD: #REF!
Name \BCYTD: #REF!
Name \bkd: #REF!
Name \BRYTD: #REF!
Name \BRYTD: #REF!
Name \BSYTD: #REF!
Name \BSYTD: #REF!
Name \BTWO: #REF!
Name \BUYTD: #REF!
Name \c: #REF!
Name \c: #REF!
Name \C: #REF!
Name \c3: #REF!
Name \cc: #REF!
Name \CFLOW: #REF!
Name \CO: #REF!
Name \CO: #REF!
Name \COGS: #REF!
Name \COGS: #REF!
Name \CTWO: #REF!
Name \D: #REF!
Name \d: #N/A
Name \DEC: #REF!
Name \DS: #REF!
Name \DTWO: #REF!
Name \E: #REF!
Name \e: #N/A
Name \ED: #REF!
Name \ED: #REF!
Name \F: #REF!
Name \f: #N/A
Name \FEB: #REF!
Name \g: #REF!
Name \g: #N/A
Name \GA: #REF!
Name \GA: #REF!

Sheet A.100 Memo
B4: Client | C4: : PT Indo American Seafoods Tbk dan Entitas Anak | F4: Prepared by | G4: : IRA | L4: Date : | M4: 45733
B5: Account | C5: : Cash and Cash Equivalents | F5: Reviewed by | G5: : KNW | L5: Date : | M5: 45735
B6: Period | C6: : 31 Desember 2024 | F6: Approved by | G6: : MGN | L6: Date : | M6: 45737
B7: Matter | C7: : Memo
B8: Index | C8: : A. Memo
A10: Objectives and Audit Procedure
C12: Objective :
C13: Memastikan kas dan setara kas yang dicatat Perseroan per 31 Desember 2024, tercatat dengan baik sesuai GAAP Indonesia
C15: Source of Documents :
C16: 1 | D16: Buku Besar per 31 Maret 2023 | H16: A.100
C17: 1 | D17: Bank Statement
C19: Procedures :
C20: 1 | D20: Mendapatkan rincian daftar Kas dan Setara Kas 2024
C21: 2 | D21: Memperoleh rekonsiliasi bank dan Rekening Koran 2024
D22: a. menyepakati saldo buku dalam rekonsiliasi bank ke buku bank dan GL (Keberadaan, Kelengkapan, Penilaian)
D23: b. menyepakati saldo per rekening koran dalam rekonsiliasi bank dengan rekening koran yang bersangkutan (Keberadaan, Kelengkapan, Penilaian)
C24: 3 | D24: Memperoleh rekonsiliasi time deposit dan membandingkan ke GL dan RK | K24: A.500
C25: 4 | D25: Mengirimkan Konfirmasi Bank | K25: A.600
B27: NATURE OF ACCOUNT
B28: Nature of WP :
B29: WP ini mewakili saldo kas dan bank per 31 2023
D31: Bank
E32: BOT IDR A/C.113855 | G32: Merupakan uang masuk dari pendapatan jasa atas penyimpanan barang customer serta untuk pembiayaan operasional perusahaan
E33: BOT US$ A/C.390564 | G33: Merupakan uang masuk dari pendapatan jasa atas penyimpanan barang customer serta untuk pembiayaan operasional perusahaan
E34: NISP IDR ACC 701.800.00776.0 | G34: Merupakan rekening bank untuk pembiayaan operasional perusahaan
E35: NISP USD ACC 701.800.00776.0 | G35: Merupakan rekening bank untuk pembiayaan operasional perusahaan
D37: Deposito | E37: TD MUFG-IDR-MONTHLY | G37: Merupakan simpanan perusahaan yang akan di gunakan untuk kegiatan operasional perusahaan
E38: TD MUFG-USD- (3 MONTH) | G38: Merupakan simpanan perusahaan yang akan di gunakan untuk kegiatan operasional perusahaan
E39: TD OCBC-USD- (1 MONTH)
B41: Finding Notes
C43: Pada akun kas dan setara kas tidak ditemukan temuan yang material
B45: CONCLUSION
C47: Semua transaksi yang berkaitan dengan kash dan setara kas sudah disajikan dan telah sesuai dengan periode terjadinya transaksi,maka akun kas dan setara kas telah disajikan secara wajar
B87: CONCLUSION
B115: CONCLUSION
B117: Based on our workdone, this account is fairly stated according to Indonesian GAAP

Sheet A. 200 Leadsheet 
A6: Client | B6: ='A.100 Memo'!C4 -> : PT Indo American Seafoods Tbk dan Entitas Anak | I6: Prepared by | J6: : IRA | R6: Date : | S6: 45733
A7: Account | B7: ='A.100 Memo'!C5 -> : Cash and Cash Equivalents | I7: Reviewed by | J7: : KNW | R7: Date : | S7: 45735
A8: Period | B8: ='A.100 Memo'!C6 -> : 31 Desember 2024 | I8: Approved by | J8: : MGN | R8: Date : | S8: 45737
A9: Index | B9: : A. 200 Leadsheet
A11: NO | B11: Description | C11: Audited PT IAS | D11: Audited PT ISP | E11: Audited PT Konsol | F11: Eliminasi | J11: Audited Konsol | L11: Audited PT IAS | M11: Audited PT ISP | N11: Audited PT Konsol | O11: Eliminasi | S11: Audited Konsol | V11: Incrase/Decrase | Z11: Incrase/Decrase 2021 dan 2020
A12: Account | C12: 45657 | D12: 45657 | E12: 45657 | F12: Ref | G12: Dr | H12: Ref | I12: Cr | J12: =E12 -> 45657 | L12: 31 Desember 2023 | M12: 31 Desember 2023 | N12: 31 Desember 2023 | O12: Ref | P12: Dr | Q12: Ref | R12: Cr | S12: =N12 -> 31 Desember 2023 | V12: Rp | W12: % | Z12: Rp | AA12: %
A14: ASSETS
A15: Cash
A16: Kas Besar
B17: Kas in Lampung | C17: 172746353 | D17: 59534151 | E17: =C17+D17 -> 232280504 | J17: =ROUND((E17+G17-I17),0) -> 232280504 | L17: 52356867 | M17: 108819809 | N17: =ROUND((L17+M17),0) -> 161176676 | S17: =ROUND((N17+P17-R17),0) -> 161176676 | V17: =J17-S17 -> 71103828 | W17: =V17/S17 -> 0.44115457
B18: Kas in Lampung (Petty Cash) | E18: =C18+D18 -> 0 | J18: =ROUND((E18+G18-I18),0) -> 0 | L18: 685258 | N18: =ROUND((L18+M18),0) -> 685258 | S18: =ROUND((N18+P18-R18),0) -> 685258 | V18: =J18-S18 -> -685258 | W18: =V18/S18 -> -1
B19: PT Bank BNI (Deposito) | E19: =C19+D19 -> 0 | J19: =ROUND((E19+G19-I19),0) -> 0 | M19: 250000000 | N19: =ROUND((L19+M19),0) -> 250000000 | S19: =ROUND((N19+P19-R19),0) -> 250000000 | V19: =J19-S19 -> -250000000 | W19: =V19/S19 -> -1
A20: ISP | B20: PT Bank Danamon Indonesia, Tbk - Tabungan | E20: =C20+D20 -> 0 | V20: =J20-S20 -> 0
E21: =C21+D21 -> 0
B22: Total Cash | C22: =SUM(C17:C20) -> 172746353 | D22: =SUM(D17:D20) -> 59534151 | E22: =C22+D22 -> 232280504 | J22: =SUM(J17:J20) -> 232280504 | L22: =SUM(L17:L20) -> 53042125 | M22: =SUM(M17:M20) -> 358819809 | N22: =SUM(N17:N20) -> 411861934 | S22: =SUM(S17:S20) -> 411861934 | V22: =J22-S22 -> -179581430 | W22: =V22/S22 -> -0.43602337
A23: Kas Kecil | E23: =C23+D23 -> 0
B24: Bank BRI Rp A/c 0285-01-220000-30-7 | E24: =C24+D24 -> 0 | J24: =ROUND((E24+G24-I24),0) -> 0 | L24: 794277 | N24: =ROUND((L24+M24),0) -> 794277 | S24: =ROUND((N24+P24-R24),0) -> 794277 | V24: =J24-S24 -> -794277 | W24: =V24/S24 -> -1
B25: Bank Mega Syariah (1000236601) | C25: 7152816 | E25: =C25+D25 -> 7152816 | J25: =ROUND((E25+G25-I25),0) -> 7152816 | L25: 13411920 | N25: =ROUND((L25+M25),0) -> 13411920 | S25: =ROUND((N25+P25-R25),0) -> 13411920 | V25: =J25-S25 -> -6259104 | W25: =V25/S25 -> -0.46668218
B26: Deposito | E26: =C26+D26 -> 0 | J26: =ROUND((E26+G26-I26),0) -> 0 | N26: =ROUND((L26+M26),0) -> 0 | S26: =ROUND((N26+P26-R26),0) -> 0 | V26: =J26-S26 -> 0 | W26: =V26/S26 -> #DIV/0!
B27: PT Bank Negara Indonesia (Persero) Tbk | C27: 1240726 | E27: =C27+D27 -> 1240726 | J27: =ROUND((E27+G27-I27),0) -> 1240726 | L27: 1432417 | N27: =ROUND((L27+M27),0) -> 1432417 | S27: =ROUND((N27+P27-R27),0) -> 1432417 | V27: =J27-S27 -> -191691 | W27: =V27/S27 -> -0.13382346
B28: Bank JTRUST (1100024149) | C28: 8375633 | E28: =C28+D28 -> 8375633 | J28: =ROUND((E28+G28-I28),0) -> 8375633 | L28: 9044094 | N28: =ROUND((L28+M28),0) -> 9044094 | S28: =ROUND((N28+P28-R28),0) -> 9044094 | V28: =J28-S28 -> -668461 | W28: =V28/S28 -> -0.073911328
B29: PT Bank Mega Syariah | D29: 3652612 | E29: =C29+D29 -> 3652612 | J29: =ROUND((E29+G29-I29),0) -> 3652612 | L29: 2098047 | M29: 571099.12 | N29: =ROUND((L29+M29),0) -> 2669146 | S29: =ROUND((N29+P29-R29),0) -> 2669146 | V29: =J29-S29 -> 983466 | W29: =V29/S29 -> 0.36845718
A30: Bank IDR | E30: =C30+D30 -> 0 | J30: =ROUND((E30+G30-I30),0) -> 0 | N30: =ROUND((L30+M30),0) -> 0 | S30: =ROUND((N30+P30-R30),0) -> 0 | V30: =J30-S30 -> 0 | W30: =V30/S30 -> #DIV/0!
B31: PT Bank BTPN | C31: 54182297 | D31: 375720277 | E31: =C31+D31 -> 429902574 | J31: =ROUND((E31+G31-I31),0) -> 429902574 | L31: 30768284 | M31: 12149873 | N31: =ROUND((L31+M31),0) -> 42918157 | S31: =ROUND((N31+P31-R31),0) -> 42918157 | V31: =J31-S31 -> 386984417 | W31: =V31/S31 -> 9.0167995
B32: PT Bank Mega Syariah | C32: 683621 | D32: 212810 | E32: =C32+D32 -> 896431 | J32: =ROUND((E32+G32-I32),0) -> 896431 | M32: 4778960 | N32: =ROUND((L32+M32),0) -> 4778960 | S32: =ROUND((N32+P32-R32),0) -> 4778960 | V32: =J32-S32 -> -3882529 | W32: =V32/S32 -> -0.81242132
B33: PT Bank BTPN | C33: 67213934 | D33: 43547299 | E33: =C33+D33 -> 110761233 | J33: =ROUND((E33+G33-I33),0) -> 110761233 | L33: 2023630252 | M33: 4011860 | N33: =ROUND((L33+M33),0) -> 2027642112 | S33: =ROUND((N33+P33-R33),0) -> 2027642112 | V33: =J33-S33 -> -1916880879 | W33: =V33/S33 -> -0.94537437
B34: Bank BNI Rp A/c 111-559-9552 | C34: 15129380 | E34: =C34+D34 -> 15129380 | J34: =ROUND((E34+G34-I34),0) -> 15129380 | N34: =ROUND((L34+M34),0) -> 0 | S34: =ROUND((N34+P34-R34),0) -> 0 | V34: =J34-S34 -> 15129380 | W34: =V34/S34 -> #DIV/0!
B35: Bank BRI (0285-02-000022-30-5) USD | C35: 1460398 | E35: =C35+D35 -> 1460398 | J35: =ROUND((E35+G35-I35),0) -> 1460398 | L35: 3242911 | M35: 0 | N35: =ROUND((L35+M35),0) -> 3242911 | S35: =ROUND((N35+P35-R35),0) -> 3242911 | V35: =J35-S35 -> -1782513 | W35: =V35/S35 -> -0.54966448
A36: ISP | B36: PT Bank Bukopin, Tbk | E36: =C36+D36 -> 0 | J36: =ROUND((E36+G36-I36),0) -> 0 | M36: 0 | N36: =ROUND((L36+M36),0) -> 0 | S36: =ROUND((N36+P36-R36),0) -> 0 | V36: =J36-S36 -> 0 | W36: =V36/S36 -> #DIV/0!
A37: ISP | B37: PT Bank Mandiri (Persero) Tbk-1140002150616 | D37: 1781825 | E37: =C37+D37 -> 1781825 | J37: =ROUND((E37+G37-I37),0) -> 1781825 | M37: 8242077.7 | N37: =ROUND((L37+M37),0) -> 8242078 | S37: =ROUND((N37+P37-R37),0) -> 8242078 | V37: =J37-S37 -> -6460253 | W37: =V37/S37 -> -0.78381362
B38: Bank Mandiri Rp A/c 114.0031009999 | E38: =C38+D38 -> 0 | J38: =ROUND((E38+G38-I38),0) -> 0 | M38: 0 | N38: =ROUND((L38+M38),0) -> 0 | S38: =ROUND((N38+P38-R38),0) -> 0 | V38: =J38-S38 -> 0 | W38: =V38/S38 -> #DIV/0!
A39: Bank USD | E39: =C39+D39 -> 0 | J39: =ROUND((E39+G39-I39),0) -> 0 | N39: =ROUND((L39+M39),0) -> 0 | S39: =ROUND((N39+P39-R39),0) -> 0 | V39: =J39-S39 -> 0 | W39: =V39/S39 -> #DIV/0!
B40: Piutang Karyawan | E40: =C40+D40 -> 0 | J40: =ROUND((E40+G40-I40),0) -> 0 | N40: =ROUND((L40+M40),0) -> 0 | S40: =ROUND((N40+P40-R40),0) -> 0 | V40: =J40-S40 -> 0 | W40: =V40/S40 -> #DIV/0!
B41: Bank Panin | E41: =C41+D41 -> 0 | J41: =ROUND((E41+G41-I41),0) -> 0 | M41: 0 | N41: =ROUND((L41+M41),0) -> 0 | S41: =ROUND((N41+P41-R41),0) -> 0 | V41: =J41-S41 -> 0 | W41: =V41/S41 -> #DIV/0!
B42: Bank Mandiri $ (114,002,744,8284) USD | E42: =C42+D42 -> 0 | J42: =ROUND((E42+G42-I42),0) -> 0 | L42: 1927000 | M42: 0 | N42: =ROUND((L42+M42),0) -> 1927000 | S42: =ROUND((N42+P42-R42),0) -> 1927000 | V42: =J42-S42 -> -1927000 | W42: =V42/S42 -> -1
A43: Deposito Berjangka | E43: =C43+D43 -> 0 | J43: =ROUND((E43+G43-I43),0) -> 0 | N43: =ROUND((L43+M43),0) -> 0 | S43: =ROUND((N43+P43-R43),0) -> 0 | V43: =J43-S43 -> 0 | W43: =V43/S43 -> #DIV/0!
B44: Bank JTRUST Rp A/c 1100024132 | C44: 3913648 | E44: =C44+D44 -> 3913648 | J44: =ROUND((E44+G44-I44),0) -> 3913648 | L44: 4766585 | M44: 0 | N44: =ROUND((L44+M44),0) -> 4766585 | S44: =ROUND((N44+P44-R44),0) -> 4766585 | V44: =J44-S44 -> -852937 | W44: =V44/S44 -> -0.1789409
B45: Bank BRI Rp A/c 0652-01-111111-301 | C45: 50621267 | E45: =C45+D45 -> 50621267 | J45: =ROUND((E45+G45-I45),0) -> 50621267 | N45: =ROUND((L45+M45),0) -> 0 | S45: =ROUND((N45+P45-R45),0) -> 0 | V45: =J45-S45 -> 50621267 | W45: =V45/S45 -> #DIV/0!
E46: =C46+D46 -> 0 | J46: =ROUND((E46+G46-I46),0) -> 0 | M46: 0 | N46: =ROUND((L46+M46),0) -> 0 | S46: =ROUND((N46+P46-R46),0) -> 0 | V46: =J46-S46 -> 0 | W46: =V46/S46 -> #DIV/0!
A47: ISP | B47: PT Bank Tabungan Negara (Persero) - Tabungan | E47: =C47+D47 -> 0 | J47: =ROUND((E47+G47-I47),0) -> 0 | L47: 2265171 | M47: 0 | N47: =ROUND((L47+M47),0) -> 2265171 | S47: =ROUND((N47+P47-R47),0) -> 2265171 | V47: =J47-S47 -> -2265171 | W47: =V47/S47 -> -1
...

Sheet A.300 Confirmation Induk 2024
A4: Client | B4: ='A.100 Memo'!C4 -> : PT Indo American Seafoods Tbk dan Entitas Anak | F4: Prepared by | G4: : IRA | O4: Date : | P4: 45733
A5: Account | B5: ='A.100 Memo'!C5 -> : Cash and Cash Equivalents | F5: Reviewed by | G5: : KNW | O5: Date : | P5: 45735
A6: Period | B6: ='A.100 Memo'!C6 -> : 31 Desember 2024 | F6: Approved by | G6: : MGN | O6: Date : | P6: 45737
A7: Index | B7: : A. 300 Confirmation Induk
B9: Item | C9: Deskripsi Bank | D9: Kurs | E9: Saldo per LK | F9: Saldo per Rekening Koran | G9: Selisih | H9: Dokumen
B10: 1 | C10: Bank Mandiri Rp A/c 114.0004692854 | E10: 4433481 | F10: 4433481 | G10: =E10-F10 -> 0
B11: 2 | C11: Bank BNI Rp A/c 111-559-9552 | E11: 15129380 | F11: 15129380 | G11: =E11-F11 -> 0
B12: 3 | C12: Bank BNI Rp A/c 115-599-4474 | E12: 1240726 | F12: 1240726 | G12: =E12-F12 -> 0
B13: 4 | C13: Bank JTRUST Rp A/c 1100024132 | E13: 3913648 | F13: 3913648 | G13: =E13-F13 -> 0
B14: 5 | C14: Bank JTRUST Rp A/c 2100596827 | E14: 726595 | F14: 726595 | G14: =E14-F14 -> 0
B15: =B14+1 -> 6 | C15: PT Bank BTPN | E15: 67213934 | F15: 67213934 | G15: =E15-F15 -> 0
B16: =B15+1 -> 7 | C16: Bank BRI Rp A/c 0652-01-111111-301 | E16: 50621267 | G16: =E16-F16 -> 50621267
B17: =B16+1 -> 8 | C17: PT Bank Mandiri (Persero) Tbk | E17: 12106954 | G17: =E17-F17 -> 12106954
B18: =B17+1 -> 9 | C18: PT Bank Negara Indonesia (Persero) Tbk $ | E18: 20695118 | F18: =1280.48*D26 -> 20695118 | G18: =E18-F18 -> 0.24
B19: =B18+1 -> 10 | C19: Bank JTRUST (1100024149) | E19: 8375633 | F19: =518.23*D26 -> 8375633.3 | G19: =E19-F19 -> -0.26
B20: =B19+1 -> 11 | C20: Bank Mega Syariah (1000236601) | E20: 7152816 | F20: =442.57*D26 -> 7152816.3 | G20: =E20-F20 -> -0.34
B21: =B20+1 -> 12 | C21: PT Bank BTPN | E21: 54182297 | F21: =3352.45*D26 -> 54182297 | G21: =E21-F21 -> 0.1
B22: =B21+1 -> 13 | C22: Bank BRI (0285-02-000022-30-5) USD | E22: 1460398 | F22: =90.36*D26 -> 1460398.3 | G22: =E22-F22 -> -0.32
B23: =B22+1 -> 14 | C23: PT Bank Mega Syariah | E23: 683621 | F23: 683621 | G23: =E23-F23 -> 0
B25: Note:
B26: Kurs USD per tanggal 31Des 24 adalah | D26: 16162
B28: Scan Konfirmasi

Sheet A.400 Cek Rekening Koran Induk
A4: Client | B4: ='A.100 Memo'!C4 -> : PT Indo American Seafoods Tbk dan Entitas Anak | I4: Prepared by | J4: : IRA | R4: Date : | S4: 45733
A5: Account | B5: ='A.100 Memo'!C5 -> : Cash and Cash Equivalents | I5: Reviewed by | J5: : KNW | R5: Date : | S5: 45735
A6: Period | B6: ='A.100 Memo'!C6 -> : 31 Desember 2024 | I6: Approved by | J6: : MGN | R6: Date : | S6: 45737
A7: Index | B7: : A. 400 Cek Rekening Koran Induk
B9: Item | C9: Deskripsi Bank | D9: No. Rekening | E9: Kurs | F9: Tanggal Konfirmasi Dikirim | G9: Tanggal Konfirmasi Diterima | H9: Saldo per LK | I9: Saldo per Konfirmasi | J9: Selisih | K9: Dokumen
B10: 1 | C10: Bank Mandiri Rp A/c 114.0004692854 | H10: 4433481 | J10: =H10-I10 -> 4433481
B11: 2 | C11: Bank BNI Rp A/c 111-559-9552 | H11: 15129380 | J11: =H11-I11 -> 15129380
B12: 3 | C12: Bank BNI Rp A/c 115-599-4474 | H12: 1240726
B13: 4 | C13: Bank JTRUST Rp A/c 1100024132 | H13: 3913648
B14: 5 | C14: Bank JTRUST Rp A/c 2100596827 | H14: 726595 | J14: =H14-I14 -> 726595
B15: =B14+1 -> 6 | C15: PT Bank BTPN | H15: 67213934
B16: =B15+1 -> 7 | C16: Bank BRI Rp A/c 0652-01-111111-301 | H16: 50621267
B17: =B16+1 -> 8 | C17: PT Bank Mandiri (Persero) Tbk | H17: 12106954
B18: =B17+1 -> 9 | C18: PT Bank Negara Indonesia (Persero) Tbk $ | H18: 20695118
B19: =B18+1 -> 10 | C19: Bank JTRUST (1100024149) | H19: 8375633
B20: =B19+1 -> 11 | C20: Bank Mega Syariah (1000236601) | H20: 7152816
B21: =B20+1 -> 12 | C21: PT Bank BTPN | H21: 54182297
B22: =B21+1 -> 13 | C22: Bank BRI (0285-02-000022-30-5) USD | H22: 1460398
B23: =B22+1 -> 14 | C23: PT Bank Mega Syariah | H23: 683621 | J23: =H23-I23 -> 683621
B25: Note:
B26: Kurs USD per tanggal 29 Des 23 adalah | F26: 15416
B28: Scan Konfirmasi

Sheet A.500 Confirmation Anak 2024
A4: Client | B4: ='A.100 Memo'!C4 -> : PT Indo American Seafoods Tbk dan Entitas Anak | I4: Prepared by | J4: : IRA | R4: Date : | S4: 45733
A5: Account | B5: ='A.100 Memo'!C5 -> : Cash and Cash Equivalents | I5: Reviewed by | J5: : KNW | R5: Date : | S5: 45735
A6: Period | B6: ='A.100 Memo'!C6 -> : 31 Desember 2024 | I6: Approved by | J6: : MGN | R6: Date : | S6: 45737
A7: Index | B7: : A. 500 Confirmation Anak 2024
B10: Bank Statements

Sheet A.600 Cek Rekening Koran Anak
A4: Client | B4: ='A.100 Memo'!C4 -> : PT Indo American Seafoods Tbk dan Entitas Anak | I4: Prepared by | J4: : IRA | R4: Date : | S4: 45733
A5: Account | B5: ='A.100 Memo'!C5 -> : Cash and Cash Equivalents | I5: Reviewed by | J5: : KNW | R5: Date : | S5: 45735
A6: Period | B6: ='A.100 Memo'!C6 -> : 31 Desember 2024 | I6: Approved by | J6: : MGN | R6: Date : | S6: 45737
A7: Index | B7: : A. 600 Cek Rekening Koran Anak
B10: Bank Statements

Sheet AA.700 Berita Acara Induk
A4: Client | B4: ='A.100 Memo'!C4 -> : PT Indo American Seafoods Tbk dan Entitas Anak | I4: Prepared by | J4: : IRA | R4: Date : | S4: 45733
A5: Account | B5: ='A.100 Memo'!C5 -> : Cash and Cash Equivalents | I5: Reviewed by | J5: : KNW | R5: Date : | S5: 45735
A6: Period | B6: ='A.100 Memo'!C6 -> : 31 Desember 2024 | I6: Approved by | J6: : MGN | R6: Date : | S6: 45737
A7: Index | B7: : A. 700 Berita Acara Induk
A34: Dokumen

Sheet A.800 Berita Acara Anak
A4: Client | B4: ='A.100 Memo'!C4 -> : PT Indo American Seafoods Tbk dan Entitas Anak | I4: Prepared by | J4: : IRA | R4: Date : | S4: 45733
A5: Account | B5: ='A.100 Memo'!C5 -> : Cash and Cash Equivalents | I5: Reviewed by | J5: : KNW | R5: Date : | S5: 45735
A6: Period | B6: ='A.100 Memo'!C6 -> : 31 Desember 2024 | I6: Approved by | J6: : MGN | R6: Date : | S6: 45737
A7: Index | B7: : A. 800 Berita Acara Anak
B9: CASH COUNT REPORT (PETTY CASH - IDR)
C12: Client: | D12: Indokom Samudra Persada | L12: Examination date: | U12: Time:
B14: RUPIAH PAPER MONEY | O14: Rupiah Coins
C15: 218 | D15: sheets | E15: @ | F15: Rp | G15: 100000 | H15: = | J15: Rp | K15: =C15*G15 -> 21800000 | Q15: coins | R15: @ | S15: USD | T15: 1000 | U15: = | V15: Rp | W15: =P15*T15 -> 0
C16: 11 | D16: sheets | E16: @ | F16: Rp | G16: 50000 | H16: = | J16: Rp | K16: =C16*G16 -> 550000 | P16: 8 | Q16: coins | R16: @ | S16: USD | T16: 500 | U16: = | V16: Rp | W16: =P16*T16 -> 4000
D17: sheets | E17: @ | F17: Rp | G17: 20000 | H17: = | J17: Rp | K17: =C17*G17 -> 0 | P17: 22 | Q17: coins | R17: @ | S17: USD | T17: 200 | U17: = | V17: Rp | W17: =P17*T17 -> 4400
C18: 200 | D18: sheets | E18: @ | F18: Rp | G18: 10000 | H18: = | J18: Rp | K18: =C18*G18 -> 2000000 | P18: 53 | Q18: coins | R18: @ | S18: USD | T18: 100 | U18: = | V18: Rp | W18: =P18*T18 -> 5300
C19: 191 | D19: sheets | E19: @ | F19: Rp | G19: 5000 | H19: = | J19: Rp | K19: =C19*G19 -> 955000 | Q19: coins | R19: @ | S19: USD | T19: 50 | U19: = | V19: Rp | W19: =P19*T19 -> 0
C20: 201 | D20: sheets | E20: @ | F20: Rp | G20: 2000 | H20: = | J20: Rp | K20: =C20*G20 -> 402000
D21: sheets | E21: @ | F21: Rp | G21: 1000 | H21: = | J21: Rp | K21: 0
D22: sheets | E22: @ | F22: Rp | G22: 500 | H22: = | J22: Rp | K22: =C22*G22 -> 0
D23: sheets | E23: @ | F23: Rp | G23: 100 | H23: = | J23: Rp | K23: =C23*G23 -> 0
J25: Rp | K25: =SUBTOTAL(9,K15:K23) -> 25707000 | V25: Rp | W25: =SUBTOTAL(9,W15:W23) -> 13700
B29: FOREIGN CURRENCY | P29: Mutasi Setelah LK
D30: Sheets | E30: @ | F30: USD | G30: 100 | H30: = | J30: USD | P30: DATE | Q30: NAME | U30: AMOUNT
D31: Sheets | E31: @ | F31: USD | G31: 50 | H31: = | J31: USD | P31: 45294 | Q31: Biaya perjalanan dinas | U31: 0 | W31: 12700000
D32: Sheets | E32: @ | F32: USD | G32: 20 | H32: = | J32: USD | P32: 45294 | Q32: Pembayaran telp & Listrik per 31 Des 2023 | U32: 0 | W32: 8500000
D33: Sheets | E33: @ | F33: USD | G33: 10 | H33: = | J33: USD | P33: 45294 | Q33: Belanja Kebutuhan ISP Group | U33: 0 | W33: 5000000
D34: Sheets | E34: @ | F34: USD | G34: 5 | H34: = | J34: USD | P34: 45274 | Q34: Biaya muat SHM pakan | U34: 0 | W34: 202500
D35: Sheets | E35: @ | F35: USD | G35: 2 | H35: = | J35: USD | P35: 45274 | Q35: Belanja kebutuhan Tambak | U35: 0 | W35: 5000000
D36: Sheets | E36: @ | F36: USD | G36: 1 | H36: = | J36: USD | P36: 45274 | Q36: Belanja kebutuhan Tambak | U36: 0 | W36: 4750000
P37: 45278 | Q37: Belanja kebutuhan Tambak | U37: 0 | W37: 5000000
P38: 45282 | Q38: Biaya operasional umum | U38: 0 | W38: 3000000
J39: USD | P39: 45282 | Q39: Belanja kebutuhan Tambak | U39: 0 | W39: 5000000
P40: 45286 | Q40: Untuk BBM dan konsumsi Bp Yazid | U40: 0 | W40: 1000000
P41: 45287 | Q41: Belanja kebutuhan Tambak | U41: 0 | W41: 5000000
P42: 45288 | Q42: Operasional umum Budidaya gebang | U42: 0 | W42: 3000000
B43: OUTSTANDING CHECK | P43: 45288 | Q43: Konsumsi karyawan tambak gebang | U43: 0 | W43: 840000
B44: No | C44: NUMBER | H44: MAT. DATE | K44: TOTAL | P44: 45289 | Q44: Operasional umum Budidaya tambak seribu | U44: 0 | W44: 3000000
P45: 45289 | Q45: Konsumsi karyawan tambak seribu | U45: 0 | W45: 6700000
P46: 45289 | Q46: Untuk panen total Blok A | U46: 0 | W46: 8475000
P47: 45290 | Q47: Panen uang jalan Harmanto | U47: 0 | W47: 5000000
P48: 45322 | U48: 0 | W48: 931552
E49: Total | K49: =SUM(K45:K48) -> 0 | Q49: Total | W49: =SUM(W31:W48) -> 83099052
B51: I am, who is a cashier and cheque, bilyet giro custodian above said that the computation has been done
B52: and all of the money, bilyet giro above had been lend to me
...

Sheet Mapping to Report
A2: KAS DAN SETARA KAS
E4: Desember
E5: 2024 | G5: 2023 | I5: 2020
A7: Kas | E7: 232280504 | G7: 161861934 | I7: 882288737 | J7: Cash on Hand
A9: Bank | J9: Cash in Banks
B10: Rupiah | K10: Rupiah
B11: Bank BTPN | E11: 110761233 | G11: 42918157 | I11: 0 | K11: Bank BTPN
B12: Bank Mandiri | E12: 6215306 | G12: 10507249 | I12: 173283361 | K12: Bank Mandiri
B13: Bank Jtrust Indonesia | E13: 4640243 | G13: 5823220 | I13: 0 | K13: Bank Jtrust Indonesia
B14: Bank Mega Syariah | E14: 896431 | G14: 2669146 | I14: 5001730 | K14: Bank Mega Syariah
B15: Bank Negara Indonesia | E15: 16370106 | G15: 1432417 | I15: 0 | K15: Bank Negara Indonesia
B16: Bank Rakyat Indonesia | E16: 50621267 | G16: 794277 | I16: 253436672 | K16: Bank Rakyat Indonesia
B17: Bank Danamon Indonesia | G17: 0 | I17: 0 | K17: Bank Danamon Indonesia
A19: Sub Jumlah | E19: =SUM(E11:E18) -> 189504586 | G19: =SUM(G11:G18) -> 64144466 | I19: =SUM(I11:I18) -> 431721763 | K19: Sub Total
B22: Dolar Amerika Serikat | K22: US Dollar
B23: Bank BTPN | E23: 429902574 | G23: 2027642112 | I23: 714045452 | K23: Bank BTPN
B24: Bank Mandiri | E24: 25185244 | G24: 27940109 | I24: 3739997246 | K24: Bank Mandiri
B25: Bank Mega Syariah | E25: 10805428 | G25: 18190880 | I25: 0 | K25: Bank Mega Syariah
B26: Bank Jtrust Indonesia | E26: 8375633 | G26: 9044094 | I26: 0 | K26: Bank Jtrust Indonesia
B27: Bank Negara Indonesia | E27: 20695118 | G27: 8054849 | I27: 0 | K27: Bank Negara Indonesia
B28: Bank Rakyat Indonesia | E28: 1460398 | G28: 3242911 | I28: 0 | K28: Bank Rakyat Indonesia
A30: Sub Jumlah | E30: =SUM(E23:E28) -> 496424395 | G30: =SUM(G23:G28) -> 2094114955 | I30: =SUM(I23:I28) -> 4454042698 | K30: Sub Total
A32: Deposito Berjangka | E32: 0 | G32: 250000000 | K32: Time Deposit
A34: Sub Jumlah | E34: =SUM(E32:E33) -> 0 | G34: =SUM(G32:G33) -> 250000000 | I34: =SUM(I33:I33) -> 0 | K34: Sub Total
A36: Jumlah | E36: =E7+E19+E30+E34 -> 918209485 | G36: =G7+G19+G30+G34 -> 2570121355 | I36: =#REF!+I19+I30+I34 -> #REF! | K36: Total
A39: C o n t r o l | E39: ='A. 200 Leadsheet '!J55 -> 918209485 | G39: ='A. 200 Leadsheet '!S55 -> 2570121355 | I39: 5514616526
A40: S e l i s i h | E40: =E36-E39 -> 0 | G40: =G36-G39 -> 0 | I40: =I36-I39 -> #REF!
