Workbook
Name \_A: #N/A
Name \0: #REF!
Name \A: #REF!
Name \A: '[1]bdrl-usg'!#REF!
Name \c: [2]FKT_PJK!#REF!
Name \c: #REF!
Name \D: #REF!
Name \E: #REF!
Name \F: #REF!
Name \g: #REF!
Name \G: #REF!
Name \h: #REF!
Name \I: #REF!
Name \j: #REF!
Name \K: #REF!
Name \l: #REF!
Name \M: #REF!
Name \M: #REF!
Name \M: #REF!
Name \M: #REF!
Name \m: #REF!
Name \N: #REF!
Name \p: #REF!
Name \p: #REF!
Name \Q: [3]DATA!#REF!
Name \r: #REF!
Name \r: #REF!
Name \s: #REF!
Name \s: #REF!
Name \U: #REF!
Name \W: #REF!
Name \x: #REF!
Name \y: #N/A
Name ________________________________ap1: #REF!
Name ________________________________des06: #REF!
Name ________________________________IRB99: #REF!
Name ________________________________PPh21: #REF!
Name ________________________________PPH23: #REF!
Name ________________________________PPh26: #REF!
Name ________________________________TOT1: #REF!
Name ________________________________TOT2: #REF!
Name _______________________________pos1: '[4]Daftar Isi'!$A$1:$L$12
Name ______________________________ap1: #REF!
Name ______________________________des06: #REF!
Name ______________________________IRB99: #REF!
Name ______________________________pos1: '[4]Daftar Isi'!$A$1:$L$12
Name ______________________________TOT1: #REF!
Name ______________________________TOT2: #REF!
Name _____________________________pos1: '[4]Daftar Isi'!$A$1:$L$12
Name ____________________________ap1: #REF!
Name ____________________________des06: #REF!
Name ____________________________IRB99: #REF!
Name ____________________________PC200: [5]asmp1!#REF!
Name ____________________________poc02: #REF!
Name ____________________________pos1: '[4]Daftar Isi'!$A$1:$L$12
Name ___________________________ap1: #REF!
Name ___________________________des06: #REF!
Name ___________________________IRB99: #REF!
Name ___________________________PC200: [5]asmp1!#REF!
Name ___________________________pos1: '[4]Daftar Isi'!$A$1:$L$12

Sheet Materiality
A5: Client: | B5: PT mcm | H5: Prepared By : | I5: LDP
A6: Closing Date: | B6: 43769 | H6: Date: | I6: 43798
A7: Schedule: | B7: PLANNING MATERIALITY
C9: Total Aset / Pendapatan | E9: Total Aset Bersih (Ekuitas) | G9: Laba Sebelum Pajak
C10: US$ (dalam jutaan) | D10: % | E10: US$ (dalam jutaan) | F10: % | G10: US$ (dalam jutaan) | H10: %
B11: Level 1 | C11: s.d. 25 | D11: 2 | E11: s.d. 10 | F11: 5 | G11: 5 | H11: 10
B12: Level 2 | C12: 25,1 s.d 50 | D12: 1.5 | E12: 10,1 s.d. 20 | F12: 4 | G12: 10 | H12: 7.5
B13: Level 3 | C13: 50,1 s.d. 75 | D13: 1 | E13: 20,1 s.d. 30 | F13: 3.5 | G13: 15 | H13: 6
B14: Level 4 | C14: 75,1 s.d. 100 | D14: 0.75 | E14: 30,1 s.d. 40 | F14: 3.25 | G14: 20 | H14: 5.5
B15: Sisa | D15: 0.5 | F15: 3 | H15: 5
A17: Calculation of Planning Materiality
A18: June | B18: Total Revenue | C18: 1364583703678
B19: Kurs | C19: 9929
B20: Rupiah | C20: =C18/C19 -> 1.3743415e+08
H21: =C20-C22 -> 0
C22: =SUM(C25:C29) -> 1.3743415e+08 | D22: =C22-C20 -> 0
C23: Dollar
C24: Range | D24: Percentage | E24: Materiality
B25: First | C25: 25000000 | D25: =D11/100 -> 0.02 | E25: =C25*D25 -> 500000
B26: Next | C26: 50000000 | D26: =D12/100 -> 0.015 | E26: =C26*D26 -> 750000
B27: Next | C27: 75000000 | D27: =D13/100 -> 0.01 | E27: =C27*D27 -> 750000
B28: Next | C28: 100000000 | D28: =D14/100 -> 0.0075 | E28: =C28*D28 -> 750000
B29: Balance | C29: =C20-SUM(C25:C28) -> -1.1256585e+08 | D29: =D15/100 -> 0.005 | E29: =C29*D29 -> -562829.24
C30: Total Overall Materiality | E30: =SUM(E25:E29) -> 2187170.8 | G30: =E30*C19 -> 2.1716419e+10
B31: 0.7 | C31: from overall materiality (PM)* | E31: =E30*B31 -> 1531019.5 | G31: =E31*C19 -> 1.5201493e+10
C32: *(Clasified as low risk client)
B33: 0.03 | C33: SUD** | E33: =E30*B33 -> 65615.123 | G33: =E33*C19 -> 6.5149256e+08
C34: **(Summary Of Unadjusted Differences)
A37: 31/06/2018 | B37: Total Sales | C37: 75758757672
B38: Kurs | C38: 14008 | D38: Using middle rate BI at Oct 31, 2019
B39: Dollar | C39: =C37/C38 -> 5408249.4
B40: Rounded | C40: =ROUND(C39,0) -> 5408249
C42: Calculated in US Dollar
C43: Range | D43: Percentage | E43: Materiality
B44: First | C44: =C40 -> 5408249 | D44: 0.02 | E44: =C44*D44 -> 108164.98
B45: Next | D45: 0.015 | E45: =C45*D45 -> 0
B46: Next | D46: 0.01 | E46: =C46*D46 -> 0
B47: Next | D47: 0.0075 | E47: =C47*D47 -> 0
B48: Balance | D48: 0.005 | E48: =C48*D48 -> 0
E49: USD | F49: IDR | G49: IDR Rounded
...

Sheet Materiality Des 20
A5: Client: | B5: PT Mitra Citra Makmur | H5: Prepared By : | I5: KNW
A6: Closing Date: | B6: 44196 | H6: Date: | I6: 44251
A7: Schedule: | B7: PLANNING MATERIALITY
C9: Total Aset / Pendapatan | E9: Total Aset Bersih (Ekuitas) | G9: Laba Sebelum Pajak
C10: US$ (dalam jutaan) | D10: % | E10: US$ (dalam jutaan) | F10: % | G10: US$ (dalam jutaan) | H10: %
B11: Level 1 | C11: s.d. 25 | D11: 2 | E11: s.d. 10 | F11: 5 | G11: 5 | H11: 10
B12: Level 2 | C12: 25,1 s.d 50 | D12: 1.5 | E12: 10,1 s.d. 20 | F12: 4 | G12: 10 | H12: 7.5
B13: Level 3 | C13: 50,1 s.d. 75 | D13: 1 | E13: 20,1 s.d. 30 | F13: 3.5 | G13: 15 | H13: 6
B14: Level 4 | C14: 75,1 s.d. 100 | D14: 0.75 | E14: 30,1 s.d. 40 | F14: 3.25 | G14: 20 | H14: 5.5
B15: Sisa | D15: 0.5 | F15: 3 | H15: 5
A17: Calculation of Planning Materiality
A18: June | B18: Total Revenue | C18: 1364583703678
B19: Kurs | C19: 9929
B20: Rupiah | C20: =C18/C19 -> 1.3743415e+08
H21: =C20-C22 -> 0
C22: =SUM(C25:C29) -> 1.3743415e+08 | D22: =C22-C20 -> 0
C23: Dollar
C24: Range | D24: Percentage | E24: Materiality
B25: First | C25: 25000000 | D25: =D11/100 -> 0.02 | E25: =C25*D25 -> 500000
B26: Next | C26: 50000000 | D26: =D12/100 -> 0.015 | E26: =C26*D26 -> 750000
B27: Next | C27: 75000000 | D27: =D13/100 -> 0.01 | E27: =C27*D27 -> 750000
B28: Next | C28: 100000000 | D28: =D14/100 -> 0.0075 | E28: =C28*D28 -> 750000
B29: Balance | C29: =C20-SUM(C25:C28) -> -1.1256585e+08 | D29: =D15/100 -> 0.005 | E29: =C29*D29 -> -562829.24
C30: Total Overall Materiality | E30: =SUM(E25:E29) -> 2187170.8 | G30: =E30*C19 -> 2.1716419e+10
B31: 0.7 | C31: from overall materiality (PM)* | E31: =E30*B31 -> 1531019.5 | G31: =E31*C19 -> 1.5201493e+10
C32: *(Clasified as low risk client)
B33: 0.03 | C33: SUD** | E33: =E30*B33 -> 65615.123 | G33: =E33*C19 -> 6.5149256e+08
C34: **(Summary Of Unadjusted Differences)
A37: 31/12/2020 | B37: Total Sales | C37: 15904252222
B38: Kurs | C38: 14105 | D38: Using Average rate BI at Dec 31, 2020
B39: Dollar | C39: =C37/C38 -> 1127561.3
B40: Rounded | C40: =ROUND(C39,0) -> 1127561
C42: Calculated in US Dollar
C43: Range | D43: Percentage | E43: Materiality
B44: First | C44: =C40 -> 1127561 | D44: 0.02 | E44: =C44*D44 -> 22551.22
B45: Next | D45: 0.015 | E45: =C45*D45 -> 0
B46: Next | D46: 0.01 | E46: =C46*D46 -> 0
B47: Next | D47: 0.0075 | E47: =C47*D47 -> 0
B48: Balance | D48: 0.005 | E48: =C48*D48 -> 0
E49: USD | F49: IDR | G49: IDR Rounded
...

Sheet Materiality 31 Oct 21 Sales
A5: Client: | B5: PT Indo Oil Perkasa Tbk | H5: Prepared By : | I5: KNW
A6: Closing Date: | B6: 44500 | H6: Date: | I6: 44530
A7: Schedule: | B7: PLANNING MATERIALITY
C9: Total Aset / Pendapatan | E9: Total Aset Bersih (Ekuitas) | G9: Laba Sebelum Pajak
C10: US$ (dalam jutaan) | D10: % | E10: US$ (dalam jutaan) | F10: % | G10: US$ (dalam jutaan) | H10: %
B11: Level 1 | C11: s.d. 25 | D11: 2 | E11: s.d. 10 | F11: 5 | G11: 5 | H11: 10
B12: Level 2 | C12: 25,1 s.d 50 | D12: 1.5 | E12: 10,1 s.d. 20 | F12: 4 | G12: 10 | H12: 7.5
B13: Level 3 | C13: 50,1 s.d. 75 | D13: 1 | E13: 20,1 s.d. 30 | F13: 3.5 | G13: 15 | H13: 6
B14: Level 4 | C14: 75,1 s.d. 100 | D14: 0.75 | E14: 30,1 s.d. 40 | F14: 3.25 | G14: 20 | H14: 5.5
B15: Sisa | D15: 0.5 | F15: 3 | H15: 5
A17: Calculation of Planning Materiality
A18: June | B18: Total Revenue | C18: 1364583703678
B19: Kurs | C19: 9929
B20: Rupiah | C20: =C18/C19 -> 1.3743415e+08
H21: =C20-C22 -> 0
C22: =SUM(C25:C29) -> 1.3743415e+08 | D22: =C22-C20 -> 0
C23: Dollar
C24: Range | D24: Percentage | E24: Materiality
B25: First | C25: 25000000 | D25: =D11/100 -> 0.02 | E25: =C25*D25 -> 500000
B26: Next | C26: 50000000 | D26: =D12/100 -> 0.015 | E26: =C26*D26 -> 750000
B27: Next | C27: 75000000 | D27: =D13/100 -> 0.01 | E27: =C27*D27 -> 750000
B28: Next | C28: 100000000 | D28: =D14/100 -> 0.0075 | E28: =C28*D28 -> 750000
B29: Balance | C29: =C20-SUM(C25:C28) -> -1.1256585e+08 | D29: =D15/100 -> 0.005 | E29: =C29*D29 -> -562829.24
C30: Total Overall Materiality | E30: =SUM(E25:E29) -> 2187170.8 | G30: =E30*C19 -> 2.1716419e+10
B31: 0.7 | C31: from overall materiality (PM)* | E31: =E30*B31 -> 1531019.5 | G31: =E31*C19 -> 1.5201493e+10
C32: *(Clasified as low risk client)
B33: 0.03 | C33: SUD** | E33: =E30*B33 -> 65615.123 | G33: =E33*C19 -> 6.5149256e+08
C34: **(Summary Of Unadjusted Differences)
A37: 44498 | B37: Total Sales | C37: 288391162953 | H37: 30/11/21 hari sabtu dan 31/11/21 hari minggu, sehingga tidak terdapat transaksi kurs
B38: Kurs | C38: 14199.01 | D38: Using Average rate BI at Oct 29, 2021
B39: Dollar | C39: =C37/C38 -> 20310653 | H39: Calculation of Performance Materiality menggunakan nilai dari penjualan, karena tolak ukur dalam menentukan sesuai dengan SA 320 "Materialitas dalam tahap perencanaan dan pelaksanaan audit" berkaitan dengan struktur kepemilikan dan pendanaan entitas yang berasal dari utang dan ekuitas sehingga menekankan pada pendapatan dari entitas
B40: Rounded | C40: =ROUND(C39,0) -> 20310653
C42: Calculated in US Dollar
C43: Range | D43: Percentage | E43: Materiality
B44: First | C44: =C40 -> 20310653 | D44: 0.02 | E44: =C44*D44 -> 406213.06
B45: Next | D45: 0.015 | E45: =C45*D45 -> 0
B46: Next | D46: 0.01 | E46: =C46*D46 -> 0
B47: Next | D47: 0.0075 | E47: =C47*D47 -> 0
B48: Balance | D48: 0.005 | E48: =C48*D48 -> 0
E49: USD | F49: IDR | G49: IDR Rounded
...

Sheet Materiality 
A5: Client: | B5: PT Indo Oil Perkasa | H5: Prepared By : | I5: KNW
A6: Closing Date: | B6: 44561 | H6: Date: | I6: 44613
A7: Schedule: | B7: PLANNING MATERIALITY
C9: Total Aset / Pendapatan | E9: Total Aset Bersih (Ekuitas) | G9: Laba Sebelum Pajak
C10: US$ (dalam jutaan) | D10: % | E10: US$ (dalam jutaan) | F10: % | G10: US$ (dalam jutaan) | H10: %
B11: Level 1 | C11: s.d. 25 | D11: 2 | E11: s.d. 10 | F11: 5 | G11: 5 | H11: 10
B12: Level 2 | C12: 25,1 s.d 50 | D12: 1.5 | E12: 10,1 s.d. 20 | F12: 4 | G12: 10 | H12: 7.5
B13: Level 3 | C13: 50,1 s.d. 75 | D13: 1 | E13: 20,1 s.d. 30 | F13: 3.5 | G13: 15 | H13: 6
B14: Level 4 | C14: 75,1 s.d. 100 | D14: 0.75 | E14: 30,1 s.d. 40 | F14: 3.25 | G14: 20 | H14: 5.5
B15: Sisa | D15: 0.5 | F15: 3 | H15: 5
A17: Calculation of Planning Materiality
A18: June | B18: Total Revenue | C18: 1364583703678
B19: Kurs | C19: 9929
B20: Rupiah | C20: =C18/C19 -> 1.3743415e+08
H21: =C20-C22 -> 0
C22: =SUM(C25:C29) -> 1.3743415e+08 | D22: =C22-C20 -> 0
C23: Dollar
C24: Range | D24: Percentage | E24: Materiality
B25: First | C25: 25000000 | D25: =D11/100 -> 0.02 | E25: =C25*D25 -> 500000
B26: Next | C26: 50000000 | D26: =D12/100 -> 0.015 | E26: =C26*D26 -> 750000
B27: Next | C27: 75000000 | D27: =D13/100 -> 0.01 | E27: =C27*D27 -> 750000
B28: Next | C28: 100000000 | D28: =D14/100 -> 0.0075 | E28: =C28*D28 -> 750000
B29: Balance | C29: =C20-SUM(C25:C28) -> -1.1256585e+08 | D29: =D15/100 -> 0.005 | E29: =C29*D29 -> -562829.24
C30: Total Overall Materiality | E30: =SUM(E25:E29) -> 2187170.8 | G30: =E30*C19 -> 2.1716419e+10
B31: 0.7 | C31: from overall materiality (PM)* | E31: =E30*B31 -> 1531019.5 | G31: =E31*C19 -> 1.5201493e+10
C32: *(Clasified as low risk client)
B33: 0.03 | C33: SUD** | E33: =E30*B33 -> 65615.123 | G33: =E33*C19 -> 6.5149256e+08
C34: **(Summary Of Unadjusted Differences)
A37: 44561 | B37: Total of Sales | C37: 375300332846
B38: Kurs | C38: 14269.01 | D38: Using Average rate BI at Dec 12, 2021
B39: Dollar | C39: =C37/C38 -> 26301778 | H39: Calculation of Performance Materiality menggunakan nilai dari penjualan, karena tolak ukur dalam menentukan sesuai dengan SA 320 "Materialitas dalam tahap perencanaan dan pelaksanaan audit" berkaitan dengan struktur kepemilikan dan pendanaan entitas yang berasal dari utang dan ekuitas sehingga menekankan pada pendapatan dari entitas
B40: Rounded | C40: =ROUND(C39,0) -> 26301778
C42: Calculated in US Dollar
C43: Range | D43: Percentage | E43: Materiality
B44: First | C44: =C40 -> 26301778 | D44: 0.02 | E44: =C44*D44 -> 526035.56
B45: Next | D45: 0.015 | E45: =C45*D45 -> 0
B46: Next | D46: 0.01 | E46: =C46*D46 -> 0
B47: Next | D47: 0.0075 | E47: =C47*D47 -> 0
B48: Balance | D48: 0.005 | E48: =C48*D48 -> 0
E49: USD | F49: IDR | G49: IDR Rounded
...

Sheet Materiality Desember Consol 24
H2: Prepared By : | I2: NLS
H3: Date: | I3: 45608
H4: Reviewed By : | I4: KNW, BPH
A5: Client: | B5: PT Indo American Seafoods Tbk dan Entitas Anak | H5: Date: | I5: 45611
A6: Closing Date: | B6: 45565 | H6: Approved by: | I6: MGN
A7: Schedule: | B7: FINAL MATERIALITY | H7: Date: | I7: 45614
C9: Total Assets or Revenue | E9: Net Assets (Equity) | H9: Income Before Taxes
C10: US$m | D10: % | E10: US$m | G10: % | H10: US$m | I10: %
B11: First | C11: 25 | D11: 2 | E11: 10 | G11: 5 | H11: 5 | I11: 10
B12: Next | C12: 50 | D12: 1.5 | E12: 20 | G12: 4 | H12: 10 | I12: 7.5
B13: Next | C13: 75 | D13: 1 | E13: 30 | G13: 3.5 | H13: 15 | I13: 6
B14: Next | C14: 100 | D14: 0.75 | E14: 40 | G14: 3.25 | H14: 20 | I14: 5.5
B15: Balance | D15: 0.5 | G15: 3 | I15: 5
A17: Calculation of Planning Materiality
A18: 45565 | B18: Total Income Before Tax | C18: ='[381]Materiality Induk 24'!C18+'[381]MTR Entintas Anak 24'!C18 -> 3.1726725e+09
B19: Kurs | C19: 15138 | D19: Using middle rate BI at 30 September 2024
B20: Dollar | C20: =C18/C19 -> 209583.34
B21: Rounded | C21: =TRUNC(C20,-3) -> 209000
C23: Calculated in US Dollar
C24: Range | D24: Percentage | E24: Materiality
B25: First | C25: =C21 -> 209000 | D25: 0.1 | E25: =C25*D25 -> 20900
B26: Next | D26: 0.075 | E26: =C26*D26 -> 0
B27: Next | D27: 0.06 | E27: =C27*D27 -> 0
B28: Next | D28: 0.055 | E28: =C28*D28 -> 0
B29: Balance | D29: 0.05 | E29: =C29*D29 -> 0
E30: USD | F30: IDR | G30: IDR Rounded
C31: Total Overall Materiality | D31: from overall materiality (PM)* | E31: =SUM(E25:E29) -> 20900 | F31: =E31*C19 -> 316384200 | G31: =TRUNC(F31,-3) -> 316384000 | H31: =H19*H25 -> 0
B32: 0.8 | E32: =E31*B32 -> 16720 | F32: =E32*C19 -> 253107360 | G32: =TRUNC(F32,-3) -> 253107000 | H32: =H31*70% -> 0
C33: *(Clasified as Non High Risk Client)
C36: Tolerable Misstatement (unadjusted misstatement) | G36: =G31-G32 -> 63277000 | H36: Agregat
B37: 0.05 | C37: MUD ** | E37: =E31*B37 -> 1045 | F37: =E37*C19 -> 15819210 | G37: =TRUNC(F37,-3) -> 15819000 | H37: Individu
C38: **(Minimum Of Unadjusted Differences)
A42: Note : | B42: Pemilihan materialitas Laba sebelum pajak mempersentasekan jumlah paling kecil dibandingkan akun lain,
B43: sehingga detail-detail atas materialitas yang didapat atas setiap akun bisa lebih mendalam untuk diteliti lebih lanjut

Sheet Vouching_Sales
A6: Client | B6: : | C6: =#REF! -> #REF! | H6: Prepared By : | I6: =#REF! -> #REF!
A7: Closing Date | B7: : | C7: =#REF! -> #REF! | H7: Date: | I7: =#REF! -> #REF!
A8: Matter | B8: : | C8: Sales
A11: Menghitung Jumlah Sampling Fix Asset
A13: Assurance Factor | B13: : | C13: 1.8
A14: Expansion Factor | B14: : | C14: 1.5
A15: Performance Materiality | B15: : | C15: =#REF! -> #REF!
A16: Population (FA) | B16: : | C16: 245651809706
A17: Expected Error (EE) | B17: : | C17: 0.05
A19: Sample Size | B19: : | C19: (Population being subject to sampling x Assurance Factor) ÷ (Performance Materiality - (Expected Error x Expansion Factor))
C21: P x AF | E21: PM | F21: EE | G21: EF
A22: Sample Size | B22: : | C22: =C16*C13 -> 4.4217326e+11 | D22: ÷ | E22: =C15 -> #REF! | F22: =C17*C16 -> 1.228259e+10 | G22: =C14 -> 1.5
A24: Sample Size | B24: : | C24: =C22/(E22-(F22*G22)) -> #REF! | D24: Angka Mutlak | F24: =F22*G22 -> 1.8423886e+10 | G24: =E22-F24 -> #REF!
A26: Kesimpulan | B26: : | C26: Ambil 31 Sampel dengan pertimbangan sebagai berikut :
C27: - Ambil Nilai yang besar
C28: - Mewakili seluruh pengeluaran untuk Revenues Tahun Berjalan
A31: Notes
A32: P | B32: : | C32: Population
A33: AF | B33: : | C33: Assurance Factor
A34: PM | B34: : | C34: Performance Materiality
A35: EE | B35: : | C35: Expected Error
A36: EF | B36: : | C36: Expansion Factor
C40: Audit Response Decision Tree
C42: Risk Materiality Assessment | D42: Assurance from Tests of Controls | E42: Assurance from Analytical Procedures | F42: Tests of detail
F43: JSSD testing | G43: Sampling
G44: AF | H44: EF
C45: High | D45: No | E45: No | F45: N/A | G45: 3.0 | H45: 1.9
E46: Yes | F46: N/A | G46: 2.5 | H46: 1.6
D47: Yes | E47: No | F47: N/A | G47: 1.6 | H47: 1.5
E48: Yes | F48: 5 to 15 | G48: 1.0 | H48: 1.3
C49: Low | D49: No | E49: No | F49: N/A | G49: 1.8 | H49: 1.5
E50: Yes | F50: 0 to 10 | G50: N/A
D51: Yes | E51: No | F51: 4 to 10 | G51: N/A
E52: Yes | F52: N/A | G52: N/A

Sheet Vouching_COGS
A6: Client | B6: : | C6: =Vouching_Sales!C6 -> #REF! | H6: Prepared By : | I6: =#REF! -> #REF!
A7: Closing Date | B7: : | C7: =#REF! -> #REF! | H7: Date: | I7: =Vouching_Sales!I7 -> #REF!
A8: Matter | B8: : | C8: COGS
A11: Menghitung Jumlah Sampling Fix Asset
A13: Assurance Factor | B13: : | C13: 1.8
A14: Expansion Factor | B14: : | C14: 1.5
A15: Performance Materiality | B15: : | C15: =#REF! -> #REF!
A16: Population (FA) | B16: : | C16: 2.0108262e+11
A17: Expected Error (EE) | B17: : | C17: 0.05
A19: Sample Size | B19: : | C19: (Population being subject to sampling x Assurance Factor) ÷ (Performance Materiality - (Expected Error x Expansion Factor))
C21: P x AF | E21: PM | F21: EE | G21: EF
A22: Sample Size | B22: : | C22: =C16*C13 -> 3.6194872e+11 | D22: ÷ | E22: =C15 -> #REF! | F22: =C17*C16 -> 1.0054131e+10 | G22: =C14 -> 1.5
A24: Sample Size | B24: : | C24: =C22/(E22-(F22*G22)) -> #REF! | D24: Angka Mutlak | F24: =F22*G22 -> 1.5081197e+10 | G24: =E22-F24 -> #REF!
A26: Kesimpulan | B26: : | C26: Ambil 32 Sampel dengan pertimbangan sebagai berikut :
C27: - Ambil Nilai yang besar
C28: - Mewakili seluruh pengeluaran untuk Other Income Tahun Berjalan
A31: Notes
A32: P | B32: : | C32: Population
A33: AF | B33: : | C33: Assurance Factor
A34: PM | B34: : | C34: Performance Materiality
A35: EE | B35: : | C35: Expected Error
A36: EF | B36: : | C36: Expansion Factor
C40: Audit Response Decision Tree
C42: Risk Materiality Assessment | D42: Assurance from Tests of Controls | E42: Assurance from Analytical Procedures | F42: Tests of detail
F43: JSSD testing | G43: Sampling
G44: AF | H44: EF
C45: High | D45: No | E45: No | F45: N/A | G45: 3.0 | H45: 1.9
E46: Yes | F46: N/A | G46: 2.5 | H46: 1.6
D47: Yes | E47: No | F47: N/A | G47: 1.6 | H47: 1.5
E48: Yes | F48: 5 to 15 | G48: 1.0 | H48: 1.3
C49: Low | D49: No | E49: No | F49: N/A | G49: 1.8 | H49: 1.5
E50: Yes | F50: 0 to 10 | G50: N/A
D51: Yes | E51: No | F51: 4 to 10 | G51: N/A
E52: Yes | F52: N/A | G52: N/A

Sheet Vouching_OPEX
A6: Client | B6: : | C6: =Vouching_COGS!C6 -> #REF! | H6: Prepared By : | I6: =#REF! -> #REF!
A7: Closing Date | B7: : | C7: =#REF! -> #REF! | H7: Date: | I7: =Vouching_COGS!I7 -> #REF!
A8: Matter | B8: : | C8: OPEX
A11: Menghitung Jumlah Sampling Fix Asset
A13: Assurance Factor | B13: : | C13: 1.8
A14: Expansion Factor | B14: : | C14: 1.5
A15: Performance Materiality | B15: : | C15: =#REF! -> #REF!
A16: Population (FA) | B16: : | C16: 9.9130448e+09
A17: Expected Error (EE) | B17: : | C17: 0.05
A19: Sample Size | B19: : | C19: (Population being subject to sampling x Assurance Factor) ÷ (Performance Materiality - (Expected Error x Expansion Factor))
C21: P x AF | E21: PM | F21: EE | G21: EF
A22: Sample Size | B22: : | C22: =C16*C13 -> 1.7843481e+10 | D22: ÷ | E22: =C15 -> #REF! | F22: =C17*C16 -> 4.9565224e+08 | G22: =C14 -> 1.5
A24: Sample Size | B24: : | C24: =C22/(E22-(F22*G22)) -> #REF! | D24: Angka Mutlak | F24: =F22*G22 -> 7.4347836e+08 | G24: =E22-F24 -> #REF!
A26: Kesimpulan | B26: : | C26: Ambil 6 Sampel dengan pertimbangan sebagai berikut :
C27: - Ambil Nilai yang besar
C28: - Mewakili seluruh pengeluaran untuk Direct Cost Tahun Berjalan
A31: Notes
A32: P | B32: : | C32: Population
A33: AF | B33: : | C33: Assurance Factor
A34: PM | B34: : | C34: Performance Materiality
A35: EE | B35: : | C35: Expected Error
A36: EF | B36: : | C36: Expansion Factor
C40: Audit Response Decision Tree
C42: Risk Materiality Assessment | D42: Assurance from Tests of Controls | E42: Assurance from Analytical Procedures | F42: Tests of detail
F43: JSSD testing | G43: Sampling
G44: AF | H44: EF
C45: High | D45: No | E45: No | F45: N/A | G45: 3.0 | H45: 1.9
E46: Yes | F46: N/A | G46: 2.5 | H46: 1.6
D47: Yes | E47: No | F47: N/A | G47: 1.6 | H47: 1.5
E48: Yes | F48: 5 to 15 | G48: 1.0 | H48: 1.3
C49: Low | D49: No | E49: No | F49: N/A | G49: 1.8 | H49: 1.5
E50: Yes | F50: 0 to 10 | G50: N/A
D51: Yes | E51: No | F51: 4 to 10 | G51: N/A
E52: Yes | F52: N/A | G52: N/A

Sheet Vouching_OPEX (Sales)
A6: Client | B6: : | C6: =Vouching_OPEX!C6 -> #REF! | H6: Prepared By : | I6: =#REF! -> #REF!
A7: Closing Date | B7: : | C7: =#REF! -> #REF! | H7: Date: | I7: =Vouching_OPEX!I7 -> #REF!
A8: Matter | B8: : | C8: OPEX
A11: Menghitung Jumlah Sampling Fix Asset
A13: Assurance Factor | B13: : | C13: 1.8
A14: Expansion Factor | B14: : | C14: 1.5
A15: Performance Materiality | B15: : | C15: =#REF! -> #REF!
A16: Population (FA) | B16: : | C16: 1.9921262e+10
A17: Expected Error (EE) | B17: : | C17: 0.05
A19: Sample Size | B19: : | C19: (Population being subject to sampling x Assurance Factor) ÷ (Performance Materiality - (Expected Error x Expansion Factor))
C21: P x AF | E21: PM | F21: EE | G21: EF
A22: Sample Size | B22: : | C22: =C16*C13 -> 3.5858271e+10 | D22: ÷ | E22: =C15 -> #REF! | F22: =C17*C16 -> 9.9606308e+08 | G22: =C14 -> 1.5
A24: Sample Size | B24: : | C24: =C22/(E22-(F22*G22)) -> #REF! | D24: Angka Mutlak | F24: =F22*G22 -> 1.4940946e+09 | G24: =E22-F24 -> #REF!
A26: Kesimpulan | B26: : | C26: Ambil 15 Sampel dengan pertimbangan sebagai berikut :
C27: - Ambil Nilai yang besar
C28: - Mewakili seluruh pengeluaran untuk Direct Cost Tahun Berjalan
A31: Notes
A32: P | B32: : | C32: Population
A33: AF | B33: : | C33: Assurance Factor
A34: PM | B34: : | C34: Performance Materiality
A35: EE | B35: : | C35: Expected Error
A36: EF | B36: : | C36: Expansion Factor
C40: Audit Response Decision Tree
C42: Risk Materiality Assessment | D42: Assurance from Tests of Controls | E42: Assurance from Analytical Procedures | F42: Tests of detail
F43: JSSD testing | G43: Sampling
G44: AF | H44: EF
C45: High | D45: No | E45: No | F45: N/A | G45: 3.0 | H45: 1.9
E46: Yes | F46: N/A | G46: 2.5 | H46: 1.6
D47: Yes | E47: No | F47: N/A | G47: 1.6 | H47: 1.5
E48: Yes | F48: 5 to 15 | G48: 1.0 | H48: 1.3
C49: Low | D49: No | E49: No | F49: N/A | G49: 1.8 | H49: 1.5
E50: Yes | F50: 0 to 10 | G50: N/A
D51: Yes | E51: No | F51: 4 to 10 | G51: N/A
E52: Yes | F52: N/A | G52: N/A

Sheet Pendapatan 
A6: Client | B6: : | C6: ='Materiality 31 Oct 21 Sales'!B5 -> PT Indo Oil Perkasa Tbk | H6: Prepared By : | I6: KNW
A7: Closing Date | B7: : | C7: ='Materiality 31 Oct 21 Sales'!B6 -> 44500 | H7: Date: | I7: 44518
A8: Matter | B8: : | C8: Pendapatan
A11: Menghitung Jumlah Samping Sales
L12: List of Sample
A13: Assurance Factor | B13: : | C13: 1.8 | L13: No | M13: COA | N13: Account | O13: Total Sampling | P13: Judgement
A14: Expansion Factor | B14: : | C14: 1.5 | L14: 1 | M14: PIC Judgement | P14: Biggest on Sales of Type
A15: Performance Materiality | B15: : | C15: ='Materiality 31 Oct 21 Sales'!G51 -> 4.6142586e+09 | L15: 2 | M15: PIC Judgement | P15: Biggest on Sales of Type
A16: Population (Sales) | B16: : | C16: 112260541854 | L16: 3 | M16: PIC Judgement | P16: Biggest on Sales of Type
A17: Expected Error (EE) | B17: : | C17: 0.05 | L17: 4 | M17: PIC Judgement | P17: Biggest on Sales of Type
L18: 5 | M18: PIC Judgement | P18: Biggest on Sales of Type
A19: Sample Size | B19: : | C19: (Population being subject to sampling x Assurance Factor) ÷ (Performance Materiality - (Expected Error x Expansion Factor)) | M19: Jumlah | O19: 57 (minimal)
C21: P x AF | E21: PM | F21: EE | G21: EF
A22: Sample Size | B22: : | C22: =C16*C13 -> 2.0206898e+11 | D22: ÷ | E22: =C15 -> 4.6142586e+09 | F22: =C17*C16 -> 5.6130271e+09 | G22: =C14 -> 1.5
A24: Sample Size | B24: : | C24: =C22/(E22-(F22*G22)) -> -53.102234 | D24: Angka Mutlak | F24: =F22*G22 -> 8.4195406e+09 | G24: =E22-F24 -> -3.805282e+09
M25: Populasi | N25: =C16 -> 112260541854
A26: Kesimpulan | B26: : | C26: Ambil 31 Sampel dengan pertimbangan sebagai berikut : | M26: SW | N26: 1.0093094e+10
C27: - Ambil Nilai yang besar | M27: TS | N27: 9.5467529e+09
C28: - Mewakili seluruh penerimaan dari pendapatan
M29: Sampel SW | N29: =N26/N25*117 -> 10.519208
M30: Sampel TS | N30: =N27/N25*117 -> 9.9498013
A31: Notes | M31: Total Sampel | N31: =N29+N30 -> 20.46901
A32: P | B32: : | C32: Population
A33: AF | B33: : | C33: Assurance Factor
A34: PM | B34: : | C34: Performance Materiality
A35: EE | B35: : | C35: Expected Error
A36: EF | B36: : | C36: Expansion Factor
C40: Audit Response Decision Tree
C42: Risk Materiality Assessment | D42: Assurance from Tests of Controls | E42: Assurance from Analytical Procedures | F42: Tests of detail
F43: JSSD testing | G43: Sampling
G44: AF | H44: EF
C45: High | D45: No | E45: No | F45: N/A | G45: 3.0 | H45: 1.9
E46: Yes | F46: N/A | G46: 2.5 | H46: 1.6
D47: Yes | E47: No | F47: N/A | G47: 1.6 | H47: 1.5
E48: Yes | F48: 5 to 15 | G48: 1.0 | H48: 1.3
C49: Low | D49: No | E49: No | F49: N/A | G49: 1.8 | H49: 1.5
E50: Yes | F50: 0 to 10 | G50: N/A
D51: Yes | E51: No | F51: 4 to 10 | G51: N/A
E52: Yes | F52: N/A | G52: N/A

Sheet Revenue
A6: Client | B6: : | C6: =Materiality!B5 -> PT mcm | H6: Prepared By : | I6: LDP
A7: Closing Date | B7: : | C7: =Materiality!B6 -> 43769 | H7: Date: | I7: 43788
A8: Matter | B8: : | C8: OPEX Sample
A11: Menghitung Jumlah Samping OPEX
L12: List of Sample
A13: Assurance Factor | B13: : | C13: 1.8 | L13: No | M13: COA | N13: Account | O13: Total Sampling | P13: Judgement
A14: Expansion Factor | B14: : | C14: 1.5 | L14: 1 | M14: PIC Judgement | P14: Biggest on Sales of Type
A15: Performance Materiality | B15: : | C15: =Materiality!G56 -> 75758752 | L15: 2 | M15: PIC Judgement | P15: Biggest on Sales of Type
A16: Population (Sales) | B16: : | C16: =Materiality!C37 -> 75758757672 | E16: 75758757672 | F16: =E16-C16 -> 0 | L16: 3 | M16: PIC Judgement | P16: Biggest on Sales of Type
A17: Expected Error (EE) | B17: : | C17: 0.05 | L17: 4 | M17: PIC Judgement | P17: Biggest on Sales of Type
L18: 5 | M18: PIC Judgement | P18: Biggest on Sales of Type
A19: Sample Size | B19: : | C19: (Population being subject to sampling x Assurance Factor) ÷ (Performance Materiality - (Expected Error x Expansion Factor)) | M19: Jumlah | O19: 57 (minimal)
C21: P x AF | E21: PM | F21: EE | G21: EF
A22: Sample Size | B22: : | C22: =C16*C13 -> 1.3636576e+11 | D22: ÷ | E22: =C15 -> 75758752 | F22: =C17*C16 -> 3.7879379e+09 | G22: =C14 -> 1.5
A24: Sample Size | B24: : | C24: =C22/(E22-(F22*G22)) -> -24.324324 | D24: Angka Mutlak | F24: =F22*G22 -> 5.6819068e+09 | G24: =E22-F24 -> -5.6061481e+09
M25: Populasi | N25: =C16 -> 75758757672
A26: Kesimpulan | B26: : | C26: Ambil 22 Sampel dengan pertimbangan sebagai berikut : | M26: SW | N26: 1.0093094e+10
C27: - Ambil Nilai yang besar | M27: TS | N27: 9.5467529e+09
C28: - Mewakili seluruh pengeluaran untuk OPEX
M29: Sampel SW | N29: =N26/N25*117 -> 15.587532
M30: Sampel TS | N30: =N27/N25*117 -> 14.743775
A31: Notes | M31: Total Sampel | N31: =N29+N30 -> 30.331307
A32: P | B32: : | C32: Population
A33: AF | B33: : | C33: Assurance Factor
A34: PM | B34: : | C34: Performance Materiality
A35: EE | B35: : | C35: Expected Error
A36: EF | B36: : | C36: Expansion Factor
C40: Audit Response Decision Tree
C42: Risk Materiality Assessment | D42: Assurance from Tests of Controls | E42: Assurance from Analytical Procedures | F42: Tests of detail
F43: JSSD testing | G43: Sampling
G44: AF | H44: EF
C45: High | D45: No | E45: No | F45: N/A | G45: 3.0 | H45: 1.9
E46: Yes | F46: N/A | G46: 2.5 | H46: 1.6
D47: Yes | E47: No | F47: N/A | G47: 1.6 | H47: 1.5
E48: Yes | F48: 5 to 15 | G48: 1.0 | H48: 1.3
C49: Low | D49: No | E49: No | F49: N/A | G49: 1.8 | H49: 1.5
E50: Yes | F50: 0 to 10 | G50: N/A
D51: Yes | E51: No | F51: 4 to 10 | G51: N/A
E52: Yes | F52: N/A | G52: N/A

Sheet COGS JAN-FEB
A6: Client | B6: : | C6: =Materiality!B5 -> PT mcm | H6: Prepared By : | I6: LDP
A7: Closing Date | B7: : | C7: =Materiality!B6 -> 43769 | H7: Date: | I7: 43788
A8: Matter | B8: : | C8: OPEX Sample
A11: Menghitung Jumlah Samping OPEX
L12: List of Sample
A13: Assurance Factor | B13: : | C13: 1.8 | L13: No | M13: COA | N13: Account | O13: Total Sampling | P13: Judgement
A14: Expansion Factor | B14: : | C14: 1.5 | L14: 1 | M14: PIC Judgement | P14: Biggest on Sales of Type
A15: Performance Materiality | B15: : | C15: =Materiality!G56 -> 75758752 | L15: 2 | M15: PIC Judgement | P15: Biggest on Sales of Type
A16: Population (OPEX) | B16: : | C16: 1.0856966e+10 | L16: 3 | M16: PIC Judgement | P16: Biggest on Sales of Type
A17: Expected Error (EE) | B17: : | C17: 0.05 | L17: 4 | M17: PIC Judgement | P17: Biggest on Sales of Type
L18: 5 | M18: PIC Judgement | P18: Biggest on Sales of Type
A19: Sample Size | B19: : | C19: (Population being subject to sampling x Assurance Factor) ÷ (Performance Materiality - (Expected Error x Expansion Factor)) | M19: Jumlah | O19: 57 (minimal)
C21: P x AF | E21: PM | F21: EE | G21: EF
A22: Sample Size | B22: : | C22: =C16*C13 -> 1.9542539e+10 | D22: ÷ | E22: =C15 -> 75758752 | F22: =C17*C16 -> 5.4284831e+08 | G22: =C14 -> 1.5
A24: Sample Size | B24: : | C24: =C22/(E22-(F22*G22)) -> -26.461985 | D24: Angka Mutlak | F24: =F22*G22 -> 8.1427247e+08 | G24: =E22-F24 -> -7.3851372e+08
M25: Populasi | N25: =C16 -> 1.0856966e+10
A26: Kesimpulan | B26: : | C26: Ambil 22 Sampel dengan pertimbangan sebagai berikut : | M26: SW | N26: 1.0093094e+10
C27: - Ambil Nilai yang besar | M27: TS | N27: 9.5467529e+09
C28: - Mewakili seluruh pengeluaran untuk OPEX
M29: Sampel SW | N29: =N26/N25*117 -> 108.76814
M30: Sampel TS | N30: =N27/N25*117 -> 102.8805
A31: Notes | M31: Total Sampel | N31: =N29+N30 -> 211.64864
A32: P | B32: : | C32: Population
A33: AF | B33: : | C33: Assurance Factor
A34: PM | B34: : | C34: Performance Materiality
A35: EE | B35: : | C35: Expected Error
A36: EF | B36: : | C36: Expansion Factor
C40: Audit Response Decision Tree
C42: Risk Materiality Assessment | D42: Assurance from Tests of Controls | E42: Assurance from Analytical Procedures | F42: Tests of detail
F43: JSSD testing | G43: Sampling
G44: AF | H44: EF
C45: High | D45: No | E45: No | F45: N/A | G45: 3.0 | H45: 1.9
E46: Yes | F46: N/A | G46: 2.5 | H46: 1.6
D47: Yes | E47: No | F47: N/A | G47: 1.6 | H47: 1.5
E48: Yes | F48: 5 to 15 | G48: 1.0 | H48: 1.3
C49: Low | D49: No | E49: No | F49: N/A | G49: 1.8 | H49: 1.5
E50: Yes | F50: 0 to 10 | G50: N/A
D51: Yes | E51: No | F51: 4 to 10 | G51: N/A
E52: Yes | F52: N/A | G52: N/A

Sheet COGS MAR-APR
A6: Client | B6: : | C6: =Materiality!B5 -> PT mcm | H6: Prepared By : | I6: LDP
A7: Closing Date | B7: : | C7: =Materiality!B6 -> 43769 | H7: Date: | I7: 43788
A8: Matter | B8: : | C8: OPEX Sample
A11: Menghitung Jumlah Samping OPEX
L12: List of Sample
A13: Assurance Factor | B13: : | C13: 1.8 | L13: No | M13: COA | N13: Account | O13: Total Sampling | P13: Judgement
A14: Expansion Factor | B14: : | C14: 1.5 | L14: 1 | M14: PIC Judgement | P14: Biggest on Sales of Type
A15: Performance Materiality | B15: : | C15: =Materiality!G56 -> 75758752 | L15: 2 | M15: PIC Judgement | P15: Biggest on Sales of Type
A16: Population (OPEX) | B16: : | C16: 1.3645857e+10 | L16: 3 | M16: PIC Judgement | P16: Biggest on Sales of Type
A17: Expected Error (EE) | B17: : | C17: 0.05 | L17: 4 | M17: PIC Judgement | P17: Biggest on Sales of Type
L18: 5 | M18: PIC Judgement | P18: Biggest on Sales of Type
A19: Sample Size | B19: : | C19: (Population being subject to sampling x Assurance Factor) ÷ (Performance Materiality - (Expected Error x Expansion Factor)) | M19: Jumlah | O19: 57 (minimal)
C21: P x AF | E21: PM | F21: EE | G21: EF
A22: Sample Size | B22: : | C22: =C16*C13 -> 2.4562543e+10 | D22: ÷ | E22: =C15 -> 75758752 | F22: =C17*C16 -> 6.8229286e+08 | G22: =C14 -> 1.5
A24: Sample Size | B24: : | C24: =C22/(E22-(F22*G22)) -> -25.91859 | D24: Angka Mutlak | F24: =F22*G22 -> 1.0234393e+09 | G24: =E22-F24 -> -9.4768053e+08
M25: Populasi | N25: =C16 -> 1.3645857e+10
A26: Kesimpulan | B26: : | C26: Ambil 22 Sampel dengan pertimbangan sebagai berikut : | M26: SW | N26: 1.0093094e+10
C27: - Ambil Nilai yang besar | M27: TS | N27: 9.5467529e+09
C28: - Mewakili seluruh pengeluaran untuk OPEX
M29: Sampel SW | N29: =N26/N25*117 -> 86.538503
M30: Sampel TS | N30: =N27/N25*117 -> 81.854154
A31: Notes | M31: Total Sampel | N31: =N29+N30 -> 168.39266
A32: P | B32: : | C32: Population
A33: AF | B33: : | C33: Assurance Factor
A34: PM | B34: : | C34: Performance Materiality
A35: EE | B35: : | C35: Expected Error
A36: EF | B36: : | C36: Expansion Factor
C40: Audit Response Decision Tree
C42: Risk Materiality Assessment | D42: Assurance from Tests of Controls | E42: Assurance from Analytical Procedures | F42: Tests of detail
F43: JSSD testing | G43: Sampling
G44: AF | H44: EF
C45: High | D45: No | E45: No | F45: N/A | G45: 3.0 | H45: 1.9
E46: Yes | F46: N/A | G46: 2.5 | H46: 1.6
D47: Yes | E47: No | F47: N/A | G47: 1.6 | H47: 1.5
E48: Yes | F48: 5 to 15 | G48: 1.0 | H48: 1.3
C49: Low | D49: No | E49: No | F49: N/A | G49: 1.8 | H49: 1.5
E50: Yes | F50: 0 to 10 | G50: N/A
D51: Yes | E51: No | F51: 4 to 10 | G51: N/A
E52: Yes | F52: N/A | G52: N/A

Sheet Sales
A6: Client | B6: : | C6: PT TRINITI DINAMIK | H6: Prepared By : | I6: VNS
A7: Closing Date | B7: : | C7: 43281 | H7: Date: | I7: 43290
A8: Matter | B8: : | C8: Sales Sample
A11: Menghitung Jumlah Samping Sales
L12: List of Sample
A13: Assurance Factor | B13: : | C13: 1.6 | L13: No | M13: COA | N13: Account | O13: Total Sampling | P13: Judgement
A14: Expansion Factor | B14: : | C14: 1.5 | L14: 1 | M14: PIC Judgement | P14: Biggest on Sales of Type
A15: Performance Materiality | B15: : | C15: =Materiality!G51 -> 1.21214e+09 | L15: 2 | M15: PIC Judgement | P15: Biggest on Sales of Type
A16: Population (Sales) | B16: : | C16: 201744952051 | L16: 3 | M16: PIC Judgement | P16: Biggest on Sales of Type
A17: Expected Error (EE) | B17: : | C17: 0.05 | L17: 4 | M17: PIC Judgement | P17: Biggest on Sales of Type
L18: 5 | M18: PIC Judgement | P18: Biggest on Sales of Type
A19: Sample Size | B19: : | C19: (Population being subject to sampling x Assurance Factor) ÷ (Performance Materiality - (Expected Error x Expansion Factor)) | M19: Jumlah | O19: 57 (minimal)
C21: P x AF | E21: PM | F21: EE | G21: EF
A22: Sample Size | B22: : | C22: =C16*C13 -> 3.2279192e+11 | D22: ÷ | E22: =C15 -> 1.21214e+09 | F22: =C17*C16 -> 1.0087248e+10 | G22: =C14 -> 1.5
A24: Sample Size | B24: : | C24: =C22/(E22-(F22*G22)) -> -23.191189 | D24: Angka Mutlak | F24: =F22*G22 -> 1.5130871e+10 | G24: =E22-F24 -> -1.3918731e+10
M25: Populasi | N25: =C16 -> 201744952051
A26: Kesimpulan | B26: : | C26: Ambil 27 Sampel dengan pertimbangan sebagai berikut : | M26: SW | N26: 61762005501
C27: - Ambil Nilai yang besar | M27: TS | N27: 13547267006
C28: - Mewakili seluruh pengeluaran untuk Sales
M29: Sampel SW | N29: =N26/N25*27 -> 8.265754
M30: Sampel TS | N30: =N27/N25*27 -> 1.8130625
A31: Notes | M31: Total Sampel | N31: =N29+N30 -> 10.078817
A32: P | B32: : | C32: Population
A33: AF | B33: : | C33: Assurance Factor
A34: PM | B34: : | C34: Performance Materiality
A35: EE | B35: : | C35: Expected Error
A36: EF | B36: : | C36: Expansion Factor
C40: Audit Response Decision Tree
C42: Risk Materiality Assessment | D42: Assurance from Tests of Controls | E42: Assurance from Analytical Procedures | F42: Tests of detail
F43: JSSD testing | G43: Sampling
G44: AF | H44: EF
C45: High | D45: No | E45: No | F45: N/A | G45: 3.0 | H45: 1.9
E46: Yes | F46: N/A | G46: 2.5 | H46: 1.6
D47: Yes | E47: No | F47: N/A | G47: 1.6 | H47: 1.5
E48: Yes | F48: 5 to 15 | G48: 1.0 | H48: 1.3
C49: Low | D49: No | E49: No | F49: N/A | G49: 1.8 | H49: 1.5
E50: Yes | F50: 0 to 10 | G50: N/A
D51: Yes | E51: No | F51: 4 to 10 | G51: N/A
E52: Yes | F52: N/A | G52: N/A

Sheet COGS
A6: Client | B6: : | C6: PT TRRINITI DINAMIK | H6: Prepared By : | I6: VNS
A7: Closing Date | B7: : | C7: 43281 | H7: Date: | I7: 43290
A8: Matter | B8: : | C8: COGS
A11: Menghitung Jumlah Samping COGS
L12: List of Sample
A13: Assurance Factor | B13: : | C13: 1.6 | L13: No | M13: COA | N13: Account | O13: Total Sampling | P13: Judgement
A14: Expansion Factor | B14: : | C14: 1.5 | L14: 1 | M14: PIC Judgement | P14: Biggest on Sales of Type
A15: Performance Materiality | B15: : | C15: =Materiality!G51 -> 1.21214e+09 | L15: 2 | M15: PIC Judgement | P15: Biggest on Sales of Type
A16: Population (COGS) | B16: : | C16: =105424376170+51826095350 -> 157250471520 | L16: 3 | M16: PIC Judgement | P16: Biggest on Sales of Type
A17: Expected Error (EE) | B17: : | C17: 0.05 | L17: 4 | M17: PIC Judgement | P17: Biggest on Sales of Type
L18: 5 | M18: PIC Judgement | P18: Biggest on Sales of Type
A19: Sample Size | B19: : | C19: (Population being subject to sampling x Assurance Factor) ÷ (Performance Materiality - (Expected Error x Expansion Factor)) | M19: Jumlah | O19: =SUM(O14:O18) -> 0
C21: P x AF | E21: PM | F21: EE | G21: EF
A22: Sample Size | B22: : | C22: =C16*C13 -> 251600754432 | D22: ÷ | E22: =C15 -> 1.21214e+09 | F22: =C17*C16 -> 7862523576 | G22: =C14 -> 1.5
A24: Sample Size | B24: : | C24: =C22/(E22-(F22*G22)) -> -23.777092 | D24: Angka Mutlak | F24: =F22*G22 -> 11793785364 | G24: =E22-F24 -> -1.0581645e+10
M25: Populasi | N25: =C16 -> 157250471520
A26: Kesimpulan | B26: : | C26: Ambil 29 Sampel dengan pertimbangan sebagai berikut : | M26: SW | N26: 44096439955
C27: - Ambil Nilai yang besar | M27: TS | N27: 12682342323
C28: - Mewakili seluruh penerimaan COGS
M29: Sampel SW | N29: =N26/N25*30 -> 8.4126501
M30: Sampel TS | N30: =N27/N25*30 -> 2.4195175
A31: Notes | M31: Total Sampel | N31: =N29+N30 -> 10.832168
A32: P | B32: : | C32: Population
A33: AF | B33: : | C33: Assurance Factor
A34: PM | B34: : | C34: Performance Materiality | M34: * untuk TOC ambil sampel konsumen SW min 30 mewakili masing2 type dan progres penerimaan
A35: EE | B35: : | C35: Expected Error | M35: * untuk sales SW diambil dari sampel TOC
A36: EF | B36: : | C36: Expansion Factor
C40: Audit Response Decision Tree
C42: Risk Materiality Assessment | D42: Assurance from Tests of Controls | E42: Assurance from Analytical Procedures | F42: Tests of detail
F43: JSSD testing | G43: Sampling
G44: AF | H44: EF
C45: High | D45: No | E45: No | F45: N/A | G45: 3.0 | H45: 1.9
E46: Yes | F46: N/A | G46: 2.5 | H46: 1.6
D47: Yes | E47: No | F47: N/A | G47: 1.6 | H47: 1.5
E48: Yes | F48: 5 to 15 | G48: 1.0 | H48: 1.3
C49: Low | D49: No | E49: No | F49: N/A | G49: 1.8 | H49: 1.5
E50: Yes | F50: 0 to 10 | G50: N/A
D51: Yes | E51: No | F51: 4 to 10 | G51: N/A
E52: Yes | F52: N/A | G52: N/A

Sheet OPEX MCM
A6: Client | B6: : | C6: ='COGS JAN-FEB'!C6 -> PT mcm | H6: Prepared By : | I6: LDP
A7: Closing Date | B7: : | C7: ='COGS JAN-FEB'!C7 -> 43769 | H7: Date: | I7: 43788
A8: Matter | B8: : | C8: Uneraned Rev
A11: Menghitung Jumlah Samping COGS
L12: List of Sample
A13: Assurance Factor | B13: : | C13: 1.8 | L13: No | M13: COA | N13: Account | O13: Total Sampling | P13: Judgement
A14: Expansion Factor | B14: : | C14: 1.5 | L14: 1 | M14: PIC Judgement | P14: Biggest on Sales of Type
A15: Performance Materiality | B15: : | C15: =Materiality!G56 -> 75758752 | L15: 2 | M15: PIC Judgement | P15: Biggest on Sales of Type
A16: Population (ARE) | B16: : | C16: 2.6075329e+09 | L16: 3 | M16: PIC Judgement | P16: Biggest on Sales of Type
A17: Expected Error (EE) | B17: : | C17: 0.05 | L17: 4 | M17: PIC Judgement | P17: Biggest on Sales of Type
L18: 5 | M18: PIC Judgement | P18: Biggest on Sales of Type
A19: Sample Size | B19: : | C19: (Population being subject to sampling x Assurance Factor) ÷ (Performance Materiality - (Expected Error x Expansion Factor)) | M19: Jumlah | O19: =SUM(O14:O18) -> 0
C21: P x AF | E21: PM | F21: EE | G21: EF
A22: Sample Size | B22: : | C22: =C16*C13 -> 4.6935591e+09 | D22: ÷ | E22: =C15 -> 75758752 | F22: =C17*C16 -> 1.3037664e+08 | G22: =C14 -> 1.5
A24: Sample Size | B24: : | C24: =C22/(E22-(F22*G22)) -> -39.176259 | D24: Angka Mutlak | F24: =F22*G22 -> 1.9556496e+08 | G24: =E22-F24 -> -1.1980621e+08
M25: Populasi | N25: 2.0012888e+11
A26: Kesimpulan | B26: : | C26: Ambil 24 Sampel dengan pertimbangan sebagai berikut : | M26: Developer | N26: 90733006173
C27: - Ambil Nilai yang besar | M27: POM | N27: 1.0939588e+11
C28: - Mewakili seluruh penerimaan ARE
M29: Sampel Dev | N29: =N26/N25*22 -> 9.9742032
M30: Sampel POM | N30: =N27/N25*22 -> 12.025797
A31: Notes | M31: Total Sampel | N31: =N29+N30 -> 22
A32: P | B32: : | C32: Population
A33: AF | B33: : | C33: Assurance Factor
A34: PM | B34: : | C34: Performance Materiality | M34: * untuk TOC ambil sampel konsumen Dev min 22 mewakili masing2 type dan progres penerimaan
A35: EE | B35: : | C35: Expected Error | M35: * untuk sales SW diambil dari sampel TOC
A36: EF | B36: : | C36: Expansion Factor
C40: Audit Response Decision Tree
C42: Risk Materiality Assessment | D42: Assurance from Tests of Controls | E42: Assurance from Analytical Procedures | F42: Tests of detail
F43: JSSD testing | G43: Sampling
G44: AF | H44: EF
C45: High | D45: No | E45: No | F45: N/A | G45: 3.0 | H45: 1.9
E46: Yes | F46: N/A | G46: 2.5 | H46: 1.6
D47: Yes | E47: No | F47: N/A | G47: 1.6 | H47: 1.5
E48: Yes | F48: 5 to 15 | G48: 1.0 | H48: 1.3
C49: Low | D49: No | E49: No | F49: N/A | G49: 1.8 | H49: 1.5
E50: Yes | F50: 0 to 10 | G50: N/A
D51: Yes | E51: No | F51: 4 to 10 | G51: N/A
E52: Yes | F52: N/A | G52: N/A

Sheet OPEX 
A6: Client | B6: : | C6: ='Pendapatan '!C6 -> PT Indo Oil Perkasa Tbk | H6: Prepared By : | I6: KNW
A7: Closing Date | B7: : | C7: ='Pendapatan '!C7 -> 44500 | H7: Date: | I7: ='Pendapatan '!I7 -> 44518
A8: Matter | B8: : | C8: Beban Operasional
A11: Menghitung Jumlah Samping OPEX
L12: List of Sample
A13: Assurance Factor | B13: : | C13: 1.8 | L13: No | M13: COA | N13: Account | O13: Total Sampling | P13: Judgement
A14: Expansion Factor | B14: : | C14: 1.5 | L14: 1 | M14: PIC Judgement | P14: Biggest on Sales of Type
A15: Performance Materiality | B15: : | C15: ='Pendapatan '!C15 -> 4.6142586e+09 | L15: 2 | M15: PIC Judgement | P15: Biggest on Sales of Type
A16: Population (ARE) | B16: : | C16: 107464154386 | L16: 3 | M16: PIC Judgement | P16: Biggest on Sales of Type
A17: Expected Error (EE) | B17: : | C17: 0.05 | L17: 4 | M17: PIC Judgement | P17: Biggest on Sales of Type
L18: 5 | M18: PIC Judgement | P18: Biggest on Sales of Type
A19: Sample Size | B19: : | C19: (Population being subject to sampling x Assurance Factor) ÷ (Performance Materiality - (Expected Error x Expansion Factor)) | M19: Jumlah | O19: =SUM(O14:O18) -> 0
C21: P x AF | E21: PM | F21: EE | G21: EF
A22: Sample Size | B22: : | C22: =C16*C13 -> 1.9343548e+11 | D22: ÷ | E22: =C15 -> 4.6142586e+09 | F22: =C17*C16 -> 5.3732077e+09 | G22: =C14 -> 1.5
A24: Sample Size | B24: : | C24: =C22/(E22-(F22*G22)) -> -56.14062 | D24: Angka Mutlak | F24: =F22*G22 -> 8.0598116e+09 | G24: =E22-F24 -> -3.4455529e+09
M25: Populasi | N25: 2.0012888e+11
A26: Kesimpulan | B26: : | C26: Ambil 31 Sampel dengan pertimbangan sebagai berikut : | M26: Developer | N26: 90733006173
C27: - Ambil Nilai yang besar | M27: POM | N27: 1.0939588e+11
C28: - Mewakili seluruh pengeluaran untuk beban operasional
M29: Sampel Dev | N29: =N26/N25*22 -> 9.9742032
M30: Sampel POM | N30: =N27/N25*22 -> 12.025797
A31: Notes | M31: Total Sampel | N31: =N29+N30 -> 22
A32: P | B32: : | C32: Population
A33: AF | B33: : | C33: Assurance Factor
A34: PM | B34: : | C34: Performance Materiality | M34: * untuk TOC ambil sampel konsumen Dev min 22 mewakili masing2 type dan progres penerimaan
A35: EE | B35: : | C35: Expected Error | M35: * untuk sales SW diambil dari sampel TOC
A36: EF | B36: : | C36: Expansion Factor
C40: Audit Response Decision Tree
C42: Risk Materiality Assessment | D42: Assurance from Tests of Controls | E42: Assurance from Analytical Procedures | F42: Tests of detail
F43: JSSD testing | G43: Sampling
G44: AF | H44: EF
C45: High | D45: No | E45: No | F45: N/A | G45: 3.0 | H45: 1.9
E46: Yes | F46: N/A | G46: 2.5 | H46: 1.6
D47: Yes | E47: No | F47: N/A | G47: 1.6 | H47: 1.5
E48: Yes | F48: 5 to 15 | G48: 1.0 | H48: 1.3
C49: Low | D49: No | E49: No | F49: N/A | G49: 1.8 | H49: 1.5
E50: Yes | F50: 0 to 10 | G50: N/A
D51: Yes | E51: No | F51: 4 to 10 | G51: N/A
E52: Yes | F52: N/A | G52: N/A

Sheet Pendapatan Lain-lain
A6: Client | B6: : | C6: ='OPEX '!C6 -> PT Indo Oil Perkasa Tbk | H6: Prepared By : | I6: KNW
A7: Closing Date | B7: : | C7: ='OPEX '!C7 -> 44500 | H7: Date: | I7: ='OPEX '!I7 -> 44518
A8: Matter | B8: : | C8: Pendapatan Lain-lain
A11: Menghitung Jumlah Samping INVENTORIES
L12: List of Sample
A13: Assurance Factor | B13: : | C13: 1.8 | L13: No | M13: COA | N13: Account | O13: Total Sampling | P13: Judgement
A14: Expansion Factor | B14: : | C14: 1.5 | L14: 1 | M14: PIC Judgement | P14: Biggest on Sales of Type
A15: Performance Materiality | B15: : | C15: ='OPEX '!C15 -> 4.6142586e+09 | L15: 2 | M15: PIC Judgement | P15: Biggest on Sales of Type
A16: Population (ARE) | B16: : | C16: 743697728 | L16: 3 | M16: PIC Judgement | P16: Biggest on Sales of Type
A17: Expected Error (EE) | B17: : | C17: 0.05 | L17: 4 | M17: PIC Judgement | P17: Biggest on Sales of Type
L18: 5 | M18: PIC Judgement | P18: Biggest on Sales of Type
A19: Sample Size | B19: : | C19: (Population being subject to sampling x Assurance Factor) ÷ (Performance Materiality - (Expected Error x Expansion Factor)) | M19: Jumlah | O19: =SUM(O14:O18) -> 0
C21: P x AF | E21: PM | F21: EE | G21: EF
A22: Sample Size | B22: : | C22: =C16*C13 -> 1.3386559e+09 | D22: ÷ | E22: =C15 -> 4.6142586e+09 | F22: =C17*C16 -> 37184886 | G22: =C14 -> 1.5
A24: Sample Size | B24: : | C24: =C22/(E22-(F22*G22)) -> 0.2936627 | D24: Angka Mutlak | F24: =F22*G22 -> 55777330 | G24: =E22-F24 -> 4.5584813e+09
M25: Populasi | N25: 2.0012888e+11
A26: Kesimpulan | B26: : | C26: Ambil Sampel dengan pertimbangan sebagai berikut : | M26: Developer | N26: 90733006173
C27: - Ambil Nilai yang besar | M27: POM | N27: 1.0939588e+11
C28: - Mewakili seluruh penerimaan atas pendapatan lain-lain
M29: Sampel Dev | N29: =N26/N25*22 -> 9.9742032
M30: Sampel POM | N30: =N27/N25*22 -> 12.025797
A31: Notes | M31: Total Sampel | N31: =N29+N30 -> 22
A32: P | B32: : | C32: Population
A33: AF | B33: : | C33: Assurance Factor
A34: PM | B34: : | C34: Performance Materiality | M34: * untuk TOC ambil sampel konsumen Dev min 22 mewakili masing2 type dan progres penerimaan
A35: EE | B35: : | C35: Expected Error | M35: * untuk sales SW diambil dari sampel TOC
A36: EF | B36: : | C36: Expansion Factor
C40: Audit Response Decision Tree
C42: Risk Materiality Assessment | D42: Assurance from Tests of Controls | E42: Assurance from Analytical Procedures | F42: Tests of detail
F43: JSSD testing | G43: Sampling
G44: AF | H44: EF
C45: High | D45: No | E45: No | F45: N/A | G45: 3.0 | H45: 1.9
E46: Yes | F46: N/A | G46: 2.5 | H46: 1.6
D47: Yes | E47: No | F47: N/A | G47: 1.6 | H47: 1.5
E48: Yes | F48: 5 to 15 | G48: 1.0 | H48: 1.3
C49: Low | D49: No | E49: No | F49: N/A | G49: 1.8 | H49: 1.5
E50: Yes | F50: 0 to 10 | G50: N/A
D51: Yes | E51: No | F51: 4 to 10 | G51: N/A
E52: Yes | F52: N/A | G52: N/A

Sheet Piutang Pendapatan
A6: Client | B6: : | C6: ='Pendapatan '!C6 -> PT Indo Oil Perkasa Tbk | H6: Prepared By : | I6: KNW
A7: Closing Date | B7: : | C7: ='Pendapatan '!C7 -> 44500 | H7: Date: | I7: ='Pendapatan Lain-lain'!I7 -> 44518
A8: Matter | B8: : | C8: Piutang Pendapatan
A11: Menghitung Jumlah Samping COGS
L12: List of Sample
A13: Assurance Factor | B13: : | C13: 1.8 | L13: No | M13: COA | N13: Account | O13: Total Sampling | P13: Judgement
A14: Expansion Factor | B14: : | C14: 1.5 | L14: 1 | M14: PIC Judgement | P14: Biggest on Sales of Type
A15: Performance Materiality | B15: : | C15: ='Pendapatan '!C15 -> 4.6142586e+09 | L15: 2 | M15: PIC Judgement | P15: Biggest on Sales of Type
A16: Population (ARE) | B16: : | C16: 2792643774 | L16: 3 | M16: PIC Judgement | P16: Biggest on Sales of Type
A17: Expected Error (EE) | B17: : | C17: 0.05 | L17: 4 | M17: PIC Judgement | P17: Biggest on Sales of Type
L18: 5 | M18: PIC Judgement | P18: Biggest on Sales of Type
A19: Sample Size | B19: : | C19: (Population being subject to sampling x Assurance Factor) ÷ (Performance Materiality - (Expected Error x Expansion Factor)) | M19: Jumlah | O19: =SUM(O14:O18) -> 0
C21: P x AF | E21: PM | F21: EE | G21: EF
A22: Sample Size | B22: : | C22: =C16*C13 -> 5.0267588e+09 | D22: ÷ | E22: =C15 -> 4.6142586e+09 | F22: =C17*C16 -> 1.3963219e+08 | G22: =C14 -> 1.5
A24: Sample Size | B24: : | C24: =C22/(E22-(F22*G22)) -> 1.1411976 | D24: Angka Mutlak | F24: =F22*G22 -> 2.0944828e+08 | G24: =E22-F24 -> 4.4048104e+09
M25: Populasi | N25: 2.0012888e+11
A26: Kesimpulan | B26: : | C26: Ambil Sampel dengan pertimbangan sebagai berikut : | M26: Developer | N26: 90733006173
C27: - Ambil Nilai yang besar | M27: POM | N27: 1.0939588e+11
C28: - Mewakili seluruh penerimaan untuk piutang pendapatan
M29: Sampel Dev | N29: =N26/N25*22 -> 9.9742032
M30: Sampel POM | N30: =N27/N25*22 -> 12.025797
A31: Notes | M31: Total Sampel | N31: =N29+N30 -> 22
A32: P | B32: : | C32: Population
A33: AF | B33: : | C33: Assurance Factor
A34: PM | B34: : | C34: Performance Materiality | M34: * untuk TOC ambil sampel konsumen Dev min 22 mewakili masing2 type dan progres penerimaan
A35: EE | B35: : | C35: Expected Error | M35: * untuk sales SW diambil dari sampel TOC
A36: EF | B36: : | C36: Expansion Factor
C40: Audit Response Decision Tree
C42: Risk Materiality Assessment | D42: Assurance from Tests of Controls | E42: Assurance from Analytical Procedures | F42: Tests of detail
F43: JSSD testing | G43: Sampling
G44: AF | H44: EF
C45: High | D45: No | E45: No | F45: N/A | G45: 3.0 | H45: 1.9
E46: Yes | F46: N/A | G46: 2.5 | H46: 1.6
D47: Yes | E47: No | F47: N/A | G47: 1.6 | H47: 1.5
E48: Yes | F48: 5 to 15 | G48: 1.0 | H48: 1.3
C49: Low | D49: No | E49: No | F49: N/A | G49: 1.8 | H49: 1.5
E50: Yes | F50: 0 to 10 | G50: N/A
D51: Yes | E51: No | F51: 4 to 10 | G51: N/A
E52: Yes | F52: N/A | G52: N/A

Sheet Biaya Pra Operasional 
A6: Client | B6: : | C6: ='Piutang Pendapatan'!C6 -> PT Indo Oil Perkasa Tbk | H6: Prepared By : | I6: KNW
A7: Closing Date | B7: : | C7: ='Piutang Pendapatan'!C7 -> 44500 | H7: Date: | I7: ='Piutang Pendapatan'!I7 -> 44518
A8: Matter | B8: : | C8: Biaya Pra Operasional
A11: Menghitung Jumlah Samping OPEX
L12: List of Sample
A13: Assurance Factor | B13: : | C13: 1.8 | L13: No | M13: COA | N13: Account | O13: Total Sampling | P13: Judgement
A14: Expansion Factor | B14: : | C14: 1.5 | L14: 1 | M14: PIC Judgement | P14: Biggest on Sales of Type
A15: Performance Materiality | B15: : | C15: ='Piutang Pendapatan'!C15 -> 4.6142586e+09 | L15: 2 | M15: PIC Judgement | P15: Biggest on Sales of Type
A16: Population (ARE) | B16: : | C16: 1065758328 | L16: 3 | M16: PIC Judgement | P16: Biggest on Sales of Type
A17: Expected Error (EE) | B17: : | C17: 0.05 | L17: 4 | M17: PIC Judgement | P17: Biggest on Sales of Type
L18: 5 | M18: PIC Judgement | P18: Biggest on Sales of Type
A19: Sample Size | B19: : | C19: (Population being subject to sampling x Assurance Factor) ÷ (Performance Materiality - (Expected Error x Expansion Factor)) | M19: Jumlah | O19: =SUM(O14:O18) -> 0
C21: P x AF | E21: PM | F21: EE | G21: EF
A22: Sample Size | B22: : | C22: =C16*C13 -> 1.918365e+09 | D22: ÷ | E22: =C15 -> 4.6142586e+09 | F22: =C17*C16 -> 53287916 | G22: =C14 -> 1.5
A24: Sample Size | B24: : | C24: =C22/(E22-(F22*G22)) -> 0.42307604 | D24: Angka Mutlak | F24: =F22*G22 -> 79931875 | G24: =E22-F24 -> 4.5343268e+09
M25: Populasi | N25: 2.0012888e+11
A26: Kesimpulan | B26: : | C26: Ambil Sampel dengan pertimbangan sebagai berikut : | M26: Developer | N26: 90733006173
C27: - Ambil Nilai yang besar | M27: POM | N27: 1.0939588e+11
C28: - Mewakili seluruh pengeluaran dan penambahan untuk biaya pra operasional
M29: Sampel Dev | N29: =N26/N25*22 -> 9.9742032
M30: Sampel POM | N30: =N27/N25*22 -> 12.025797
A31: Notes | M31: Total Sampel | N31: =N29+N30 -> 22
A32: P | B32: : | C32: Population
A33: AF | B33: : | C33: Assurance Factor
A34: PM | B34: : | C34: Performance Materiality | M34: * untuk TOC ambil sampel konsumen Dev min 22 mewakili masing2 type dan progres penerimaan
A35: EE | B35: : | C35: Expected Error | M35: * untuk sales SW diambil dari sampel TOC
A36: EF | B36: : | C36: Expansion Factor
C40: Audit Response Decision Tree
C42: Risk Materiality Assessment | D42: Assurance from Tests of Controls | E42: Assurance from Analytical Procedures | F42: Tests of detail
F43: JSSD testing | G43: Sampling
G44: AF | H44: EF
C45: High | D45: No | E45: No | F45: N/A | G45: 3.0 | H45: 1.9
E46: Yes | F46: N/A | G46: 2.5 | H46: 1.6
D47: Yes | E47: No | F47: N/A | G47: 1.6 | H47: 1.5
E48: Yes | F48: 5 to 15 | G48: 1.0 | H48: 1.3
C49: Low | D49: No | E49: No | F49: N/A | G49: 1.8 | H49: 1.5
E50: Yes | F50: 0 to 10 | G50: N/A
D51: Yes | E51: No | F51: 4 to 10 | G51: N/A
E52: Yes | F52: N/A | G52: N/A

Sheet Fixed asset
A6: Client | B6: : | C6: ='Piutang Pendapatan'!C6 -> PT Indo Oil Perkasa Tbk | H6: Prepared By : | I6: KNW
A7: Closing Date | B7: : | C7: ='Piutang Pendapatan'!C7 -> 44500 | H7: Date: | I7: 44268
A8: Matter | B8: : | C8: Fix Assets
A11: Menghitung Jumlah Samping Fixed assets
L12: List of Sample
A13: Assurance Factor | B13: : | C13: 1.8 | L13: No | M13: COA | N13: Account | O13: Total Sampling | P13: Judgement
A14: Expansion Factor | B14: : | C14: 1.5 | L14: 1 | M14: PIC Judgement | P14: Biggest on Sales of Type
A15: Performance Materiality | B15: : | C15: ='OPEX '!C15 -> 4.6142586e+09 | L15: 2 | M15: PIC Judgement | P15: Biggest on Sales of Type
A16: Population (ARE) | B16: : | C16: 15551398658 | L16: 3 | M16: PIC Judgement | P16: Biggest on Sales of Type
A17: Expected Error (EE) | B17: : | C17: 0.05 | L17: 4 | M17: PIC Judgement | P17: Biggest on Sales of Type
L18: 5 | M18: PIC Judgement | P18: Biggest on Sales of Type
A19: Sample Size | B19: : | C19: (Population being subject to sampling x Assurance Factor) ÷ (Performance Materiality - (Expected Error x Expansion Factor)) | M19: Jumlah | O19: =SUM(O14:O18) -> 0
C21: P x AF | E21: PM | F21: EE | G21: EF
A22: Sample Size | B22: : | C22: =C16*C13 -> 2.7992518e+10 | D22: ÷ | E22: =C15 -> 4.6142586e+09 | F22: =C17*C16 -> 7.7756993e+08 | G22: =C14 -> 1.5
A24: Sample Size | B24: : | C24: =C22/(E22-(F22*G22)) -> 8.1187062 | D24: Angka Mutlak | F24: =F22*G22 -> 1.1663549e+09 | G24: =E22-F24 -> 3.4479037e+09
M25: Populasi | N25: 2.0012888e+11
A26: Kesimpulan | B26: : | C26: Ambil 1 Sampel dengan pertimbangan sebagai berikut : | M26: Developer | N26: 90733006173
C27: - Ambil Nilai yang besar | M27: POM | N27: 1.0939588e+11
C28: - Mewakili seluruh penambahan atas aset tetap
M29: Sampel Dev | N29: =N26/N25*22 -> 9.9742032
M30: Sampel POM | N30: =N27/N25*22 -> 12.025797
A31: Notes | M31: Total Sampel | N31: =N29+N30 -> 22
A32: P | B32: : | C32: Population
A33: AF | B33: : | C33: Assurance Factor
A34: PM | B34: : | C34: Performance Materiality | M34: * untuk TOC ambil sampel konsumen Dev min 22 mewakili masing2 type dan progres penerimaan
A35: EE | B35: : | C35: Expected Error | M35: * untuk sales SW diambil dari sampel TOC
A36: EF | B36: : | C36: Expansion Factor
C40: Audit Response Decision Tree
C42: Risk Materiality Assessment | D42: Assurance from Tests of Controls | E42: Assurance from Analytical Procedures | F42: Tests of detail
F43: JSSD testing | G43: Sampling
G44: AF | H44: EF
C45: High | D45: No | E45: No | F45: N/A | G45: 3.0 | H45: 1.9
E46: Yes | F46: N/A | G46: 2.5 | H46: 1.6
D47: Yes | E47: No | F47: N/A | G47: 1.6 | H47: 1.5
E48: Yes | F48: 5 to 15 | G48: 1.0 | H48: 1.3
C49: Low | D49: No | E49: No | F49: N/A | G49: 1.8 | H49: 1.5
E50: Yes | F50: 0 to 10 | G50: N/A
D51: Yes | E51: No | F51: 4 to 10 | G51: N/A
E52: Yes | F52: N/A | G52: N/A

Sheet Utang lain-lain
A6: Client | B6: : | C6: ='Piutang Pendapatan'!C6 -> PT Indo Oil Perkasa Tbk | H6: Prepared By : | I6: KNW
A7: Closing Date | B7: : | C7: ='Piutang Pendapatan'!C7 -> 44500 | H7: Date: | I7: ='Biaya Pra Operasional '!I7 -> 44518
A8: Matter | B8: : | C8: Utang Lain-lain
A11: Menghitung Jumlah Samping Fixed assets
L12: List of Sample
A13: Assurance Factor | B13: : | C13: 1.8 | L13: No | M13: COA | N13: Account | O13: Total Sampling | P13: Judgement
A14: Expansion Factor | B14: : | C14: 1.5 | L14: 1 | M14: PIC Judgement | P14: Biggest on Sales of Type
A15: Performance Materiality | B15: : | C15: ='OPEX '!C15 -> 4.6142586e+09 | L15: 2 | M15: PIC Judgement | P15: Biggest on Sales of Type
A16: Population (ARE) | B16: : | C16: 2851627036 | L16: 3 | M16: PIC Judgement | P16: Biggest on Sales of Type
A17: Expected Error (EE) | B17: : | C17: 0.05 | L17: 4 | M17: PIC Judgement | P17: Biggest on Sales of Type
L18: 5 | M18: PIC Judgement | P18: Biggest on Sales of Type
A19: Sample Size | B19: : | C19: (Population being subject to sampling x Assurance Factor) ÷ (Performance Materiality - (Expected Error x Expansion Factor)) | M19: Jumlah | O19: =SUM(O14:O18) -> 0
C21: P x AF | E21: PM | F21: EE | G21: EF
A22: Sample Size | B22: : | C22: =C16*C13 -> 5.1329287e+09 | D22: ÷ | E22: =C15 -> 4.6142586e+09 | F22: =C17*C16 -> 1.4258135e+08 | G22: =C14 -> 1.5
A24: Sample Size | B24: : | C24: =C22/(E22-(F22*G22)) -> 1.1664722 | D24: Angka Mutlak | F24: =F22*G22 -> 2.1387203e+08 | G24: =E22-F24 -> 4.4003866e+09
M25: Populasi | N25: 2.0012888e+11
A26: Kesimpulan | B26: : | C26: Ambil Sampel dengan pertimbangan sebagai berikut : | M26: Developer | N26: 90733006173
C27: - Ambil Nilai yang besar | M27: POM | N27: 1.0939588e+11
C28: - Mewakili seluruh penambahan atas utang lain-lain
M29: Sampel Dev | N29: =N26/N25*22 -> 9.9742032
M30: Sampel POM | N30: =N27/N25*22 -> 12.025797
A31: Notes | M31: Total Sampel | N31: =N29+N30 -> 22
A32: P | B32: : | C32: Population
A33: AF | B33: : | C33: Assurance Factor
A34: PM | B34: : | C34: Performance Materiality | M34: * untuk TOC ambil sampel konsumen Dev min 22 mewakili masing2 type dan progres penerimaan
A35: EE | B35: : | C35: Expected Error | M35: * untuk sales SW diambil dari sampel TOC
A36: EF | B36: : | C36: Expansion Factor
C40: Audit Response Decision Tree
C42: Risk Materiality Assessment | D42: Assurance from Tests of Controls | E42: Assurance from Analytical Procedures | F42: Tests of detail
F43: JSSD testing | G43: Sampling
G44: AF | H44: EF
C45: High | D45: No | E45: No | F45: N/A | G45: 3.0 | H45: 1.9
E46: Yes | F46: N/A | G46: 2.5 | H46: 1.6
D47: Yes | E47: No | F47: N/A | G47: 1.6 | H47: 1.5
E48: Yes | F48: 5 to 15 | G48: 1.0 | H48: 1.3
C49: Low | D49: No | E49: No | F49: N/A | G49: 1.8 | H49: 1.5
E50: Yes | F50: 0 to 10 | G50: N/A
D51: Yes | E51: No | F51: 4 to 10 | G51: N/A
E52: Yes | F52: N/A | G52: N/A

Sheet Unearned Revenue
A6: Client | B6: : | C6: ='Piutang Pendapatan'!C6 -> PT Indo Oil Perkasa Tbk | H6: Prepared By : | I6: KNW
A7: Closing Date | B7: : | C7: ='Piutang Pendapatan'!C7 -> 44500 | H7: Date: | I7: 44268
A8: Matter | B8: : | C8: Pendapatan diterima dimuka
A11: Menghitung Jumlah Samping Fixed assets
L12: List of Sample
A13: Assurance Factor | B13: : | C13: 1.8 | L13: No | M13: COA | N13: Account | O13: Total Sampling | P13: Judgement
A14: Expansion Factor | B14: : | C14: 1.5 | L14: 1 | M14: PIC Judgement | P14: Biggest on Sales of Type
A15: Performance Materiality | B15: : | C15: ='OPEX '!C15 -> 4.6142586e+09 | L15: 2 | M15: PIC Judgement | P15: Biggest on Sales of Type
