Workbook
Name _\b: #N/A
Name _\g: #N/A
Name _\n: #N/A
Name __\b: #N/A
Name __\g: #N/A
Name __\n: #N/A
Name ___\a: #REF!
Name ___\a: #REF!
Name ___\a: #REF!
Name ___\a: #REF!
Name ___\a: #REF!
Name ___\a: #REF!
Name ______\a: #REF!
Name ______\a: #REF!
Name ______\a: #REF!
Name ______\a: #REF!
Name ______\a: #REF!
Name ______\a: #REF!
Name ____DAT1: #REF!
Name ____DAT1: #REF!
Name ____DAT1: #REF!
Name ____DAT1: #REF!
Name ____DAT1: #REF!
Name ____DAT10: #REF!
Name ____DAT11: #REF!
Name ____DAT12: #REF!
Name ____DAT13: #REF!
Name ____DAT14: #REF!
Name ____DAT15: #REF!
Name ____DAT16: #REF!
Name ____DAT17: #REF!
Name ____DAT18: #REF!
Name ____DAT19: #REF!
Name ____DAT2: #REF!
Name ____DAT20: #REF!
Name ____DAT3: #REF!
Name ____DAT4: #REF!
Name ____DAT5: #REF!
Name ____DAT6: #REF!
Name ____DAT7: #REF!
Name ____DAT8: #REF!
Name ____DAT9: #REF!
Name ___RSE2: '[1]CMA Addition'!$H$139
Name ___TGL1: #REF!
Name ___TGL2: #REF!
Name __COA08: [5]coa!$E$6:$E$944
Name __DAT1: #REF!
Name __DAT10: #REF!
Name __DAT11: #REF!
Name __DAT12: #REF!
Name __DAT13: #REF!
Name __DAT14: #REF!
Name __DAT15: #REF!
Name __DAT16: #REF!
Name __DAT17: #REF!
Name __DAT18: #REF!
Name __DAT19: #REF!
Name __DAT2: #REF!
Name __DAT20: #REF!
Name __DAT3: #REF!

Sheet KONSOL
A2: Aging Utang Usaha Konsol
D3: 45627 | F3: 45536 | H3: 45444 | J3: 2023 | L3: 2022 | N3: 2021 | P3: 2020
B5: Lancar | D5: ='Summary ISP'!D5+'Summay IAS'!E6 -> 2.9436997e+09 | F5: ='Summary ISP'!F5+'Summay IAS'!G6 -> 7.7670721e+09 | H5: ='Summay IAS'!I6+'Summary ISP'!H5 -> 8.1227284e+09 | J5: ='Hutang Usaha IAS 23'!M164+'Hutang Usaha ISP 2023'!M225 -> 1.1409263e+10 | L5: ='Summary ISP'!L5+'Summay IAS'!M6 -> 21343364113 | N5: ='Summary ISP'!N5+'Summay IAS'!O6 -> 1.6067701e+10 | P5: ='Summary ISP'!P5+'Summay IAS'!Q6 -> 13648880412
B6: 1-30 Hari | D6: ='Summary ISP'!D6+'Summay IAS'!E7 -> 2.2807174e+09 | F6: ='Summary ISP'!F6+'Summay IAS'!G7 -> 2.4155684e+09 | H6: ='Summay IAS'!I7+'Summary ISP'!H6 -> 4.0359602e+09 | J6: ='Hutang Usaha IAS 23'!N164+'Hutang Usaha ISP 2023'!N225 -> 2.1948297e+09 | L6: ='Summary ISP'!L6+'Summay IAS'!M7 -> 3600153738 | N6: ='Summary ISP'!N6+'Summay IAS'!O7 -> 9.536016e+09 | P6: ='Summary ISP'!P6+'Summay IAS'!Q7 -> 2376774695
B7: 31-60 Hari | D7: ='Summary ISP'!D7+'Summay IAS'!E8 -> 1073353781 | F7: ='Summary ISP'!F7+'Summay IAS'!G8 -> 198335036 | H7: ='Summay IAS'!I8+'Summary ISP'!H7 -> 682156919 | J7: ='Hutang Usaha IAS 23'!O164+'Hutang Usaha ISP 2023'!O225 -> 835729636 | L7: ='Summary ISP'!L7+'Summay IAS'!M8 -> 1960441734 | N7: ='Summary ISP'!N7+'Summay IAS'!O8 -> 1066105902 | P7: ='Summary ISP'!P7+'Summay IAS'!Q8 -> 1327345930
B8: 61-90 Hari | D8: ='Summary ISP'!D8+'Summay IAS'!E9 -> 92483018 | F8: ='Summary ISP'!F8+'Summay IAS'!G9 -> 90386309 | H8: ='Summay IAS'!I9+'Summary ISP'!H8 -> 140700000 | J8: ='Hutang Usaha IAS 23'!P164+'Hutang Usaha ISP 2023'!P225 -> 625732392 | L8: ='Summary ISP'!L8+'Summay IAS'!M9 -> 1335608520 | N8: ='Summary ISP'!N8+'Summay IAS'!O9 -> 1161585758 | P8: ='Summary ISP'!P8+'Summay IAS'!Q9 -> 641088591 | R8: Utang Pph 28 A (IAS)
B9: > 90 Hari | D9: ='Summary ISP'!D9+'Summay IAS'!E10 -> 222607955 | F9: ='Summary ISP'!F9+'Summay IAS'!G10 -> 1.7373273e+08 | H9: ='Summay IAS'!I10+'Summary ISP'!H9 -> 1.2047462e+09 | J9: ='Hutang Usaha IAS 23'!Q164+'Hutang Usaha ISP 2023'!Q225+R9 -> 5.342346e+09 | L9: ='Summary ISP'!L9+'Summay IAS'!M10 -> 1524723595 | N9: ='Summary ISP'!N9+'Summay IAS'!O10 -> 7.8155146e+08 | P9: ='Summary ISP'!P9+'Summay IAS'!Q10 -> 143873935 | R9: 451584604
D11: =SUM(D5:D9) -> 6.6128619e+09 | F11: =SUM(F5:F9) -> 1.0645095e+10 | H11: =SUM(H5:H9) -> 1.4186292e+10 | J11: =SUM(J5:J9) -> 2.0407901e+10 | L11: =SUM(L5:L9) -> 29764291700 | N11: =SUM(N5:N9) -> 2.861296e+10 | P11: =SUM(P5:P9) -> 18137963563
F12: 10645094570 | J12: 19956316532
D13: =D11-D12 -> 6.6128619e+09 | F13: =F11-F12 -> -0.16999817 | J13: =J12-J11 -> -4.515846e+08
A15: Aging Piutang Usaha Konsol
D16: =D3 -> 45627 | F16: =F3 -> 45536 | H16: =H3 -> 45444 | J16: 2023 | L16: 2022 | N16: 2021 | P16: 2020
B18: Lancar | D18: ='Summary ISP'!D18+'Summay IAS'!E18 -> 9.2392365e+10 | F18: ='Summary ISP'!F18+'Summay IAS'!G18 -> 3.9695394e+10 | H18: ='Summay IAS'!I18+'Summary ISP'!H18 -> 2.6009582e+10 | J18: ='Piutang IAS 2023'!N27+'Piutang Usaha ISP 2023'!N19 -> 2.141207e+10 | L18: ='Summary ISP'!L18+'Summay IAS'!M18 -> 1.7814611e+10 | N18: ='Summary ISP'!N18+'Summay IAS'!O18 -> 1.8022331e+10 | P18: ='Summary ISP'!P18+'Summay IAS'!Q18 -> 1.2963143e+10
B19: 1-30 Hari | D19: ='Summary ISP'!D19+'Summay IAS'!E19 -> 57064075 | F19: ='Summary ISP'!F19+'Summay IAS'!G19 -> 63909662 | H19: ='Summay IAS'!I19+'Summary ISP'!H19 -> 210888877 | J19: ='Piutang IAS 2023'!O27+'Piutang Usaha ISP 2023'!O19 -> 1.3132425e+08 | L19: ='Summary ISP'!L19+'Summay IAS'!M19 -> 7808151396 | N19: ='Summary ISP'!N19+'Summay IAS'!O19 -> 9038288773 | P19: ='Summary ISP'!P19+'Summay IAS'!Q19 -> 3445391093
B20: 31-60 Hari | D20: ='Summary ISP'!D20+'Summay IAS'!E20 -> 0 | F20: ='Summary ISP'!F20+'Summay IAS'!G20 -> 0 | H20: ='Summay IAS'!I20+'Summary ISP'!H20 -> 42280500 | J20: ='Piutang IAS 2023'!P27+'Piutang Usaha ISP 2023'!P19 -> 0 | L20: ='Summary ISP'!L20+'Summay IAS'!M20 -> 24721078650 | N20: ='Summary ISP'!N20+'Summay IAS'!O20 -> 9104769380 | P20: ='Summary ISP'!P20+'Summay IAS'!Q20 -> 19885079001
B21: 61-90 Hari | D21: ='Summary ISP'!D21+'Summay IAS'!E21 -> 37592200 | F21: ='Summary ISP'!F21+'Summay IAS'!G21 -> 0 | H21: ='Summay IAS'!I21+'Summary ISP'!H21 -> 1.7000768e+08 | J21: ='Piutang IAS 2023'!Q27+'Piutang Usaha ISP 2023'!Q19 -> 0 | L21: ='Summary ISP'!L21+'Summay IAS'!M21 -> 6313862115 | N21: ='Summary ISP'!N21+'Summay IAS'!O21 -> 14206236599 | P21: ='Summary ISP'!P21+'Summay IAS'!Q21 -> 378957063
B22: > 90 Hari | D22: ='Summary ISP'!D22+'Summay IAS'!E22 -> 305037330 | F22: ='Summary ISP'!F22+'Summay IAS'!G22 -> 0 | H22: ='Summay IAS'!I22+'Summary ISP'!H22 -> 1751895969 | J22: ='Piutang Usaha ISP 2023'!R19+'Piutang IAS 2023'!R27 -> 211054410 | L22: ='Summary ISP'!L22+'Summay IAS'!M22 -> 23799994791 | N22: ='Summary ISP'!N22+'Summay IAS'!O22 -> 11603897335 | P22: ='Summary ISP'!P22+'Summay IAS'!Q22 -> 6.5116783e+09
D24: =SUM(D18:D22) -> 9.2792058e+10 | F24: =SUM(F18:F22) -> 3.9759303e+10 | H24: =SUM(H18:H22) -> 2.8184655e+10 | J24: =SUM(J18:J22) -> 2.1754448e+10 | L24: =SUM(L18:L22) -> 8.0457698e+10 | N24: =SUM(N18:N22) -> 6.1975523e+10 | P24: =SUM(P18:P22) -> 43184248010
B25: WBS | F25: 39419408952 | H25: 27762015495 | J25: =21754550980-102746 -> 21754448234
B26: CV Kanian | D26: =D24-D25 -> 9.2792058e+10 | F26: =F24-F25 -> 3.3989448e+08 | H26: =H24-H25 -> 4.2263968e+08 | J26: =J24-J25 -> -0.84999466

Sheet Summary ISP
A2: Aging Utang Usaha
D3: 45627 | F3: 45536 | H3: 45444 | J3: 2023 | L3: 2022 | N3: 2021 | P3: 2020
B5: Lancar | D5: ='Hutang ISP Des 24'!H4 -> 8.8174967e+08 | F5: ='Hutang Usaha ISP Sept 2024'!H$4 -> 4.9834664e+09 | H5: ='Hutang Usaha ISP Juni 2024'!H228 -> 4.5823272e+09 | J5: ='Hutang Usaha ISP 2023'!H279 -> 8.7971075e+09 | L5: ='Hutang Usaha ISP 2022'!H309 -> 18791185975 | N5: ='Hutang Usaha ISP 2021'!H366 -> 1.3487582e+10 | P5: ='Utang Usaha ISP 2020'!K552 -> 7552183808
B6: 1-30 Hari | D6: ='Hutang ISP Des 24'!I4 -> 5.2566013e+08 | F6: ='Hutang Usaha ISP Sept 2024'!I$4 -> 1982303832 | H6: ='Hutang Usaha ISP Juni 2024'!I228 -> 1381916011 | J6: ='Hutang Usaha ISP 2023'!I279 -> 1.3501358e+09 | L6: ='Hutang Usaha ISP 2022'!I309 -> 1424588796 | N6: ='Hutang Usaha ISP 2021'!I366 -> 4.4328274e+09 | P6: ='Utang Usaha ISP 2020'!L552 -> 1169547930
B7: 31-60 Hari | D7: ='Hutang ISP Des 24'!J4 -> 623745086 | F7: ='Hutang Usaha ISP Sept 2024'!J$4 -> 184180750 | H7: ='Hutang Usaha ISP Juni 2024'!J228 -> 147745253 | J7: ='Hutang Usaha ISP 2023'!J279 -> 1.4036498e+09 | L7: ='Hutang Usaha ISP 2022'!J309 -> 392915468 | N7: ='Hutang Usaha ISP 2021'!J366 -> 714613618 | P7: ='Utang Usaha ISP 2020'!M552 -> 265263198
B8: 61-90 Hari | D8: ='Hutang ISP Des 24'!K4 -> 69093320 | F8: ='Hutang Usaha ISP Sept 2024'!K$4 -> 82354849 | H8: ='Hutang Usaha ISP Juni 2024'!K228 -> 140700000 | J8: ='Hutang Usaha ISP 2023'!K279 -> 81175580 | L8: ='Hutang Usaha ISP 2022'!K309 -> 1110656008 | N8: ='Hutang Usaha ISP 2021'!K366 -> 707307780 | P8: ='Utang Usaha ISP 2020'!N552 -> 75373754
B9: > 90 Hari | D9: ='Hutang ISP Des 24'!L4 -> 220877955 | F9: ='Hutang Usaha ISP Sept 2024'!L$4-2.49000072479248 -> 1.5486446e+08 | H9: ='Hutang Usaha ISP Juni 2024'!L228+1.80000019073486 -> 5.5688433e+08 | J9: ='Hutang Usaha ISP 2023'!L279 -> 4.8263521e+09 | L9: ='Hutang Usaha ISP 2022'!L309 -> 1299771083 | N9: ='Hutang Usaha ISP 2021'!L366 -> 4.2055298e+08 | P9: ='Utang Usaha ISP 2020'!O552+52 -> 143873935
D11: =SUM(D5:D9) -> 2.3211262e+09 | F11: =SUM(F5:F9) -> 7387170280 | H11: =SUM(H5:H9) -> 6809572845 | J11: =SUM(J5:J9) -> 1.6458421e+10 | L11: =SUM(L5:L9) -> 23019117330 | N11: =SUM(N5:N9) -> 1.9762883e+10 | P11: =SUM(P5:P9) -> 9206242625
A12: Ctrl WBS | F12: 7387170280 | H12: 6809572845 | J12: =16458420785.62-J11 -> 0 | L12: =23019876420-L11-759090 -> 0 | N12: =19763642459-N11-759090 -> 0.36000061 | P12: =9206242625-P11 -> 0
D13: =D11-D12 -> 2.3211262e+09 | F13: =F11-F12 -> 0 | H13: =H11-H12 -> 0
A15: Aging Piutang Usaha
D16: =D3 -> 45627 | F16: 45536 | H16: 45444 | J16: 2023 | L16: 2022 | N16: 2021 | P16: 2020
B18: Lancar | D18: ='Piutang ISP Des 24'!H4 -> 4.8098656e+10 | F18: ='Piutang ISP Sept 24'!H4 -> 1.5860138e+10 | H18: ='Piutang ISP Juni 24'!H38 -> 1.5075406e+10 | J18: ='Piutang Usaha ISP 2023'!H22 -> 6.3984403e+10 | L18: ='Piutang Usaha 2022'!H59 -> 1.7814611e+10 | N18: ='Piutang Usaha 2021'!H58 -> 1.8022331e+10 | P18: ='Piutang Usaha ISP 2020'!H101 -> 1.2963143e+10
B19: 1-30 Hari | D19: ='Piutang ISP Des 24'!I4 -> 28450775 | F19: ='Piutang ISP Sept 24'!I4-0.239997863769531 -> 28090775 | H19: ='Piutang ISP Juni 24'!I38 -> 22200777 | J19: ='Piutang Usaha ISP 2023'!I22 -> 1.2542766e+09 | L19: ='Piutang Usaha 2022'!I59 -> 1884240300 | N19: ='Piutang Usaha 2021'!I58 -> 222013407 | P19: ='Piutang Usaha ISP 2020'!I101 -> 656469141
B20: 31-60 Hari | D20: ='Piutang ISP Des 24'!J4 -> 0 | H20: ='Piutang ISP Juni 24'!J38 -> 11760000 | J20: ='Piutang Usaha ISP 2023'!J22 -> 0 | L20: ='Piutang Usaha 2022'!J59 -> 0 | N20: ='Piutang Usaha 2021'!J58 -> 232475433 | P20: ='Piutang Usaha ISP 2020'!J101 -> 0
B21: 61-90 Hari | D21: ='Piutang ISP Des 24'!K4 -> 12560000 | H21: ='Piutang ISP Juni 24'!K38 -> 0 | J21: ='Piutang Usaha ISP 2023'!K22 -> 1.5016481e+09 | L21: ='Piutang Usaha 2022'!K59 -> 0 | N21: ='Piutang Usaha 2021'!K58 -> 0 | P21: ='Piutang Usaha ISP 2020'!K101 -> 0
B22: > 90 Hari | D22: ='Piutang ISP Des 24'!L4 -> 0 | H22: ='Piutang ISP Juni 24'!L38 -> 1751895969 | J22: ='Piutang Usaha ISP 2023'!L22 -> 3.5018697e+09 | L22: ='Piutang Usaha 2022'!L59 -> 9061414092 | N22: ='Piutang Usaha 2021'!L58 -> 6510500000 | P22: ='Piutang Usaha ISP 2020'!L101-5.08 -> 6.5116783e+09
D24: =SUM(D18:D22) -> 4.8139666e+10 | F24: =SUM(F18:F22) -> 1.5888229e+10 | H24: =SUM(H18:H22) -> 1.6861263e+10 | J24: =SUM(J18:J22) -> 7.0242197e+10 | L24: =SUM(L18:L22) -> 2.8760266e+10 | N24: =SUM(N18:N22) -> 2.4987319e+10 | P24: =SUM(P18:P22) -> 20131289994
F25: 1.5888229e+10
A26: Ctrl WBS | D26: =D24-D25 -> 4.8139666e+10 | F26: =F24-F25 -> 0 | J26: =70242197387-J24 -> -1.2800446 | L26: =28760265833.56-L24 -> 0 | N26: =24987319485.2-N24 -> 0 | P26: =20131289994 -P24 -> 0

Sheet Summay IAS
B3: Aging Utang Usaha
E4: 45627 | G4: 45536 | I4: 45444 | K4: 2023 | M4: 2022 | O4: 2021 | Q4: 2020
C6: Lancar | E6: ='Hutang IAS Des 24'!H4 -> 2061950055 | G6: ='Hutang IAS Sept 24'!H4 -> 2.7836057e+09 | I6: ='Hutang Usaha IAS Juni 24'!H126 -> 3.5404012e+09 | K6: ='Hutang Usaha IAS 23'!H228 -> 6.2904413e+10 | M6: 2552178138 | O6: 2580119628 | Q6: 6096696604
C7: 1-30 Hari | E7: ='Hutang IAS Des 24'!I4 -> 1.7550573e+09 | G7: ='Hutang IAS Sept 24'!I$4 -> 4.332646e+08 | I7: ='Hutang Usaha IAS Juni 24'!I126 -> 2.6540442e+09 | K7: ='Hutang Usaha IAS 23'!I228 -> 2.5693704e+09 | M7: 2175564942 | O7: 5103188666 | Q7: 1207226765
C8: 31-60 Hari | E8: ='Hutang IAS Des 24'!J4 -> 449608695 | G8: ='Hutang IAS Sept 24'!J$4 -> 14154286 | I8: ='Hutang Usaha IAS Juni 24'!J126 -> 534411666 | K8: ='Hutang Usaha IAS 23'!J228 -> 756696191 | M8: 1567526266 | O8: 351492284 | Q8: 1062082732
C9: 61-90 Hari | E9: ='Hutang IAS Des 24'!K4 -> 23389698 | G9: ='Hutang IAS Sept 24'!K$4 -> 8031460 | I9: ='Hutang Usaha IAS Juni 24'!K126 -> 0 | K9: ='Hutang Usaha IAS 23'!K228 -> 2.0462049e+09 | M9: 224952512 | O9: 454277978 | Q9: 565714837
C10: > 90 Hari | E10: ='Hutang IAS Des 24'!L4 -> 1730000 | G10: ='Hutang IAS Sept 24'!L$4+0.100000381469727 -> 18868270 | I10: ='Hutang Usaha IAS Juni 24'!L126 -> 647861889 | K10: ='Hutang Usaha IAS 23'!L228 -> 5.8189221e+09 | M10: 224952512 | O10: 360998482 | Q10: 0
E12: =SUM(E6:E10) -> 4.2917358e+09 | G12: =SUM(G6:G10) -> 3.2579243e+09 | I12: =SUM(I6:I10) -> 7.3767189e+09 | K12: =SUM(K6:K10) -> 7.4095606e+10 | M12: =SUM(M6:M10) -> 6745174370 | O12: =SUM(O6:O10) -> 8850077038 | Q12: =SUM(Q6:Q10) -> 8931720938
G13: =3257924291-1 -> 3257924290
E14: =E12-E13 -> 4.2917358e+09 | G14: =G12-G13 -> -0.17000008
B15: Aging Piutang Usaha
E16: =E4 -> 45627 | G16: 45536 | I16: 45444 | K16: 2023 | M16: 2022 | O16: 2021 | Q16: 2020
C18: Lancar | E18: ='Piutang IAS Des 24'!H4 -> 4.4293709e+10 | G18: ='Piutang IAS Sept 24'!H4+0.5 -> 23835255708 | I18: ='Piutang IAS Juni 24'!H47 -> 10934175830 | K18: ='Piutang IAS 2023'!H80 -> 1.7719923e+10 | M18: 0 | O18: 0 | Q18: ='Piutang Usaha ISP 2020'!I102 -> 0
C19: 1-30 Hari | E19: ='Piutang IAS Des 24'!I4 -> 28613300 | G19: ='Piutang IAS Sept 24'!I4 -> 35818887 | I19: ='Piutang IAS Juni 24'!I47 -> 188688100 | K19: ='Piutang IAS 2023'!I80 -> 6.0172413e+08 | M19: 5923911096 | O19: 8816275366 | Q19: 2788921952
C20: 31-60 Hari | E20: ='Piutang IAS Des 24'!J4 -> 0 | G20: ='Piutang IAS Sept 24'!J4 -> 0 | I20: ='Piutang IAS Juni 24'!J47 -> 30520500 | K20: ='Piutang IAS 2023'!J80 -> 1.3246163e+09 | M20: 24721078650 | O20: 8872293947 | Q20: 19885079001
C21: 61-90 Hari | E21: ='Piutang IAS Des 24'!K4 -> 25032200 | G21: ='Piutang IAS Sept 24'!K4 -> 0 | I21: ='Piutang IAS Juni 24'!K47 -> 1.7000768e+08 | K21: ='Piutang IAS 2023'!K80 -> 0 | M21: 6313862115 | O21: 14206236599 | Q21: 378957063
C22: > 90 Hari | E22: ='Piutang IAS Des 24'!L4 -> 305037330 | G22: ='Piutang IAS Sept 24'!L4 -> 0 | I22: ='Piutang IAS Juni 24'!L47 -> 0 | K22: ='Piutang IAS 2023'!L80 -> 2.4636975e+09 | M22: 14738580699 | O22: 5093397335 | Q22: 0
E24: =SUM(E18:E22) -> 4.4652392e+10 | G24: =SUM(G18:G22) -> 23871074595 | I24: =SUM(I18:I22) -> 1.1323392e+10 | K24: =SUM(K18:K22) -> 2.2109961e+10 | M24: =SUM(M18:M22) -> 51697432560 | O24: =SUM(O18:O22) -> 36988203247 | Q24: =SUM(Q18:Q22) -> 23052958016
G25: 23871074595 | I25: 11323392105
E26: =E24-E25 -> 4.4652392e+10 | G26: =G24-G25 -> 0 | I26: =I24-I25 -> 0.42000008

Sheet Hutang IAS Des 24
A1: Aging Hutang Usaha & Subsequent | B1: =SUM(B3:B4)-B2 -> 0
A2: PT Indo American Seafoods | B2: 4.2917358e+09 | C2: WBS
A3: 45657
B4: =SUBTOTAL(9,B6:B105) -> 4.2917358e+09 | H4: =SUBTOTAL(9,H6:H105) -> 2061950055 | I4: =SUBTOTAL(9,I6:I105) -> 1.7550573e+09 | J4: =SUBTOTAL(9,J6:J105) -> 449608695 | K4: =SUBTOTAL(9,K6:K105) -> 23389698 | L4: =SUBTOTAL(9,L6:L105) -> 1730000 | M4: =SUM(H4:L4)-B4 -> 0
A5: Nama | B5: Nominal | C5: No Invoice | D5: Tgl Invoice | E5: Jatuh Tempo | F5: Tgl Jatuh Tempo | G5: Aging | H5: Lancar | I5: 1-30 Hari | J5: 31-60 Hari | K5: 61-90 Hari | L5: >90 Hari
A6: PT Anesta Agung | B6: 284103154 | C6: 1048 | D6: 45649 | E6: 30 | F6: =D6+E6 -> 45679 | G6: =$A$3-F6 -> -22 | H6: =B6 -> 284103154
A7: PT Anesta Agung | B7: 210298296 | C7: 1057 | D7: 45650 | E7: 30 | F7: =D7+E7 -> 45680 | G7: =$A$3-F7 -> -23 | H7: =B7 -> 210298296
A9: PT Konverta Mitra Abadi | B9: 15717156 | C9: 704 | D9: 45572 | E9: 30 | F9: =D9+E9 -> 45602 | G9: =$A$3-F9 -> 55 | J9: =B9 -> 15717156
A10: PT Konverta Mitra Abadi | B10: 84992700 | C10: 719 | D10: 45577 | E10: 30 | F10: =D10+E10 -> 45607 | G10: =$A$3-F10 -> 50 | J10: =B10 -> 84992700
A11: PT Konverta Mitra Abadi | B11: =1403317+12 -> 1403329 | C11: 738 | D11: 45582 | E11: 30 | F11: =D11+E11 -> 45612 | G11: =$A$3-F11 -> 45 | J11: =B11 -> 1403329
A12: PT Konverta Mitra Abadi | B12: 29592600 | C12: 739 | D12: 45582 | E12: 30 | F12: =D12+E12 -> 45612 | G12: =$A$3-F12 -> 45 | J12: =B12 -> 29592600
A13: PT Konverta Mitra Abadi | B13: 48518100 | C13: 743 | D13: 45584 | E13: 30 | F13: =D13+E13 -> 45614 | G13: =$A$3-F13 -> 43 | J13: =B13 -> 48518100
A14: PT Konverta Mitra Abadi | B14: 2752800 | C14: 744 | D14: 45584 | E14: 30 | F14: =D14+E14 -> 45614 | G14: =$A$3-F14 -> 43 | J14: =B14 -> 2752800
A15: PT Konverta Mitra Abadi | B15: 4129200 | C15: 747 | D15: 45586 | E15: 30 | F15: =D15+E15 -> 45616 | G15: =$A$3-F15 -> 41 | J15: =B15 -> 4129200
A16: PT Konverta Mitra Abadi | B16: 1455432 | C16: 748 | D16: 45586 | E16: 30 | F16: =D16+E16 -> 45616 | G16: =$A$3-F16 -> 41 | J16: =B16 -> 1455432
A17: PT Konverta Mitra Abadi | B17: 46825905 | C17: 760 | D17: 45588 | E17: 30 | F17: =D17+E17 -> 45618 | G17: =$A$3-F17 -> 39 | J17: =B17 -> 46825905
A18: PT Konverta Mitra Abadi | B18: 13382604 | C18: 866 | D18: 45621 | E18: 30 | F18: =D18+E18 -> 45651 | G18: =$A$3-F18 -> 6 | I18: =B18 -> 13382604
A19: PT Konverta Mitra Abadi | B19: 5017477 | C19: 867 | D19: 45621 | E19: 30 | F19: =D19+E19 -> 45651 | G19: =$A$3-F19 -> 6 | I19: =B19 -> 5017477
A20: PT Konverta Mitra Abadi | B20: 8559432 | C20: 868 | D20: 45621 | E20: 30 | F20: =D20+E20 -> 45651 | G20: =$A$3-F20 -> 6 | I20: =B20 -> 8559432
A21: PT Konverta Mitra Abadi | B21: 5839809.9 | C21: 869 | D21: 45621 | E21: 30 | F21: =D21+E21 -> 45651 | G21: =$A$3-F21 -> 6 | I21: =B21 -> 5839809.9
A22: PT Konverta Mitra Abadi | B22: 4856250 | C22: 870 | D22: 45621 | E22: 30 | F22: =D22+E22 -> 45651 | G22: =$A$3-F22 -> 6 | I22: =B22 -> 4856250
A23: PT Konverta Mitra Abadi | B23: 4944184 | C23: 871 | D23: 45621 | E23: 30 | F23: =D23+E23 -> 45651 | G23: =$A$3-F23 -> 6 | I23: =B23 -> 4944184
A24: PT Konverta Mitra Abadi | B24: 2593670 | C24: 895 | D24: 45631 | E24: 30 | F24: =D24+E24 -> 45661 | G24: =$A$3-F24 -> -4 | H24: =B24 -> 2593670
A25: PT Konverta Mitra Abadi | B25: 47416980 | C25: 939 | D25: 45655 | E25: 30 | F25: =D25+E25 -> 45685 | G25: =$A$3-F25 -> -28 | H25: =B25 -> 47416980
A26: PT Konverta Mitra Abadi | B26: 5011650 | C26: 940 | D26: 45655 | E26: 30 | F26: =D26+E26 -> 45685 | G26: =$A$3-F26 -> -28 | H26: =B26 -> 5011650
A27: PT Konverta Mitra Abadi | B27: 5137524 | C27: 941 | D27: 45655 | E27: 30 | F27: =D27+E27 -> 45685 | G27: =$A$3-F27 -> -28 | H27: =B27 -> 5137524
A29: PT Sumber Energy | B29: 31635000 | C29: 819 | D29: 45598 | E29: 30 | F29: =D29+E29 -> 45628 | G29: =$A$3-F29 -> 29 | I29: =B29 -> 31635000
A31: PT Indonesia Makan Udang | B31: 263573280 | C31: 991 | D31: 45644 | E31: 30 | F31: =D31+E31 -> 45674 | G31: =$A$3-F31 -> -17 | H31: =B31 -> 263573280
A32: PT Indonesia Makan Udang | B32: 195716165 | C32: 990 | D32: 45644 | E32: 30 | F32: =D32+E32 -> 45674 | G32: =$A$3-F32 -> -17 | H32: =B32 -> 195716165
A33: PT Indonesia Makan Udang | B33: 258146422 | C33: 989 | D33: 45644 | E33: 30 | F33: =D33+E33 -> 45674 | G33: =$A$3-F33 -> -17 | H33: =B33 -> 258146422
A34: PT Indonesia Makan Udang | B34: 97381200 | C34: 948 | D34: 45619 | E34: 30 | F34: =D34+E34 -> 45649 | G34: =$A$3-F34 -> 8 | I34: =B34 -> 97381200
A35: PT Indonesia Makan Udang | B35: 133422750 | C35: 943 | D35: 45618 | E35: 30 | F35: =D35+E35 -> 45648 | G35: =$A$3-F35 -> 9 | I35: =B35 -> 133422750
A36: PT Indonesia Makan Udang | B36: 259527644 | C36: 897 | D36: 45608 | E36: 30 | F36: =D36+E36 -> 45638 | G36: =$A$3-F36 -> 19 | I36: =B36 -> 259527644
A37: PT Indonesia Makan Udang | B37: 369633462 | C37: 851 | D37: 45598 | E37: 30 | F37: =D37+E37 -> 45628 | G37: =$A$3-F37 -> 29 | I37: =B37 -> 369633462
A38: PT Indonesia Makan Udang | B38: 289827482 | C38: 847 | D38: 45597 | E38: 30 | F38: =D38+E38 -> 45627 | G38: =$A$3-F38 -> 30 | I38: =B38 -> 289827482
A39: PT Indonesia Makan Udang | B39: 69901783 | C39: 813 | D39: 45591 | E39: 30 | F39: =D39+E39 -> 45621 | G39: =$A$3-F39 -> 36 | J39: =B39 -> 69901783
A40: PT Indonesia Makan Udang | B40: 132927190 | C40: 805 | D40: 45590 | E40: 30 | F40: =D40+E40 -> 45620 | G40: =$A$3-F40 -> 37 | J40: =B40 -> 132927190
A43: PT Sinergy Indopack Makmur | B43: 23976000 | C43: 859 | D43: 45618 | E43: 30 | F43: =D43+E43 -> 45648 | G43: =$A$3-F43 -> 9 | I43: =B43 -> 23976000
A44: PT Sinergy Indopack Makmur | B44: 23976000 | C44: 860 | D44: 45618 | E44: 30 | F44: =D44+E44 -> 45648 | G44: =$A$3-F44 -> 9 | I44: =B44 -> 23976000
A45: PT Sinergy Indopack Makmur | B45: 11188800 | C45: 908 | D45: 45635 | E45: 30 | F45: =D45+E45 -> 45665 | G45: =$A$3-F45 -> -8 | H45: =B45 -> 11188800
...

Sheet Piutang IAS Des 24
A1: PT Ind American Seafoods
A2: Aging Piutang Dagang | B2: =B3-B4 -> 0
A3: 45657 | B3: 4.4652392e+10 | D3: WBS | F3: =SUM(B45:B114) -> 8.0796574e+09 | G3: Dengan ISP | H3: =SUBTOTAL(9,H8:H114) -> 4.5770142e+10 | I3: =SUBTOTAL(9,I8:I114) -> 1.5431764e+09 | J3: =SUBTOTAL(9,J8:J114) -> 2.9575242e+08 | K3: =SUBTOTAL(9,K8:K114) -> 625607200 | L3: =SUBTOTAL(9,L8:L114) -> 1.8434506e+09 | M3: =B3+F3-SUM(H3:L3) -> 2.6539202e+09 | N3: Rincian ISP blm ditemukan
B4: =SUM(B8:B43) -> 4.4652392e+10 | G4: Tanpa ISP | H4: =SUM(H8:H43) -> 4.4293709e+10 | I4: =SUM(I8:I43) -> 28613300 | J4: =SUM(J8:J43) -> 0 | K4: =SUM(K8:K43) -> 25032200 | L4: =SUM(L8:L43) -> 305037330 | M4: =SUM(H4:L4)-B4 -> 0
C5: Invoice | G5: AGING
A6: Nama | B6: Nominal | C6: No | D6: Tanggal | E6: Jatuh Tempo | F6: Tanggal Jatuh Tempo | G6: Aging | H6: Lancar | I6: 1-30 Hari | J6: 31-60 Hari | K6: 61-90 Hari | L6: > 90 Hari
A7: Piutang Usaha - IDR
A8: CV Kanian Persada | B8: 35252600 | D8: 45627 | E8: 30 | F8: =D8+E8 -> 45657 | G8: =$A$3-F8 -> 0 | H8: =B8 -> 35252600
A9: CV Kanian Persada | B9: 28613300 | D9: 45597 | E9: 30 | F9: =D9+E9 -> 45627 | G9: =$A$3-F9 -> 30 | I9: =B9 -> 28613300
A10: CV Kanian Persada | B10: 25032200 | D10: 45566 | E10: 30 | F10: =D10+E10 -> 45596 | G10: =$A$3-F10 -> 61 | K10: =B10 -> 25032200
A11: CV Kanian Persada | B11: 26149000 | D11: 45536 | E11: 30 | F11: =D11+E11 -> 45566 | G11: =$A$3-F11 -> 91 | L11: =B11 -> 26149000
A12: CV Kanian Persada | B12: 278888330 | D12: 45505 | E12: 30 | F12: =D12+E12 -> 45535 | G12: =$A$3-F12 -> 122 | L12: =B12 -> 278888330
A14: Piutang Usaha - USD
A16: Censea Inc | B16: =3763011200 -> 3763011200 | C16: CENSEA PO 72073 & 72075 | D16: 45716 | E16: 60 | F16: =D16+E16 -> 45776 | G16: =$A$3-F16 -> -119 | H16: =B16 -> 3763011200
A17: Censea Inc | B17: 2075160429 | C17: CENSEA PO 71246 | D17: 45680 | E17: 60 | F17: =D17+E17 -> 45740 | G17: =$A$3-F17 -> -83 | H17: =B17 -> 2075160429
A18: Censea Inc | B18: 2434889600 | C18: CENSEA PO 71857 | D18: 45680 | E18: 60 | F18: =D18+E18 -> 45740 | G18: =$A$3-F18 -> -83 | H18: =B18 -> 2434889600
A19: Censea Inc | B19: 2054031200 | C19: CENSEA PO 71468 | D19: 45680 | E19: 60 | F19: =D19+E19 -> 45740 | G19: =$A$3-F19 -> -83 | H19: =B19 -> 2054031200
A20: Censea Inc | B20: 1998423576 | C20: CENSEA 72082 | D20: 45680 | E20: 60 | F20: =D20+E20 -> 45740 | G20: =$A$3-F20 -> -83 | H20: =B20 -> 1998423576
A21: Censea Inc | B21: =2400857500-5729640 -> 2395127860 | C21: 084/IAS-EXP | D21: 45646 | E21: 60 | F21: =D21+E21 -> 45706 | G21: =$A$3-F21 -> -49 | H21: =B21 -> 2395127860
A22: Censea Inc | B22: =2133756300-5729640 -> 2128026660 | C22: 085/IAS - EXP | D22: 45656 | E22: 60 | F22: =D22+E22 -> 45716 | G22: =$A$3-F22 -> -59 | H22: =B22 -> 2128026660
A23: Censea Inc | B23: =1923278000-5729640 -> 1917548360 | C23: 086/IAS - EXP | D23: 45657 | E23: 60 | F23: =D23+E23 -> 45717 | G23: =$A$3-F23 -> -60 | H23: =B23 -> 1917548360
A24: Censea Inc | B24: =2383895000-5729640 -> 2378165360 | C24: 089/IAS - EXP | D24: 45657 | E24: 60 | F24: =D24+E24 -> 45717 | G24: =$A$3-F24 -> -60 | H24: =B24 -> 2378165360
A25: Censea Inc | B25: =2054190200-5729640 -> 2048460560 | C25: 090/IAS - EXP | D25: 45657 | E25: 60 | F25: =D25+E25 -> 45717 | G25: =$A$3-F25 -> -60 | H25: =B25 -> 2048460560
A27: Alpha Trading Co. Ltd | B27: 1.8781602e+09 | C27: 087/IAS-EXP | D27: 45657 | E27: 60 | F27: =D27+E27 -> 45717 | G27: =$A$3-F27 -> -60 | H27: =B27 -> 1.8781602e+09
A28: Alpha Trading Co. Ltd | B28: 1310038964 | C28: ALPHA TRADING PO IAS ALT/005 | D28: 45682 | E28: 60 | F28: =D28+E28 -> 45742 | G28: =$A$3-F28 -> -85 | H28: =B28 -> 1310038964
A30: Ael Seafood Enterprises, LLC | B30: 1909174800 | C30: PO 11161 | D30: 45716 | E30: 60 | F30: =D30+E30 -> 45776 | G30: =$A$3-F30 -> -119 | H30: =B30 -> 1909174800
A31: Ael Seafood Enterprises, LLC | B31: 1909174800 | C31: PO 11162 | D31: 45716 | E31: 60 | F31: =D31+E31 -> 45776 | G31: =$A$3-F31 -> -119 | H31: =B31 -> 1909174800
A32: Ael Seafood Enterprises, LLC | B32: 1909174800 | C32: PO 11160 | D32: 45716 | E32: 60 | F32: =D32+E32 -> 45776 | G32: =$A$3-F32 -> -119 | H32: =B32 -> 1909174800
A34: Slade Gorton,,Inc | B34: 2019851600 | C34: NEW PO | D34: 45716 | E34: 60 | F34: =D34+E34 -> 45776 | G34: =$A$3-F34 -> -119 | H34: =B34 -> 2019851600
A36: Yachiyo Corporation | B36: 752163318 | C36: 088/IAS-EXP | D36: 45657 | E36: 60 | F36: =D36+E36 -> 45717 | G36: =$A$3-F36 -> -60 | H36: =B36 -> 752163318
A38: Hohsui Corporation | B38: 1396448248 | C38: NEW PO | D38: 45716 | E38: 60 | F38: =D38+E38 -> 45776 | G38: =$A$3-F38 -> -119 | H38: =B38 -> 1396448248
A40: Ssc Inc Sunnyvale Seafood, | B40: 1859370240 | C40: PO 67592 | D40: 45682 | E40: 60 | F40: =D40+E40 -> 45742 | G40: =$A$3-F40 -> -85 | H40: =B40 -> 1859370240
A41: Ssc Inc Sunnyvale Seafood, | B41: 1827794800 | C41: PO 67591 | D41: 45682 | E41: 60 | F41: =D41+E41 -> 45742 | G41: =$A$3-F41 -> -85 | H41: =B41 -> 1827794800
A42: Ssc Inc Sunnyvale Seafood, | B42: 2047520800 | C42: PO 67736 | D42: 45716 | E42: 60 | F42: =D42+E42 -> 45776 | G42: =$A$3-F42 -> -119 | H42: =B42 -> 2047520800
A43: Ssc Inc Sunnyvale Seafood, | B43: 2246739040 | C43: PO 67807 | D43: 45716 | E43: 60 | F43: =D43+E43 -> 45776 | G43: =$A$3-F43 -> -119 | H43: =B43 -> 2246739040
A45: ISP | B45: =8079657361-SUM(B46:B114) -> 2.6539202e+09
A46: PT Indokom Samudra Persada | B46: 15684827 | C46: 106 | D46: 45328 | E46: 30 | F46: =D46+E46 -> 45358 | G46: =$A$3-F46 -> 299 | L46: =B46 -> 15684827
A47: PT Indokom Samudra Persada | B47: 17212340 | C47: 123 | D47: 45337 | E47: 30 | F47: =D47+E47 -> 45367 | G47: =$A$3-F47 -> 290 | L47: =B47 -> 17212340
A48: PT Indokom Samudra Persada | B48: 5253259.6 | C48: 129 | D48: 45358 | E48: 30 | F48: =D48+E48 -> 45388 | G48: =$A$3-F48 -> 269 | L48: =B48 -> 5253259.6
A49: PT Indokom Samudra Persada | B49: 13964904 | C49: 132 | D49: 45359 | E49: 30 | F49: =D49+E49 -> 45389 | G49: =$A$3-F49 -> 268 | L49: =B49 -> 13964904
...

Sheet Hutang ISP Des 24
A1: Aging Hutang Usaha & Subsequent
A2: PT Indokom Samudra Persada | B2: =B3-B4 -> -0.46000004
A3: 45657 | B3: 2321126163 | C3: WBS
B4: =SUBTOTAL(9,B6:B78) -> 2.3211262e+09 | H4: =SUBTOTAL(9,H6:H78) -> 8.8174967e+08 | I4: =SUBTOTAL(9,I6:I78) -> 5.2566013e+08 | J4: =SUBTOTAL(9,J6:J78) -> 623745086 | K4: =SUBTOTAL(9,K6:K78) -> 69093320 | L4: =SUBTOTAL(9,L6:L78) -> 220877955 | M4: =SUM(H4:L4)-B4 -> 0
A5: Nama | B5: Nominal | C5: No Invoice | D5: Tgl Invoice | E5: Jatuh Tempo | F5: Tgl Jatuh Tempo | G5: Aging | H5: Lancar | I5: 1-30 Hari | J5: 31-60 Hari | K5: 61-90 Hari | L5: >90 Hari
A6: Bapak Cipto | B6: 19544752 | I6: =B6 -> 19544752
A8: AGS Sejahtera, CV, | B8: 22904000 | C8: 18 | D8: 45566 | E8: 30 | F8: =D8+E8 -> 45596 | G8: =$A$3-F8 -> 61 | K8: =B8 -> 22904000
A9: AGS Sejahtera, CV, | B9: 17115800 | C9: 23 | D9: 45640 | E9: 30 | F9: =D9+E9 -> 45670 | G9: =$A$3-F9 -> -13 | H9: =B9 -> 17115800
A11: Halim Sakti Pratama, PT | B11: 13506480 | C11: 36 | D11: 45553 | E11: 30 | F11: =D11+E11 -> 45583 | G11: =$A$3-F11 -> 74 | K11: =B11 -> 13506480
A13: Intiragam Oliefindo, PT | B13: 24975000 | C13: 397 | D13: 45546 | E13: 30 | F13: =D13+E13 -> 45576 | G13: =$A$3-F13 -> 81 | K13: =B13 -> 24975000
A15: Konverta Mitra Abadi, PT | B15: 7707840 | C15: 518 | D15: 45586 | E15: 30 | F15: =D15+E15 -> 45616 | G15: =$A$3-F15 -> 41 | K15: =B15 -> 7707840
A16: Konverta Mitra Abadi, PT | B16: 9145290 | C16: 529 | D16: 45593 | E16: 30 | F16: =D16+E16 -> 45623 | G16: =$A$3-F16 -> 34 | J16: =B16 -> 9145290
A17: Konverta Mitra Abadi, PT | B17: 23742900 | C17: 540 | D17: 45597 | E17: 30 | F17: =D17+E17 -> 45627 | G17: =$A$3-F17 -> 30 | I17: =B17 -> 23742900
A18: Konverta Mitra Abadi, PT | B18: 5505600 | C18: 602 | D18: 45621 | E18: 30 | F18: =D18+E18 -> 45651 | G18: =$A$3-F18 -> 6 | I18: =B18 -> 5505600
A19: Konverta Mitra Abadi, PT | B19: =1340325-408848 -> 931477 | C19: 603 | D19: 45621 | E19: 30 | F19: =D19+E19 -> 45651 | G19: =$A$3-F19 -> 6 | I19: =B19 -> 931477
A20: Konverta Mitra Abadi, PT | B20: 8286705 | C20: 605 | D20: 45621 | E20: 30 | F20: =D20+E20 -> 45651 | G20: =$A$3-F20 -> 6 | I20: =B20 -> 8286705
A21: Konverta Mitra Abadi, PT | B21: 10217938 | C21: 606 | D21: 45621 | E21: 30 | F21: =D21+E21 -> 45651 | G21: =$A$3-F21 -> 6 | I21: =B21 -> 10217938
A22: Konverta Mitra Abadi, PT | B22: 16350566 | C22: 607 | D22: 45621 | E22: 30 | F22: =D22+E22 -> 45651 | G22: =$A$3-F22 -> 6 | I22: =B22 -> 16350566
A23: Konverta Mitra Abadi, PT | B23: 6643350 | C23: 608 | D23: 45621 | E23: 30 | F23: =D23+E23 -> 45651 | G23: =$A$3-F23 -> 6 | I23: =B23 -> 6643350
A24: Konverta Mitra Abadi, PT | B24: 8974350 | C24: 609 | D24: 45621 | E24: 30 | F24: =D24+E24 -> 45651 | G24: =$A$3-F24 -> 6 | I24: =B24 -> 8974350
A25: Konverta Mitra Abadi, PT | B25: 8974350 | C25: 610 | D25: 45621 | E25: 30 | F25: =D25+E25 -> 45651 | G25: =$A$3-F25 -> 6 | I25: =B25 -> 8974350
A26: Konverta Mitra Abadi, PT | B26: 3869404 | C26: 611 | D26: 45621 | E26: 30 | F26: =D26+E26 -> 45651 | G26: =$A$3-F26 -> 6 | I26: =B26 -> 3869404
A27: Konverta Mitra Abadi, PT | B27: 8602500 | C27: 616 | D27: 45624 | E27: 30 | F27: =D27+E27 -> 45654 | G27: =$A$3-F27 -> 3 | I27: =B27 -> 8602500
A28: Konverta Mitra Abadi, PT | B28: 6959700 | C28: 620 | D28: 45628 | E28: 30 | F28: =D28+E28 -> 45658 | G28: =$A$3-F28 -> -1 | H28: =B28 -> 6959700
A29: Konverta Mitra Abadi, PT | B29: 23742900 | C29: 654 | D29: 45639 | E29: 30 | F29: =D29+E29 -> 45669 | G29: =$A$3-F29 -> -12 | H29: =B29 -> 23742900
A30: Konverta Mitra Abadi, PT | B30: 7776660 | C30: 655 | D30: 45639 | E30: 30 | F30: =D30+E30 -> 45669 | G30: =$A$3-F30 -> -12 | H30: =B30 -> 7776660
A31: Konverta Mitra Abadi, PT | B31: 2408700 | C31: 656 | D31: 45639 | E31: 30 | F31: =D31+E31 -> 45669 | G31: =$A$3-F31 -> -12 | H31: =B31 -> 2408700
A32: Konverta Mitra Abadi, PT | B32: 2381172 | C32: 658 | D32: 45639 | E32: 30 | F32: =D32+E32 -> 45669 | G32: =$A$3-F32 -> -12 | H32: =B32 -> 2381172
A33: Konverta Mitra Abadi, PT | B33: 2340990 | C33: 659 | D33: 45639 | E33: 30 | F33: =D33+E33 -> 45669 | G33: =$A$3-F33 -> -12 | H33: =B33 -> 2340990
A35: Lima Pendawa, CV | B35: 22200000 | C35: 657 | D35: 45639 | E35: 30 | F35: =D35+E35 -> 45669 | G35: =$A$3-F35 -> -12 | H35: =B35 -> 22200000
A37: Seven Mountain Internasional, PT | B37: 13098000 | C37: 601 | D37: 45621 | E37: 30 | F37: =D37+E37 -> 45651 | G37: =$A$3-F37 -> 6 | I37: =B37 -> 13098000
A38: Seven Mountain Internasional, PT | B38: 16761000 | C38: 664 | D38: 45642 | E38: 30 | F38: =D38+E38 -> 45672 | G38: =$A$3-F38 -> -15 | H38: =B38 -> 16761000
A40: Sinar Setia Mulia , PT | B40: 13470000 | C40: 43 | D40: 45604 | E40: 30 | F40: =D40+E40 -> 45634 | G40: =$A$3-F40 -> 23 | I40: =B40 -> 13470000
A41: Sinar Setia Mulia , PT | B41: 960000 | C41: 44 | D41: 45604 | E41: 30 | F41: =D41+E41 -> 45634 | G41: =$A$3-F41 -> 23 | I41: =B41 -> 960000
A42: Sinar Setia Mulia , PT | B42: 40800000 | C42: 46 | D42: 45611 | E42: 30 | F42: =D42+E42 -> 45641 | G42: =$A$3-F42 -> 16 | I42: =B42 -> 40800000
A44: Sumber Energy, PT | B44: 31635000 | C44: 579 | D44: 45614 | E44: 30 | F44: =D44+E44 -> 45644 | G44: =$A$3-F44 -> 13 | I44: =B44 -> 31635000
A46: Prima Larvae, PT | B46: 25704000 | C46: 575 | D46: 45637 | E46: 30 | F46: =D46+E46 -> 45667 | G46: =$A$3-F46 -> -10 | H46: =B46 -> 25704000
A47: Prima Larvae, PT | B47: 28800000 | C47: 607 | D47: 45656 | E47: 30 | F47: =D47+E47 -> 45686 | G47: =$A$3-F47 -> -29 | H47: =B47 -> 28800000
A49: Sumatra Motor Teknindo, PT | B49: 34791785 | I49: =B49 -> 34791785
A51: International Packaging M, (IPM), PT | B51: 971250 | L51: =B51 -> 971250 | M51: Info Manajemen angka ini sudah sesuai untuk LK 24 (04.02.2025)
...

Sheet Piutang ISP Des 24
A1: PT Indokom Samudra Persada
A2: Aging Piutang Dagang | B2: =B4-B3 -> -0.0019836426
A3: 45657 | B3: 4.8139666e+10
B4: =SUM(B8:B54) -> 4.8139666e+10 | H4: =SUM(H8:H54) -> 4.8098656e+10 | I4: =SUM(I8:I54) -> 28450775 | J4: =SUM(J8:J54) -> 0 | K4: =SUM(K8:K54) -> 12560000 | L4: =SUM(L8:L54) -> 0
C5: Invoice | G5: AGING
A6: Nama | B6: Nominal | C6: No | D6: Tanggal | E6: Jatuh Tempo | F6: Tanggal Jatuh Tempo | G6: Aging | H6: Lancar | I6: 1-30 Hari | J6: 31-60 Hari | K6: 61-90 Hari | L6: > 90 Hari
A7: Piutang Usaha - IDR
A8: PT Maju Tambak Sumur Es | B8: 2100000 | C8: 2259 | D8: 45633 | E8: 30 | F8: =D8+E8 -> 45663 | G8: =$A$3-F8 -> -6 | H8: =B8 -> 2100000
A9: PT Maju Tambak Sumur Es | B9: 3360000 | C9: 2261 | D9: 45633 | E9: 30 | F9: =D9+E9 -> 45663 | G9: =$A$3-F9 -> -6 | H9: =B9 -> 3360000
A10: PT Maju Tambak Sumur Es | B10: 3360000 | C10: 2265 | D10: 45634 | E10: 30 | F10: =D10+E10 -> 45664 | G10: =$A$3-F10 -> -7 | H10: =B10 -> 3360000
A11: PT Maju Tambak Sumur Es | B11: 1680000 | C11: 2266 | D11: 45635 | E11: 30 | F11: =D11+E11 -> 45665 | G11: =$A$3-F11 -> -8 | H11: =B11 -> 1680000
A12: PT Maju Tambak Sumur Es | B12: 1680000 | C12: 2271 | D12: 45635 | E12: 30 | F12: =D12+E12 -> 45665 | G12: =$A$3-F12 -> -8 | H12: =B12 -> 1680000
A13: PT Maju Tambak Sumur Es | B13: 1680000 | C13: 2302 | D13: 45642 | E13: 30 | F13: =D13+E13 -> 45672 | G13: =$A$3-F13 -> -15 | H13: =B13 -> 1680000
A14: PT Maju Tambak Sumur Es | B14: 2100000 | C14: 2339 | D14: 45649 | E14: 30 | F14: =D14+E14 -> 45679 | G14: =$A$3-F14 -> -22 | H14: =B14 -> 2100000
A16: Bapak Iwan-Es | B16: 59370000 | D16: 45627 | E16: 30 | F16: =D16+E16 -> 45657 | G16: =$A$3-F16 -> 0 | H16: =B16 -> 59370000
A17: Bapak Iwan-Es | B17: 7920000 | D17: 45597 | E17: 30 | F17: =D17+E17 -> 45627 | G17: =$A$3-F17 -> 30 | I17: =B17 -> 7920000
A18: Bapak Iwan-Es | B18: 12560000 | D18: 45566 | E18: 30 | F18: =D18+E18 -> 45596 | G18: =$A$3-F18 -> 61 | K18: =B18 -> 12560000
A20: Piutang Lain-lain di bawah Rp 20.000.000,- IDR | B20: 20530775 | E20: 30 | F20: =D20+E20 -> 30 | I20: =B20 -> 20530775
A23: Piutang Usaha - USD
A24: Crystal Cove Seafoods Corporation | B24: 2.3087255e+09 | C24: 063/ISP-EXP | D24: 45649 | E24: 60 | F24: =D24+E24 -> 45709 | G24: =$A$3-F24 -> -52 | H24: =B24 -> 2.3087255e+09
A25: Crystal Cove Seafoods Corporation | B25: 2208548733 | C25: PO 30977 | D25: 45674 | E25: 60 | F25: =D25+E25 -> 45734 | G25: =$A$3-F25 -> -77 | H25: =B25 -> 2208548733
A26: Crystal Cove Seafoods Corporation | B26: 1856847460 | C26: PO 001-2025 | D26: 45716 | E26: 60 | F26: =D26+E26 -> 45776 | G26: =$A$3-F26 -> -119 | H26: =B26 -> 1856847460
A28: Great American Seafoods Imports Co. | B28: 1895802600 | C28: 053/ISP - EXP | D28: 45657 | E28: 60 | F28: =D28+E28 -> 45717 | G28: =$A$3-F28 -> -60 | H28: =B28 -> 1895802600
A30: Censea Inc. | B30: 1936844000 | C30: PO. 72074 | D30: 45716 | E30: 60 | F30: =D30+E30 -> 45776 | G30: =$A$3-F30 -> -119 | H30: =B30 -> 1936844000
A31: Censea Inc. | B31: =1869424835.12-3516621 -> 1.8659082e+09 | C31: 065/ISP-EXP | D31: 45656 | E31: 60 | F31: =D31+E31 -> 45716 | G31: =$A$3-F31 -> -59 | H31: =B31 -> 1.8659082e+09
A32: Censea Inc. | B32: 2058914000 | C32: PO. 71482 | D32: 45681 | E32: 60 | F32: =D32+E32 -> 45741 | G32: =$A$3-F32 -> -84 | H32: =B32 -> 2058914000
A33: Censea Inc. | B33: 2146804400 | C33: PO. 71255 | D33: 45681 | E33: 60 | F33: =D33+E33 -> 45741 | G33: =$A$3-F33 -> -84 | H33: =B33 -> 2146804400
A35: Kyokuyo Co,, Ltd | B35: 2198904748 | C35: 064/ISP-EXP | D35: 45651 | E35: 60 | F35: =D35+E35 -> 45711 | G35: =$A$3-F35 -> -54 | H35: =B35 -> 2198904748
A36: Kyokuyo Co,, Ltd | B36: 2.0539002e+09 | C36: PO. ISP-010/2024 | D36: 45671 | E36: 60 | F36: =D36+E36 -> 45731 | G36: =$A$3-F36 -> -74 | H36: =B36 -> 2.0539002e+09
A37: Kyokuyo Co,, Ltd | B37: 1853540178 | C37: PO. ISP-011/2024 | D37: 45682 | E37: 60 | F37: =D37+E37 -> 45742 | G37: =$A$3-F37 -> -85 | H37: =B37 -> 1853540178
A38: Kyokuyo Co,, Ltd | B38: 1953120000 | C38: PO. 012-2024 | D38: 45716 | E38: 60 | F38: =D38+E38 -> 45776 | G38: =$A$3-F38 -> -119 | H38: =B38 -> 1953120000
A39: Kyokuyo Co,, Ltd | B39: 1953120000 | C39: PO. 013-2024 | D39: 45716 | E39: 60 | F39: =D39+E39 -> 45776 | G39: =$A$3-F39 -> -119 | H39: =B39 -> 1953120000
A40: Kyokuyo Co,, Ltd | B40: 1871740000 | C40: PO. 001-2025 | D40: 45716 | E40: 60 | F40: =D40+E40 -> 45776 | G40: =$A$3-F40 -> -119 | H40: =B40 -> 1871740000
A42: Nissui Corporation | B42: =2176601141+202049 -> 2176803190 | C42: 062/ISP-EXP | D42: 45651 | E42: 60 | F42: =D42+E42 -> 45711 | G42: =$A$3-F42 -> -54 | H42: =B42 -> 2176803190
A43: Nissui Corporation | B43: =2128131350+202048 -> 2128333398 | C43: 066/ISP-EXP | D43: 45657 | E43: 60 | F43: =D43+E43 -> 45717 | G43: =$A$3-F43 -> -60 | H43: =B43 -> 2128333398
A44: Nissui Corporation | B44: 2147708672 | C44: PO. ISP-NISSUI 012 | D44: 45672 | E44: 60 | F44: =D44+E44 -> 45732 | G44: =$A$3-F44 -> -75 | H44: =B44 -> 2147708672
A45: Nissui Corporation | B45: 2.1050026e+09 | C45: PO. ISP-NISSUI 014 | D45: 45679 | E45: 60 | F45: =D45+E45 -> 45739 | G45: =$A$3-F45 -> -82 | H45: =B45 -> 2.1050026e+09
A46: Nissui Corporation | B46: 2264382224 | C46: ISP-NISSUI 015 | D46: 45716 | E46: 60 | F46: =D46+E46 -> 45776 | G46: =$A$3-F46 -> -119 | H46: =B46 -> 2264382224
A47: Nissui Corporation | B47: 2398659224 | C47: ISP-NISSUI 016 | D47: 45716 | E47: 60 | F47: =D47+E47 -> 45776 | G47: =$A$3-F47 -> -119 | H47: =B47 -> 2398659224
A49: Ssc Inc Sunnyvale Seafood, | B49: 1958979360 | C49: PO 67610 | D49: 45681 | E49: 60 | F49: =D49+E49 -> 45741 | G49: =$A$3-F49 -> -84 | H49: =B49 -> 1958979360
...

Sheet Piutang IAS Sept 24
A1: PT Ind American Seafoods
A2: Aging Piutang Dagang
A3: 45565
B4: =SUM(B8:B31) -> 2.3871075e+10 | H4: =SUM(H8:H31) -> 2.3835256e+10 | I4: =SUM(I8:I31) -> 35818887 | J4: =SUM(J8:J31) -> 0 | K4: =SUM(K8:K31) -> 0 | L4: =SUM(L8:L31) -> 0
C5: Invoice | G5: AGING
A6: Nama | B6: Nominal | C6: No | D6: Tanggal | E6: Jatuh Tempo | F6: Tanggal Jatuh Tempo | G6: Aging | H6: Lancar | I6: 1-30 Hari | J6: 31-60 Hari | K6: 61-90 Hari | L6: > 90 Hari
A7: Piutang Usaha - IDR
A8: CV Kanian Persada | B8: 35818887 | D8: 45504 | E8: 30 | F8: =D8+E8 -> 45534 | G8: =$A$3-F8 -> 31 | I8: =B8 -> 35818887
A9: CV Kanian Persada | B9: 302993500 | D9: 45535 | E9: 30 | F9: =D9+E9 -> 45565 | G9: =$A$3-F9 -> 0 | H9: =B9 -> 302993500
A10: CV Kanian Persada | B10: 1082094 | D10: 45565 | E10: 30 | F10: =D10+E10 -> 45595 | G10: =$A$3-F10 -> -30 | H10: =B10 -> 1082094
A12: Piutang Usaha - USD
A14: Censea Inc | B14: 2304857600 | C14: Censea (PO. 71389) | D14: 45576 | E14: 60 | F14: =D14+E14 -> 45636 | G14: =$A$3-F14 -> -71 | H14: =B14 -> 2304857600
A15: Censea Inc | B15: 1998078000 | C15: Censea (PO. 71226) | D15: 45587 | E15: 60 | F15: =D15+E15 -> 45647 | G15: =$A$3-F15 -> -82 | H15: =B15 -> 1998078000
A16: Censea Inc | B16: 1930996000 | C16: Censea (PO. 71658) | D16: 45588 | E16: 60 | F16: =D16+E16 -> 45648 | G16: =$A$3-F16 -> -83 | H16: =B16 -> 1930996000
A17: Censea Inc | B17: 1647014400 | C17: 50 | D17: 45565 | E17: 60 | F17: =D17+E17 -> 45625 | G17: =$A$3-F17 -> -60 | H17: =B17 -> 1647014400
A18: Censea Inc | B18: 1565193150 | C18: 51 | D18: 45565 | E18: 60 | F18: =D18+E18 -> 45625 | G18: =$A$3-F18 -> -60 | H18: =B18 -> 1565193150
A19: Censea Inc | B19: 1878625800 | C19: 52 | D19: 45565 | E19: 60 | F19: =D19+E19 -> 45625 | G19: =$A$3-F19 -> -60 | H19: =B19 -> 1878625800
A20: Censea Inc | B20: 1856930400 | C20: 49 | D20: 45563 | E20: 60 | F20: =D20+E20 -> 45623 | G20: =$A$3-F20 -> -58 | H20: =B20 -> 1856930400
A21: Censea Inc | B21: =1580599365-38442196+0.5 -> 1.5421572e+09 | C21: 46 | D21: 45556 | E21: 60 | F21: =D21+E21 -> 45616 | G21: =$A$3-F21 -> -51 | H21: =B21 -> 1.5421572e+09
A22: Censea Inc | B22: 1949092500 | C22: 44 | D22: 45555 | E22: 60 | F22: =D22+E22 -> 45615 | G22: =$A$3-F22 -> -50 | H22: =B22 -> 1949092500
A24: Eastern Fish Company LLC | B24: 1353639940 | C24: 31 | D24: 45520 | E24: 60 | F24: =D24+E24 -> 45580 | G24: =$A$3-F24 -> -15 | H24: =B24 -> 1353639940
A26: Slade Gorton,,Inc | B26: 1783098720 | C26: Slade Gorton (PO. 309485) | D26: 45584 | E26: 60 | F26: =D26+E26 -> 45644 | G26: =$A$3-F26 -> -79 | H26: =B26 -> 1783098720
A27: Slade Gorton,,Inc | B27: 1739932234 | C27: 47 | D27: 45561 | E27: 60 | F27: =D27+E27 -> 45621 | G27: =$A$3-F27 -> -56 | H27: =B27 -> 1739932234
A29: H & T SEAFOODS INC | B29: 1981564200 | C29: 48 | D29: 45562 | E29: 60 | F29: =D29+E29 -> 45622 | G29: =$A$3-F29 -> -57 | H29: =B29 -> 1981564200

Sheet Hutang IAS Sept 24
A1: Aging Hutang Usaha & Subsequent
A2: PT Indo American Seafoods
A3: 45565
B4: =SUBTOTAL(9,B6:B107) -> 3.2579243e+09 | H4: =SUBTOTAL(9,H6:H107) -> 2.7836057e+09 | I4: =SUBTOTAL(9,I6:I107) -> 4.332646e+08 | J4: =SUBTOTAL(9,J6:J107) -> 14154286 | K4: =SUBTOTAL(9,K6:K107) -> 8031460 | L4: =SUBTOTAL(9,L6:L107) -> 18868270 | M4: =SUM(H4:L4)-B4 -> 0
A5: Nama | B5: Nominal | C5: No Invoice | D5: Tgl Invoice | E5: Jatuh Tempo | F5: Tgl Jatuh Tempo | G5: Aging | H5: Lancar | I5: 1-30 Hari | J5: 31-60 Hari | K5: 61-90 Hari | L5: >90 Hari
A6: PT Anesta Agung | B6: 2.8762729e+08 | C6: 648 | D6: 45561 | E6: 30 | F6: =D6+E6 -> 45591 | G6: =$A$3-F6 -> -26 | H6: =B6 -> 2.8762729e+08
A8: PT Konverta Mitra Abadi | B8: 1113430 | D8: 45443 | E8: 30 | F8: =D8+E8 -> 45473 | G8: =$A$3-F8 -> 92 | L8: =B8 -> 1113430
A9: PT Konverta Mitra Abadi | B9: 8031460 | C9: 417 | D9: 45448 | E9: 30 | F9: =D9+E9 -> 45478 | G9: =$A$3-F9 -> 87 | K9: =B9 -> 8031460
A10: PT Konverta Mitra Abadi | B10: 3059437 | C10: 484 | D10: 45489 | E10: 30 | F10: =D10+E10 -> 45519 | G10: =$A$3-F10 -> 46 | J10: =B10 -> 3059437
A11: PT Konverta Mitra Abadi | B11: 27872100 | C11: 543 | D11: 45523 | E11: 30 | F11: =D11+E11 -> 45553 | G11: =$A$3-F11 -> 12 | I11: =B11 -> 27872100
A12: PT Konverta Mitra Abadi | B12: 24431100 | C12: 544 | D12: 45523 | E12: 30 | F12: =D12+E12 -> 45553 | G12: =$A$3-F12 -> 12 | I12: =B12 -> 24431100
A13: PT Konverta Mitra Abadi | B13: 16516800 | C13: 551 | D13: 45526 | E13: 30 | F13: =D13+E13 -> 45556 | G13: =$A$3-F13 -> 9 | I13: =B13 -> 16516800
A14: PT Konverta Mitra Abadi | B14: 7914300 | C14: 552 | D14: 45527 | E14: 30 | F14: =D14+E14 -> 45557 | G14: =$A$3-F14 -> 8 | I14: =B14 -> 7914300
A15: PT Konverta Mitra Abadi | B15: 5782045.5 | C15: 555 | D15: 45528 | E15: 30 | F15: =D15+E15 -> 45558 | G15: =$A$3-F15 -> 7 | I15: =B15 -> 5782045.5
A16: PT Konverta Mitra Abadi | B16: 4142320 | C16: 556 | D16: 45528 | E16: 30 | F16: =D16+E16 -> 45558 | G16: =$A$3-F16 -> 7 | I16: =B16 -> 4142320
A17: PT Konverta Mitra Abadi | B17: 3291838 | C17: 557 | D17: 45528 | E17: 30 | F17: =D17+E17 -> 45558 | G17: =$A$3-F17 -> 7 | I17: =B17 -> 3291838
A18: PT Konverta Mitra Abadi | B18: 11507203 | C18: 558 | D18: 45529 | E18: 30 | F18: =D18+E18 -> 45559 | G18: =$A$3-F18 -> 6 | I18: =B18 -> 11507203
A19: PT Konverta Mitra Abadi | B19: 787212 | C19: 559 | D19: 45529 | E19: 30 | F19: =D19+E19 -> 45559 | G19: =$A$3-F19 -> 6 | I19: =B19 -> 787212
A20: PT Konverta Mitra Abadi | B20: 4784377 | C20: 577 | D20: 45533 | E20: 30 | F20: =D20+E20 -> 45563 | G20: =$A$3-F20 -> 2 | I20: =B20 -> 4784377
A21: PT Konverta Mitra Abadi | B21: 39463164 | C21: 580 | D21: 45534 | E21: 30 | F21: =D21+E21 -> 45564 | G21: =$A$3-F21 -> 1 | I21: =B21 -> 39463164
A22: PT Konverta Mitra Abadi | B22: 35519500 | C22: 581 | D22: 45534 | E22: 30 | F22: =D22+E22 -> 45564 | G22: =$A$3-F22 -> 1 | I22: =B22 -> 35519500
A23: PT Konverta Mitra Abadi | B23: 17118975 | C23: 582 | D23: 45534 | E23: 30 | F23: =D23+E23 -> 45564 | G23: =$A$3-F23 -> 1 | I23: =B23 -> 17118975
A24: PT Konverta Mitra Abadi | B24: 3892548 | C24: 587 | D24: 45535 | E24: 30 | F24: =D24+E24 -> 45565 | G24: =$A$3-F24 -> 0 | H24: =B24 -> 3892548
A25: PT Konverta Mitra Abadi | B25: 23605260 | C25: 588 | D25: 45535 | E25: 30 | F25: =D25+E25 -> 45565 | G25: =$A$3-F25 -> 0 | H25: =B25 -> 23605260
A26: PT Konverta Mitra Abadi | B26: 21403020 | C26: 597 | D26: 45540 | E26: 30 | F26: =D26+E26 -> 45570 | G26: =$A$3-F26 -> -5 | H26: =B26 -> 21403020
A27: PT Konverta Mitra Abadi | B27: 2339880 | C27: 609 | D27: 45542 | E27: 30 | F27: =D27+E27 -> 45572 | G27: =$A$3-F27 -> -7 | H27: =B27 -> 2339880
A28: PT Konverta Mitra Abadi | B28: 94076940 | C28: 631 | D28: 45547 | E28: 30 | F28: =D28+E28 -> 45577 | G28: =$A$3-F28 -> -12 | H28: =B28 -> 94076940
A29: PT Konverta Mitra Abadi | B29: 961537 | C29: 632 | D29: 45547 | E29: 30 | F29: =D29+E29 -> 45577 | G29: =$A$3-F29 -> -12 | H29: =B29 -> 961537
A30: PT Konverta Mitra Abadi | B30: 17120473 | C30: 649 | D30: 45551 | E30: 30 | F30: =D30+E30 -> 45581 | G30: =$A$3-F30 -> -16 | H30: =B30 -> 17120473
A31: PT Konverta Mitra Abadi | B31: 11837040 | C31: 655 | D31: 45552 | E31: 30 | F31: =D31+E31 -> 45582 | G31: =$A$3-F31 -> -17 | H31: =B31 -> 11837040
A32: PT Konverta Mitra Abadi | B32: 6905587 | C32: 658 | D32: 45553 | E32: 30 | F32: =D32+E32 -> 45583 | G32: =$A$3-F32 -> -18 | H32: =B32 -> 6905587
A33: PT Konverta Mitra Abadi | B33: 11905860 | C33: 659 | D33: 45553 | E33: 30 | F33: =D33+E33 -> 45583 | G33: =$A$3-F33 -> -18 | H33: =B33 -> 11905860
A34: PT Konverta Mitra Abadi | B34: 39164352 | C34: 660 | D34: 45553 | E34: 30 | F34: =D34+E34 -> 45583 | G34: =$A$3-F34 -> -18 | H34: =B34 -> 39164352
A35: PT Konverta Mitra Abadi | B35: 5292480 | C35: 664 | D35: 45554 | E35: 30 | F35: =D35+E35 -> 45584 | G35: =$A$3-F35 -> -19 | H35: =B35 -> 5292480
... A39: PT Konverta Mitra Abadi | B39: 8031460 | C39: 685 | D39: 45565 | E39: 30 | F39: =D39+E39 -> 45595 | G39: =$A$3-F39 -> -30 | H39: =B39 -> 8031460
A41: PT RBFood Supply Indonesia | B41: 28860000 | C41: 616 | D41: 45514 | E41: 30 | F41: =D41+E41 -> 45544 | G41: =$A$3-F41 -> 21 | I41: =B41 -> 28860000
A42: PT RBFood Supply Indonesia | B42: 28860000 | C42: 527 | D42: 45546 | E42: 30 | F42: =D42+E42 -> 45576 | G42: =$A$3-F42 -> -11 | H42: =B42 -> 28860000
A43: PT RBFood Supply Indonesia | B43: 6660000 | C43: 31 | D43: 45302 | E43: 30 | F43: =D43+E43 -> 45332 | G43: =$A$3-F43 -> 233 | L43: =B43 -> 6660000
A45: PT CJ Cheiljedang Feed Lampung | B45: 79300000 | C45: 2434 | D45: 45548 | E45: 30 | F45: =D45+E45 -> 45578 | G45: =$A$3-F45 -> -13 | H45: =B45 -> 79300000
A46: PT CJ Cheiljedang Feed Lampung | B46: 79325000 | C46: 2435 | D46: 45548 | E46: 30 | F46: =D46+E46 -> 45578 | G46: =$A$3-F46 -> -13 | H46: =B46 -> 79325000
...

Sheet Hutang Usaha ISP Sept 2024
A1: Aging Hutang Usaha & Subsequent
A2: PT Indokom Samudra Persada
A3: 45565
B4: =SUM(B6:B216) -> 7.3871703e+09 | H4: =SUM(H6:H216) -> 4.9834664e+09 | I4: =SUM(I6:I216) -> 1982303832 | J4: =SUM(J6:J216) -> 184180750 | K4: =SUM(K6:K216) -> 82354849 | L4: =SUM(L6:L216) -> 154864460 | M4: =SUM(H4:L4)-B4 -> 0
A5: Nama | B5: Nominal | C5: No Purchase | D5: Tgl Purchase | E5: Jatuh Tempo | F5: Tgl Jatuh Tempo | G5: Aging | H5: Lancar | I5: 1-30 Hari | J5: 31-60 Hari | K5: 61-90 Hari | L5: >90 Hari
A6: Bapak Cipto | B6: 27237008 | E6: 30 | I6: =B6 -> 27237008
A8: Halim Sakti Pratama, PT | B8: 13506480 | C8: 36 | D8: 45553 | E8: 30 | F8: =D8+E8 -> 45583 | G8: =$A$3-F8 -> -18 | H8: =B8 -> 13506480
A10: Intiragam Oliefindo, PT | B10: 24975000 | C10: 397 | D10: 45546 | E10: 30 | F10: =D10+E10 -> 45576 | G10: =$A$3-F10 -> -11 | H10: =B10 -> 24975000
A12: Samara Cipta Solution, CV | B12: 69903226 | C12: 311 | D12: 45514 | E12: 30 | F12: =D12+E12 -> 45544 | G12: =$A$3-F12 -> 21 | I12: =B12 -> 69903226
B13: 32190000 | C13: 438 | D13: 45560 | E13: 30 | F13: =D13+E13 -> 45590 | G13: =$A$3-F13 -> -25 | H13: =B13 -> 32190000
B14: 48037780 | C14: 439 | D14: 45560 | E14: 30 | F14: =D14+E14 -> 45590 | G14: =$A$3-F14 -> -25 | H14: =B14 -> 48037780
A16: Seven Mountain Internasional, PT | B16: 29859000 | C16: 314 | D16: 45516 | E16: 30 | F16: =D16+E16 -> 45546 | G16: =$A$3-F16 -> 19 | I16: =B16 -> 29859000
A18: Sinar Panca Surya, PT | B18: 48888562 | C18: 405 | D18: 45548 | E18: 30 | F18: =D18+E18 -> 45578 | G18: =$A$3-F18 -> -13 | H18: =B18 -> 48888562
B19: 41990190 | C19: 442 | D19: 45561 | E19: 30 | F19: =D19+E19 -> 45591 | G19: =$A$3-F19 -> -26 | H19: =B19 -> 41990190
B20: 42525657 | C20: 447 | D20: 45563 | E20: 30 | F20: =D20+E20 -> 45593 | G20: =$A$3-F20 -> -28 | H20: =B20 -> 42525657
A22: Sinar Setia Mulia , PT | B22: 40800003 | C22: 35 | D22: 45546 | E22: 30 | F22: =D22+E22 -> 45576 | G22: =$A$3-F22 -> -11 | H22: =B22 -> 40800003
A24: Nusantara, Toko | B24: 5025000 | D24: 45292 | E24: 30 | F24: =D24+E24 -> 45322 | G24: =$A$3-F24 -> 243 | L24: =B24 -> 5025000 | M24: apakah perlu di adj ?
A26: Surya Serba Mulia, PT | B26: 70999869 | C26: 411 | D26: 45549 | E26: 30 | F26: =D26+E26 -> 45579 | G26: =$A$3-F26 -> -14 | H26: =B26 -> 70999869
A28: Sumatra Motor Teknindo, PT | B28: 8646900 | C28: 231 | D28: 45477 | E28: 30 | F28: =D28+E28 -> 45507 | G28: =$A$3-F28 -> 58 | J28: =B28 -> 8646900
B29: 301032 | C29: 232 | D29: 45477 | E29: 30 | F29: =D29+E29 -> 45507 | G29: =$A$3-F29 -> 58 | J29: =B29 -> 301032
B30: 357420 | C30: 233 | D30: 45477 | E30: 30 | F30: =D30+E30 -> 45507 | G30: =$A$3-F30 -> 58 | J30: =B30 -> 357420
B31: 619380 | C31: 14 | D31: 45477 | E31: 30 | F31: =D31+E31 -> 45507 | G31: =$A$3-F31 -> 58 | J31: =B31 -> 619380
B32: 2426460 | C32: 327 | D32: 45505 | E32: 30 | F32: =D32+E32 -> 45535 | G32: =$A$3-F32 -> 30 | I32: =B32 -> 2426460
B33: 7856025 | C33: 328 | D33: 45505 | E33: 30 | F33: =D33+E33 -> 45535 | G33: =$A$3-F33 -> 30 | I33: =B33 -> 7856025
B34: =457875-17988 -> 439887 | C34: 331 | D34: 45505 | E34: 30 | F34: =D34+E34 -> 45535 | G34: =$A$3-F34 -> 30 | I34: =B34 -> 439887
B35: 567432 | C35: 306 | D35: 45514 | E35: 30 | F35: =D35+E35 -> 45544 | G35: =$A$3-F35 -> 21 | I35: =B35 -> 567432
B36: 2411475 | C36: 307 | D36: 45514 | E36: 30 | F36: =D36+E36 -> 45544 | G36: =$A$3-F36 -> 21 | I36: =B36 -> 2411475
B37: 510600 | C37: 308 | D37: 45514 | E37: 30 | F37: =D37+E37 -> 45544 | G37: =$A$3-F37 -> 21 | I37: =B37 -> 510600
B38: 222000 | C38: 32 | D38: 45533 | E38: 30 | F38: =D38+E38 -> 45563 | G38: =$A$3-F38 -> 2 | I38: =B38 -> 222000
B39: 366300 | C39: 365 | D39: 45537 | E39: 30 | F39: =D39+E39 -> 45567 | G39: =$A$3-F39 -> -2 | H39: =B39 -> 366300
B40: 3046950 | C40: 366 | D40: 45537 | E40: 30 | F40: =D40+E40 -> 45567 | G40: =$A$3-F40 -> -2 | H40: =B40 -> 3046950
B41: 1198800 | C41: 34 | D41: 45537 | E41: 30 | F41: =D41+E41 -> 45567 | G41: =$A$3-F41 -> -2 | H41: =B41 -> 1198800
B42: 2424240 | C42: 390 | D42: 45536 | E42: 30 | F42: =D42+E42 -> 45566 | G42: =$A$3-F42 -> -1 | H42: =B42 -> 2424240
B43: 3762900 | C43: 391 | D43: 45536 | E43: 30 | F43: =D43+E43 -> 45566 | G43: =$A$3-F43 -> -1 | H43: =B43 -> 3762900
A45: Tri Jaya Sukses | B45: 38500000 | C45: 271 | D45: 45475 | E45: 30 | F45: =D45+E45 -> 45505 | G45: =$A$3-F45 -> 60 | J45: =B45 -> 38500000
B46: 38500000 | C46: 311 | D46: 45500 | E46: 30 | F46: =D46+E46 -> 45530 | G46: =$A$3-F46 -> 35 | J46: =B46 -> 38500000
B47: 26500000 | C47: 365 | D47: 45523 | E47: 30 | F47: =D47+E47 -> 45553 | G47: =$A$3-F47 -> 12 | I47: =B47 -> 26500000
B48: 2537500 | C48: 366 | D48: 45523 | E48: 30 | F48: =D48+E48 -> 45553 | G48: =$A$3-F48 -> 12 | I48: =B48 -> 2537500
A50: General Agromesin Lestari, PT | B50: 58185000 | C50: 416 | D50: 45548 | E50: 30 | F50: =D50+E50 -> 45578 | G50: =$A$3-F50 -> -13 | H50: =B50 -> 58185000
B51: 27153000 | C51: 417 | D51: 45548 | E51: 30 | F51: =D51+E51 -> 45578 | G51: =$A$3-F51 -> -13 | H51: =B51 -> 27153000
...

Sheet Piutang ISP Sept 24
A1: PT Indokom Samudra Persada
A2: Aging Piutang Dagang
A3: 45565
B4: =SUM(B8:B40) -> 1.5888229e+10 | H4: =SUM(H8:H40) -> 1.5860138e+10 | I4: =SUM(I8:I40) -> 28090775
C5: Invoice | G5: AGING
A6: Nama | B6: Nominal | C6: No | D6: Tanggal | E6: Jatuh Tempo | F6: Tanggal Jatuh Tempo | G6: Aging | H6: Lancar | I6: 1-30 Hari | J6: 31-60 Hari | K6: 61-90 Hari | L6: > 90 Hari
A7: Piutang Usaha - IDR
A8: Bapak Iwan-Es | B8: =13790000-9150000 -> 4640000 | D8: 45542 | E8: 30 | F8: =D8+E8 -> 45572 | G8: =$A$3-F8 -> -7 | H8: =B8 -> 4640000
A9: Bapak Iwan-Es | B9: 12120000 | C9: 993 | D9: 45549 | E9: 30 | F9: =D9+E9 -> 45579 | G9: =$A$3-F9 -> -14 | H9: =B9 -> 12120000
A10: Bapak Iwan-Es | B10: 15460000 | C10: 1017 | D10: 45556 | E10: 30 | F10: =D10+E10 -> 45586 | G10: =$A$3-F10 -> -21 | H10: =B10 -> 15460000
A11: Bapak Iwan-Es | B11: 10060000 | C11: 1037 | D11: 45563 | E11: 30 | F11: =D11+E11 -> 45593 | G11: =$A$3-F11 -> -28 | H11: =B11 -> 10060000
A13: Deska-ES | B13: 1680000 | C13: 1774 | D13: 45548 | E13: 30 | F13: =D13+E13 -> 45578 | G13: =$A$3-F13 -> -13 | H13: =B13 -> 1680000
A14: Deska-ES | B14: 1680000 | C14: 1779 | D14: 45549 | E14: 30 | F14: =D14+E14 -> 45579 | G14: =$A$3-F14 -> -14 | H14: =B14 -> 1680000
A15: Deska-ES | B15: 1260000 | C15: 1780 | D15: 45549 | E15: 30 | F15: =D15+E15 -> 45579 | G15: =$A$3-F15 -> -14 | H15: =B15 -> 1260000
A16: Deska-ES | B16: 1260000 | C16: 1781 | D16: 45549 | E16: 30 | F16: =D16+E16 -> 45579 | G16: =$A$3-F16 -> -14 | H16: =B16 -> 1260000
A17: Deska-ES | B17: 1680000 | C17: 1784 | D17: 45550 | E17: 30 | F17: =D17+E17 -> 45580 | G17: =$A$3-F17 -> -15 | H17: =B17 -> 1680000
A18: Deska-ES | B18: 1260000 | C18: 1785 | D18: 45550 | E18: 30 | F18: =D18+E18 -> 45580 | G18: =$A$3-F18 -> -15 | H18: =B18 -> 1260000
A19: Deska-ES | B19: 1680000 | C19: 1789 | D19: 45551 | E19: 30 | F19: =D19+E19 -> 45581 | G19: =$A$3-F19 -> -16 | H19: =B19 -> 1680000
A20: Deska-ES | B20: 1260000 | C20: 1790 | D20: 45551 | E20: 30 | F20: =D20+E20 -> 45581 | G20: =$A$3-F20 -> -16 | H20: =B20 -> 1260000
A21: Deska-ES | B21: 1680000 | C21: 1790 | D21: 45551 | E21: 30 | F21: =D21+E21 -> 45581 | G21: =$A$3-F21 -> -16 | H21: =B21 -> 1680000
A22: Deska-ES | B22: 1680000 | C22: 1849 | D22: 45563 | E22: 30 | F22: =D22+E22 -> 45593 | G22: =$A$3-F22 -> -28 | H22: =B22 -> 1680000
A24: Piutang Lain-lain di bawah Rp 20.000.000,- IDR | B24: 28090775 | I24: =B24 -> 28090775
A26: Piutang Usaha - USD
A27: Censea Inc | B27: 1663225600 | D27: 45555 | E27: 60 | F27: =D27+E27 -> 45615 | G27: =$A$3-F27 -> -50 | H27: =B27 -> 1663225600
A28: Censea Inc | B28: =1570673445-23956859 -> 1546716586 | D28: 45559 | E28: 60 | F28: =D28+E28 -> 45619 | G28: =$A$3-F28 -> -54 | H28: =B28 -> 1546716586
A29: Censea Inc | B29: 1956962250 | D29: 45569 | E29: 60 | F29: =D29+E29 -> 45629 | G29: =$A$3-F29 -> -64 | H29: =B29 -> 1956962250
A30: Censea Inc | B30: 1916539200 | D30: 45576 | E30: 60 | F30: =D30+E30 -> 45636 | G30: =$A$3-F30 -> -71 | H30: =B30 -> 1916539200
A32: Honsui Corporation | B32: 1509175660 | D32: 45580 | E32: 60 | F32: =D32+E32 -> 45640 | G32: =$A$3-F32 -> -75 | H32: =B32 -> 1509175660
A33: Honsui Corporation | B33: =1232713219-16074457 -> 1216638762 | C33: 33 | D33: 45553 | E33: 60 | F33: =D33+E33 -> 45613 | G33: =$A$3-F33 -> -48 | H33: =B33 -> 1216638762
A35: Kyo Kuyo Co, Ltd | B35: 1589028594 | C35: 30 | D35: 45546 | E35: 60 | F35: =D35+E35 -> 45606 | G35: =$A$3-F35 -> -41 | H35: =B35 -> 1589028594
A37: Nissui Corporation | B37: 2.507554e+09 | D37: 45581 | E37: 60 | F37: =D37+E37 -> 45641 | G37: =$A$3-F37 -> -76 | H37: =B37 -> 2.507554e+09
A38: Nissui Corporation | B38: =1902912102-6014734 -> 1896897368 | C38: 36 | D38: 45560 | E38: 60 | F38: =D38+E38 -> 45620 | G38: =$A$3-F38 -> -55 | H38: =B38 -> 1896897368
A41: Deska / WMM Es -IDR | B41: 1680000 | C41: 1774 | D41: 45548 | E41: 60 | F41: =D41+E41 -> 45608 | G41: =$A$3-F41 -> -43 | H41: =B41 -> 1680000
A42: Deska / WMM Es -IDR | B42: 1680000 | C42: 1779 | D42: 45549 | E42: 60 | F42: =D42+E42 -> 45609 | G42: =$A$3-F42 -> -44 | H42: =B42 -> 1680000
A43: Deska / WMM Es -IDR | B43: 1260000 | C43: 1780 | D43: 45549 | E43: 60 | F43: =D43+E43 -> 45609 | G43: =$A$3-F43 -> -44 | H43: =B43 -> 1260000
A44: Deska / WMM Es -IDR | B44: 1260000 | C44: 1781 | D44: 45549 | E44: 60 | F44: =D44+E44 -> 45609 | G44: =$A$3-F44 -> -44 | H44: =B44 -> 1260000
A45: Deska / WMM Es -IDR | B45: 1680000 | C45: 1784 | D45: 45550 | E45: 60 | F45: =D45+E45 -> 45610 | G45: =$A$3-F45 -> -45 | H45: =B45 -> 1680000
A46: Deska / WMM Es -IDR | B46: 1260000 | C46: 1785 | D46: 45550 | E46: 60 | F46: =D46+E46 -> 45610 | G46: =$A$3-F46 -> -45 | H46: =B46 -> 1260000
A47: Deska / WMM Es -IDR | B47: 1680000 | C47: 1789 | D47: 45551 | E47: 60 | F47: =D47+E47 -> 45611 | G47: =$A$3-F47 -> -46 | H47: =B47 -> 1680000
A48: Deska / WMM Es -IDR | B48: 1260000 | C48: 1790 | D48: 45551 | E48: 60 | F48: =D48+E48 -> 45611 | G48: =$A$3-F48 -> -46 | H48: =B48 -> 1260000
...

Sheet Hutang Usaha IAS Juni 24
A1: Aging Hutang Usaha & Subsequent
A2: PT Indo American Seafoods
A3: 45473
A5: Nama | B5: Nominal | C5: No Invoice | D5: Tgl Invoice | E5: Jatuh Tempo | F5: Tgl Jatuh Tempo | G5: Aging | H5: Lancar | I5: 1-30 Hari | J5: 31-60 Hari | K5: 61-90 Hari | L5: >90 Hari
A6: PT International Packaging Manufacturing | B6: 194250000 | C6: 459 | D6: 45075 | E6: 30 | F6: =D6+E6 -> 45105 | G6: =$A$3-F6 -> 368 | L6: =B6 -> 194250000
A8: PT Konverta Mitra Abadi | B8: =958485+11 -> 958496 | C8: 321 | D8: 45417 | E8: 30 | F8: =D8+E8 -> 45447 | G8: =$A$3-F8 -> 26 | I8: =B8 -> 958496
A9: PT Konverta Mitra Abadi | B9: 223909 | C9: 322 | D9: 45417 | E9: 30 | F9: =D9+E9 -> 45447 | G9: =$A$3-F9 -> 26 | I9: =B9 -> 223909
A10: PT Konverta Mitra Abadi | B10: 1282050 | C10: 323 | D10: 45417 | E10: 30 | F10: =D10+E10 -> 45447 | G10: =$A$3-F10 -> 26 | I10: =B10 -> 1282050
A11: PT Konverta Mitra Abadi | B11: 6205122 | C11: 334 | D11: 45420 | E11: 30 | F11: =D11+E11 -> 45450 | G11: =$A$3-F11 -> 23 | I11: =B11 -> 6205122
A12: PT Konverta Mitra Abadi | B12: 7272720 | C12: 335 | D12: 45420 | E12: 30 | F12: =D12+E12 -> 45450 | G12: =$A$3-F12 -> 23 | I12: =B12 -> 7272720
A13: PT Konverta Mitra Abadi | B13: 5011650 | C13: 336 | D13: 45420 | E13: 30 | F13: =D13+E13 -> 45450 | G13: =$A$3-F13 -> 23 | I13: =B13 -> 5011650
A14: PT Konverta Mitra Abadi | B14: 27512793 | C14: 337 | D14: 45420 | E14: 30 | F14: =D14+E14 -> 45450 | G14: =$A$3-F14 -> 23 | I14: =B14 -> 27512793
A15: PT Konverta Mitra Abadi | B15: 3775054 | C15: 338 | D15: 45420 | E15: 30 | F15: =D15+E15 -> 45450 | G15: =$A$3-F15 -> 23 | I15: =B15 -> 3775054
A16: PT Konverta Mitra Abadi | B16: 8811180 | C16: 339 | D16: 45420 | E16: 30 | F16: =D16+E16 -> 45450 | G16: =$A$3-F16 -> 23 | I16: =B16 -> 8811180
A17: PT Konverta Mitra Abadi | B17: 4623771 | C17: 346 | D17: 45425 | E17: 30 | F17: =D17+E17 -> 45455 | G17: =$A$3-F17 -> 18 | I17: =B17 -> 4623771
A18: PT Konverta Mitra Abadi | B18: 16516800 | C18: 355 | D18: 45427 | E18: 30 | F18: =D18+E18 -> 45457 | G18: =$A$3-F18 -> 16 | I18: =B18 -> 16516800
A19: PT Konverta Mitra Abadi | B19: 3104892 | C19: 371 | D19: 45431 | E19: 30 | F19: =D19+E19 -> 45461 | G19: =$A$3-F19 -> 12 | I19: =B19 -> 3104892
A20: PT Konverta Mitra Abadi | B20: 7171044 | C20: 372 | D20: 45431 | E20: 30 | F20: =D20+E20 -> 45461 | G20: =$A$3-F20 -> 12 | I20: =B20 -> 7171044
... A23: PT Konverta Mitra Abadi | B23: 6118875 | C23: 400 | D23: 45442 | E23: 30 | F23: =D23+E23 -> 45472 | G23: =$A$3-F23 -> 1 | I23: =B23 -> 6118875
A24: PT Konverta Mitra Abadi | B24: 4198575 | C24: 404 | D24: 45443 | E24: 30 | F24: =D24+E24 -> 45473 | G24: =$A$3-F24 -> 0 | H24: =B24 -> 4198575
A25: PT Konverta Mitra Abadi | B25: 7557235 | C25: 405 | D25: 45443 | E25: 30 | F25: =D25+E25 -> 45473 | G25: =$A$3-F25 -> 0 | H25: =B25 -> 7557235
A26: PT Konverta Mitra Abadi | B26: 7109550 | C26: 410 | D26: 45446 | E26: 30 | F26: =D26+E26 -> 45476 | G26: =$A$3-F26 -> -3 | H26: =B26 -> 7109550
A27: PT Konverta Mitra Abadi | B27: 8510481 | C27: 411 | D27: 45446 | E27: 30 | F27: =D27+E27 -> 45476 | G27: =$A$3-F27 -> -3 | H27: =B27 -> 8510481
A28: PT Konverta Mitra Abadi | B28: 7226100 | C28: 412 | D28: 45446 | E28: 30 | F28: =D28+E28 -> 45476 | G28: =$A$3-F28 -> -3 | H28: =B28 -> 7226100
