Workbook
Name \m: #REF!
Name \u: #REF!
Name ____ALZ1: #REF!
Name ____CSO58: #REF!
Name ____CSO80: #REF!
Name ____KM2: #REF!
Name ____MAC1: #REF!
Name ____MAC2: #REF!
Name ____tmi93: #REF!
Name ___ALZ1: #REF!
Name ___CSO58: #REF!
Name ___CSO80: #REF!
Name ___KM2: #REF!
Name ___MAC1: #REF!
Name ___MAC2: #REF!
Name ___tmi93: #REF!
Name __ALZ1: #REF!
Name __CSO58: #REF!
Name __CSO80: #REF!
Name __KM2: #REF!
Name __kmt1: [1]KmtNaik!$A$5:$L$115
Name __MAC1: #REF!
Name __MAC2: #REF!
Name __tmi93: #REF!
Name _ALZ1: #REF!
Name _CSO58: #REF!
Name _CSO80: #REF!
Name _KM2: #REF!
Name _kmt1: #REF!
Name _kmt2: #REF!
Name _MAC1: #REF!
Name _MAC2: #REF!
Name _NTREST: [4]TARIP!$B$3:$C$63
Name _TGL1: #REF!
Name _TGL2: #REF!
Name _tmi93: #REF!
Name _wl1: #REF!
Name a: #REF!
Name AL: #REF!
Name ALAMAT: #REF!
Name alfa: #REF!
Name ALNT: #REF!
Name ALP: #REF!
Name ALPCV: #REF!
Name ALPZ: #REF!
Name ALZ: #REF!
Name ALZT: #REF!
Name AN: #REF!
Name ANCER: #REF!
Name ANT: #REF!
Name ANW: #REF!
Name AT: #REF!
Name AX: #REF!
Name B: #REF!
Name BA: #REF!
Name BE: #REF!
Name beta: #REF!
Name BILANG: [5]RUMUS!$A$1:$B$1000
Name Blok: #REF!
Name BT: #REF!

Sheet CKPN_23_22, 21 & 20-Adj MGN
A4: Client | B4: : PT INDO AMERICAN SEAFOODS | K4: Prepared by | L4: : | M4: Date | N4: :
A5: Period | B5: : 2022, 2021 & 2020 | K5: Reviewed by | L5: : | M5: Date | N5: :
A6: Account | B6: : Piutang Usaha
A7: Index | B7: : PSAK 71 - Cadangan Kerugian Penurunan Nilai
B9: PIUTANG IAS (belum jatuh tempo) | D9: 0 | H9: Total CKPN per 31 Desember 2023 | K9: =E15+E25+E34+E43 -> 1.1930406e+08
B10: Suku bunga ORI | E10: 0.061
B11: Suku bunga per hari | E11: =E10/360 -> 0.00016944444 | H11: Catatan :
B12: Jatuh Tempo | E12: 10 | H12: *) Dasar suku bunga
B13: PVIF | E13: =1/(1+E11)^10 -> 0.99830713
B14: Nilai sekarang dari piutang | E14: =D9*E13 -> 0 | H14: Selisih | K14: =K9-K50 -> -2.5981613e+08
B15: ECL | E15: =D9-E14 -> 0
B19: PIUTANG IAS ( Jatuh tempo 30 hari) | D19: ='Aging IAS 23-20-Adj MGN-SQS'!D23 -> 4.6908335e+09
B20: Suku bunga ORI | E20: =E10 -> 0.061
B21: =B11 -> Suku bunga per hari | E21: =E20/360 -> 0.00016944444
B22: =B12 -> Jatuh Tempo | E22: 30
B23: PVIF | E23: =1/(1+E21)^30 -> 0.99492999
B24: Nilai sekarang dari piutang | E24: =D19*E23 -> 4.6670509e+09
B25: ECL | E25: =D19-E24 -> 23782557
B28: PIUTANG IAS ( Jatuh tempo 60 hari) | D28: ='Aging IAS 23-20-Adj MGN-SQS'!E23 -> 9.128416e+09
B29: Suku bunga ORI | E29: =E20 -> 0.061
B30: =B21 -> Suku bunga per hari | E30: =E29/360 -> 0.00016944444
B31: =B12 -> Jatuh Tempo | E31: 60
B32: PVIF | E32: =1/(1+E30)^60 -> 0.98988569
B33: Nilai sekarang dari piutang | E33: =D28*E32 -> 9.0360884e+09
B34: ECL | E34: =D28-E33 -> 92327614
B37: PIUTANG IAS ( Jatuh tempo 90 hari) | D37: ='Aging IAS 23-20-Adj MGN-SQS'!F23+'Aging IAS 23-20-Adj MGN-SQS'!G23 -> 211054410
B38: Suku bunga ORI | E38: =E20 -> 0.061
B39: =B11 -> Suku bunga per hari | E39: =E38/360 -> 0.00016944444
B40: =B31 -> Jatuh Tempo | E40: 90
B41: PVIF | E41: =1/(1+E39)^90 -> 0.98486696
B42: Nilai sekarang dari piutang | E42: =D37*E41 -> 2.0786052e+08
B43: ECL | E43: =D37-E42 -> 3193893.8
D44: =SUM(D9:D43) -> 1.4030304e+10
B50: PIUTANG IAS (belum jatuh tempo) | D50: 0 | H50: Total CKPN per 31 Desember 2022 | K50: =E56+E66+E75+E84 -> 3.7912019e+08
B51: Suku bunga ORI | E51: 0.0595
B52: Suku bunga per hari | E52: =E51/360 -> 0.00016527778 | H52: Catatan :
B53: Jatuh Tempo | E53: 10 | H53: *) Dasar suku bunga sebesar diambil 9% diambil dari suku bunga pinjaman
B54: PVIF | E54: =1/(1+E52)^10 -> 0.99834872
B55: Nilai sekarang dari piutang | E55: =D50*E54 -> 0 | H55: Selisih | K55: =K50-K89 -> 1.5142772e+08
B56: ECL | E56: =D50-E55 -> 0
...

Sheet Aging IAS 23-20-Adj MGN-SQS
A1: PT INDO AMERICAN SEAFOODS
A3: UMUR PIUTANG PER 31 Desember 2023
A5: NAMA PELANGGAN | B5: PIUTANG | C5: BELUM JATUH TEMPO | D5: SUDAH JATUH TEMPO
D6: < 30 HARI | E6: < 60 HARI | F6: < 90 HARI | G6: > 90 HARI
A8: Piutang Expor
A9: Censea Inc | B9: 8.0624293e+09 | D9: =B9-E9 -> 5.9585802e+08 | E9: =B9*I13 -> 7.4665712e+09 | H9: porsi 2022
A10: Eastern Fish Company LLC | B10: 1.6618448e+09 | E10: =B10 -> 1.6618448e+09 | H10: 23090276420
A11: Eiger Co Ltd | B11: 5.5005059e+08 | D11: =B11 -> 5.5005059e+08 | H11: 21383777540
A12: San Sugar Co Ltd | B12: 2.0288998e+09 | D12: =B12 -> 2.0288998e+09 | H12: 1706498880
A13: Yachiyo Corporation | B13: 6.2427092e+08 | D13: =B13 -> 6.2427092e+08 | I13: =H11/H10 -> 0.92609448
A14: Hohsui Corporation | B14: 8.90274e+08 | D14: =B14 -> 8.90274e+08 | I14: =H12/H10 -> 0.07390552
A16: Piutang Lokal | B16: =SUM(C16:G16) -> 0
A17: CV Kanian Persada | B17: 211054410 | G17: =B17 -> 211054410
A18: Piutang Karyawan | B18: 1480185 | D18: =B18 -> 1480185
B19: =SUM(C19:G19) -> 0
A20: Piutang Afiliasi | B20: =SUM(C20:G20) -> 0
A21: Indokom Samudra Persada, PT
A23: JUMLAH | B23: =SUM(B9:B21) -> 1.4030304e+10 | C23: =SUM(C7:C22) -> 0 | D23: =SUM(D9:D21) -> 4.6908335e+09 | E23: =SUM(E9:E21) -> 9.128416e+09 | F23: =SUM(F9:F21) -> 0 | G23: =SUM(G9:G21) -> 211054410
A27: UMUR PIUTANG PER 31 Desember 2022
A29: NAMA PELANGGAN | B29: PIUTANG | C29: BELUM JATUH TEMPO | D29: SUDAH JATUH TEMPO
D30: < 30 HARI | E30: < 60 HARI | F30: < 90 HARI | G30: > 90 HARI
A32: Piutang Expor
A33: Alpha Trading Co Ltd | B33: =SUM(C33:G33) -> 1154639669 | E33: 1154639669
A34: Censea Inc | B34: =SUM(C34:G34) -> 1839819105 | E34: 1839819105
A35: Censea Inc | B35: =SUM(C35:G35) -> 1925474400 | E35: 1925474400
A36: Censea Inc | B36: =SUM(C36:G36) -> 1741421700 | E36: 1741421700
A37: Censea Inc | B37: =SUM(C37:G37) -> 2107954000 | E37: 2107954000
A38: Censea Inc | B38: =SUM(C38:G38) -> 1679834835 | E38: 1679834835
A39: Censea Inc | B39: =SUM(C39:G39) -> 1524333900 | E39: 1524333900
A40: Censea Inc | B40: =SUM(C40:G40) -> 1706498880 | D40: 1706498880
A41: Censea Inc | B41: =SUM(C41:G41) -> 1816930500 | E41: 1816930500
A42: Censea Inc | B42: =SUM(C42:G42) -> 1756051530 | E42: 1756051530
A43: Censea Inc | B43: =SUM(C43:G43) -> 2032445200 | E43: 2032445200
A44: Censea Inc | B44: =SUM(C44:G44) -> 1679834835 | E44: 1679834835
A45: Censea Inc | B45: =SUM(C45:G45) -> 1599842700 | E45: 1599842700
A46: Censea Inc | B46: =SUM(C46:G46) -> 1679834835 | E46: 1679834835
A47: Eastern Fish Company LLc | B47: =SUM(C47:G47) -> 2075233520 | F47: 2075233520
A48: Eastern Fish Company LLc | B48: =SUM(C48:G48) -> 1791760900 | E48: 1791760900
A49: Eastern Fish Company LLc | B49: =SUM(C49:G49) -> 1791760900 | G49: 1791760900
A50: Eiger Co Ltd | B50: =SUM(C50:G50) -> 1469275400 | D50: 1469275400
...

Sheet Aging IAS 22, 21 & 20-Adj MGN
A1: PT INDO AMERICAN SEAFOODS
A3: UMUR PIUTANG PER 31 Desember 2022
A5: NAMA PELANGGAN | B5: PIUTANG | C5: BELUM JATUH TEMPO | D5: SUDAH JATUH TEMPO
D6: < 30 HARI | E6: < 60 HARI | F6: < 90 HARI | G6: > 90 HARI
A8: Piutang Expor
A9: Alpha Trading Co Ltd | B9: =SUM(C9:G9) -> 1154639669 | E9: 1154639669
A10: Censea Inc | B10: =SUM(C10:G10) -> 1839819105 | E10: 1839819105
A11: Censea Inc | B11: =SUM(C11:G11) -> 1925474400 | E11: 1925474400
A12: Censea Inc | B12: =SUM(C12:G12) -> 1741421700 | E12: 1741421700
A13: Censea Inc | B13: =SUM(C13:G13) -> 2107954000 | E13: 2107954000
A14: Censea Inc | B14: =SUM(C14:G14) -> 1679834835 | E14: 1679834835
A15: Censea Inc | B15: =SUM(C15:G15) -> 1524333900 | E15: 1524333900
A16: Censea Inc | B16: =SUM(C16:G16) -> 1706498880 | D16: 1706498880
A17: Censea Inc | B17: =SUM(C17:G17) -> 1816930500 | E17: 1816930500
A18: Censea Inc | B18: =SUM(C18:G18) -> 1756051530 | E18: 1756051530
A19: Censea Inc | B19: =SUM(C19:G19) -> 2032445200 | E19: 2032445200
A20: Censea Inc | B20: =SUM(C20:G20) -> 1679834835 | E20: 1679834835
A21: Censea Inc | B21: =SUM(C21:G21) -> 1599842700 | E21: 1599842700
A22: Censea Inc | B22: =SUM(C22:G22) -> 1679834835 | E22: 1679834835
A23: Eastern Fish Company LLc | B23: =SUM(C23:G23) -> 2075233520 | F23: 2075233520
A24: Eastern Fish Company LLc | B24: =SUM(C24:G24) -> 1791760900 | E24: 1791760900
A25: Eastern Fish Company LLc | B25: =SUM(C25:G25) -> 1791760900 | G25: 1791760900
A26: Eiger Co Ltd | B26: =SUM(C26:G26) -> 1469275400 | D26: 1469275400
A27: Export Packer Co Ltd | B27: =SUM(C27:G27) -> 3.9848212e+08 | G27: 3.9848212e+08
A28: San Sugar Co Ltd | B28: =SUM(C28:G28) -> 1060584020 | D28: 1060584020
A29: Slade Gorton Inc | B29: =SUM(C29:G29) -> 1678812320 | F29: 1678812320
B30: =SUM(C30:G30) -> 0
A31: Piutang Lokal | B31: =SUM(C31:G31) -> 0
A32: CV Kanian Persada | B32: =SUM(C32:G32) -> 338402918 | G32: 338402918
A33: UD, Slamet | B33: =SUM(C33:G33) -> 30389987 | D33: 30389987
A34: Roda Jaya, Toko | B34: =SUM(C34:G34) -> 0
B35: =SUM(C35:G35) -> 0
A36: Piutang Afiliasi | B36: =SUM(C36:G36) -> 0
A37: Indokom Samudra Persada, PT | B37: =SUM(C37:G37) -> 0 | D37: =1657162809*0 -> 0 | E37: =390900541*0 -> 0 | F37: =2559816275*0 -> 0 | G37: =10819146361.4*0 -> 0 | H37: 1657162809 | I37: 390900541 | J37: 2559816275 | K37: 1.0819146e+10
A38: Irian Marine Product Development , PT | B38: =SUM(C38:G38) -> 1706915034 | G38: =3126475129-G43 -> 1706915034 | K38: 3126475129
B39: =SUM(C39:G39) -> 0
A40: JUMLAH | B40: =SUM(B7:B39) -> 3.6586533e+10 | C40: =SUM(C7:C39) -> 0 | D40: =SUM(D7:D39) -> 4266748287 | E40: =SUM(E7:E39) -> 24330178109 | F40: =SUM(F7:F39) -> 3754045840 | G40: =SUM(G7:G39) -> 4.235561e+09
G42: Note Irian Marin (Adj)
G43: 1419560095
A44: UMUR PIUTANG PER 31 Desember 2021
...

Sheet Suku bunga
S7: 2020
S24: 2021
S36: 2022

Sheet Aging IAS 22, 21 & 20
A1: PT INDO AMERICAN SEAFOODS
A3: UMUR PIUTANG PER 31 Desember 2022
A5: NAMA PELANGGAN | B5: PIUTANG | C5: BELUM JATUH TEMPO | D5: SUDAH JATUH TEMPO
D6: < 30 HARI | E6: < 60 HARI | F6: < 90 HARI | G6: > 90 HARI
A8: Piutang Expor
A9: Alpha Trading Co Ltd | B9: =SUM(C9:G9) -> 1154639669 | E9: 1154639669
A10: Censea Inc | B10: =SUM(C10:G10) -> 1839819105 | E10: 1839819105
A11: Censea Inc | B11: =SUM(C11:G11) -> 1925474400 | E11: 1925474400
A12: Censea Inc | B12: =SUM(C12:G12) -> 1741421700 | E12: 1741421700
A13: Censea Inc | B13: =SUM(C13:G13) -> 2107954000 | E13: 2107954000
A14: Censea Inc | B14: =SUM(C14:G14) -> 1679834835 | E14: 1679834835
A15: Censea Inc | B15: =SUM(C15:G15) -> 1524333900 | E15: 1524333900
A16: Censea Inc | B16: =SUM(C16:G16) -> 1706498880 | D16: 1706498880
A17: Censea Inc | B17: =SUM(C17:G17) -> 1816930500 | E17: 1816930500
A18: Censea Inc | B18: =SUM(C18:G18) -> 1756051530 | E18: 1756051530
A19: Censea Inc | B19: =SUM(C19:G19) -> 2032445200 | E19: 2032445200
A20: Censea Inc | B20: =SUM(C20:G20) -> 1679834835 | E20: 1679834835
A21: Censea Inc | B21: =SUM(C21:G21) -> 1599842700 | E21: 1599842700
A22: Censea Inc | B22: =SUM(C22:G22) -> 1679834835 | E22: 1679834835
A23: Eastern Fish Company LLc | B23: =SUM(C23:G23) -> 2075233520 | F23: 2075233520
A24: Eastern Fish Company LLc | B24: =SUM(C24:G24) -> 1791760900 | E24: 1791760900
A25: Eastern Fish Company LLc | B25: =SUM(C25:G25) -> 1791760900 | G25: 1791760900
A26: Eiger Co Ltd | B26: =SUM(C26:G26) -> 1469275400 | D26: 1469275400
A27: Export Packer Co Ltd | B27: =SUM(C27:G27) -> 3.9848212e+08 | G27: 3.9848212e+08
A28: San Sugar Co Ltd | B28: =SUM(C28:G28) -> 1060584020 | D28: 1060584020
A29: Slade Gorton Inc | B29: =SUM(C29:G29) -> 1678812320 | F29: 1678812320
B30: =SUM(C30:G30) -> 0
A31: Piutang Lokal | B31: =SUM(C31:G31) -> 0
A32: CV Kanian Persada | B32: =SUM(C32:G32) -> 338402918 | G32: 338402918
A33: UD, Slamet | B33: =SUM(C33:G33) -> 30389987 | D33: 30389987
A34: Roda Jaya, Toko | B34: =SUM(C34:G34) -> 0
B35: =SUM(C35:G35) -> 0
A36: Piutang Afiliasi | B36: =SUM(C36:G36) -> 0
A37: Indokom Samudra Persada, PT | B37: =SUM(C37:G37) -> 1.5427026e+10 | D37: 1657162809 | E37: 390900541 | F37: 2559816275 | G37: 1.0819146e+10
A38: Irian Marine Product Development , PT | B38: =SUM(C38:G38) -> 3126475129 | G38: 3126475129
B39: =SUM(C39:G39) -> 0
A40: JUMLAH | B40: =SUM(B7:B39) -> 5.3433119e+10 | C40: =SUM(C7:C39) -> 0 | D40: =SUM(D7:D39) -> 5923911096 | E40: =SUM(E7:E39) -> 24721078650 | F40: =SUM(F7:F39) -> 6313862115 | G40: =SUM(G7:G39) -> 1.6474267e+10
A42: UMUR PIUTANG PER 31 Desember 2021
A44: NAMA PELANGGAN | B44: PIUTANG | C44: BELUM JATUH TEMPO | D44: SUDAH JATUH TEMPO
D45: < 30 HARI | E45: < 60 HARI | F45: < 90 HARI | G45: > 90 HARI
...
