Workbook
Name \1: #REF!
Name \2: #REF!
Name \3: #REF!
Name \4: #REF!
Name \5: #REF!
Name \6: #REF!
Name \a: [1]JUL!#REF!
Name \A: #REF!
Name \APR: #REF!
Name \AUG: #REF!
Name \b: [2]T.B!#REF!
Name \B: #REF!
Name \BCYTD: '[3]CF WORKSHEET'!#REF!
Name \BRYTD: #REF!
Name \BSYTD: #REF!
Name \BTWO: #REF!
Name \BUYTD: #REF!
Name \C: #REF!
Name \CTWO: #REF!
Name \d: [2]T.B!#REF!
Name \D: #REF!
Name \DEC: #REF!
Name \DTWO: #REF!
Name \E: [4]SMITH!#REF!
Name \E: #REF!
Name \F: [4]SMITH!#REF!
Name \F: #REF!
Name \FEB: #REF!
Name \G: #REF!
Name \H: #REF!
Name \I: #REF!
Name \J: #REF!
Name \JAN: #REF!
Name \K: #REF!
Name \L: #REF!
Name \m: [2]T.B!#REF!
Name \M: #REF!
Name \MAR: #REF!
Name \MAY: #REF!
Name \MSN: #N/A
Name \n: #N/A
Name \NOV: #REF!
Name \O: #REF!
Name \OCT: #REF!
Name \p: #REF!
Name \Q: #REF!
Name \r: #REF!
Name \s: #REF!
Name \SEP: #REF!
Name \T: '[3]CF WORKSHEET'!#REF!
Name \T: #REF!
Name \T2: '[5]ban-ling'!#REF!
Name \U: #REF!
Name \V: #REF!
Name \w: #N/A
Name \x: #N/A
Name \y: #N/A
Name \Z: #REF!
Name \z: #N/A
Name _\b: #N/A

Sheet MAP
A1: ACCOUNTS PAYABLE AND ACCRUED LIABILITIES – AUDIT PROGRAM | C1: RMAP
A3: Client name: | B3: PT Indo American Seafoods Tbk dan Entitas Anak | C3: Sign-off: | D3: Initials | E3: Date
C4: Prepared: | D4: NLS | E4: 45814
C5: Reviewed: | D5: KNW | E5: 45817
A6: Period end: | B6: 45657 | C6: Approved: | D6: MGN | E6: 45822
A8: Financial Statement Assertions
A10: C. Completeness
A11: E. Existence
A12: A. Accuracy
A13: V. Valuation
A15: A. BASIC PROCEDURES
A16: No. | B16: Audit Procedure | C16: Assert | D16: Comment | E16: Ref.
A17: Accounts Payable Listing
A18: 0.041666667 | B18: For manual listings: | C18: A
B19: Obtain client's accounts payable listing and:
B20: a) Agree listing to general ledger.
B21: b) Test mathematical accuracy of listing.
A22: 0.083333333 | B22: For electronic listings: | C22: A
B23: Obtain electronically the client's detailed accounts payable listing and using the IDEA Audit Automation Tool:
B24: a) Agree control total to general ledger to ensure the listing was imported accurately and completely.
B25: b) Test mathematical accuracy of accounts payable listing.
A26: Debit balances
A27: 0.125 | B27: For electronic listings: | C27: A
B28: Using the Audit Automation tool, extract debit balances. Investigate significant debit balances and consider their transfer to accounts receivable.
A29: 0.16666667 | B29: For manual listings: | C29: A
B30: Investigate significant debit balances and consider their transfer to accounts receivable.
A31: Related Party Transactions
A32: 0.20833333 | B32: Document transactions and ending balances with related parties and ensure they are disclosed in the financial statements. | C32: CEAV
A33: 0.25 | B33: Verify that inter entity accounts are in agreement if we are the auditors of both entities. If not, obtain written confirmation. | C33: CEA
A34: 0.29166667 | B34: Enquire of management whether all related party transactions were appropriately identified (e.g. major cancelable contract, transact a significant volume of business with a sole customer, provide free use of space, personnel and services, preferential rates or lease property to and from related party) and recorded. | C34: C
A35: Merchandise Received on Consignment
A36: 0.33333333 | B36: Discuss with a responsible official that no amounts payable are included for merchandise received on consignment. | C36: A
A37: Major Suppliers
A38: 0.375 | B38: Select a sample of the client's major supplier(s) based on annual purchases and review a statement showing all outstanding invoices as at year end. (The statement may be obtained internally or by confirmation depending on the circumstances). | C38: CEAV
B39: a) Agree accounts payable on the A/P listing to supplier's statement or confirmation.
B40: b) Summarize the results and investigate differences by examining the supporting documentation and enquiry.
A41: 0.41666667 | B41: Perform alternative procedures where no reply was received from the supplier or where suppliers’ statements were not retained by the client. | C41: CE
B42: a) Obtain a detailed general ledger breakdown of the account;
B43: b) Review payments in the subsequent period and consider the need to examine supporting documentation;
B44: c) Check other significant debits to supporting documentation;
...

Sheet G. 100 Memo
A5: Client | B5: : PT Indo American Seafoods Tbk dan Entitas Anak | E5: Prepared by | F5: : NLS | K5: Date : | L5: 45814
A6: Account | B6: : Trade payable | E6: Reviewed by | F6: : KNW | K6: Date : | L6: 45817
A7: Period | B7: : 31 Desember 2024 | E7: Approved by: | F7: : MGN | K7: Date : | L7: 45822
A8: Matter | B8: : Memo
A11: NATURE OF ACCOUNT
B13: Utang Usaha | C13: : Merupakan utang usaha kepada supplier dan vendor terkait untuk kegiatan operasional Perusahaan
A15: PROCEDURES
B18: - Mencocokan angka Inhouse dengan general ledger
B19: - Mengirimkan Surat Konfirmasi
B20: - Meminta List AP
B21: - Mapping to Report
B22: - Meminta Aging Utang Usaha
A23: FINDINGS
B25: Pada akun Utang tidak ditemukan temuan yang material
A27: CONCLUSION
B29: Semua transaksi terkait Utang sudah disajikan dan telah sesuai dengan periode terjadinya transaksi, maka Utang telah disajikan secara wajar

Sheet G.200 Eliminasi 2023
B1: JURNAL ELIMINASI | F1: =SUM(F7:F513) -> 204309487586 | G1: =SUM(G7:G513) -> 204309487586 | I1: =F109-F112 -> 0
B2: KONSOLIDASI 2022
B5: Account No. | C5: Account Name | E5: WP Reff | F5: Balance Sheet | H5: Income Statement | J5: Description
F6: Debit | G6: Credit | H6: Debit | I6: Credit
A8: EL | C8: IAS - Modal | G8: 1050000000
D9: Investasi pada entitas anak | F9: =G8 -> 1050000000
C11: Piutang ISP | G11: 62518053072
D12: Utang IAS ke ISP | F12: =G11 -> 62518053072
D13: Penjualan ke IAS _ Pembelian ISP
A15: 2 | D15: Piutang IAS | G15: 132646777153
D16: Utang ISP | F16: =G15 -> 132646777153
D17: Penjualan ke ISP _
A18: 3
D19: Piutang IAS | G19: 8079657361
D20: Utang ISP | F20: =G19 -> 8079657361
A22: 4 | D22: Total Pembelian IAS ke ISP Udang | H22: 86959145763
D23: Roti | H23: 1694239200
D24: Lain" Sticker | H24: 583412160
D25: Pembelian IAS ke ISP Udang | I25: 86959145763
D26: Roti | I26: 1694239200
D27: Lain" Sticker | I27: 583412160
D30: Penjualan ke ISP | H30: 16455117914
D32: Pembelian | I32: =H30 -> 16455117914
D34: Pendapatan Lain" Sewa IPAL | H34: =15000000 -> 15000000
D35: Beban Sewa IPAL | I35: =H34 -> 15000000
B37: AJE | D37: Biaya YMH | F37: 15000000
D38: Piutang Lain-lain | G38: =F37 -> 15000000
D42: Jurnal Eliminasi 2022 & 2021

Sheet ELIM & CAJE Des 24
A1: JURNAL ELIMINASI | F1: Diff | G1: =G2-H2 -> 0
A2: Konsolidasi Desember 2024 | F2: Kontrol | G2: =F3+H3 -> 34150403486 | H2: =G3+I3 -> 34150403486
F3: =SUM(F8:F12) -> 34150403486 | G3: =SUM(G8:G12) -> 34150403486 | H3: =SUM(H8:H12) -> 0 | I3: =SUM(I8:I12) -> 0
A5: Account No. | B5: Date | C5: Account Name | E5: WP Reff | F5: Balance Sheet | H5: PL | J5: Description
F6: Debit | G6: Credit | H6: Debit | I6: Credit
A8: ELIM 2 | C8: PT Indokom Samudra Persada | F8: 29592782261 | J8: Eleminasi Utang Piutang
A9: =A8 -> ELIM 2 | D9: PT Indo American Seafoods | G9: =F8 -> 29592782261 | J9: =J8 -> Eleminasi Utang Piutang
A11: ELIM 3 | C11: PT Indo American Seafoods | F11: 4557621225 | J11: Eleminasi Utang Piutang
A12: =A11 -> ELIM 3 | D12: PT Indokom Samudra Persada | G12: =F11 -> 4557621225 | J12: =J11 -> Eleminasi Utang Piutang

Sheet G.500 LeadSheet
B6: Client | C6: : PT Indo American Seafoods Tbk dan Entitas Anak | F6: Prepared by | G6: : LFS | M6: Date : | N6: 03/07/2024
B7: Account | C7: : Piutang Usaha | F7: Reviewed by | G7: : FMN | M7: Date : | N7: 06/07/2024
B8: Period | C8: : 31 Desember 203,2022, dan 2021 | F8: Approved by: | G8: : MGN | M8: Date : | N8: 10/07/2024
B9: Index | C9: : Memo
B11: NO | C11: Description | D11: Audited PT IAS | E11: Audited PT ISP | F11: Audited PT Konsol | G11: Eliminasi | K11: Audited Konsol | M11: Audited PT IAS | N11: Audited PT ISP | O11: Audited PT Konsol | P11: Eliminasi | T11: Audited Konsol | V11: Incrase/Decrase 2024 dan 2023 | Y11: Incrase/Decrase 2021 dan 2020
B12: Account | D12: 31 Desember 2024 | E12: 31 Desember 2024 | F12: 31 Desember 2024 | G12: Ref | H12: Dr | I12: Ref | J12: Cr | K12: =F12 -> 31 Desember 2024 | M12: 45291 | N12: =M12 -> 45291 | O12: =N12 -> 45291 | P12: Ref | Q12: Dr | R12: Ref | S12: Cr | T12: =O12 -> 45291 | V12: Rp | W12: % | Y12: Rp | Z12: %
B13: Trade Payable
C14: Hutang Usaha | D14: 0 | F14: =ROUND((D14+E14),0) -> 0 | K14: =ROUND((F14-H14+J14),0) -> 0 | M14: 0 | N14: 0 | O14: =ROUND((M14+N14),0) -> 0 | T14: =ROUND((O14-Q14+S14),0) -> 0 | V14: =K14-T14 -> 0 | W14: =IFERROR(V14/T14,0) -> 0
B15: ISP | C15: Bapak Cipto | D15: 0 | E15: 19544752 | F15: =ROUND((D15+E15),0) -> 19544752 | K15: =ROUND((F15-H15+J15),0) -> 19544752 | M15: 0 | N15: 21911630 | O15: =ROUND((M15+N15),0) -> 21911630 | T15: =ROUND((O15-Q15+S15),0) -> 21911630 | V15: =K15-T15 -> -2366878 | W15: =IFERROR(V15/T15,0) -> -0.10801926
B16: ISP | C16: Supplier Bahan Baku Udang & Non Udang | D16: 0 | E16: 0 | F16: =ROUND((D16+E16),0) -> 0 | K16: =ROUND((F16-H16+J16),0) -> 0 | M16: 0 | N16: 0 | O16: =ROUND((M16+N16),0) -> 0 | T16: =ROUND((O16-Q16+S16),0) -> 0 | V16: =K16-T16 -> 0 | W16: =IFERROR(V16/T16,0) -> 0
B17: ISP | C17: Bakti Angurah Kreasi,CV | D17: 0 | E17: 0 | F17: =ROUND((D17+E17),0) -> 0 | K17: =ROUND((F17-H17+J17),0) -> 0 | M17: 0 | N17: 0 | O17: =ROUND((M17+N17),0) -> 0 | T17: =ROUND((O17-Q17+S17),0) -> 0 | V17: =K17-T17 -> 0 | W17: =IFERROR(V17/T17,0) -> 0
B18: ISP | C18: AGS Sejahtera, CV, | D18: 0 | E18: 40019800 | F18: =ROUND((D18+E18),0) -> 40019800 | K18: =ROUND((F18-H18+J18),0) -> 40019800 | M18: 0 | N18: 0 | O18: =ROUND((M18+N18),0) -> 0 | T18: =ROUND((O18-Q18+S18),0) -> 0 | V18: =K18-T18 -> 40019800 | W18: =IFERROR(V18/T18,0) -> 0
B19: ISP | C19: GEA Refrigeration Indonesia, PT | D19: 0 | E19: 0 | F19: =ROUND((D19+E19),0) -> 0 | K19: =ROUND((F19-H19+J19),0) -> 0 | M19: 0 | N19: 0 | O19: =ROUND((M19+N19),0) -> 0 | T19: =ROUND((O19-Q19+S19),0) -> 0 | V19: =K19-T19 -> 0 | W19: =IFERROR(V19/T19,0) -> 0
B20: ISP | C20: Halim Sakti Pratama, PT | D20: 0 | E20: 13506480 | F20: =ROUND((D20+E20),0) -> 13506480 | K20: =ROUND((F20-H20+J20),0) -> 13506480 | M20: 0 | N20: 1720500 | O20: =ROUND((M20+N20),0) -> 1720500 | T20: =ROUND((O20-Q20+S20),0) -> 1720500 | V20: =K20-T20 -> 11785980 | W20: =IFERROR(V20/T20,0) -> 6.8503226
B21: ISP | C21: Harapan Abadi, CV | D21: 0 | E21: 0 | F21: =ROUND((D21+E21),0) -> 0 | K21: =ROUND((F21-H21+J21),0) -> 0 | M21: 0 | N21: 0 | O21: =ROUND((M21+N21),0) -> 0 | T21: =ROUND((O21-Q21+S21),0) -> 0 | V21: =K21-T21 -> 0 | W21: =IFERROR(V21/T21,0) -> 0
B22: ISP | C22: Intiragam Oliefindo, PT | D22: 0 | E22: 24975000 | F22: =ROUND((D22+E22),0) -> 24975000 | K22: =ROUND((F22-H22+J22),0) -> 24975000 | M22: 0 | N22: 49950000 | O22: =ROUND((M22+N22),0) -> 49950000 | T22: =ROUND((O22-Q22+S22),0) -> 49950000 | V22: =K22-T22 -> -24975000 | W22: =IFERROR(V22/T22,0) -> -0.5
B23: ISP | C23: KARYA EKATAMA, PT | D23: 0 | E23: 0 | F23: =ROUND((D23+E23),0) -> 0 | K23: =ROUND((F23-H23+J23),0) -> 0 | M23: 0 | N23: 0 | O23: =ROUND((M23+N23),0) -> 0 | T23: =ROUND((O23-Q23+S23),0) -> 0 | V23: =K23-T23 -> 0 | W23: =IFERROR(V23/T23,0) -> 0
C24: R&B FOOD SUPPLY CO, LTD, | E24: 355200000 | F24: =ROUND((D24+E24),0) -> 355200000 | K24: =ROUND((F24-H24+J24),0) -> 355200000
B25: ISP | C25: Samara Cipta Solution, CV | D25: 0 | E25: 0 | F25: =ROUND((D25+E25),0) -> 0 | K25: =ROUND((F25-H25+J25),0) -> 0 | M25: 0 | N25: 122323133 | O25: =ROUND((M25+N25),0) -> 122323133 | T25: =ROUND((O25-Q25+S25),0) -> 122323133 | V25: =K25-T25 -> -122323133 | W25: =IFERROR(V25/T25,0) -> -1
B26: ISP | C26: Seven Mountain Internasional, PT | D26: 0 | E26: 29859000 | F26: =ROUND((D26+E26),0) -> 29859000 | K26: =ROUND((F26-H26+J26),0) -> 29859000 | M26: 0 | N26: 20684850 | O26: =ROUND((M26+N26),0) -> 20684850 | T26: =ROUND((O26-Q26+S26),0) -> 20684850 | V26: =K26-T26 -> 9174150 | W26: =IFERROR(V26/T26,0) -> 0.44352026
B27: ISP | C27: Sinar Panca Surya, PT | D27: 0 | E27: 0 | F27: =ROUND((D27+E27),0) -> 0 | K27: =ROUND((F27-H27+J27),0) -> 0 | M27: 0 | N27: 34576502 | O27: =ROUND((M27+N27),0) -> 34576502 | T27: =ROUND((O27-Q27+S27),0) -> 34576502 | V27: =K27-T27 -> -34576502 | W27: =IFERROR(V27/T27,0) -> -1
B28: ISP | C28: Sinar Setia Mulia , PT | D28: 0 | E28: 55230003 | F28: =ROUND((D28+E28),0) -> 55230003 | K28: =ROUND((F28-H28+J28),0) -> 55230003 | M28: 0 | N28: 56950000 | O28: =ROUND((M28+N28),0) -> 56950000 | T28: =ROUND((O28-Q28+S28),0) -> 56950000 | V28: =K28-T28 -> -1719997 | W28: =IFERROR(V28/T28,0) -> -0.030201879
C29: CV Windu Segara Hatchery | D29: 0 | E29: 0 | F29: =ROUND((D29+E29),0) -> 0 | K29: =ROUND((F29-H29+J29),0) -> 0 | O29: =ROUND((M29+N29),0) -> 0 | T29: =ROUND((O29-Q29+S29),0) -> 0 | V29: =K29-T29 -> 0 | W29: =IFERROR(V29/T29,0) -> 0
B30: ISP | C30: Central Proteina Prima, PT | D30: 0 | E30: 0 | F30: =ROUND((D30+E30),0) -> 0 | K30: =ROUND((F30-H30+J30),0) -> 0 | M30: 0 | N30: 0 | O30: =ROUND((M30+N30),0) -> 0 | T30: =ROUND((O30-Q30+S30),0) -> 0 | V30: =K30-T30 -> 0 | W30: =IFERROR(V30/T30,0) -> 0
B31: ISP | C31: Citra Boga Sentosa, PT | D31: 0 | E31: 0 | F31: =ROUND((D31+E31),0) -> 0 | K31: =ROUND((F31-H31+J31),0) -> 0 | M31: 0 | N31: 0 | O31: =ROUND((M31+N31),0) -> 0 | T31: =ROUND((O31-Q31+S31),0) -> 0 | V31: =K31-T31 -> 0 | W31: =IFERROR(V31/T31,0) -> 0
B32: ISP | C32: Indo Surya Cemerlang, CV | D32: 0 | E32: 0 | F32: =ROUND((D32+E32),0) -> 0 | K32: =ROUND((F32-H32+J32),0) -> 0 | M32: 0 | N32: 0 | O32: =ROUND((M32+N32),0) -> 0 | T32: =ROUND((O32-Q32+S32),0) -> 0 | V32: =K32-T32 -> 0 | W32: =IFERROR(V32/T32,0) -> 0
B33: ISP | C33: Nusantara, Toko | D33: 0 | E33: 0 | F33: =ROUND((D33+E33),0) -> 0 | K33: =ROUND((F33-H33+J33),0) -> 0 | M33: 0 | N33: 5025000 | O33: =ROUND((M33+N33),0) -> 5025000 | T33: =ROUND((O33-Q33+S33),0) -> 5025000 | V33: =K33-T33 -> -5025000 | W33: =IFERROR(V33/T33,0) -> -1
B34: ISP | C34: Newhope Aqua Feed Indonesia, PT | D34: 0 | E34: 0 | F34: =ROUND((D34+E34),0) -> 0 | K34: =ROUND((F34-H34+J34),0) -> 0 | M34: 0 | N34: 0 | O34: =ROUND((M34+N34),0) -> 0 | T34: =ROUND((O34-Q34+S34),0) -> 0 | V34: =K34-T34 -> 0 | W34: =IFERROR(V34/T34,0) -> 0
B35: ISP | C35: Surya Serba Mulia, PT | D35: 0 | E35: 0 | F35: =ROUND((D35+E35),0) -> 0 | K35: =ROUND((F35-H35+J35),0) -> 0 | M35: 0 | N35: 0 | O35: =ROUND((M35+N35),0) -> 0 | T35: =ROUND((O35-Q35+S35),0) -> 0 | V35: =K35-T35 -> 0 | W35: =IFERROR(V35/T35,0) -> 0
B36: ISP | C36: Sumatra Motor Teknindo, PT | D36: 0 | E36: 0 | F36: =ROUND((D36+E36),0) -> 0 | K36: =ROUND((F36-H36+J36),0) -> 0 | M36: 0 | N36: 97993099 | O36: =ROUND((M36+N36),0) -> 97993099 | T36: =ROUND((O36-Q36+S36),0) -> 97993099 | V36: =K36-T36 -> -97993099 | W36: =IFERROR(V36/T36,0) -> -1
B37: ISP | C37: Tri Jaya Sukses | D37: 17646570 | E37: 34791785 | F37: =ROUND((D37+E37),0) -> 52438355 | K37: =ROUND((F37-H37+J37),0) -> 52438355 | M37: 0 | N37: 0 | O37: =ROUND((M37+N37),0) -> 0 | T37: =ROUND((O37-Q37+S37),0) -> 0 | V37: =K37-T37 -> 52438355 | W37: =IFERROR(V37/T37,0) -> 0
B38: ISP | C38: Perc, Salma | D38: 0 | E38: 0 | F38: =ROUND((D38+E38),0) -> 0 | K38: =ROUND((F38-H38+J38),0) -> 0 | M38: 0 | N38: 0 | O38: =ROUND((M38+N38),0) -> 0 | T38: =ROUND((O38-Q38+S38),0) -> 0 | V38: =K38-T38 -> 0 | W38: =IFERROR(V38/T38,0) -> 0
B39: ISP | C39: AKR Corporindo Tbk, PT | D39: 0 | E39: 0 | F39: =ROUND((D39+E39),0) -> 0 | K39: =ROUND((F39-H39+J39),0) -> 0 | M39: 0 | N39: 75000000 | O39: =ROUND((M39+N39),0) -> 75000000 | T39: =ROUND((O39-Q39+S39),0) -> 75000000 | V39: =K39-T39 -> -75000000 | W39: =IFERROR(V39/T39,0) -> -1
B40: ISP | C40: General Agromesin Lestari, PT | D40: 0 | E40: 0 | F40: =ROUND((D40+E40),0) -> 0 | K40: =ROUND((F40-H40+J40),0) -> 0 | M40: 0 | N40: 116369995 | O40: =ROUND((M40+N40),0) -> 116369995 | T40: =ROUND((O40-Q40+S40),0) -> 116369995 | V40: =K40-T40 -> -116369995 | W40: =IFERROR(V40/T40,0) -> -1
B41: ISP | C41: Maju Tambak Sumur, PT | D41: 0 | E41: 0 | F41: =ROUND((D41+E41),0) -> 0 | K41: =ROUND((F41-H41+J41),0) -> 0 | M41: 0 | N41: 29249998 | O41: =ROUND((M41+N41),0) -> 29249998 | T41: =ROUND((O41-Q41+S41),0) -> 29249998 | V41: =K41-T41 -> -29249998 | W41: =IFERROR(V41/T41,0) -> -1
B42: ISP | C42: SUMBERDAYA SINAR BARU, PT | D42: 0 | E42: 55366010 | F42: =ROUND((D42+E42),0) -> 55366010 | K42: =ROUND((F42-H42+J42),0) -> 55366010 | M42: 0 | N42: 19068210 | O42: =ROUND((M42+N42),0) -> 19068210 | T42: =ROUND((O42-Q42+S42),0) -> 19068210 | V42: =K42-T42 -> 36297800 | W42: =IFERROR(V42/T42,0) -> 1.9035767
C43: PT Anesta Agung | D43: 494401450 | E43: 398165412 | F43: =ROUND((D43+E43),0) -> 892566862 | K43: =ROUND((F43-H43+J43),0) -> 892566862 | M43: 0 | N43: 9 | O43: =ROUND((M43+N43),0) -> 9 | T43: =ROUND((O43-Q43+S43),0) -> 9 | V43: =K43-T43 -> 892566853 | W43: =IFERROR(V43/T43,0) -> 99174095
C44: Choice Canning Company Inc, | D44: 0 | E44: 0 | F44: =ROUND((D44+E44),0) -> 0 | K44: =ROUND((F44-H44+J44),0) -> 0 | M44: 1356603529 | N44: 0 | O44: =ROUND((M44+N44),0) -> 1356603529 | T44: =ROUND((O44-Q44+S44),0) -> 1356603529 | V44: =K44-T44 -> -1356603529 | W44: =IFERROR(V44/T44,0) -> -1
C45: Tn. Julius Juyanto | D45: 0 | E45: 0 | F45: =ROUND((D45+E45),0) -> 0 | K45: =ROUND((F45-H45+J45),0) -> 0 | M45: 0 | N45: 0 | O45: =ROUND((M45+N45),0) -> 0 | T45: =ROUND((O45-Q45+S45),0) -> 0 | V45: =K45-T45 -> 0 | W45: =IFERROR(V45/T45,0) -> 0
C46: Tn. Sudirman | D46: 0 | E46: 0 | F46: =ROUND((D46+E46),0) -> 0 | K46: =ROUND((F46-H46+J46),0) -> 0 | M46: 0 | N46: 0 | O46: =ROUND((M46+N46),0) -> 0 | T46: =ROUND((O46-Q46+S46),0) -> 0 | V46: =K46-T46 -> 0 | W46: =IFERROR(V46/T46,0) -> 0
...

Sheet G.600 Konfirmasi Induk 2023
B6: Client | C6: : PT Indo American Seafoods Tbk dan Entitas Anak | F6: Prepared by | G6: : LFS | H6: Date : | I6: 45476
B7: Account | C7: : Trade payable | F7: Reviewed by | G7: : FMN | H7: Date : | I7: 45479
B8: Period | C8: : 31 Desember 2023, 2022, dan 2021 | F8: Approved by: | G8: : MGN | H8: Date : | I8: 45483
B9: Matter | C9: : Memo
B11: LIST KONFIRMASI UTANG USAHA (IDR)
B13: Item | C13: Nama | D13: Tanggal Konfirmasi Dikirim | E13: Tanggal Konfirmasi Diterima | F13: Saldo per LK | G13: Saldo per Konfirmasi | H13: Selisih | I13: Dokumen | J13: Telah Didiskusikan dengan Klien/Tim
B14: 1 | C14: Graha Makmur Cipta Pratama | D14: 45331 | E14: 45335 | F14: 1618149192 | G14: 1618150000 | H14: =F14-G14 -> -808
B15: 2 | C15: PT Konverta Mitra Abadi | D15: 45331 | E15: 45338 | F15: 304771930 | G15: 304771919 | H15: =F15-G15 -> 11
B16: 3 | C16: CV Putra Widjaja Marine | D16: 45331 | E16: 45355 | F16: 4355506677 | G16: 5016334672 | H16: =F16-G16 -> -660827995
B17: 4 | C17: Choice Canning Company Income | D17: 45331 | E17: 45355 | F17: 1356603529 | G17: 1356603529 | H17: =F17-G17 -> 0
B18: 5 | C18: PT Indocom Samudra Persada | D18: 45331 | E18: 45357 | F18: 62518053072 | G18: 62518053072 | H18: =F18-G18 -> 0
B19: 6 | C19: PT Indonesia Makan Udang | D19: 45331 | E19: 45357 | F19: 2634498031 | G19: 2634498031 | H19: =F19-G19 -> 0
B20: 7 | C20: PT Indoplast Jaya Sukses Makmur | D20: 45331 | F20: 121624520
B21: 8 | C21: PT International Packaging Manufaktuaring | D21: 45331 | F21: 668830500
B25: LIST KONFIRMASI UTANG USAHA (USD)
B27: Item | C27: Nama | D27: Tanggal Konfirmasi Dikirim | E27: Tanggal Konfirmasi Diterima | F27: Saldo per LK | G27: Saldo per Konfirmasi (USD) | H27: KURS | I27: IDR | J27: Selisih | K27: Dokumen
B28: 1 | C28: Choice Canning Company Income | D28: 45331 | E28: 45341 | F28: 1356603529 | G28: 87999.71 | H28: 15416 | I28: =G28*H28 -> 1.3566035e+09 | J28: =F28-I28 -> -0.36000013

Sheet KONSOL
A2: Aging Utang Usaha Konsol
D3: 45627 | F3: 45536 | H3: 45444 | J3: 2023 | L3: 2022 | N3: 2021 | P3: 2020
B5: Lancar | D5: ='Summary ISP'!D5+'Summay IAS'!E6 -> 2.2146511e+09 | F5: ='Summary ISP'!F5+'Summay IAS'!G6 -> 7.7670721e+09 | H5: ='Summay IAS'!I6+'Summary ISP'!H5 -> #REF! | J5: =#REF!+#REF! -> #REF! | L5: ='Summary ISP'!L5+'Summay IAS'!M6 -> #REF! | N5: ='Summary ISP'!N5+'Summay IAS'!O6 -> #REF! | P5: ='Summary ISP'!P5+'Summay IAS'!Q6 -> 13648880412
B6: 1-30 Hari | D6: ='Summary ISP'!D6+'Summay IAS'!E7 -> 2.1037291e+09 | F6: ='Summary ISP'!F6+'Summay IAS'!G7 -> 2.4155684e+09 | H6: ='Summay IAS'!I7+'Summary ISP'!H6 -> #REF! | J6: =#REF!+#REF! -> #REF! | L6: ='Summary ISP'!L6+'Summay IAS'!M7 -> #REF! | N6: ='Summary ISP'!N6+'Summay IAS'!O7 -> #REF! | P6: ='Summary ISP'!P6+'Summay IAS'!Q7 -> 2376774695
B7: 31-60 Hari | D7: ='Summary ISP'!D7+'Summay IAS'!E8 -> 1073353781 | F7: ='Summary ISP'!F7+'Summay IAS'!G8 -> 198335036 | H7: ='Summay IAS'!I8+'Summary ISP'!H7 -> #REF! | J7: =#REF!+#REF! -> #REF! | L7: ='Summary ISP'!L7+'Summay IAS'!M8 -> #REF! | N7: ='Summary ISP'!N7+'Summay IAS'!O8 -> #REF! | P7: ='Summary ISP'!P7+'Summay IAS'!Q8 -> 1327345930
B8: 61-90 Hari | D8: ='Summary ISP'!D8+'Summay IAS'!E9 -> 92483018 | F8: ='Summary ISP'!F8+'Summay IAS'!G9 -> 90386309 | H8: ='Summay IAS'!I9+'Summary ISP'!H8 -> #REF! | J8: =#REF!+#REF! -> #REF! | L8: ='Summary ISP'!L8+'Summay IAS'!M9 -> #REF! | N8: ='Summary ISP'!N8+'Summay IAS'!O9 -> #REF! | P8: ='Summary ISP'!P8+'Summay IAS'!Q9 -> 641088591 | R8: Utang Pph 28 A (IAS)
B9: > 90 Hari | D9: ='Summary ISP'!D9+'Summay IAS'!E10 -> 220877955 | F9: ='Summary ISP'!F9+'Summay IAS'!G10 -> 1.7373273e+08 | H9: ='Summay IAS'!I10+'Summary ISP'!H9 -> #REF! | J9: =#REF!+#REF!+R9 -> #REF! | L9: ='Summary ISP'!L9+'Summay IAS'!M10 -> #REF! | N9: ='Summary ISP'!N9+'Summay IAS'!O10 -> #REF! | P9: ='Summary ISP'!P9+'Summay IAS'!Q10 -> 143873935 | R9: 451584604
D11: =SUM(D5:D9) -> 5.705095e+09 | F11: =SUM(F5:F9) -> 1.0645095e+10 | H11: =SUM(H5:H9) -> #REF! | J11: =SUM(J5:J9) -> #REF! | L11: =SUM(L5:L9) -> #REF! | N11: =SUM(N5:N9) -> #REF! | P11: =SUM(P5:P9) -> 18137963563
F12: 10645094570 | J12: 19956316532
D13: =D11-D12 -> 5.705095e+09 | F13: =F11-F12 -> -0.16999817 | J13: =J12-J11 -> #REF!
A14: Aging Piutang Usaha Konsol
D15: =D3 -> 45627 | F15: =F3 -> 45536 | H15: =H3 -> 45444 | J15: 2023 | L15: 2022 | N15: 2021 | P15: 2020
B17: Lancar | D17: ='Summary ISP'!D18+'Summay IAS'!E18 -> #REF! | F17: ='Summary ISP'!F18+'Summay IAS'!G18 -> #REF! | H17: ='Summay IAS'!I18+'Summary ISP'!H18 -> #REF! | J17: =#REF!+#REF! -> #REF! | L17: ='Summary ISP'!L18+'Summay IAS'!M18 -> #REF! | N17: ='Summary ISP'!N18+'Summay IAS'!O18 -> #REF! | P17: ='Summary ISP'!P18+'Summay IAS'!Q18 -> #REF!
B18: 1-30 Hari | D18: ='Summary ISP'!D19+'Summay IAS'!E19 -> #REF! | F18: ='Summary ISP'!F19+'Summay IAS'!G19 -> #REF! | H18: ='Summay IAS'!I19+'Summary ISP'!H19 -> #REF! | J18: =#REF!+#REF! -> #REF! | L18: ='Summary ISP'!L19+'Summay IAS'!M19 -> #REF! | N18: ='Summary ISP'!N19+'Summay IAS'!O19 -> #REF! | P18: ='Summary ISP'!P19+'Summay IAS'!Q19 -> #REF!
B19: 31-60 Hari | D19: ='Summary ISP'!D20+'Summay IAS'!E20 -> #REF! | F19: ='Summary ISP'!F20+'Summay IAS'!G20 -> #REF! | H19: ='Summay IAS'!I20+'Summary ISP'!H20 -> #REF! | J19: =#REF!+#REF! -> #REF! | L19: ='Summary ISP'!L20+'Summay IAS'!M20 -> #REF! | N19: ='Summary ISP'!N20+'Summay IAS'!O20 -> #REF! | P19: ='Summary ISP'!P20+'Summay IAS'!Q20 -> #REF!
B20: 61-90 Hari | D20: ='Summary ISP'!D21+'Summay IAS'!E21 -> #REF! | F20: ='Summary ISP'!F21+'Summay IAS'!G21 -> #REF! | H20: ='Summay IAS'!I21+'Summary ISP'!H21 -> #REF! | J20: =#REF!+#REF! -> #REF! | L20: ='Summary ISP'!L21+'Summay IAS'!M21 -> #REF! | N20: ='Summary ISP'!N21+'Summay IAS'!O21 -> #REF! | P20: ='Summary ISP'!P21+'Summay IAS'!Q21 -> #REF!
B21: > 90 Hari | D21: ='Summary ISP'!D22+'Summay IAS'!E22 -> #REF! | F21: ='Summary ISP'!F22+'Summay IAS'!G22 -> #REF! | H21: ='Summay IAS'!I22+'Summary ISP'!H22 -> #REF! | J21: =#REF!+#REF! -> #REF! | L21: ='Summary ISP'!L22+'Summay IAS'!M22 -> #REF! | N21: ='Summary ISP'!N22+'Summay IAS'!O22 -> #REF! | P21: ='Summary ISP'!P22+'Summay IAS'!Q22 -> #REF!
D23: =SUM(D17:D21) -> #REF! | F23: =SUM(F17:F21) -> #REF! | H23: =SUM(H17:H21) -> #REF! | J23: =SUM(J17:J21) -> #REF! | L23: =SUM(L17:L21) -> #REF! | N23: =SUM(N17:N21) -> #REF! | P23: =SUM(P17:P21) -> #REF!
B24: WBS | F24: 39419408952 | H24: 27762015495 | J24: =21754550980-102746 -> 21754448234
B25: CV Kanian | D25: =D23-D24 -> #REF! | F25: =F23-F24 -> #REF! | H25: =H23-H24 -> #REF! | J25: =J23-J24 -> #REF!

Sheet Summary ISP
A2: Aging Utang Usaha
D3: 45627 | F3: 45536 | H3: 45444 | J3: 2023 | L3: 2022 | N3: 2021 | P3: 2020
B5: Lancar | D5: ='Hutang ISP Des 24'!H4 -> 8.8174967e+08 | F5: ='Hutang Usaha ISP Sept 2024'!H$4 -> 4.9834664e+09 | H5: =#REF! -> #REF! | J5: =#REF! -> #REF! | L5: =#REF! -> #REF! | N5: =#REF! -> #REF! | P5: ='[188]Utang Usaha ISP 2020'!K552 -> 7552183808
B6: 1-30 Hari | D6: ='Hutang ISP Des 24'!I4 -> 5.2566013e+08 | F6: ='Hutang Usaha ISP Sept 2024'!I$4 -> 1982303832 | H6: =#REF! -> #REF! | J6: =#REF! -> #REF! | L6: =#REF! -> #REF! | N6: =#REF! -> #REF! | P6: ='[188]Utang Usaha ISP 2020'!L552 -> 1169547930
B7: 31-60 Hari | D7: ='Hutang ISP Des 24'!J4 -> 623745086 | F7: ='Hutang Usaha ISP Sept 2024'!J$4 -> 184180750 | H7: =#REF! -> #REF! | J7: =#REF! -> #REF! | L7: =#REF! -> #REF! | N7: =#REF! -> #REF! | P7: ='[188]Utang Usaha ISP 2020'!M552 -> 265263198
B8: 61-90 Hari | D8: ='Hutang ISP Des 24'!K4 -> 69093320 | F8: ='Hutang Usaha ISP Sept 2024'!K$4 -> 82354849 | H8: =#REF! -> #REF! | J8: =#REF! -> #REF! | L8: =#REF! -> #REF! | N8: =#REF! -> #REF! | P8: ='[188]Utang Usaha ISP 2020'!N552 -> 75373754
B9: > 90 Hari | D9: ='Hutang ISP Des 24'!L4 -> 220877955 | F9: ='Hutang Usaha ISP Sept 2024'!L$4-2.49000072479248 -> 1.5486446e+08 | H9: =#REF!+1.80000019073486 -> #REF! | J9: =#REF! -> #REF! | L9: =#REF! -> #REF! | N9: =#REF! -> #REF! | P9: ='[188]Utang Usaha ISP 2020'!O552+52 -> 143873935
D11: =SUM(D5:D9) -> 2.3211262e+09 | F11: =SUM(F5:F9) -> 7387170280 | H11: =SUM(H5:H9) -> #REF! | J11: =SUM(J5:J9) -> #REF! | L11: =SUM(L5:L9) -> #REF! | N11: =SUM(N5:N9) -> #REF! | P11: =SUM(P5:P9) -> 9206242625
A12: Ctrl WBS | F12: 7387170280 | H12: 6809572845 | J12: =16458420785.62-J11 -> #REF! | L12: =23019876420-L11-759090 -> #REF! | N12: =19763642459-N11-759090 -> #REF! | P12: =9206242625-P11 -> 0
D13: =D11-D12 -> 2.3211262e+09 | F13: =F11-F12 -> 0 | H13: =H11-H12 -> #REF!
A15: Aging Piutang Usaha
D16: =D3 -> 45627 | F16: 45536 | H16: 45444 | J16: 2023 | L16: 2022 | N16: 2021 | P16: 2020
B18: Lancar | D18: =#REF! -> #REF! | F18: =#REF! -> #REF! | H18: =#REF! -> #REF! | J18: =#REF! -> #REF! | L18: =#REF! -> #REF! | N18: =#REF! -> #REF! | P18: =#REF! -> #REF!
B19: 1-30 Hari | D19: =#REF! -> #REF! | F19: =#REF!-0.239997863769531 -> #REF! | H19: =#REF! -> #REF! | J19: =#REF! -> #REF! | L19: =#REF! -> #REF! | N19: =#REF! -> #REF! | P19: =#REF! -> #REF!
B20: 31-60 Hari | D20: =#REF! -> #REF! | H20: =#REF! -> #REF! | J20: =#REF! -> #REF! | L20: =#REF! -> #REF! | N20: =#REF! -> #REF! | P20: =#REF! -> #REF!
B21: 61-90 Hari | D21: =#REF! -> #REF! | H21: =#REF! -> #REF! | J21: =#REF! -> #REF! | L21: =#REF! -> #REF! | N21: =#REF! -> #REF! | P21: =#REF! -> #REF!
B22: > 90 Hari | D22: =#REF! -> #REF! | H22: =#REF! -> #REF! | J22: =#REF! -> #REF! | L22: =#REF! -> #REF! | N22: =#REF! -> #REF! | P22: =#REF!-5.08 -> #REF!
D24: =SUM(D18:D22) -> #REF! | F24: =SUM(F18:F22) -> #REF! | H24: =SUM(H18:H22) -> #REF! | J24: =SUM(J18:J22) -> #REF! | L24: =SUM(L18:L22) -> #REF! | N24: =SUM(N18:N22) -> #REF! | P24: =SUM(P18:P22) -> #REF!
F25: 1.5888229e+10
A26: Ctrl WBS | D26: =D24-D25 -> #REF! | F26: =F24-F25 -> #REF! | J26: =70242197387-J24 -> #REF! | L26: =28760265833.56-L24 -> #REF! | N26: =24987319485.2-N24 -> #REF! | P26: =20131289994 -P24 -> #REF!

Sheet Summay IAS
B3: Aging Utang Usaha
E4: 45627 | G4: 45536 | I4: 45444 | K4: 2023 | M4: 2022 | O4: 2021 | Q4: 2020
C6: Lancar | E6: ='Hutang IAS Des 24'!H4 -> 1332901449 | G6: ='Hutang IAS Sept 24'!H4 -> 2.7836057e+09 | I6: =#REF! -> #REF! | K6: =#REF! -> #REF! | M6: 2552178138 | O6: 2580119628 | Q6: 6096696604
C7: 1-30 Hari | E7: ='Hutang IAS Des 24'!I4 -> 1.578069e+09 | G7: ='Hutang IAS Sept 24'!I$4 -> 4.332646e+08 | I7: =#REF! -> #REF! | K7: =#REF! -> #REF! | M7: 2175564942 | O7: 5103188666 | Q7: 1207226765
C8: 31-60 Hari | E8: ='Hutang IAS Des 24'!J4 -> 449608695 | G8: ='Hutang IAS Sept 24'!J$4 -> 14154286 | I8: =#REF! -> #REF! | K8: =#REF! -> #REF! | M8: 1567526266 | O8: 351492284 | Q8: 1062082732
C9: 61-90 Hari | E9: ='Hutang IAS Des 24'!K4 -> 23389698 | G9: ='Hutang IAS Sept 24'!K$4 -> 8031460 | I9: =#REF! -> #REF! | K9: =#REF! -> #REF! | M9: 224952512 | O9: 454277978 | Q9: 565714837
C10: > 90 Hari | E10: ='Hutang IAS Des 24'!L4 -> 0 | G10: ='Hutang IAS Sept 24'!L$4+0.100000381469727 -> 18868270 | I10: =#REF! -> #REF! | K10: =#REF! -> #REF! | M10: 224952512 | O10: 360998482 | Q10: 0
E12: =SUM(E6:E10) -> 3.3839688e+09 | G12: =SUM(G6:G10) -> 3.2579243e+09 | I12: =SUM(I6:I10) -> #REF! | K12: =SUM(K6:K10) -> #REF! | M12: =SUM(M6:M10) -> 6745174370 | O12: =SUM(O6:O10) -> 8850077038 | Q12: =SUM(Q6:Q10) -> 8931720938
G13: =3257924291-1 -> 3257924290
E14: =E12-E13 -> 3.3839688e+09 | G14: =G12-G13 -> -0.17000008
B15: Aging Piutang Usaha
E16: =E4 -> 45627 | G16: 45536 | I16: 45444 | K16: 2023 | M16: 2022 | O16: 2021 | Q16: 2020
C18: Lancar | E18: =#REF! -> #REF! | G18: =#REF!+0.5 -> #REF! | I18: =#REF! -> #REF! | K18: =#REF! -> #REF! | M18: 0 | O18: 0 | Q18: =#REF! -> #REF!
C19: 1-30 Hari | E19: =#REF! -> #REF! | G19: =#REF! -> #REF! | I19: =#REF! -> #REF! | K19: =#REF! -> #REF! | M19: 5923911096 | O19: 8816275366 | Q19: 2788921952
C20: 31-60 Hari | E20: =#REF! -> #REF! | G20: =#REF! -> #REF! | I20: =#REF! -> #REF! | K20: =#REF! -> #REF! | M20: 24721078650 | O20: 8872293947 | Q20: 19885079001
C21: 61-90 Hari | E21: =#REF! -> #REF! | G21: =#REF! -> #REF! | I21: =#REF! -> #REF! | K21: =#REF! -> #REF! | M21: 6313862115 | O21: 14206236599 | Q21: 378957063
C22: > 90 Hari | E22: =#REF! -> #REF! | G22: =#REF! -> #REF! | I22: =#REF! -> #REF! | K22: =#REF! -> #REF! | M22: 14738580699 | O22: 5093397335 | Q22: 0
E24: =SUM(E18:E22) -> #REF! | G24: =SUM(G18:G22) -> #REF! | I24: =SUM(I18:I22) -> #REF! | K24: =SUM(K18:K22) -> #REF! | M24: =SUM(M18:M22) -> 51697432560 | O24: =SUM(O18:O22) -> 36988203247 | Q24: =SUM(Q18:Q22) -> #REF!
G25: 23871074595 | I25: 11323392105
E26: =E24-E25 -> #REF! | G26: =G24-G25 -> #REF! | I26: =I24-I25 -> #REF!

Sheet Hutang IAS Des 24
A1: Aging Hutang Usaha & Subsequent | B1: =SUM(B3:B4)-B2 -> 0.43000031
A2: PT Indo American Seafoods | B2: 4.3068897e+09 | C2: WBS
A3: 45657
B4: =SUBTOTAL(9,B6:B105) -> 4.3068897e+09 | H4: =SUBTOTAL(9,H6:H90) -> 1332901449 | I4: =SUBTOTAL(9,I6:I90) -> 1.578069e+09 | J4: =SUBTOTAL(9,J6:J90) -> 449608695 | K4: =SUBTOTAL(9,K6:K90) -> 23389698 | L4: =SUBTOTAL(9,L6:L90) -> 0 | M4: =SUM(H4:L4)-B4 -> -9.2292085e+08
A5: Nama | B5: Nominal | C5: No Invoice | D5: Tgl Invoice | E5: Jatuh Tempo | F5: Tgl Jatuh Tempo | G5: Aging | H5: Lancar | I5: 1-30 Hari | J5: 31-60 Hari | K5: 61-90 Hari | L5: >90 Hari
A6: PT Anesta Agung | B6: 284103154 | C6: 1048 | D6: 45649 | E6: 30 | F6: =D6+E6 -> 45679 | G6: =$A$3-F6 -> -22 | H6: =B6 -> 284103154
A7: PT Anesta Agung | B7: 210298296 | C7: 1057 | D7: 45650 | E7: 30 | F7: =D7+E7 -> 45680 | G7: =$A$3-F7 -> -23 | H7: =B7 -> 210298296
A9: PT Konverta Mitra Abadi | B9: 15717156 | C9: 704 | D9: 45572 | E9: 30 | F9: =D9+E9 -> 45602 | G9: =$A$3-F9 -> 55 | J9: =B9 -> 15717156
A10: PT Konverta Mitra Abadi | B10: 84992700 | C10: 719 | D10: 45577 | E10: 30 | F10: =D10+E10 -> 45607 | G10: =$A$3-F10 -> 50 | J10: =B10 -> 84992700
A11: PT Konverta Mitra Abadi | B11: =1403317+12 -> 1403329 | C11: 738 | D11: 45582 | E11: 30 | F11: =D11+E11 -> 45612 | G11: =$A$3-F11 -> 45 | J11: =B11 -> 1403329
A12: PT Konverta Mitra Abadi | B12: 29592600 | C12: 739 | D12: 45582 | E12: 30 | F12: =D12+E12 -> 45612 | G12: =$A$3-F12 -> 45 | J12: =B12 -> 29592600
A13: PT Konverta Mitra Abadi | B13: 48518100 | C13: 743 | D13: 45584 | E13: 30 | F13: =D13+E13 -> 45614 | G13: =$A$3-F13 -> 43 | J13: =B13 -> 48518100
A14: PT Konverta Mitra Abadi | B14: 2752800 | C14: 744 | D14: 45584 | E14: 30 | F14: =D14+E14 -> 45614 | G14: =$A$3-F14 -> 43 | J14: =B14 -> 2752800
A15: PT Konverta Mitra Abadi | B15: 4129200 | C15: 747 | D15: 45586 | E15: 30 | F15: =D15+E15 -> 45616 | G15: =$A$3-F15 -> 41 | J15: =B15 -> 4129200
A16: PT Konverta Mitra Abadi | B16: 1455432 | C16: 748 | D16: 45586 | E16: 30 | F16: =D16+E16 -> 45616 | G16: =$A$3-F16 -> 41 | J16: =B16 -> 1455432
A17: PT Konverta Mitra Abadi | B17: 46825905 | C17: 760 | D17: 45588 | E17: 30 | F17: =D17+E17 -> 45618 | G17: =$A$3-F17 -> 39 | J17: =B17 -> 46825905
A18: PT Konverta Mitra Abadi | B18: 13382604 | C18: 866 | D18: 45621 | E18: 30 | F18: =D18+E18 -> 45651 | G18: =$A$3-F18 -> 6 | I18: =B18 -> 13382604
A19: PT Konverta Mitra Abadi | B19: 5017477 | C19: 867 | D19: 45621 | E19: 30 | F19: =D19+E19 -> 45651 | G19: =$A$3-F19 -> 6 | I19: =B19 -> 5017477
A20: PT Konverta Mitra Abadi | B20: 8559432 | C20: 868 | D20: 45621 | E20: 30 | F20: =D20+E20 -> 45651 | G20: =$A$3-F20 -> 6 | I20: =B20 -> 8559432
A21: PT Konverta Mitra Abadi | B21: 5839809.9 | C21: 869 | D21: 45621 | E21: 30 | F21: =D21+E21 -> 45651 | G21: =$A$3-F21 -> 6 | I21: =B21 -> 5839809.9
A22: PT Konverta Mitra Abadi | B22: 4856250 | C22: 870 | D22: 45621 | E22: 30 | F22: =D22+E22 -> 45651 | G22: =$A$3-F22 -> 6 | I22: =B22 -> 4856250
A23: PT Konverta Mitra Abadi | B23: 4944184 | C23: 871 | D23: 45621 | E23: 30 | F23: =D23+E23 -> 45651 | G23: =$A$3-F23 -> 6 | I23: =B23 -> 4944184
A24: PT Konverta Mitra Abadi | B24: 2593670 | C24: 895 | D24: 45631 | E24: 30 | F24: =D24+E24 -> 45661 | G24: =$A$3-F24 -> -4 | H24: =B24 -> 2593670
A25: PT Konverta Mitra Abadi | B25: 47416980 | C25: 939 | D25: 45655 | E25: 30 | F25: =D25+E25 -> 45685 | G25: =$A$3-F25 -> -28 | H25: =B25 -> 47416980
A26: PT Konverta Mitra Abadi | B26: 5011650 | C26: 940 | D26: 45655 | E26: 30 | F26: =D26+E26 -> 45685 | G26: =$A$3-F26 -> -28 | H26: =B26 -> 5011650
A27: PT Konverta Mitra Abadi | B27: 5137524 | C27: 941 | D27: 45655 | E27: 30 | F27: =D27+E27 -> 45685 | G27: =$A$3-F27 -> -28 | H27: =B27 -> 5137524
A29: PT Sumber Energy | B29: 31635000 | C29: 819 | D29: 45598 | E29: 30 | F29: =D29+E29 -> 45628 | G29: =$A$3-F29 -> 29 | I29: =B29 -> 31635000
A31: PT Indonesia Makan Udang | B31: 263573280 | C31: 991 | D31: 45644 | E31: 30 | F31: =D31+E31 -> 45674 | G31: =$A$3-F31 -> -17 | H31: =B31 -> 263573280
A32: PT Indonesia Makan Udang | B32: 195716165 | C32: 990 | D32: 45644 | E32: 30 | F32: =D32+E32 -> 45674 | G32: =$A$3-F32 -> -17 | H32: =B32 -> 195716165
A33: PT Indonesia Makan Udang | B33: 258146422 | C33: 989 | D33: 45644 | E33: 30 | F33: =D33+E33 -> 45674 | G33: =$A$3-F33 -> -17 | H33: =B33 -> 258146422
A34: PT Indonesia Makan Udang | B34: 97381200 | C34: 948 | D34: 45619 | E34: 30 | F34: =D34+E34 -> 45649 | G34: =$A$3-F34 -> 8 | I34: =B34 -> 97381200
A35: PT Indonesia Makan Udang | B35: 133422750 | C35: 943 | D35: 45618 | E35: 30 | F35: =D35+E35 -> 45648 | G35: =$A$3-F35 -> 9 | I35: =B35 -> 133422750
A36: PT Indonesia Makan Udang | B36: 259527644 | C36: 897 | D36: 45608 | E36: 30 | F36: =D36+E36 -> 45638 | G36: =$A$3-F36 -> 19 | I36: =B36 -> 259527644
A37: PT Indonesia Makan Udang | B37: 369633462 | C37: 851 | D37: 45598 | E37: 30 | F37: =D37+E37 -> 45628 | G37: =$A$3-F37 -> 29 | I37: =B37 -> 369633462
A38: PT Indonesia Makan Udang | B38: 289827482 | C38: 847 | D38: 45597 | E38: 30 | F38: =D38+E38 -> 45627 | G38: =$A$3-F38 -> 30 | I38: =B38 -> 289827482
A39: PT Indonesia Makan Udang | B39: 69901783 | C39: 813 | D39: 45591 | E39: 30 | F39: =D39+E39 -> 45621 | G39: =$A$3-F39 -> 36 | J39: =B39 -> 69901783
A40: PT Indonesia Makan Udang | B40: 132927190 | C40: 805 | D40: 45590 | E40: 30 | F40: =D40+E40 -> 45620 | G40: =$A$3-F40 -> 37 | J40: =B40 -> 132927190
A43: PT Sinergy Indopack Makmur | B43: 23976000 | C43: 859 | D43: 45618 | E43: 30 | F43: =D43+E43 -> 45648 | G43: =$A$3-F43 -> 9 | I43: =B43 -> 23976000
A44: PT Sinergy Indopack Makmur | B44: 23976000 | C44: 860 | D44: 45618 | E44: 30 | F44: =D44+E44 -> 45648 | G44: =$A$3-F44 -> 9 | I44: =B44 -> 23976000
A45: PT Sinergy Indopack Makmur | B45: 11188800 | C45: 908 | D45: 45635 | E45: 30 | F45: =D45+E45 -> 45665 | G45: =$A$3-F45 -> -8 | H45: =B45 -> 11188800
...

Sheet Hutang ISP Des 24
A1: Aging Hutang Usaha & Subsequent
A2: PT Indokom Samudra Persada | B2: =B3-B4 -> -0.46000004
A3: 45657 | B3: 2321126163 | C3: WBS
B4: =SUBTOTAL(9,B6:B78) -> 2.3211262e+09 | H4: =SUBTOTAL(9,H6:H78) -> 8.8174967e+08 | I4: =SUBTOTAL(9,I6:I78) -> 5.2566013e+08 | J4: =SUBTOTAL(9,J6:J78) -> 623745086 | K4: =SUBTOTAL(9,K6:K78) -> 69093320 | L4: =SUBTOTAL(9,L6:L78) -> 220877955 | M4: =SUM(H4:L4)-B4 -> 0
A5: Nama | B5: Nominal | C5: No Invoice | D5: Tgl Invoice | E5: Jatuh Tempo | F5: Tgl Jatuh Tempo | G5: Aging | H5: Lancar | I5: 1-30 Hari | J5: 31-60 Hari | K5: 61-90 Hari | L5: >90 Hari
A6: Bapak Cipto | B6: 19544752 | I6: =B6 -> 19544752
A8: AGS Sejahtera, CV, | B8: 22904000 | C8: 18 | D8: 45566 | E8: 30 | F8: =D8+E8 -> 45596 | G8: =$A$3-F8 -> 61 | K8: =B8 -> 22904000
A9: AGS Sejahtera, CV, | B9: 17115800 | C9: 23 | D9: 45640 | E9: 30 | F9: =D9+E9 -> 45670 | G9: =$A$3-F9 -> -13 | H9: =B9 -> 17115800
A11: Halim Sakti Pratama, PT | B11: 13506480 | C11: 36 | D11: 45553 | E11: 30 | F11: =D11+E11 -> 45583 | G11: =$A$3-F11 -> 74 | K11: =B11 -> 13506480
A13: Intiragam Oliefindo, PT | B13: 24975000 | C13: 397 | D13: 45546 | E13: 30 | F13: =D13+E13 -> 45576 | G13: =$A$3-F13 -> 81 | K13: =B13 -> 24975000
A15: Konverta Mitra Abadi, PT | B15: 7707840 | C15: 518 | D15: 45586 | E15: 30 | F15: =D15+E15 -> 45616 | G15: =$A$3-F15 -> 41 | K15: =B15 -> 7707840
A16: Konverta Mitra Abadi, PT | B16: 9145290 | C16: 529 | D16: 45593 | E16: 30 | F16: =D16+E16 -> 45623 | G16: =$A$3-F16 -> 34 | J16: =B16 -> 9145290
A17: Konverta Mitra Abadi, PT | B17: 23742900 | C17: 540 | D17: 45597 | E17: 30 | F17: =D17+E17 -> 45627 | G17: =$A$3-F17 -> 30 | I17: =B17 -> 23742900
A18: Konverta Mitra Abadi, PT | B18: 5505600 | C18: 602 | D18: 45621 | E18: 30 | F18: =D18+E18 -> 45651 | G18: =$A$3-F18 -> 6 | I18: =B18 -> 5505600
A19: Konverta Mitra Abadi, PT | B19: =1340325-408848 -> 931477 | C19: 603 | D19: 45621 | E19: 30 | F19: =D19+E19 -> 45651 | G19: =$A$3-F19 -> 6 | I19: =B19 -> 931477
A20: Konverta Mitra Abadi, PT | B20: 8286705 | C20: 605 | D20: 45621 | E20: 30 | F20: =D20+E20 -> 45651 | G20: =$A$3-F20 -> 6 | I20: =B20 -> 8286705
A21: Konverta Mitra Abadi, PT | B21: 10217938 | C21: 606 | D21: 45621 | E21: 30 | F21: =D21+E21 -> 45651 | G21: =$A$3-F21 -> 6 | I21: =B21 -> 10217938
A22: Konverta Mitra Abadi, PT | B22: 16350566 | C22: 607 | D22: 45621 | E22: 30 | F22: =D22+E22 -> 45651 | G22: =$A$3-F22 -> 6 | I22: =B22 -> 16350566
A23: Konverta Mitra Abadi, PT | B23: 6643350 | C23: 608 | D23: 45621 | E23: 30 | F23: =D23+E23 -> 45651 | G23: =$A$3-F23 -> 6 | I23: =B23 -> 6643350
A24: Konverta Mitra Abadi, PT | B24: 8974350 | C24: 609 | D24: 45621 | E24: 30 | F24: =D24+E24 -> 45651 | G24: =$A$3-F24 -> 6 | I24: =B24 -> 8974350
A25: Konverta Mitra Abadi, PT | B25: 8974350 | C25: 610 | D25: 45621 | E25: 30 | F25: =D25+E25 -> 45651 | G25: =$A$3-F25 -> 6 | I25: =B25 -> 8974350
A26: Konverta Mitra Abadi, PT | B26: 3869404 | C26: 611 | D26: 45621 | E26: 30 | F26: =D26+E26 -> 45651 | G26: =$A$3-F26 -> 6 | I26: =B26 -> 3869404
A27: Konverta Mitra Abadi, PT | B27: 8602500 | C27: 616 | D27: 45624 | E27: 30 | F27: =D27+E27 -> 45654 | G27: =$A$3-F27 -> 3 | I27: =B27 -> 8602500
A28: Konverta Mitra Abadi, PT | B28: 6959700 | C28: 620 | D28: 45628 | E28: 30 | F28: =D28+E28 -> 45658 | G28: =$A$3-F28 -> -1 | H28: =B28 -> 6959700
A29: Konverta Mitra Abadi, PT | B29: 23742900 | C29: 654 | D29: 45639 | E29: 30 | F29: =D29+E29 -> 45669 | G29: =$A$3-F29 -> -12 | H29: =B29 -> 23742900
A30: Konverta Mitra Abadi, PT | B30: 7776660 | C30: 655 | D30: 45639 | E30: 30 | F30: =D30+E30 -> 45669 | G30: =$A$3-F30 -> -12 | H30: =B30 -> 7776660
A31: Konverta Mitra Abadi, PT | B31: 2408700 | C31: 656 | D31: 45639 | E31: 30 | F31: =D31+E31 -> 45669 | G31: =$A$3-F31 -> -12 | H31: =B31 -> 2408700
A32: Konverta Mitra Abadi, PT | B32: 2381172 | C32: 658 | D32: 45639 | E32: 30 | F32: =D32+E32 -> 45669 | G32: =$A$3-F32 -> -12 | H32: =B32 -> 2381172
A33: Konverta Mitra Abadi, PT | B33: 2340990 | C33: 659 | D33: 45639 | E33: 30 | F33: =D33+E33 -> 45669 | G33: =$A$3-F33 -> -12 | H33: =B33 -> 2340990
A35: Lima Pendawa, CV | B35: 22200000 | C35: 657 | D35: 45639 | E35: 30 | F35: =D35+E35 -> 45669 | G35: =$A$3-F35 -> -12 | H35: =B35 -> 22200000
A37: Seven Mountain Internasional, PT | B37: 13098000 | C37: 601 | D37: 45621 | E37: 30 | F37: =D37+E37 -> 45651 | G37: =$A$3-F37 -> 6 | I37: =B37 -> 13098000
A38: Seven Mountain Internasional, PT | B38: 16761000 | C38: 664 | D38: 45642 | E38: 30 | F38: =D38+E38 -> 45672 | G38: =$A$3-F38 -> -15 | H38: =B38 -> 16761000
A40: Sinar Setia Mulia , PT | B40: 13470000 | C40: 43 | D40: 45604 | E40: 30 | F40: =D40+E40 -> 45634 | G40: =$A$3-F40 -> 23 | I40: =B40 -> 13470000
A41: Sinar Setia Mulia , PT | B41: 960000 | C41: 44 | D41: 45604 | E41: 30 | F41: =D41+E41 -> 45634 | G41: =$A$3-F41 -> 23 | I41: =B41 -> 960000
A42: Sinar Setia Mulia , PT | B42: 40800000 | C42: 46 | D42: 45611 | E42: 30 | F42: =D42+E42 -> 45641 | G42: =$A$3-F42 -> 16 | I42: =B42 -> 40800000
A44: Sumber Energy, PT | B44: 31635000 | C44: 579 | D44: 45614 | E44: 30 | F44: =D44+E44 -> 45644 | G44: =$A$3-F44 -> 13 | I44: =B44 -> 31635000
A46: Prima Larvae, PT | B46: 25704000 | C46: 575 | D46: 45637 | E46: 30 | F46: =D46+E46 -> 45667 | G46: =$A$3-F46 -> -10 | H46: =B46 -> 25704000
A47: Prima Larvae, PT | B47: 28800000 | C47: 607 | D47: 45656 | E47: 30 | F47: =D47+E47 -> 45686 | G47: =$A$3-F47 -> -29 | H47: =B47 -> 28800000
A49: Sumatra Motor Teknindo, PT | B49: 34791785 | I49: =B49 -> 34791785
A51: International Packaging M, (IPM), PT | B51: 971250 | L51: =B51 -> 971250 | M51: Info Manajemen angka ini sudah sesuai untuk LK 24 (04.02.2025)
...

Sheet Hutang IAS Sept 24
A1: Aging Hutang Usaha & Subsequent
A2: PT Indo American Seafoods
A3: 45565
B4: =SUBTOTAL(9,B6:B107) -> 3.2579243e+09 | H4: =SUBTOTAL(9,H6:H107) -> 2.7836057e+09 | I4: =SUBTOTAL(9,I6:I107) -> 4.332646e+08 | J4: =SUBTOTAL(9,J6:J107) -> 14154286 | K4: =SUBTOTAL(9,K6:K107) -> 8031460 | L4: =SUBTOTAL(9,L6:L107) -> 18868270 | M4: =SUM(H4:L4)-B4 -> 0
A5: Nama | B5: Nominal | C5: No Invoice | D5: Tgl Invoice | E5: Jatuh Tempo | F5: Tgl Jatuh Tempo | G5: Aging | H5: Lancar | I5: 1-30 Hari | J5: 31-60 Hari | K5: 61-90 Hari | L5: >90 Hari
A6: PT Anesta Agung | B6: 2.8762729e+08 | C6: 648 | D6: 45561 | E6: 30 | F6: =D6+E6 -> 45591 | G6: =$A$3-F6 -> -26 | H6: =B6 -> 2.8762729e+08
A8: PT Konverta Mitra Abadi | B8: 1113430 | D8: 45443 | E8: 30 | F8: =D8+E8 -> 45473 | G8: =$A$3-F8 -> 92 | L8: =B8 -> 1113430
A9: PT Konverta Mitra Abadi | B9: 8031460 | C9: 417 | D9: 45448 | E9: 30 | F9: =D9+E9 -> 45478 | G9: =$A$3-F9 -> 87 | K9: =B9 -> 8031460
A10: PT Konverta Mitra Abadi | B10: 3059437 | C10: 484 | D10: 45489 | E10: 30 | F10: =D10+E10 -> 45519 | G10: =$A$3-F10 -> 46 | J10: =B10 -> 3059437
A11: PT Konverta Mitra Abadi | B11: 27872100 | C11: 543 | D11: 45523 | E11: 30 | F11: =D11+E11 -> 45553 | G11: =$A$3-F11 -> 12 | I11: =B11 -> 27872100
A12: PT Konverta Mitra Abadi | B12: 24431100 | C12: 544 | D12: 45523 | E12: 30 | F12: =D12+E12 -> 45553 | G12: =$A$3-F12 -> 12 | I12: =B12 -> 24431100
A13: PT Konverta Mitra Abadi | B13: 16516800 | C13: 551 | D13: 45526 | E13: 30 | F13: =D13+E13 -> 45556 | G13: =$A$3-F13 -> 9 | I13: =B13 -> 16516800
A14: PT Konverta Mitra Abadi | B14: 7914300 | C14: 552 | D14: 45527 | E14: 30 | F14: =D14+E14 -> 45557 | G14: =$A$3-F14 -> 8 | I14: =B14 -> 7914300
A15: PT Konverta Mitra Abadi | B15: 5782045.5 | C15: 555 | D15: 45528 | E15: 30 | F15: =D15+E15 -> 45558 | G15: =$A$3-F15 -> 7 | I15: =B15 -> 5782045.5
A16: PT Konverta Mitra Abadi | B16: 4142320 | C16: 556 | D16: 45528 | E16: 30 | F16: =D16+E16 -> 45558 | G16: =$A$3-F16 -> 7 | I16: =B16 -> 4142320
A17: PT Konverta Mitra Abadi | B17: 3291838 | C17: 557 | D17: 45528 | E17: 30 | F17: =D17+E17 -> 45558 | G17: =$A$3-F17 -> 7 | I17: =B17 -> 3291838
A18: PT Konverta Mitra Abadi | B18: 11507203 | C18: 558 | D18: 45529 | E18: 30 | F18: =D18+E18 -> 45559 | G18: =$A$3-F18 -> 6 | I18: =B18 -> 11507203
A19: PT Konverta Mitra Abadi | B19: 787212 | C19: 559 | D19: 45529 | E19: 30 | F19: =D19+E19 -> 45559 | G19: =$A$3-F19 -> 6 | I19: =B19 -> 787212
A20: PT Konverta Mitra Abadi | B20: 4784377 | C20: 577 | D20: 45533 | E20: 30 | F20: =D20+E20 -> 45563 | G20: =$A$3-F20 -> 2 | I20: =B20 -> 4784377
A21: PT Konverta Mitra Abadi | B21: 39463164 | C21: 580 | D21: 45534 | E21: 30 | F21: =D21+E21 -> 45564 | G21: =$A$3-F21 -> 1 | I21: =B21 -> 39463164
A22: PT Konverta Mitra Abadi | B22: 35519500 | C22: 581 | D22: 45534 | E22: 30 | F22: =D22+E22 -> 45564 | G22: =$A$3-F22 -> 1 | I22: =B22 -> 35519500
A23: PT Konverta Mitra Abadi | B23: 17118975 | C23: 582 | D23: 45534 | E23: 30 | F23: =D23+E23 -> 45564 | G23: =$A$3-F23 -> 1 | I23: =B23 -> 17118975
A24: PT Konverta Mitra Abadi | B24: 3892548 | C24: 587 | D24: 45535 | E24: 30 | F24: =D24+E24 -> 45565 | G24: =$A$3-F24 -> 0 | H24: =B24 -> 3892548
A25: PT Konverta Mitra Abadi | B25: 23605260 | C25: 588 | D25: 45535 | E25: 30 | F25: =D25+E25 -> 45565 | G25: =$A$3-F25 -> 0 | H25: =B25 -> 23605260
A26: PT Konverta Mitra Abadi | B26: 21403020 | C26: 597 | D26: 45540 | E26: 30 | F26: =D26+E26 -> 45570 | G26: =$A$3-F26 -> -5 | H26: =B26 -> 21403020
A27: PT Konverta Mitra Abadi | B27: 2339880 | C27: 609 | D27: 45542 | E27: 30 | F27: =D27+E27 -> 45572 | G27: =$A$3-F27 -> -7 | H27: =B27 -> 2339880
A28: PT Konverta Mitra Abadi | B28: 94076940 | C28: 631 | D28: 45547 | E28: 30 | F28: =D28+E28 -> 45577 | G28: =$A$3-F28 -> -12 | H28: =B28 -> 94076940
A29: PT Konverta Mitra Abadi | B29: 961537 | C29: 632 | D29: 45547 | E29: 30 | F29: =D29+E29 -> 45577 | G29: =$A$3-F29 -> -12 | H29: =B29 -> 961537
A30: PT Konverta Mitra Abadi | B30: 17120473 | C30: 649 | D30: 45551 | E30: 30 | F30: =D30+E30 -> 45581 | G30: =$A$3-F30 -> -16 | H30: =B30 -> 17120473
A31: PT Konverta Mitra Abadi | B31: 11837040 | C31: 655 | D31: 45552 | E31: 30 | F31: =D31+E31 -> 45582 | G31: =$A$3-F31 -> -17 | H31: =B31 -> 11837040
A32: PT Konverta Mitra Abadi | B32: 6905587 | C32: 658 | D32: 45553 | E32: 30 | F32: =D32+E32 -> 45583 | G32: =$A$3-F32 -> -18 | H32: =B32 -> 6905587
A33: PT Konverta Mitra Abadi | B33: 11905860 | C33: 659 | D33: 45553 | E33: 30 | F33: =D33+E33 -> 45583 | G33: =$A$3-F33 -> -18 | H33: =B33 -> 11905860
A34: PT Konverta Mitra Abadi | B34: 39164352 | C34: 660 | D34: 45553 | E34: 30 | F34: =D34+E34 -> 45583 | G34: =$A$3-F34 -> -18 | H34: =B34 -> 39164352
A35: PT Konverta Mitra Abadi | B35: 5292480 | C35: 664 | D35: 45554 | E35: 30 | F35: =D35+E35 -> 45584 | G35: =$A$3-F35 -> -19 | H35: =B35 -> 5292480
... A39: PT Konverta Mitra Abadi | B39: 8031460 | C39: 685 | D39: 45565 | E39: 30 | F39: =D39+E39 -> 45595 | G39: =$A$3-F39 -> -30 | H39: =B39 -> 8031460
A41: PT RBFood Supply Indonesia | B41: 28860000 | C41: 616 | D41: 45514 | E41: 30 | F41: =D41+E41 -> 45544 | G41: =$A$3-F41 -> 21 | I41: =B41 -> 28860000
A42: PT RBFood Supply Indonesia | B42: 28860000 | C42: 527 | D42: 45546 | E42: 30 | F42: =D42+E42 -> 45576 | G42: =$A$3-F42 -> -11 | H42: =B42 -> 28860000
A43: PT RBFood Supply Indonesia | B43: 6660000 | C43: 31 | D43: 45302 | E43: 30 | F43: =D43+E43 -> 45332 | G43: =$A$3-F43 -> 233 | L43: =B43 -> 6660000
A45: PT CJ Cheiljedang Feed Lampung | B45: 79300000 | C45: 2434 | D45: 45548 | E45: 30 | F45: =D45+E45 -> 45578 | G45: =$A$3-F45 -> -13 | H45: =B45 -> 79300000
A46: PT CJ Cheiljedang Feed Lampung | B46: 79325000 | C46: 2435 | D46: 45548 | E46: 30 | F46: =D46+E46 -> 45578 | G46: =$A$3-F46 -> -13 | H46: =B46 -> 79325000
...

Sheet Hutang Usaha ISP Sept 2024
A1: Aging Hutang Usaha & Subsequent
A2: PT Indokom Samudra Persada
A3: 45565
B4: =SUM(B6:B216) -> 7.3871703e+09 | H4: =SUM(H6:H216) -> 4.9834664e+09 | I4: =SUM(I6:I216) -> 1982303832 | J4: =SUM(J6:J216) -> 184180750 | K4: =SUM(K6:K216) -> 82354849 | L4: =SUM(L6:L216) -> 154864460 | M4: =SUM(H4:L4)-B4 -> 0
A5: Nama | B5: Nominal | C5: No Purchase | D5: Tgl Purchase | E5: Jatuh Tempo | F5: Tgl Jatuh Tempo | G5: Aging | H5: Lancar | I5: 1-30 Hari | J5: 31-60 Hari | K5: 61-90 Hari | L5: >90 Hari
A6: Bapak Cipto | B6: 27237008 | E6: 30 | I6: =B6 -> 27237008
A8: Halim Sakti Pratama, PT | B8: 13506480 | C8: 36 | D8: 45553 | E8: 30 | F8: =D8+E8 -> 45583 | G8: =$A$3-F8 -> -18 | H8: =B8 -> 13506480
A10: Intiragam Oliefindo, PT | B10: 24975000 | C10: 397 | D10: 45546 | E10: 30 | F10: =D10+E10 -> 45576 | G10: =$A$3-F10 -> -11 | H10: =B10 -> 24975000
A12: Samara Cipta Solution, CV | B12: 69903226 | C12: 311 | D12: 45514 | E12: 30 | F12: =D12+E12 -> 45544 | G12: =$A$3-F12 -> 21 | I12: =B12 -> 69903226
B13: 32190000 | C13: 438 | D13: 45560 | E13: 30 | F13: =D13+E13 -> 45590 | G13: =$A$3-F13 -> -25 | H13: =B13 -> 32190000
B14: 48037780 | C14: 439 | D14: 45560 | E14: 30 | F14: =D14+E14 -> 45590 | G14: =$A$3-F14 -> -25 | H14: =B14 -> 48037780
A16: Seven Mountain Internasional, PT | B16: 29859000 | C16: 314 | D16: 45516 | E16: 30 | F16: =D16+E16 -> 45546 | G16: =$A$3-F16 -> 19 | I16: =B16 -> 29859000
A18: Sinar Panca Surya, PT | B18: 48888562 | C18: 405 | D18: 45548 | E18: 30 | F18: =D18+E18 -> 45578 | G18: =$A$3-F18 -> -13 | H18: =B18 -> 48888562
B19: 41990190 | C19: 442 | D19: 45561 | E19: 30 | F19: =D19+E19 -> 45591 | G19: =$A$3-F19 -> -26 | H19: =B19 -> 41990190
B20: 42525657 | C20: 447 | D20: 45563 | E20: 30 | F20: =D20+E20 -> 45593 | G20: =$A$3-F20 -> -28 | H20: =B20 -> 42525657
A22: Sinar Setia Mulia , PT | B22: 40800003 | C22: 35 | D22: 45546 | E22: 30 | F22: =D22+E22 -> 45576 | G22: =$A$3-F22 -> -11 | H22: =B22 -> 40800003
A24: Nusantara, Toko | B24: 5025000 | D24: 45292 | E24: 30 | F24: =D24+E24 -> 45322 | G24: =$A$3-F24 -> 243 | L24: =B24 -> 5025000 | M24: apakah perlu di adj ?
A26: Surya Serba Mulia, PT | B26: 70999869 | C26: 411 | D26: 45549 | E26: 30 | F26: =D26+E26 -> 45579 | G26: =$A$3-F26 -> -14 | H26: =B26 -> 70999869
A28: Sumatra Motor Teknindo, PT | B28: 8646900 | C28: 231 | D28: 45477 | E28: 30 | F28: =D28+E28 -> 45507 | G28: =$A$3-F28 -> 58 | J28: =B28 -> 8646900
B29: 301032 | C29: 232 | D29: 45477 | E29: 30 | F29: =D29+E29 -> 45507 | G29: =$A$3-F29 -> 58 | J29: =B29 -> 301032
B30: 357420 | C30: 233 | D30: 45477 | E30: 30 | F30: =D30+E30 -> 45507 | G30: =$A$3-F30 -> 58 | J30: =B30 -> 357420
B31: 619380 | C31: 14 | D31: 45477 | E31: 30 | F31: =D31+E31 -> 45507 | G31: =$A$3-F31 -> 58 | J31: =B31 -> 619380
B32: 2426460 | C32: 327 | D32: 45505 | E32: 30 | F32: =D32+E32 -> 45535 | G32: =$A$3-F32 -> 30 | I32: =B32 -> 2426460
B33: 7856025 | C33: 328 | D33: 45505 | E33: 30 | F33: =D33+E33 -> 45535 | G33: =$A$3-F33 -> 30 | I33: =B33 -> 7856025
B34: =457875-17988 -> 439887 | C34: 331 | D34: 45505 | E34: 30 | F34: =D34+E34 -> 45535 | G34: =$A$3-F34 -> 30 | I34: =B34 -> 439887
B35: 567432 | C35: 306 | D35: 45514 | E35: 30 | F35: =D35+E35 -> 45544 | G35: =$A$3-F35 -> 21 | I35: =B35 -> 567432
B36: 2411475 | C36: 307 | D36: 45514 | E36: 30 | F36: =D36+E36 -> 45544 | G36: =$A$3-F36 -> 21 | I36: =B36 -> 2411475
B37: 510600 | C37: 308 | D37: 45514 | E37: 30 | F37: =D37+E37 -> 45544 | G37: =$A$3-F37 -> 21 | I37: =B37 -> 510600
B38: 222000 | C38: 32 | D38: 45533 | E38: 30 | F38: =D38+E38 -> 45563 | G38: =$A$3-F38 -> 2 | I38: =B38 -> 222000
B39: 366300 | C39: 365 | D39: 45537 | E39: 30 | F39: =D39+E39 -> 45567 | G39: =$A$3-F39 -> -2 | H39: =B39 -> 366300
B40: 3046950 | C40: 366 | D40: 45537 | E40: 30 | F40: =D40+E40 -> 45567 | G40: =$A$3-F40 -> -2 | H40: =B40 -> 3046950
B41: 1198800 | C41: 34 | D41: 45537 | E41: 30 | F41: =D41+E41 -> 45567 | G41: =$A$3-F41 -> -2 | H41: =B41 -> 1198800
B42: 2424240 | C42: 390 | D42: 45536 | E42: 30 | F42: =D42+E42 -> 45566 | G42: =$A$3-F42 -> -1 | H42: =B42 -> 2424240
B43: 3762900 | C43: 391 | D43: 45536 | E43: 30 | F43: =D43+E43 -> 45566 | G43: =$A$3-F43 -> -1 | H43: =B43 -> 3762900
A45: Tri Jaya Sukses | B45: 38500000 | C45: 271 | D45: 45475 | E45: 30 | F45: =D45+E45 -> 45505 | G45: =$A$3-F45 -> 60 | J45: =B45 -> 38500000
B46: 38500000 | C46: 311 | D46: 45500 | E46: 30 | F46: =D46+E46 -> 45530 | G46: =$A$3-F46 -> 35 | J46: =B46 -> 38500000
B47: 26500000 | C47: 365 | D47: 45523 | E47: 30 | F47: =D47+E47 -> 45553 | G47: =$A$3-F47 -> 12 | I47: =B47 -> 26500000
B48: 2537500 | C48: 366 | D48: 45523 | E48: 30 | F48: =D48+E48 -> 45553 | G48: =$A$3-F48 -> 12 | I48: =B48 -> 2537500
A50: General Agromesin Lestari, PT | B50: 58185000 | C50: 416 | D50: 45548 | E50: 30 | F50: =D50+E50 -> 45578 | G50: =$A$3-F50 -> -13 | H50: =B50 -> 58185000
B51: 27153000 | C51: 417 | D51: 45548 | E51: 30 | F51: =D51+E51 -> 45578 | G51: =$A$3-F51 -> -13 | H51: =B51 -> 27153000
...

Sheet Mapping to Report 
C2: UTANG USAHA | I2: TRADE ACCOUNTS PAYABLES
E4: 2024 | G4: 2023
C6: PT Indonesia Makan Udang | E6: 2887775246 | G6: 4451894010 | I6: PT Indonesia Makan Udang
C7: PT CJ Cheiljedang Feed Lampung | E7: 2043145000 | G7: 1115222500 | I7: PT CJ Cheiljedang Feed Lampung
C8: PT Anesta Agung | E8: 892566862 | G8: - | I8: PT Anesta Agung
C9: PT R&B Food Supply Co, Ltd | E9: 739260000 | G9: - | I9: R&B Food Supply Co, Ltd
C10: CV Sion Vannamei Raharja | E10: 648548775 | G10: - | I10: CV Sion Vannamei Raharja
C11: PT Konverta Mitra Abadi | E11: 502709194 | G11: 406242378 | I11: PT Konverta Mitra Abadi
C12: PT Mitra Lestari Mandiri | E12: 483155250 | G12: - | I12: PT Mitra Lestari Mandiri
C13: PT RBFood Manufaktur Indonesia | E13: 306138000 | G13: - | I13: PT RBFood Manufaktur Indonesia
C14: PT Multidaya Teknologi Nusantara | E14: 210906705 | G14: 310906705 | I14: PT Multidaya Teknologi Nusantara
C15: PT Maju Tambak Sumur | E15: 199585239 | G15: 29249998 | I15: PT Maju Tambak Sumur
C16: PT Gemilang Primajaya Trimandiri | E16: 179926294 | G16: 30862329 | I16: PT Gemilang Primajaya Trimandiri
C17: PT Indolabel Surya Pratama | E17: 71230920 | G17: - | I17: PT Indolabel Surya Pratama
C18: PT Sumber Energy | E18: 63270000 | G18: 27000000 | I18: PT Sumber Energy
C19: Suranto | E19: 61090000 | G19: - | I19: Suranto
C20: PT Sinergy Indopack Makmur | E20: 59140800 | G20: 40182000 | I20: PT Sinergy Indopack Makmur
C21: PT Sumberdaya Sinar Baru | E21: 55366010 | G21: 19068210 | I21: PT Sumberdaya Sinar Baru
C22: PT Sinar Setia Mulia | E22: 55230003 | G22: 56950000 | I22: PT Sinar Setia Mulia
C23: PT Mida Trade Ventures Indonesia | E23: 54835465 | G23: - | I23: PT Mida Trade Ventures Indonesia
C24: PT Prima Larvae | E24: 54504000 | G24: - | I24: PT Prima Larvae
C25: PT Sumatra Motor Teknindo | E25: 52438355 | G25: 156386992 | I25: PT Sumatra Motor Teknindo
C26: PT Dinamika Lubsindo Utama | E26: 44379395 | G26: 50335347 | I26: PT Dinamika Lubsindo Utama
C27: CV AGS Sejahtera | E27: 40019800 | G27: - | I27: CV AGS Sejahtera
C28: PT Prima Sari Indotama | E28: 32435303 | G28: 28510258 | I28: PT Prima Sari Indotama
C29: PT Seven Mountain Internasional | E29: 29859000 | G29: 20684850 | I29: PT Seven Mountain Internasional
C30: CV Sri Rejeki | E30: 29399082 | G30: - | I30: CV Sri Rejeki
C31: Nusa Jaya | E31: 25502001 | G31: 47152462 | I31: Nusa Jaya
C32: PT Intiragam Oliefindo | E32: 24975000 | G32: 49950000 | I32: PT Intiragam Oliefindo
C33: CV Lima Pendawa | E33: 22200000 | G33: 44400000 | I33: CV Lima Pendawa
C34: PT Sumatraco Langgeng Abadi | E34: 20535000 | G34: 34965000 | I34: PT Sumatraco Langgeng Abadi
C35: PT International Packaging Manufacturing | E35: 971250 | G35: 669801750 | I35: PT International Packaging Manufacturing
C36: CV Putra Widjaja Marine | E36: - | G36: 5240992985 | I36: CV Putra Widjaja Marine
C37: PT Grahamakmur Ciptapratama | E37: - | G37: 1618149192 | I37: PT Grahamakmur Ciptapratama
C38: Choice Canning Company Inc, | E38: - | G38: 1356603529 | I38: Choice Canning Company Inc,
C39: PT CJ Cheiljedang Feed Lampung | E39: - | G39: 1115222500 | I39: PT CJ Cheiljedang Feed Lampung
C40: Hendro Hariyanto | E40: - | G40: 323468632 | I40: Hendro Hariyanto
C41: Toko Nusantara | E41: - | G41: 310906705 | I41: Nusantara
C42: CV Windu Segara Hatchery | E42: - | G42: 190050000 | I42: CV Windu Segara Hatchery
C43: CV Nerimo Ing Pandum | E43: - | G43: 187956458 | I43: CV Nerimo Ing Pandum
...
